Workbook

Sheet Ingredientes
A1: Detalles de formulación | G1: Proximates | O1: Carbohydrates | AA1: Minerals | AL1: Vitamins and Other Components | CK1: Lipids | EG1: Amino acids
A2: FDC ID | B2: Descripcion | C2: Marca / Origen | D2: Tipo de dato | E2: Cantidad (g) | F2: Cantidad (%) | G2: Water (g) | H2: Energy (kcal) | I2: Energy (kJ) | J2: Nitrogen (g) | K2: Protein (g) | L2: Total lipid (fat) (g) | M2: Total fat (NLEA) (g) | N2: Ash (g) | O2: Carbohydrate, by difference (g) | P2: Carbohydrate, by summation (g) | Q2: Fiber, total dietary (g) | R2: Sugars, Total (g) | S2: Sucrose (g) | T2: Glucose (g) | U2: Fructose (g) | V2: Lactose (g) | W2: Maltose (g) | X2: Starch (g) | Y2: Total Sugars (g) | Z2: Galactose (g) | AA2: Calcium, Ca (mg) | AB2: Iron, Fe (mg) | AC2: Magnesium, Mg (mg) | AD2: Phosphorus, P (mg) | AE2: Potassium, K (mg) | AF2: Sodium, Na (mg) | AG2: Zinc, Zn (mg) | AH2: Copper, Cu (mg) | AI2: Manganese, Mn (mg) | AJ2: Iodine, I (µg) | AK2: Selenium, Se (µg) | AL2: Thiamin (mg) | AM2: Riboflavin (mg) | AN2: Niacin (mg) | AO2: Vitamin B-6 (mg) | AP2: Folate, total (µg) | AQ2: Choline, total (mg) | AR2: Choline, free (mg) | AS2: Choline, from phosphocholine (mg) | AT2: Choline, from phosphotidyl choline (mg) | AU2: Choline, from glycerophosphocholine (mg) | AV2: Choline, from sphingomyelin (mg) | AW2: Betaine (mg) | AX2: Vitamin B-12 (µg) | AY2: Vitamin A, RAE (µg) | AZ2: Retinol (µg) | BA2: Carotene, beta (µg) | BB2: cis-beta-Carotene (µg) | BC2: trans-beta-Carotene (µg) | BD2: Carotene, alpha (µg) | BE2: Cryptoxanthin, beta (µg) | BF2: Cryptoxanthin, alpha (µg) | BG2: Lycopene (µg) | BH2: cis-Lycopene (µg) | BI2: trans-Lycopene (µg) | BJ2: cis-Lutein/Zeaxanthin (µg) | BK2: Lutein (µg) | BL2: Zeaxanthin (µg) | BM2: Vitamin D (D2 + D3), International Units (IU) | BN2: Vitamin D (D2 + D3) (µg) | BO2: Vitamin D2 (ergocalciferol) (µg) | BP2: Vitamin D3 (cholecalciferol) (µg) | BQ2: 25-hydroxycholecalciferol (µg) | BR2: Vitamin C, total ascorbic acid (mg) | BS2: Pantothenic acid (mg) | BT2: Folic acid (µg) | BU2: Folate, food (µg) | BV2: Folate, DFE (µg) | BW2: Vitamin B-12, added (µg) | BX2: Vitamin A, IU (IU) | BY2: Lutein + zeaxanthin (µg) | BZ2: Vitamin E (alpha-tocopherol) (mg) | CA2: Vitamin E, added (mg) | CB2: Vitamin K (phylloquinone) (µg) | CC2: Tocopherol, beta (mg) | CD2: Tocopherol, gamma (mg) | CE2: Tocopherol, delta (mg) | CF2: Tocotrienol, alpha (mg) | CG2: Tocotrienol, beta (mg) | CH2: Tocotrienol, gamma (mg) | CI2: Tocotrienol, delta (mg) | CJ2: Vitamin K (Dihydrophylloquinone) (µg) | CK2: Fatty acids, total saturated (g) | CL2: SFA 14:0 (g) | CM2: SFA 16:0 (g) | CN2: SFA 18:0 (g) | CO2: Fatty acids, total monounsaturated (g) | CP2: MUFA 16:1 c (g) | CQ2: MUFA 18:1 c (g) | CR2: Fatty acids, total polyunsaturated (g) | CS2: PUFA 18:2 c (g) | CT2: PUFA 18:2 n-6 c,c (g) | CU2: PUFA 18:3 c (g) | CV2: PUFA 18:3 n-6 c,c,c (g) | CW2: PUFA 20:3 c (g) | CX2: PUFA 20:3 n-6 (g) | CY2: Cholesterol (mg) | CZ2: SFA 4:0 (g) | DA2: SFA 6:0 (g) | DB2: SFA 8:0 (g) | DC2: SFA 10:0 (g) | DD2: SFA 12:0 (g) | DE2: MUFA 16:1 (g) | DF2: MUFA 18:1 (g) | DG2: MUFA 20:1 (g) | DH2: MUFA 22:1 (g) | DI2: PUFA 18:2 (g) | DJ2: PUFA 18:3 (g) | DK2: PUFA 18:4 (g) | DL2: PUFA 20:4 (g) | DM2: PUFA 20:5 n-3 (EPA) (g) | DN2: PUFA 22:5 n-3 (DPA) (g) | DO2: PUFA 22:6 n-3 (DHA) (g) | DP2: Fatty acids, total trans (g) | DQ2: SFA 13:0 (g) | DR2: SFA 15:0 (g) | DS2: SFA 17:0 (g) | DT2: SFA 20:0 (g) | DU2: SFA 22:0 (g) | DV2: SFA 24:0 (g) | DW2: MUFA 14:1 (g) | DX2: MUFA 15:1 (g) | DY2: MUFA 17:1 (g) | DZ2: MUFA 24:1 c (g) | EA2: PUFA 18:3 n-3 c,c,c (ALA) (g) | EB2: PUFA 20:2 n-6 c,c (g) | EC2: PUFA 20:3 (g) | ED2: Fatty acids, total trans-monoenoic (g) | EE2: TFA 18:1 t (g) | EF2: Phytosterols (mg) | EG2: Tryptophan (g) | EH2: Threonine (g) | EI2: Isoleucine (g) | EJ2: Leucine (g) | EK2: Lysine (g) | EL2: Methionine (g) | EM2: Phenylalanine (g) | EN2: Tyrosine (g) | EO2: Valine (g) | EP2: Arginine (g) | EQ2: Histidine (g) | ER2: Alanine (g) | ES2: Aspartic acid (g) | ET2: Glutamic acid (g) | EU2: Glycine (g) | EV2: Proline (g) | EW2: Serine (g) | EX2: Hydroxyproline (g) | EY2: Cysteine (g) | EZ2: Alcohol, ethyl (g) | FA2: Caffeine (mg) | FB2: Theobromine (mg) | FC2: Cystine (g)
A3: 748967 | B3: Eggs, Grade A, Large, egg whole | D3: Foundation | E3: 100 | F3: =E3/SUM($E$3:$E$5) | G3: 75.8 | H3: 148 | I3: 617 | J3: 1.99 | K3: 12.4 | L3: 9.96 | M3: 8.65 | N3: 0.85 | O3: 0.96 | P3: 0.2 | Q3: 0 | R3: 0.2 | S3: 0 | T3: 0.2 | U3: 0 | V3: 0 | W3: 0 | X3: 0 | AA3: 48 | AB3: 1.67 | AC3: 11.4 | AD3: 184 | AE3: 132 | AF3: 129 | AG3: 1.24 | AH3: 0 | AI3: 0 | AJ3: 49.1 | AK3: 31.1 | AL3: 0.077 | AM3: 0.419 | AN3: 0 | AO3: 0.063 | AP3: 71 | AQ3: 335 | AR3: 0.6 | AS3: 309 | AT3: 0.2 | AU3: 0.2 | AV3: 25.1 | AW3: 0.3 | AX3: 1.02 | AY3: 180 | AZ3: 179 | BA3: 0 | BB3: 0 | BC3: 0 | BD3: 0 | BE3: 13 | BF3: 13 | BG3: 0 | BH3: 0 | BI3: 0 | BJ3: 57 | BK3: 230 | BL3: 229 | BM3: 98.4 | BN3: 2.46 | BO3: 0 | BP3: 2.46 | BQ3: 0.56 | CK3: 3.2 | CL3: 0.032 | CM3: 2.32 | CN3: 0.813 | CO3: 3.63 | CP3: 0.238 | CQ3: 3.35 | CR3: 1.82 | CS3: 1.46 | CT3: 1.46 | CU3: 0.011 | CV3: 0.011 | CW3: 0.02 | CX3: 0.02 | CY3: 411 | EG3: 0.166 | EH3: 0.594 | EI3: 0.616 | EJ3: 1.05 | EK3: 0.832 | EL3: 0.418 | EM3: 0.66 | EN3: 0.512 | EO3: 0.734 | EP3: 0.787 | EQ3: 0.283 | ER3: 0.667 | ES3: 1.27 | ET3: 1.63 | EU3: 0.408 | EV3: 0.56 | EW3: 0.919 | EX3: 0 | EY3: 0.385
A4: 174158 | B4: Water, bottled, generic | D4: SR Legacy | E4: 150 | F4: =E4/SUM($E$3:$E$5) | G4: 99.98 | H4: 0 | I4: 0 | K4: 0 | L4: 0 | N4: 0.07 | O4: 0 | Q4: 0 | Y4: 0 | AA4: 10 | AB4: 0 | AC4: 2 | AD4: 0 | AE4: 0 | AF4: 2 | AG4: 0 | AH4: 0.007 | AK4: 0 | AL4: 0 | AM4: 0 | AN4: 0 | AO4: 0 | AP4: 0 | AQ4: 0 | AX4: 0 | AY4: 0 | AZ4: 0 | BA4: 0 | BD4: 0 | BE4: 0 | BG4: 0 | BM4: 0 | BN4: 0 | BR4: 0 | BS4: 0 | BT4: 0 | BU4: 0 | BV4: 0 | BW4: 0 | BX4: 0 | BY4: 0 | BZ4: 0 | CA4: 0 | CB4: 0 | CK4: 0 | CL4: 0 | CM4: 0 | CN4: 0 | CO4: 0 | CR4: 0 | CY4: 0 | CZ4: 0 | DA4: 0 | DB4: 0 | DC4: 0 | DD4: 0 | DE4: 0 | DF4: 0 | DG4: 0 | DH4: 0 | DI4: 0 | DJ4: 0 | DK4: 0 | DL4: 0 | DM4: 0 | DN4: 0 | DO4: 0 | DP4: 0 | EZ4: 0 | FA4: 0 | FB4: 0
A5: 171320 | B5: Spices, cinnamon, ground | D5: SR Legacy | E5: 50 | F5: =E5/SUM($E$3:$E$5) | G5: 10.58 | H5: 247 | I5: 1035 | K5: 3.99 | L5: 1.24 | N5: 3.6 | O5: 80.59 | Q5: 53.1 | S5: 0.02 | T5: 1.04 | U5: 1.11 | V5: 0 | W5: 0 | Y5: 2.17 | Z5: 0 | AA5: 1002 | AB5: 8.32 | AC5: 60 | AD5: 64 | AE5: 431 | AF5: 10 | AG5: 1.83 | AH5: 0.339 | AI5: 17.466 | AK5: 3.1 | AL5: 0.022 | AM5: 0.041 | AN5: 1.332 | AO5: 0.158 | AP5: 6 | AQ5: 11 | AW5: 3.9 | AX5: 0 | AY5: 15 | AZ5: 0 | BA5: 112 | BD5: 1 | BE5: 129 | BG5: 15 | BM5: 0 | BN5: 0 | BR5: 3.8 | BS5: 0.358 | BT5: 0 | BU5: 6 | BV5: 6 | BW5: 0 | BX5: 295 | BY5: 222 | BZ5: 2.32 | CA5: 0 | CB5: 31.2 | CC5: 0 | CD5: 10.44 | CE5: 0.26 | CF5: 0 | CG5: 0 | CH5: 0 | CI5: 0 | CJ5: 0 | CK5: 0.345 | CL5: 0.009 | CM5: 0.104 | CN5: 0.082 | CO5: 0.246 | CQ5: 0.246 | CR5: 0.068 | CV5: 0 | CY5: 0 | CZ5: 0 | DA5: 0 | DB5: 0 | DC5: 0.003 | DD5: 0.006 | DE5: 0.001 | DF5: 0.246 | DG5: 0 | DH5: 0 | DI5: 0.044 | DJ5: 0.011 | DK5: 0 | DL5: 0 | DM5: 0 | DN5: 0 | DO5: 0 | DP5: 0 | DQ5: 0 | DR5: 0 | DS5: 0.136 | DT5: 0 | DU5: 0 | DV5: 0 | DW5: 0 | DX5: 0 | DY5: 0 | DZ5: 0 | EA5: 0.011 | EB5: 0 | EC5: 0 | ED5: 0 | EE5: 0 | EF5: 26 | EG5: 0.049 | EH5: 0.136 | EI5: 0.146 | EJ5: 0.253 | EK5: 0.243 | EL5: 0.078 | EM5: 0.146 | EN5: 0.136 | EO5: 0.224 | EP5: 0.166 | EQ5: 0.117 | ER5: 0.166 | ES5: 0.438 | ET5: 0.37 | EU5: 0.195 | EV5: 0.419 | EW5: 0.195 | EX5: 0 | EZ5: 0 | FA5: 0 | FB5: 0 | FC5: 0.058
A6: Total | B6: Formulado | C6: Formulado | D6: Formulado | E6: =SUBTOTAL(9,E3:E5) | F6: 100% | G6: =SUMPRODUCT($F$3:$F$5,$G$3:$G$5) | H6: =SUMPRODUCT($F$3:$F$5,$H$3:$H$5) | I6: =SUMPRODUCT($F$3:$F$5,$I$3:$I$5) | J6: =SUMPRODUCT($F$3:$F$5,$J$3:$J$5) | K6: =SUMPRODUCT($F$3:$F$5,$K$3:$K$5) | L6: =SUMPRODUCT($F$3:$F$5,$L$3:$L$5) | M6: =SUMPRODUCT($F$3:$F$5,$M$3:$M$5) | N6: =SUMPRODUCT($F$3:$F$5,$N$3:$N$5) | O6: =SUMPRODUCT($F$3:$F$5,$O$3:$O$5) | P6: =SUMPRODUCT($F$3:$F$5,$P$3:$P$5) | Q6: =SUMPRODUCT($F$3:$F$5,$Q$3:$Q$5) | R6: =SUMPRODUCT($F$3:$F$5,$R$3:$R$5) | S6: =SUMPRODUCT($F$3:$F$5,$S$3:$S$5) | T6: =SUMPRODUCT($F$3:$F$5,$T$3:$T$5) | U6: =SUMPRODUCT($F$3:$F$5,$U$3:$U$5) | V6: =SUMPRODUCT($F$3:$F$5,$V$3:$V$5) | W6: =SUMPRODUCT($F$3:$F$5,$W$3:$W$5) | X6: =SUMPRODUCT($F$3:$F$5,$X$3:$X$5) | Y6: =SUMPRODUCT($F$3:$F$5,$Y$3:$Y$5) | Z6: =SUMPRODUCT($F$3:$F$5,$Z$3:$Z$5) | AA6: =SUMPRODUCT($F$3:$F$5,$AA$3:$AA$5) | AB6: =SUMPRODUCT($F$3:$F$5,$AB$3:$AB$5) | AC6: =SUMPRODUCT($F$3:$F$5,$AC$3:$AC$5) | AD6: =SUMPRODUCT($F$3:$F$5,$AD$3:$AD$5) | AE6: =SUMPRODUCT($F$3:$F$5,$AE$3:$AE$5) | AF6: =SUMPRODUCT($F$3:$F$5,$AF$3:$AF$5) | AG6: =SUMPRODUCT($F$3:$F$5,$AG$3:$AG$5) | AH6: =SUMPRODUCT($F$3:$F$5,$AH$3:$AH$5) | AI6: =SUMPRODUCT($F$3:$F$5,$AI$3:$AI$5) | AJ6: =SUMPRODUCT($F$3:$F$5,$AJ$3:$AJ$5) | AK6: =SUMPRODUCT($F$3:$F$5,$AK$3:$AK$5) | AL6: =SUMPRODUCT($F$3:$F$5,$AL$3:$AL$5) | AM6: =SUMPRODUCT($F$3:$F$5,$AM$3:$AM$5) | AN6: =SUMPRODUCT($F$3:$F$5,$AN$3:$AN$5) | AO6: =SUMPRODUCT($F$3:$F$5,$AO$3:$AO$5) | AP6: =SUMPRODUCT($F$3:$F$5,$AP$3:$AP$5) | AQ6: =SUMPRODUCT($F$3:$F$5,$AQ$3:$AQ$5) | AR6: =SUMPRODUCT($F$3:$F$5,$AR$3:$AR$5) | AS6: =SUMPRODUCT($F$3:$F$5,$AS$3:$AS$5) | AT6: =SUMPRODUCT($F$3:$F$5,$AT$3:$AT$5) | AU6: =SUMPRODUCT($F$3:$F$5,$AU$3:$AU$5) | AV6: =SUMPRODUCT($F$3:$F$5,$AV$3:$AV$5) | AW6: =SUMPRODUCT($F$3:$F$5,$AW$3:$AW$5) | AX6: =SUMPRODUCT($F$3:$F$5,$AX$3:$AX$5) | AY6: =SUMPRODUCT($F$3:$F$5,$AY$3:$AY$5) | AZ6: =SUMPRODUCT($F$3:$F$5,$AZ$3:$AZ$5) | BA6: =SUMPRODUCT($F$3:$F$5,$BA$3:$BA$5) | BB6: =SUMPRODUCT($F$3:$F$5,$BB$3:$BB$5) | BC6: =SUMPRODUCT($F$3:$F$5,$BC$3:$BC$5) | BD6: =SUMPRODUCT($F$3:$F$5,$BD$3:$BD$5) | BE6: =SUMPRODUCT($F$3:$F$5,$BE$3:$BE$5) | BF6: =SUMPRODUCT($F$3:$F$5,$BF$3:$BF$5) | BG6: =SUMPRODUCT($F$3:$F$5,$BG$3:$BG$5) | BH6: =SUMPRODUCT($F$3:$F$5,$BH$3:$BH$5) | BI6: =SUMPRODUCT($F$3:$F$5,$BI$3:$BI$5) | BJ6: =SUMPRODUCT($F$3:$F$5,$BJ$3:$BJ$5) | BK6: =SUMPRODUCT($F$3:$F$5,$BK$3:$BK$5) | BL6: =SUMPRODUCT($F$3:$F$5,$BL$3:$BL$5) | BM6: =SUMPRODUCT($F$3:$F$5,$BM$3:$BM$5) | BN6: =SUMPRODUCT($F$3:$F$5,$BN$3:$BN$5) | BO6: =SUMPRODUCT($F$3:$F$5,$BO$3:$BO$5) | BP6: =SUMPRODUCT($F$3:$F$5,$BP$3:$BP$5) | BQ6: =SUMPRODUCT($F$3:$F$5,$BQ$3:$BQ$5) | BR6: =SUMPRODUCT($F$3:$F$5,$BR$3:$BR$5) | BS6: =SUMPRODUCT($F$3:$F$5,$BS$3:$BS$5) | BT6: =SUMPRODUCT($F$3:$F$5,$BT$3:$BT$5) | BU6: =SUMPRODUCT($F$3:$F$5,$BU$3:$BU$5) | BV6: =SUMPRODUCT($F$3:$F$5,$BV$3:$BV$5) | BW6: =SUMPRODUCT($F$3:$F$5,$BW$3:$BW$5) | BX6: =SUMPRODUCT($F$3:$F$5,$BX$3:$BX$5) | BY6: =SUMPRODUCT($F$3:$F$5,$BY$3:$BY$5) | BZ6: =SUMPRODUCT($F$3:$F$5,$BZ$3:$BZ$5) | CA6: =SUMPRODUCT($F$3:$F$5,$CA$3:$CA$5) | CB6: =SUMPRODUCT($F$3:$F$5,$CB$3:$CB$5) | CC6: =SUMPRODUCT($F$3:$F$5,$CC$3:$CC$5) | CD6: =SUMPRODUCT($F$3:$F$5,$CD$3:$CD$5) | CE6: =SUMPRODUCT($F$3:$F$5,$CE$3:$CE$5) | CF6: =SUMPRODUCT($F$3:$F$5,$CF$3:$CF$5) | CG6: =SUMPRODUCT($F$3:$F$5,$CG$3:$CG$5) | CH6: =SUMPRODUCT($F$3:$F$5,$CH$3:$CH$5) | CI6: =SUMPRODUCT($F$3:$F$5,$CI$3:$CI$5) | CJ6: =SUMPRODUCT($F$3:$F$5,$CJ$3:$CJ$5) | CK6: =SUMPRODUCT($F$3:$F$5,$CK$3:$CK$5) | CL6: =SUMPRODUCT($F$3:$F$5,$CL$3:$CL$5) | CM6: =SUMPRODUCT($F$3:$F$5,$CM$3:$CM$5) | CN6: =SUMPRODUCT($F$3:$F$5,$CN$3:$CN$5) | CO6: =SUMPRODUCT($F$3:$F$5,$CO$3:$CO$5) | CP6: =SUMPRODUCT($F$3:$F$5,$CP$3:$CP$5) | CQ6: =SUMPRODUCT($F$3:$F$5,$CQ$3:$CQ$5) | CR6: =SUMPRODUCT($F$3:$F$5,$CR$3:$CR$5) | CS6: =SUMPRODUCT($F$3:$F$5,$CS$3:$CS$5) | CT6: =SUMPRODUCT($F$3:$F$5,$CT$3:$CT$5) | CU6: =SUMPRODUCT($F$3:$F$5,$CU$3:$CU$5) | CV6: =SUMPRODUCT($F$3:$F$5,$CV$3:$CV$5) | CW6: =SUMPRODUCT($F$3:$F$5,$CW$3:$CW$5) | CX6: =SUMPRODUCT($F$3:$F$5,$CX$3:$CX$5) | CY6: =SUMPRODUCT($F$3:$F$5,$CY$3:$CY$5) | CZ6: =SUMPRODUCT($F$3:$F$5,$CZ$3:$CZ$5) | DA6: =SUMPRODUCT($F$3:$F$5,$DA$3:$DA$5) | DB6: =SUMPRODUCT($F$3:$F$5,$DB$3:$DB$5) | DC6: =SUMPRODUCT($F$3:$F$5,$DC$3:$DC$5) | DD6: =SUMPRODUCT($F$3:$F$5,$DD$3:$DD$5) | DE6: =SUMPRODUCT($F$3:$F$5,$DE$3:$DE$5) | DF6: =SUMPRODUCT($F$3:$F$5,$DF$3:$DF$5) | DG6: =SUMPRODUCT($F$3:$F$5,$DG$3:$DG$5) | DH6: =SUMPRODUCT($F$3:$F$5,$DH$3:$DH$5) | DI6: =SUMPRODUCT($F$3:$F$5,$DI$3:$DI$5) | DJ6: =SUMPRODUCT($F$3:$F$5,$DJ$3:$DJ$5) | DK6: =SUMPRODUCT($F$3:$F$5,$DK$3:$DK$5) | DL6: =SUMPRODUCT($F$3:$F$5,$DL$3:$DL$5) | DM6: =SUMPRODUCT($F$3:$F$5,$DM$3:$DM$5) | DN6: =SUMPRODUCT($F$3:$F$5,$DN$3:$DN$5) | DO6: =SUMPRODUCT($F$3:$F$5,$DO$3:$DO$5) | DP6: =SUMPRODUCT($F$3:$F$5,$DP$3:$DP$5) | DQ6: =SUMPRODUCT($F$3:$F$5,$DQ$3:$DQ$5) | DR6: =SUMPRODUCT($F$3:$F$5,$DR$3:$DR$5) | DS6: =SUMPRODUCT($F$3:$F$5,$DS$3:$DS$5) | DT6: =SUMPRODUCT($F$3:$F$5,$DT$3:$DT$5) | DU6: =SUMPRODUCT($F$3:$F$5,$DU$3:$DU$5) | DV6: =SUMPRODUCT($F$3:$F$5,$DV$3:$DV$5) | DW6: =SUMPRODUCT($F$3:$F$5,$DW$3:$DW$5) | DX6: =SUMPRODUCT($F$3:$F$5,$DX$3:$DX$5) | DY6: =SUMPRODUCT($F$3:$F$5,$DY$3:$DY$5) | DZ6: =SUMPRODUCT($F$3:$F$5,$DZ$3:$DZ$5) | EA6: =SUMPRODUCT($F$3:$F$5,$EA$3:$EA$5) | EB6: =SUMPRODUCT($F$3:$F$5,$EB$3:$EB$5) | EC6: =SUMPRODUCT($F$3:$F$5,$EC$3:$EC$5) | ED6: =SUMPRODUCT($F$3:$F$5,$ED$3:$ED$5) | EE6: =SUMPRODUCT($F$3:$F$5,$EE$3:$EE$5) | EF6: =SUMPRODUCT($F$3:$F$5,$EF$3:$EF$5) | EG6: =SUMPRODUCT($F$3:$F$5,$EG$3:$EG$5) | EH6: =SUMPRODUCT($F$3:$F$5,$EH$3:$EH$5) | EI6: =SUMPRODUCT($F$3:$F$5,$EI$3:$EI$5) | EJ6: =SUMPRODUCT($F$3:$F$5,$EJ$3:$EJ$5) | EK6: =SUMPRODUCT($F$3:$F$5,$EK$3:$EK$5) | EL6: =SUMPRODUCT($F$3:$F$5,$EL$3:$EL$5) | EM6: =SUMPRODUCT($F$3:$F$5,$EM$3:$EM$5) | EN6: =SUMPRODUCT($F$3:$F$5,$EN$3:$EN$5) | EO6: =SUMPRODUCT($F$3:$F$5,$EO$3:$EO$5) | EP6: =SUMPRODUCT($F$3:$F$5,$EP$3:$EP$5) | EQ6: =SUMPRODUCT($F$3:$F$5,$EQ$3:$EQ$5) | ER6: =SUMPRODUCT($F$3:$F$5,$ER$3:$ER$5) | ES6: =SUMPRODUCT($F$3:$F$5,$ES$3:$ES$5) | ET6: =SUMPRODUCT($F$3:$F$5,$ET$3:$ET$5) | EU6: =SUMPRODUCT($F$3:$F$5,$EU$3:$EU$5) | EV6: =SUMPRODUCT($F$3:$F$5,$EV$3:$EV$5) | EW6: =SUMPRODUCT($F$3:$F$5,$EW$3:$EW$5) | EX6: =SUMPRODUCT($F$3:$F$5,$EX$3:$EX$5) | EY6: =SUMPRODUCT($F$3:$F$5,$EY$3:$EY$5) | EZ6: =SUMPRODUCT($F$3:$F$5,$EZ$3:$EZ$5) | FA6: =SUMPRODUCT($F$3:$F$5,$FA$3:$FA$5) | FB6: =SUMPRODUCT($F$3:$F$5,$FB$3:$FB$5) | FC6: =SUMPRODUCT($F$3:$F$5,$FC$3:$FC$5)

Sheet Totales
A1: Nutriente | B1: Total | C1: Unidad
A2: Water | B2: =Ingredientes!G6 | C2: g
A3: Energy | B3: =Ingredientes!H6 | C3: kcal
A4: Energy | B4: =Ingredientes!I6 | C4: kJ
A5: Nitrogen | B5: =Ingredientes!J6 | C5: g
A6: Protein | B6: =Ingredientes!K6 | C6: g
A7: Total lipid (fat) | B7: =Ingredientes!L6 | C7: g
A8: Total fat (NLEA) | B8: =Ingredientes!M6 | C8: g
A9: Ash | B9: =Ingredientes!N6 | C9: g
A10: Carbohydrate, by difference | B10: =Ingredientes!O6 | C10: g
A11: Carbohydrate, by summation | B11: =Ingredientes!P6 | C11: g
A12: Fiber, total dietary | B12: =Ingredientes!Q6 | C12: g
A13: Sugars, Total | B13: =Ingredientes!R6 | C13: g
A14: Sucrose | B14: =Ingredientes!S6 | C14: g
A15: Glucose | B15: =Ingredientes!T6 | C15: g
A16: Fructose | B16: =Ingredientes!U6 | C16: g
A17: Lactose | B17: =Ingredientes!V6 | C17: g
A18: Maltose | B18: =Ingredientes!W6 | C18: g
A19: Starch | B19: =Ingredientes!X6 | C19: g
A20: Total Sugars | B20: =Ingredientes!Y6 | C20: g
A21: Galactose | B21: =Ingredientes!Z6 | C21: g
A22: Calcium, Ca | B22: =Ingredientes!AA6 | C22: mg
A23: Iron, Fe | B23: =Ingredientes!AB6 | C23: mg
A24: Magnesium, Mg | B24: =Ingredientes!AC6 | C24: mg
A25: Phosphorus, P | B25: =Ingredientes!AD6 | C25: mg
A26: Potassium, K | B26: =Ingredientes!AE6 | C26: mg
A27: Sodium, Na | B27: =Ingredientes!AF6 | C27: mg
A28: Zinc, Zn | B28: =Ingredientes!AG6 | C28: mg
A29: Copper, Cu | B29: =Ingredientes!AH6 | C29: mg
A30: Manganese, Mn | B30: =Ingredientes!AI6 | C30: mg
A31: Iodine, I | B31: =Ingredientes!AJ6 | C31: µg
A32: Selenium, Se | B32: =Ingredientes!AK6 | C32: µg
A33: Thiamin | B33: =Ingredientes!AL6 | C33: mg
A34: Riboflavin | B34: =Ingredientes!AM6 | C34: mg
A35: Niacin | B35: =Ingredientes!AN6 | C35: mg
A36: Vitamin B-6 | B36: =Ingredientes!AO6 | C36: mg
A37: Folate, total | B37: =Ingredientes!AP6 | C37: µg
A38: Choline, total | B38: =Ingredientes!AQ6 | C38: mg
A39: Choline, free | B39: =Ingredientes!AR6 | C39: mg
A40: Choline, from phosphocholine | B40: =Ingredientes!AS6 | C40: mg
...
