Workbook

Sheet Ingredientes
A1: Detalles de formulación | G1: Proximates | O1: Carbohydrates | AE1: Minerals | AS1: Vitamins and Other Components | CU1: Lipids | FZ1: Amino acids | GW1: Vitamin A | GY1: Phytosterols | HG1: Organic acids | HK1: Oligosaccharides | HN1: Isoflavones
A2: FDC ID | B2: Ingrediente | C2: Marca / Origen | D2: Tipo de dato | E2: Cantidad (g) | F2: Cantidad (%) | G2: Water (g) | H2: Energy (kcal) | I2: Energy (kJ) | J2: Nitrogen (g) | K2: Protein (g) | L2: Total fat (NLEA) (g) | M2: Total lipid (fat) (g) | N2: Ash (g) | O2: Carbohydrate, by difference (g) | P2: Fiber, total dietary (g) | Q2: Fiber, soluble (g) | R2: Fiber, insoluble (g) | S2: Total dietary fiber (AOAC 2011.25) (g) | T2: High Molecular Weight Dietary Fiber (HMWDF) (g) | U2: Low Molecular Weight Dietary Fiber (LMWDF) (g) | V2: Sugars, Total (g) | W2: Sucrose (g) | X2: Glucose (g) | Y2: Fructose (g) | Z2: Lactose (g) | AA2: Maltose (g) | AB2: Galactose (g) | AC2: Starch (g) | AD2: Resistant starch (g) | AE2: Sugars, added (g) | AF2: Calcium, Ca (mg) | AG2: Iron, Fe (mg) | AH2: Magnesium, Mg (mg) | AI2: Phosphorus, P (mg) | AJ2: Potassium, K (mg) | AK2: Sodium, Na (mg) | AL2: Zinc, Zn (mg) | AM2: Copper, Cu (mg) | AN2: Manganese, Mn (mg) | AO2: Iodine, I (µg) | AP2: Selenium, Se (µg) | AQ2: Fluoride, F (µg) | AR2: Molybdenum, Mo (µg) | AS2: Vitamin C, total ascorbic acid (mg) | AT2: Thiamin (mg) | AU2: Riboflavin (mg) | AV2: Niacin (mg) | AW2: Pantothenic acid (mg) | AX2: Vitamin B-6 (mg) | AY2: Biotin (µg) | AZ2: Folate, total (µg) | BA2: Folic acid (µg) | BB2: Folate, food (µg) | BC2: Folate, DFE (µg) | BD2: Choline, total (mg) | BE2: Choline, free (mg) | BF2: Choline, from phosphocholine (mg) | BG2: Choline, from phosphotidyl choline (mg) | BH2: Choline, from glycerophosphocholine (mg) | BI2: Choline, from sphingomyelin (mg) | BJ2: Betaine (mg) | BK2: Vitamin B-12 (µg) | BL2: Vitamin B-12, added (µg) | BM2: Vitamin A, RAE (µg) | BN2: Retinol (µg) | BO2: Carotene, beta (µg) | BP2: cis-beta-Carotene (µg) | BQ2: trans-beta-Carotene (µg) | BR2: Carotene, alpha (µg) | BS2: Carotene, gamma (µg) | BT2: Cryptoxanthin, beta (µg) | BU2: Cryptoxanthin, alpha (µg) | BV2: Vitamin A, IU (iu) | BW2: Lycopene (µg) | BX2: cis-Lycopene (µg) | BY2: trans-Lycopene (µg) | BZ2: Lutein + zeaxanthin (µg) | CA2: cis-Lutein/Zeaxanthin (µg) | CB2: Lutein (µg) | CC2: Zeaxanthin (µg) | CD2: Phytoene (µg) | CE2: Phytofluene (µg) | CF2: Vitamin E (alpha-tocopherol) (mg) | CG2: Vitamin E, added (mg) | CH2: Tocopherol, beta (mg) | CI2: Tocopherol, gamma (mg) | CJ2: Tocopherol, delta (mg) | CK2: Tocotrienol, alpha (mg) | CL2: Tocotrienol, beta (mg) | CM2: Tocotrienol, gamma (mg) | CN2: Tocotrienol, delta (mg) | CO2: Vitamin D (D2 + D3), International Units (iu) | CP2: Vitamin D (D2 + D3) (µg) | CQ2: Vitamin D2 (ergocalciferol) (µg) | CR2: Vitamin D3 (cholecalciferol) (µg) | CS2: 25-hydroxycholecalciferol (µg) | CT2: Vitamin K (phylloquinone) (µg) | CU2: Fatty acids, total saturated (g) | CV2: SFA 4:0 (g) | CW2: SFA 5:0 (g) | CX2: SFA 6:0 (g) | CY2: SFA 7:0 (g) | CZ2: SFA 8:0 (g) | DA2: SFA 9:0 (g) | DB2: SFA 10:0 (g) | DC2: SFA 11:0 (g) | DD2: SFA 12:0 (g) | DE2: SFA 13:0 (g) | DF2: SFA 14:0 (g) | DG2: SFA 15:0 (g) | DH2: SFA 16:0 (g) | DI2: SFA 17:0 (g) | DJ2: SFA 18:0 (g) | DK2: SFA 20:0 (g) | DL2: SFA 21:0 (g) | DM2: SFA 22:0 (g) | DN2: SFA 23:0 (g) | DO2: SFA 24:0 (g) | DP2: Fatty acids, total monounsaturated (g) | DQ2: MUFA 12:1 (g) | DR2: MUFA 14:1 (g) | DS2: MUFA 14:1 c (g) | DT2: MUFA 15:1 (g) | DU2: MUFA 16:1 (g) | DV2: MUFA 16:1 c (g) | DW2: MUFA 17:1 (g) | DX2: MUFA 17:1 c (g) | DY2: MUFA 18:1 (g) | DZ2: MUFA 18:1 c (g) | EA2: MUFA 20:1 (g) | EB2: MUFA 20:1 c (g) | EC2: MUFA 22:1 (g) | ED2: MUFA 22:1 c (g) | EE2: MUFA 22:1 n-9 (g) | EF2: MUFA 22:1 n-11 (g) | EG2: MUFA 24:1 c (g) | EH2: Fatty acids, total polyunsaturated (g) | EI2: PUFA 18:2 (g) | EJ2: PUFA 18:2 c (g) | EK2: PUFA 18:2 n-6 c,c (g) | EL2: PUFA 18:2 CLAs (g) | EM2: PUFA 18:2 i (g) | EN2: PUFA 18:3 (g) | EO2: PUFA 18:3 c (g) | EP2: PUFA 18:3 n-3 c,c,c (ALA) (g) | EQ2: PUFA 18:3 n-6 c,c,c (g) | ER2: PUFA 18:4 (g) | ES2: PUFA 20:2 c (g) | ET2: PUFA 20:2 n-6 c,c (g) | EU2: PUFA 20:3 (g) | EV2: PUFA 20:3 c (g) | EW2: PUFA 20:3 n-3 (g) | EX2: PUFA 20:3 n-6 (g) | EY2: PUFA 20:3 n-9 (g) | EZ2: PUFA 22:3 (g) | FA2: PUFA 20:4 (g) | FB2: PUFA 20:4c (g) | FC2: PUFA 20:5c (g) | FD2: PUFA 20:5 n-3 (EPA) (g) | FE2: PUFA 22:2 (g) | FF2: PUFA 22:5 c (g) | FG2: PUFA 22:4 (g) | FH2: PUFA 22:5 n-3 (DPA) (g) | FI2: PUFA 22:6 c (g) | FJ2: PUFA 22:6 n-3 (DHA) (g) | FK2: Fatty acids, total trans (g) | FL2: Fatty acids, total trans-monoenoic (g) | FM2: TFA 14:1 t (g) | FN2: TFA 16:1 t (g) | FO2: TFA 18:1 t (g) | FP2: TFA 20:1 t (g) | FQ2: TFA 22:1 t (g) | FR2: Fatty acids, total trans-dienoic (g) | FS2: TFA 18:2 t not further defined (g) | FT2: TFA 18:2 t (g) | FU2: TFA 18:2 t,t (g) | FV2: Fatty acids, total trans-polyenoic (g) | FW2: TFA 18:3 t (g) | FX2: Cholesterol (mg) | FY2: Phytosterols (mg) | FZ2: Tryptophan (g) | GA2: Threonine (g) | GB2: Isoleucine (g) | GC2: Leucine (g) | GD2: Lysine (g) | GE2: Methionine (g) | GF2: Cystine (g) | GG2: Phenylalanine (g) | GH2: Tyrosine (g) | GI2: Valine (g) | GJ2: Arginine (g) | GK2: Histidine (g) | GL2: Alanine (g) | GM2: Aspartic acid (g) | GN2: Glutamic acid (g) | GO2: Glycine (g) | GP2: Proline (g) | GQ2: Serine (g) | GR2: Hydroxyproline (g) | GS2: Cysteine (g) | GT2: Alcohol, ethyl (g) | GU2: Caffeine (mg) | GV2: Theobromine (mg) | GW2: Vitamin K (Dihydrophylloquinone) (µg) | GX2: Vitamin K (Menaquinone-4) (µg) | GY2: Stigmasterol (mg) | GZ2: Campesterol (mg) | HA2: Brassicasterol (mg) | HB2: Beta-sitosterol (mg) | HC2: Campestanol (mg) | HD2: Beta-sitostanol (mg) | HE2: Delta-5-avenasterol (mg) | HF2: Phytosterols, other (mg) | HG2: Citric acid (mg) | HH2: Malic acid (mg) | HI2: Oxalic acid (mg) | HJ2: Quinic acid (mg) | HK2: Raffinose (g) | HL2: Stachyose (g) | HM2: Verbascose (g) | HN2: Daidzein (mg) | HO2: Genistein (mg) | HP2: Daidzin (mg) | HQ2: Genistin (mg) | HR2: Glycitin (mg)
A3: 167755 | B3: Raspberries, raw | D3: SR Legacy | E3: 100 | F3: =E3/SUM($E$3:$E$82) -> 0.013025803 | G3: 85.75 | H3: 58.41 | I3: 244.38744 | K3: 1.2 | L3: 0.65 | M3: 0.65 | N3: 0.46 | O3: 11.94 | P3: 6.5 | V3: 4.42 | W3: 0.2 | X3: 1.86 | Y3: 2.35 | Z3: 0 | AA3: 0 | AB3: 0 | AC3: 0 | AF3: 25 | AG3: 0.69 | AH3: 22 | AI3: 29 | AJ3: 151 | AK3: 1 | AL3: 0.42 | AM3: 0.09 | AN3: 0.67 | AP3: 0.2 | AS3: 26.2 | AT3: 0.032 | AU3: 0.038 | AV3: 0.598 | AW3: 0.329 | AX3: 0.055 | AZ3: 21 | BA3: 0 | BB3: 21 | BC3: 21 | BD3: 12.3 | BJ3: 0.8 | BK3: 0 | BL3: 0 | BM3: 2 | BN3: 0 | BO3: 12 | BR3: 16 | BT3: 0 | BV3: 33 | BW3: 0 | BZ3: 136 | CF3: 0.87 | CG3: 0 | CH3: 0.06 | CI3: 1.42 | CJ3: 1.04 | CK3: 0 | CL3: 0 | CM3: 0 | CN3: 0 | CO3: 0 | CP3: 0 | CT3: 7.8 | CU3: 0.019 | CV3: 0 | CX3: 0 | CZ3: 0 | DB3: 0 | DD3: 0 | DF3: 0 | DH3: 0.016 | DJ3: 0.004 | DP3: 0.064 | DU3: 0 | DY3: 0.059 | EA3: 0.005 | EC3: 0 | EH3: 0.375 | EI3: 0.249 | EN3: 0.126 | ER3: 0 | FA3: 0 | FD3: 0 | FH3: 0 | FJ3: 0 | FK3: 0 | FX3: 0 | GT3: 0 | GU3: 0 | GV3: 0 | GW3: 0
A4: 168113 | B4: Frozen novelties, juice type, orange | D4: SR Legacy | E4: 100 | F4: =E4/SUM($E$3:$E$82) -> 0.013025803 | G4: 76.1 | H4: 94.68 | I4: 396.14112 | K4: 0.5 | L4: 0 | M4: 0 | N4: 0.23 | O4: 23.17 | P4: 0.1 | V4: 19.99 | AF4: 9 | AG4: 0.47 | AH4: 8 | AI4: 13 | AJ4: 100 | AK4: 8 | AL4: 0.02 | AM4: 0.022 | AN4: 0.008 | AP4: 0.1 | AQ4: 77 | AS4: 25.7 | AT4: 0.01 | AU4: 0.03 | AV4: 0.16 | AW4: 0.065 | AX4: 0.018 | AZ4: 18 | BA4: 0 | BB4: 18 | BC4: 18 | BD4: 2.9 | BK4: 0 | BL4: 0 | BM4: 1 | BN4: 0 | BO4: 12 | BR4: 0 | BT4: 0 | BV4: 21 | BW4: 0 | BZ4: 39 | CF4: 0.04 | CG4: 0 | CO4: 0 | CP4: 0 | CT4: 0.1 | CU4: 0 | CV4: 0 | CX4: 0 | CZ4: 0 | DB4: 0 | DD4: 0 | DF4: 0 | DH4: 0 | DJ4: 0 | DP4: 0 | DU4: 0 | DY4: 0 | EA4: 0 | EC4: 0 | EH4: 0 | EI4: 0 | EN4: 0 | ER4: 0 | FA4: 0 | FD4: 0 | FH4: 0 | FJ4: 0 | FX4: 0 | GT4: 0 | GU4: 0 | GV4: 0
A5: 168191 | B5: Dates, medjool | D5: SR Legacy | E5: 100 | F5: =E5/SUM($E$3:$E$82) -> 0.013025803 | G5: 21.32 | H5: 308.47 | I5: 1290.6385 | K5: 1.81 | L5: 0.15 | M5: 0.15 | N5: 1.74 | O5: 74.97 | P5: 6.7 | V5: 66.47 | W5: 0.53 | X5: 33.68 | Y5: 31.95 | Z5: 0 | AA5: 0.3 | AB5: 0 | AF5: 64 | AG5: 0.9 | AH5: 54 | AI5: 62 | AJ5: 696 | AK5: 1 | AL5: 0.44 | AM5: 0.362 | AN5: 0.296 | AS5: 0 | AT5: 0.05 | AU5: 0.06 | AV5: 1.61 | AW5: 0.805 | AX5: 0.249 | AZ5: 15 | BA5: 0 | BB5: 15 | BC5: 15 | BD5: 9.9 | BJ5: 0.4 | BM5: 7 | BO5: 89 | BR5: 0 | BT5: 0 | BV5: 149 | BW5: 0 | BZ5: 23 | CO5: 0 | CP5: 0 | CT5: 2.7 | FK5: 0 | FZ5: 0.007 | GA5: 0.042 | GB5: 0.045 | GC5: 0.082 | GD5: 0.054 | GE5: 0.017 | GF5: 0.046 | GG5: 0.048 | GH5: 0.016 | GI5: 0.066 | GJ5: 0.06 | GK5: 0.029 | GL5: 0.078 | GM5: 0.22 | GN5: 0.265 | GO5: 0.09 | GP5: 0.111 | GQ5: 0.062 | GW5: 0
A6: 168482 | B6: Sweet potato, raw, unprepared (Includes foods for USDA's Food Distribution Program) | D6: SR Legacy | E6: 100 | F6: =E6/SUM($E$3:$E$82) -> 0.013025803 | G6: 77.28 | H6: 87.21 | I6: 364.88664 | K6: 1.57 | L6: 0.05 | M6: 0.05 | N6: 0.99 | O6: 20.12 | P6: 3 | V6: 4.18 | W6: 2.52 | X6: 0.96 | Y6: 0.7 | Z6: 0 | AA6: 0 | AB6: 0 | AC6: 12.65 | AF6: 30 | AG6: 0.61 | AH6: 25 | AI6: 47 | AJ6: 337 | AK6: 55 | AL6: 0.3 | AM6: 0.151 | AN6: 0.258 | AP6: 0.6 | AS6: 2.4 | AT6: 0.078 | AU6: 0.061 | AV6: 0.557 | AW6: 0.8 | AX6: 0.209 | AZ6: 11 | BA6: 0 | BB6: 11 | BC6: 11 | BD6: 12.3 | BK6: 0 | BL6: 0 | BM6: 709 | BN6: 0 | BO6: 8509 | BR6: 7 | BT6: 0 | BV6: 14187 | BW6: 0 | BZ6: 0 | CF6: 0.26 | CG6: 0 | CH6: 0.01 | CI6: 0 | CJ6: 0 | CK6: 0.01 | CL6: 0 | CM6: 0 | CN6: 0 | CO6: 0 | CP6: 0 | CT6: 1.8 | CU6: 0.018 | CV6: 0 | CX6: 0 | CZ6: 0 | DB6: 0 | DD6: 0 | DF6: 0 | DG6: 0 | DH6: 0.018 | DI6: 0 | DJ6: 0.001 | DK6: 0 | DM6: 0 | DO6: 0 | DP6: 0.001 | DR6: 0 | DT6: 0 | DU6: 0 | DW6: 0 | DY6: 0.001 | EA6: 0 | EC6: 0 | EH6: 0.014 | EI6: 0.013 | EN6: 0.001 | ER6: 0 | ET6: 0 | EU6: 0 | FA6: 0 | FD6: 0 | FH6: 0 | FJ6: 0 | FK6: 0 | FX6: 0 | FY6: 12 | FZ6: 0.031 | GA6: 0.083 | GB6: 0.055 | GC6: 0.092 | GD6: 0.066 | GE6: 0.029 | GF6: 0.022 | GG6: 0.089 | GH6: 0.034 | GI6: 0.086 | GJ6: 0.055 | GK6: 0.031 | GL6: 0.077 | GM6: 0.382 | GN6: 0.155 | GO6: 0.063 | GP6: 0.052 | GQ6: 0.088 | GT6: 0 | GU6: 0 | GV6: 0 | GW6: 0
A7: 168483 | B7: Sweet potato, cooked, baked in skin, flesh, without salt | D7: SR Legacy | E7: 100 | F7: =E7/SUM($E$3:$E$82) -> 0.013025803 | G7: 75.78 | H7: 92.23 | I7: 385.89032 | K7: 2.01 | L7: 0.15 | M7: 0.15 | N7: 1.35 | O7: 20.71 | P7: 3.3 | V7: 6.48 | W7: 2.28 | X7: 0.57 | Y7: 0.5 | Z7: 0 | AA7: 3.12 | AB7: 0 | AC7: 7.05 | AF7: 38 | AG7: 0.69 | AH7: 27 | AI7: 54 | AJ7: 475 | AK7: 36 | AL7: 0.32 | AM7: 0.161 | AN7: 0.497 | AP7: 0.2 | AS7: 19.6 | AT7: 0.107 | AU7: 0.106 | AV7: 1.487 | AW7: 0.884 | AX7: 0.286 | AZ7: 6 | BA7: 0 | BB7: 6 | BC7: 6 | BD7: 13.1 | BJ7: 34.6 | BK7: 0 | BL7: 0 | BM7: 961 | BN7: 0 | BO7: 11509 | BR7: 43 | BT7: 0 | BV7: 19218 | BW7: 0 | BZ7: 0 | CF7: 0.71 | CG7: 0 | CH7: 0 | CI7: 0.01 | CJ7: 0 | CK7: 0.02 | CL7: 0 | CM7: 0 | CN7: 0 | CO7: 0 | CP7: 0 | CT7: 2.3 | CU7: 0.052 | CV7: 0 | CX7: 0 | CZ7: 0 | DB7: 0 | DD7: 0 | DF7: 0 | DG7: 0 | DH7: 0.05 | DI7: 0 | DJ7: 0.002 | DK7: 0 | DM7: 0 | DO7: 0 | DP7: 0.002 | DR7: 0 | DT7: 0 | DU7: 0 | DW7: 0 | DY7: 0.002 | EA7: 0 | EC7: 0 | EH7: 0.092 | EI7: 0.09 | EN7: 0.006 | ER7: 0 | ET7: 0 | EU7: 0 | FA7: 0 | FD7: 0 | FH7: 0 | FJ7: 0 | FK7: 0 | FX7: 0 | FZ7: 0.04 | GA7: 0.107 | GB7: 0.07 | GC7: 0.118 | GD7: 0.084 | GE7: 0.037 | GF7: 0.028 | GG7: 0.114 | GH7: 0.044 | GI7: 0.11 | GJ7: 0.07 | GK7: 0.039 | GL7: 0.099 | GM7: 0.488 | GN7: 0.198 | GO7: 0.081 | GP7: 0.067 | GQ7: 0.113 | GT7: 0 | GU7: 0 | GV7: 0 | GW7: 0
A8: 168746 | B8: Alcoholic beverage, beer, regular, all | D8: SR Legacy | E8: 100 | F8: =E8/SUM($E$3:$E$82) -> 0.013025803 | G8: 91.96 | H8: 16.04 | I8: 67.11136 | K8: 0.46 | L8: 0 | M8: 0 | N8: 0.16 | O8: 3.55 | P8: 0 | V8: 0 | W8: 0 | X8: 0 | Y8: 0 | Z8: 0 | AA8: 0 | AB8: 0 | AC8: 0 | AF8: 4 | AG8: 0.02 | AH8: 6 | AI8: 14 | AJ8: 27 | AK8: 4 | AL8: 0.01 | AM8: 0.005 | AN8: 0.008 | AP8: 0.6 | AQ8: 44.2 | AS8: 0 | AT8: 0.005 | AU8: 0.025 | AV8: 0.513 | AW8: 0.041 | AX8: 0.046 | AZ8: 6 | BA8: 0 | BB8: 6 | BC8: 6 | BD8: 10.1 | BK8: 0.02 | BL8: 0 | BM8: 0 | BN8: 0 | BO8: 0 | BR8: 0 | BT8: 0 | BV8: 0 | BW8: 0 | BZ8: 0 | CF8: 0 | CG8: 0 | CH8: 0 | CI8: 0 | CJ8: 0 | CO8: 0 | CP8: 0 | CT8: 0 | CU8: 0 | CV8: 0 | CX8: 0 | CZ8: 0 | DB8: 0 | DD8: 0 | DF8: 0 | DH8: 0 | DJ8: 0 | DP8: 0 | DU8: 0 | DY8: 0 | EA8: 0 | EC8: 0 | EH8: 0 | EI8: 0 | EN8: 0 | ER8: 0 | FA8: 0 | FD8: 0 | FH8: 0 | FJ8: 0 | FK8: 0 | FX8: 0 | FZ8: 0 | GA8: 0 | GB8: 0 | GC8: 0 | GD8: 0 | GE8: 0 | GF8: 0 | GG8: 0 | GH8: 0 | GI8: 0 | GJ8: 0 | GK8: 0 | GL8: 0.012 | GM8: 0.016 | GN8: 0.047 | GO8: 0.013 | GP8: 0.035 | GQ8: 0 | GT8: 3.9 | GU8: 0 | GV8: 0 | GW8: 0
A9: 169102 | B9: Orange juice, frozen concentrate, unsweetened, diluted with 3 volume water | D9: SR Legacy | E9: 100 | F9: =E9/SUM($E$3:$E$82) -> 0.013025803 | G9: 90.07 | H9: 38.14 | I9: 159.57776 | K9: 0.6 | L9: 0.06 | M9: 0.06 | N9: 0.47 | O9: 8.8 | P9: 0.2 | V9: 7.42 | AF9: 12 | AG9: 0.08 | AH9: 10 | AI9: 15 | AJ9: 158 | AK9: 4 | AL9: 0.04 | AM9: 0.021 | AP9: 0.1 | AS9: 36.2 | AT9: 0.069 | AU9: 0.044 | AV9: 0.273 | AX9: 0.065 | AZ9: 19 | BA9: 0 | BB9: 19 | BC9: 19 | BD9: 5 | BK9: 0 | BL9: 0 | BM9: 3 | BN9: 0 | BO9: 13 | BR9: 5 | BT9: 48 | BV9: 66 | BW9: 0 | BZ9: 83 | CF9: 0.15 | CG9: 0 | CO9: 0 | CP9: 0 | CT9: 0.1 | CU9: 0.015 | CV9: 0 | CX9: 0 | CZ9: 0 | DB9: 0 | DD9: 0.001 | DF9: 0.001 | DH9: 0.011 | DJ9: 0.002 | DP9: 0.012 | DU9: 0.002 | DY9: 0.011 | EA9: 0 | EC9: 0 | EH9: 0.016 | EI9: 0.012 | EN9: 0.004 | ER9: 0 | FA9: 0 | FD9: 0 | FH9: 0 | FJ9: 0 | FK9: 0 | FX9: 0 | GT9: 0 | GU9: 0 | GV9: 0
A10: 169707 | B10: Rice, white, long-grain, parboiled, enriched, dry | D10: SR Legacy | E10: 100 | F10: =E10/SUM($E$3:$E$82) -> 0.013025803 | G10: 9.86 | H10: 362.87 | I10: 1518.2481 | K10: 7.51 | L10: 1.03 | M10: 1.03 | N10: 0.71 | O10: 80.89 | P10: 1.8 | V10: 0.33 | W10: 0.21 | X10: 0.11 | Y10: 0.02 | Z10: 0 | AA10: 0 | AB10: 0 | AC10: 68.29 | AF10: 71 | AG10: 3.33 | AH10: 27 | AI10: 153 | AJ10: 174 | AK10: 2 | AL10: 1.02 | AM10: 0.284 | AN10: 1.035 | AP10: 19.9 | AS10: 0 | AT10: 0.603 | AU10: 0.05 | AV10: 5.048 | AW10: 0.672 | AX10: 0.452 | AZ10: 257 | BA10: 249 | BB10: 8 | BC10: 431 | BD10: 6 | BK10: 0 | BL10: 0 | BM10: 0 | BN10: 0 | BO10: 0 | BR10: 0 | BT10: 0 | BV10: 0 | BW10: 0 | BZ10: 0 | CF10: 0.03 | CG10: 0 | CH10: 0.02 | CI10: 0.17 | CJ10: 0 | CK10: 0.05 | CL10: 0 | CM10: 0 | CN10: 0 | CO10: 0 | CP10: 0 | CT10: 0.1 | CU10: 0.294 | CV10: 0 | CX10: 0 | CZ10: 0 | DB10: 0 | DD10: 0 | DF10: 0 | DG10: 0 | DH10: 0.277 | DI10: 0 | DJ10: 0.017 | DK10: 0 | DM10: 0 | DO10: 0 | DP10: 0.258 | DR10: 0 | DU10: 0 | DY10: 0.258 | EA10: 0 | EC10: 0 | EH10: 0.322 | EI10: 0.305 | EN10: 0.017 | ER10: 0 | FA10: 0 | FD10: 0 | FH10: 0 | FJ10: 0 | FX10: 0 | FZ10: 0.103 | GA10: 0.271 | GB10: 0.339 | GC10: 0.656 | GD10: 0.215 | GE10: 0.183 | GF10: 0.153 | GG10: 0.398 | GH10: 0.216 | GI10: 0.47 | GJ10: 0.651 | GK10: 0.185 | GL10: 0.433 | GM10: 0.795 | GN10: 1.395 | GO10: 0.358 | GP10: 0.484 | GQ10: 0.366 | GT10: 0 | GU10: 0 | GV10: 0
A11: 169758 | B11: Rice, white, long-grain, parboiled, unenriched, dry | D11: SR Legacy | E11: 100 | F11: =E11/SUM($E$3:$E$82) -> 0.013025803 | G11: 9.86 | H11: 362.87 | I11: 1518.2481 | K11: 7.51 | L11: 1.03 | M11: 1.03 | N11: 0.71 | O11: 80.89 | P11: 1.8 | V11: 0.33 | W11: 0.21 | X11: 0.11 | Y11: 0.02 | Z11: 0 | AA11: 0 | AB11: 0 | AC11: 68.29 | AF11: 71 | AG11: 0.74 | AH11: 27 | AI11: 153 | AJ11: 174 | AK11: 2 | AL11: 1.02 | AM11: 0.284 | AN11: 1.035 | AP11: 19.9 | AS11: 0 | AT11: 0.224 | AU11: 0.05 | AV11: 5.048 | AW11: 0.672 | AX11: 0.452 | AZ11: 8 | BA11: 0 | BB11: 8 | BC11: 8 | BK11: 0 | BL11: 0 | BN11: 0 | BV11: 0 | CF11: 0.03 | CG11: 0 | CH11: 0.02 | CI11: 0.17 | CJ11: 0 | CK11: 0.05 | CL11: 0 | CM11: 0 | CN11: 0 | CO11: 0 | CP11: 0 | CT11: 0.1 | CU11: 0.294 | CV11: 0 | CX11: 0 | CZ11: 0 | DB11: 0 | DD11: 0 | DF11: 0 | DG11: 0 | DH11: 0.277 | DI11: 0 | DJ11: 0.017 | DK11: 0 | DM11: 0 | DO11: 0 | DP11: 0.258 | DR11: 0 | DU11: 0 | DY11: 0.258 | EA11: 0 | EC11: 0 | EH11: 0.322 | EI11: 0.305 | EN11: 0.017 | ER11: 0 | FA11: 0 | FD11: 0 | FH11: 0 | FJ11: 0 | FX11: 0 | FZ11: 0.103 | GA11: 0.271 | GB11: 0.339 | GC11: 0.656 | GD11: 0.215 | GE11: 0.183 | GF11: 0.153 | GG11: 0.398 | GH11: 0.216 | GI11: 0.47 | GJ11: 0.651 | GK11: 0.185 | GL11: 0.433 | GM11: 0.795 | GN11: 1.395 | GO11: 0.358 | GP11: 0.484 | GQ11: 0.366 | GT11: 0
A12: 169802 | B12: Cloudberries, raw (Alaska Native) | D12: SR Legacy | E12: 100 | F12: =E12/SUM($E$3:$E$82) -> 0.013025803 | G12: 87 | H12: 51.2 | I12: 214.2208 | K12: 2.4 | L12: 0.8 | M12: 0.8 | N12: 1.2 | O12: 8.6 | AF12: 18 | AG12: 0.7 | AI12: 35 | AS12: 158 | AT12: 0.05 | AU12: 0.07 | AV12: 0.9 | BV12: 210
A13: 169913 | B13: Mulberries, raw | D13: SR Legacy | E13: 100 | F13: =E13/SUM($E$3:$E$82) -> 0.013025803 | G13: 87.68 | H13: 48.47 | I13: 202.79848 | K13: 1.44 | L13: 0.39 | M13: 0.39 | N13: 0.69 | O13: 9.8 | P13: 1.7 | V13: 8.1 | AF13: 39 | AG13: 1.85 | AH13: 18 | AI13: 38 | AJ13: 194 | AK13: 10 | AL13: 0.12 | AM13: 0.06 | AP13: 0.6 | AS13: 36.4 | AT13: 0.029 | AU13: 0.101 | AV13: 0.62 | AX13: 0.05 | AZ13: 6 | BA13: 0 | BB13: 6 | BC13: 6 | BD13: 12.3 | BK13: 0 | BL13: 0 | BM13: 1 | BN13: 0 | BO13: 9 | BR13: 12 | BT13: 0 | BV13: 25 | BW13: 0 | BZ13: 136 | CF13: 0.87 | CG13: 0 | CO13: 0 | CP13: 0 | CT13: 7.8 | CU13: 0.027 | CV13: 0 | CX13: 0 | CZ13: 0 | DB13: 0 | DD13: 0 | DF13: 0 | DH13: 0.006 | DJ13: 0.02 | DP13: 0.041 | DU13: 0 | DY13: 0.041 | EA13: 0 | EC13: 0 | EH13: 0.207 | EI13: 0.206 | EN13: 0.001 | ER13: 0 | FA13: 0 | FD13: 0 | FH13: 0 | FJ13: 0 | FK13: 0 | FX13: 0 | GT13: 0 | GU13: 0 | GV13: 0
A14: 169967 | B14: Broccoli, cooked, boiled, drained, without salt | D14: SR Legacy | E14: 100 | F14: =E14/SUM($E$3:$E$82) -> 0.013025803 | G14: 89.25 | H14: 41.93 | I14: 175.43512 | K14: 2.38 | L14: 0.41 | M14: 0.41 | N14: 0.77 | O14: 7.18 | P14: 3.3 | V14: 1.39 | W14: 0.08 | X14: 0.49 | Y14: 0.74 | Z14: 0 | AA14: 0 | AB14: 0 | AC14: 0 | AF14: 40 | AG14: 0.67 | AH14: 21 | AI14: 67 | AJ14: 293 | AK14: 41 | AL14: 0.45 | AM14: 0.061 | AN14: 0.194 | AP14: 1.6 | AQ14: 4 | AS14: 64.9 | AT14: 0.063 | AU14: 0.123 | AV14: 0.553 | AW14: 0.616 | AX14: 0.2 | AZ14: 108 | BA14: 0 | BB14: 108 | BC14: 108 | BD14: 40.1 | BJ14: 0.1 | BK14: 0 | BL14: 0 | BM14: 77 | BN14: 0 | BO14: 929 | BR14: 0 | BT14: 0 | BV14: 1548 | BW14: 0 | BZ14: 1080 | CF14: 1.45 | CG14: 0 | CH14: 0.01 | CI14: 0.25 | CJ14: 0 | CK14: 0 | CL14: 0 | CM14: 0 | CN14: 0 | CO14: 0 | CP14: 0 | CT14: 141.1 | CU14: 0.079 | CV14: 0 | CX14: 0 | CZ14: 0 | DB14: 0 | DD14: 0.002 | DF14: 0 | DG14: 0 | DH14: 0.056 | DI14: 0 | DJ14: 0.013 | DK14: 0.004 | DM14: 0.005 | DP14: 0.04 | DR14: 0 | DT14: 0 | DU14: 0.009 | DW14: 0.002 | DY14: 0.029 | EA14: 0 | EC14: 0 | EH14: 0.17 | EI14: 0.051 | EN14: 0.119 | EQ14: 0 | ER14: 0 | ET14: 0 | EU14: 0 | FA14: 0 | FD14: 0 | FH14: 0 | FJ14: 0 | FK14: 0 | FX14: 0 | FZ14: 0.034 | GA14: 0.096 | GB14: 0.092 | GC14: 0.147 | GD14: 0.155 | GE14: 0.043 | GF14: 0.031 | GG14: 0.116 | GH14: 0.06 | GI14: 0.138 | GJ14: 0.2 | GK14: 0.063 | GL14: 0.114 | GM14: 0.329 | GN14: 0.549 | GO14: 0.101 | GP14: 0.111 | GQ14: 0.129 | GT14: 0 | GU14: 0 | GV14: 0 | GW14: 0
A15: 169969 | B15: Broccoli, frozen, chopped, cooked, boiled, drained, without salt | D15: SR Legacy | E15: 100 | F15: =E15/SUM($E$3:$E$82) -> 0.013025803 | G15: 90.72 | H15: 34.88 | I15: 145.93792 | K15: 3.1 | L15: 0.12 | M15: 0.12 | N15: 0.71 | O15: 5.35 | P15: 3 | V15: 1.47 | AF15: 33 | AG15: 0.61 | AH15: 13 | AI15: 49 | AJ15: 142 | AK15: 11 | AL15: 0.28 | AM15: 0.034 | AN15: 0.223 | AP15: 0.7 | AS15: 40.1 | AT15: 0.055 | AU15: 0.081 | AV15: 0.458 | AW15: 0.274 | AX15: 0.13 | AZ15: 56 | BA15: 0 | BB15: 56 | BC15: 56 | BD15: 16.2 | BK15: 0 | BL15: 0 | BM15: 51 | BN15: 0 | BO15: 597 | BR15: 19 | BT15: 1 | BV15: 1011 | BW15: 0 | BZ15: 1095 | CF15: 1.32 | CG15: 0 | CO15: 0 | CP15: 0 | CT15: 88.1 | CU15: 0.018 | CV15: 0 | CX15: 0 | CZ15: 0 | DB15: 0 | DD15: 0 | DF15: 0 | DH15: 0.016 | DJ15: 0.002 | DP15: 0.008 | DU15: 0 | DY15: 0.008 | EA15: 0 | EC15: 0 | EH15: 0.055 | EI15: 0.013 | EN15: 0.042 | ER15: 0 | FA15: 0 | FD15: 0 | FH15: 0 | FJ15: 0 | FK15: 0 | FX15: 0 | FZ15: 0.032 | GA15: 0.101 | GB15: 0.121 | GC15: 0.145 | GD15: 0.156 | GE15: 0.037 | GF15: 0.022 | GG15: 0.094 | GH15: 0.07 | GI15: 0.142 | GJ15: 0.161 | GK15: 0.055 | GL15: 0.13 | GM15: 0.236 | GN15: 0.417 | GO15: 0.105 | GP15: 0.127 | GQ15: 0.111 | GT15: 0 | GU15: 0 | GV15: 0
A16: 170330 | B16: BURGER KING, Premium Fish Sandwich | D16: SR Legacy | E16: 100 | F16: =E16/SUM($E$3:$E$82) -> 0.013025803 | G16: 48.44 | H16: 259.97 | I16: 1087.7145 | K16: 10.29 | L16: 12.45 | M16: 12.45 | N16: 2.13 | O16: 26.69 | P16: 0.9 | V16: 3.53 | W16: 0 | X16: 1.2 | Y16: 1.47 | Z16: 0 | AA16: 0.87 | AB16: 0 | AF16: 37 | AG16: 1.5 | AH16: 25 | AI16: 116 | AJ16: 206 | AK16: 602 | AL16: 0.49 | AM16: 0.075 | AN16: 0.264 | AP16: 24.3 | AS16: 0.2 | AT16: 0.197 | AU16: 0.18 | AV16: 2.09 | AW16: 0.17 | AX16: 0.036 | CT16: 22.5 | CU16: 1.949 | CV16: 0.001 | CX16: 0 | CZ16: 0.002 | DB16: 0.004 | DD16: 0.001 | DF16: 0.022 | DG16: 0.003 | DH16: 1.435 | DI16: 0.012 | DJ16: 0.389 | DK16: 0.037 | DM16: 0.029 | DO16: 0.015 | DP16: 2.595 | DR16: 0 | DT16: 0 | DU16: 0.028 | DV16: 0.028 | DW16: 0.006 | DY16: 2.498 | DZ16: 2.471 | EA16: 0.055 | EC16: 0.004 | ED16: 0.004 | EG16: 0.003 | EH16: 6.257 | EI16: 5.627 | EK16: 5.561 | EL16: 0.013 | EN16: 0.512 | EP16: 0.489 | EQ16: 0.023 | ER16: 0.002 | ET16: 0.005 | EU16: 0.003 | EW16: 0.001 | EX16: 0.002 | FA16: 0.008 | FD16: 0.029 | FG16: 0.004 | FH16: 0.003 | FJ16: 0.064 | FK16: 0.08 | FL16: 0.028 | FN16: 0 | FO16: 0.027 | FQ16: 0 | FS16: 0.053 | FV16: 0.053 | FX16: 31 | FZ16: 0.081 | GA16: 0.356 | GB16: 0.386 | GC16: 0.803 | GD16: 0.661 | GE16: 0.234 | GF16: 0.153 | GG16: 0.478 | GH16: 0.336 | GI16: 0.458 | GJ16: 0.488 | GK16: 0.213 | GL16: 0.376 | GM16: 0.712 | GN16: 2.471 | GO16: 0.407 | GP16: 0.712 | GQ16: 0.488 | GR16: 0 | GW16: 9.1
A17: 170331 | B17: BURGER KING, Original Chicken Sandwich | D17: SR Legacy | E17: 100 | F17: =E17/SUM($E$3:$E$82) -> 0.013025803 | G17: 44.7 | H17: 285.65 | I17: 1195.1596 | K17: 12.14 | L17: 14.69 | M17: 14.69 | N17: 2.25 | O17: 26.22 | P17: 2.4 | V17: 3.02 | W17: 0.07 | X17: 1 | Y17: 1.37 | Z17: 0.02 | AA17: 0.57 | AB17: 0 | AF17: 46 | AG17: 1.79 | AH17: 23 | AI17: 128 | AJ17: 196 | AK17: 638 | AL17: 0.62 | AM17: 0.089 | AN17: 0.401 | AP17: 23.4 | AS17: 0.2 | AT17: 0.281 | AU17: 0.16 | AV17: 4.71 | AW17: 0.43 | AX17: 0.154 | AZ17: 33 | BA17: 21 | BB17: 12 | BC17: 48 | CT17: 23.7 | CU17: 2.723 | CV17: 0.001 | CX17: 0 | CZ17: 0.003 | DB17: 0.005 | DD17: 0.003 | DF17: 0.03 | DG17: 0.005 | DH17: 1.95 | DI17: 0.015 | DJ17: 0.616 | DK17: 0.042 | DM17: 0.037 | DO17: 0.017 | DP17: 3.704 | DR17: 0.004 | DT17: 0 | DU17: 0.144 | DV17: 0.143 | DW17: 0.009 | DY17: 3.475 | DZ17: 3.453 | EA17: 0.068 | EC17: 0.001 | ED17: 0.001 | EG17: 0.003 | EH17: 7.22 | EI17: 6.491 | EK17: 6.417 | EL17: 0.015 | EN17: 0.668 | EP17: 0.649 | EQ17: 0.018 | ER17: 0.001 | ET17: 0.009 | EU17: 0.01 | EW17: 0.002 | EX17: 0.008 | FA17: 0.027 | FD17: 0.001 | FG17: 0.01 | FH17: 0.002 | FJ17: 0.002 | FK17: 0.082 | FL17: 0.023 | FN17: 0.001 | FO17: 0.022 | FQ17: 0 | FS17: 0.059 | FV17: 0.059 | FX17: 31 | FZ17: 0.145 | GA17: 0.367 | GB17: 0.55 | GC17: 0.936 | GD17: 0.811 | GE17: 0.27 | GF17: 0.212 | GG17: 0.56 | GH17: 0.328 | GI17: 0.608 | GJ17: 0.685 | GK17: 0.367 | GL17: 0.521 | GM17: 0.879 | GN17: 2.732 | GO17: 0.637 | GP17: 1.091 | GQ17: 0.357 | GR17: 0.08 | GW17: 7.7
A18: 170571 | B18: Nuts, cashew nuts, dry roasted, without salt added | D18: SR Legacy | E18: 100 | F18: =E18/SUM($E$3:$E$82) -> 0.013025803 | G18: 1.7 | H18: 609.15 | I18: 2548.6836 | K18: 15.31 | L18: 46.35 | M18: 46.35 | N18: 3.95 | O18: 32.69 | P18: 3 | V18: 5.01 | AF18: 45 | AG18: 6 | AH18: 260 | AI18: 490 | AJ18: 565 | AK18: 16 | AL18: 5.6 | AM18: 2.22 | AN18: 0.826 | AP18: 11.7 | AS18: 0 | AT18: 0.2 | AU18: 0.2 | AV18: 1.4 | AW18: 1.217 | AX18: 0.256 | AZ18: 69 | BA18: 0 | BB18: 69 | BC18: 69 | BD18: 61 | BK18: 0 | BL18: 0 | BM18: 0 | BN18: 0 | BO18: 0 | BR18: 0 | BT18: 0 | BV18: 0 | BW18: 0 | BZ18: 23 | CF18: 0.92 | CG18: 0 | CO18: 0 | CP18: 0 | CT18: 34.7 | CU18: 9.157 | CV18: 0 | CX18: 0 | CZ18: 0.132 | DB18: 0.132 | DD18: 0.784 | DF18: 0.347 | DH18: 4.351 | DJ18: 2.972 | DP18: 27.317 | DU18: 0.318 | DY18: 26.808 | EA18: 0.139 | EC18: 0 | EH18: 7.836 | EI18: 7.66 | EN18: 0.161 | ER18: 0 | FA18: 0 | FD18: 0 | FH18: 0 | FJ18: 0 | FX18: 0 | FY18: 158 | FZ18: 0.237 | GA18: 0.592 | GB18: 0.731 | GC18: 1.285 | GD18: 0.817 | GE18: 0.274 | GF18: 0.283 | GG18: 0.791 | GH18: 0.491 | GI18: 1.04 | GJ18: 1.741 | GK18: 0.399 | GL18: 0.702 | GM18: 1.505 | GN18: 3.624 | GO18: 0.803 | GP18: 0.69 | GQ18: 0.849 | GT18: 0 | GU18: 0 | GV18: 0
A19: 171320 | B19: Spices, cinnamon, ground | D19: SR Legacy | E19: 39.666667 | F19: =E19/SUM($E$3:$E$82) -> 0.0051669019 | G19: 10.58 | H19: 349.48 | I19: 1462.2243 | K19: 3.99 | L19: 1.24 | M19: 1.24 | N19: 3.6 | O19: 80.59 | P19: 53.1 | V19: 2.17 | W19: 0.02 | X19: 1.04 | Y19: 1.11 | Z19: 0 | AA19: 0 | AB19: 0 | AF19: 1002 | AG19: 8.32 | AH19: 60 | AI19: 64 | AJ19: 431 | AK19: 10 | AL19: 1.83 | AM19: 0.339 | AN19: 17.466 | AP19: 3.1 | AS19: 3.8 | AT19: 0.022 | AU19: 0.041 | AV19: 1.332 | AW19: 0.358 | AX19: 0.158 | AZ19: 6 | BA19: 0 | BB19: 6 | BC19: 6 | BD19: 11 | BJ19: 3.9 | BK19: 0 | BL19: 0 | BM19: 15 | BN19: 0 | BO19: 112 | BR19: 1 | BT19: 129 | BV19: 295 | BW19: 15 | BZ19: 222 | CF19: 2.32 | CG19: 0 | CH19: 0 | CI19: 10.44 | CJ19: 0.26 | CK19: 0 | CL19: 0 | CM19: 0 | CN19: 0 | CO19: 0 | CP19: 0 | CT19: 31.2 | CU19: 0.345 | CV19: 0 | CX19: 0 | CZ19: 0 | DB19: 0.003 | DD19: 0.006 | DE19: 0 | DF19: 0.009 | DG19: 0 | DH19: 0.104 | DI19: 0.136 | DJ19: 0.082 | DK19: 0 | DM19: 0 | DO19: 0 | DP19: 0.246 | DR19: 0 | DT19: 0 | DU19: 0.001 | DW19: 0 | DY19: 0.246 | DZ19: 0.246 | EA19: 0 | EC19: 0 | EG19: 0 | EH19: 0.068 | EI19: 0.044 | EN19: 0.011 | EP19: 0.011 | EQ19: 0 | ER19: 0 | ET19: 0 | EU19: 0 | FA19: 0 | FD19: 0 | FH19: 0 | FJ19: 0 | FK19: 0 | FL19: 0 | FO19: 0 | FX19: 0 | FY19: 26 | FZ19: 0.049 | GA19: 0.136 | GB19: 0.146 | GC19: 0.253 | GD19: 0.243 | GE19: 0.078 | GF19: 0.058 | GG19: 0.146 | GH19: 0.136 | GI19: 0.224 | GJ19: 0.166 | GK19: 0.117 | GL19: 0.166 | GM19: 0.438 | GN19: 0.37 | GO19: 0.195 | GP19: 0.419 | GQ19: 0.195 | GR19: 0 | GT19: 0 | GU19: 0 | GV19: 0 | GW19: 0
A20: 171354 | B20: Babyfood, juice, orange | D20: SR Legacy | E20: 100 | F20: =E20/SUM($E$3:$E$82) -> 0.013025803 | G20: 88.5 | H20: 45.9 | I20: 192.0456 | K20: 0.6 | L20: 0.3 | M20: 0.3 | N20: 0.4 | O20: 10.2 | P20: 0.1 | V20: 8.26 | AF20: 12 | AG20: 0.17 | AH20: 9 | AI20: 11 | AJ20: 184 | AK20: 0 | AL20: 0.06 | AM20: 0.046 | AP20: 0.1 | AS20: 62.5 | AT20: 0.045 | AU20: 0.028 | AV20: 0.239 | AW20: 0.137 | AX20: 0.054 | AZ20: 26 | BA20: 0 | BB20: 26 | BC20: 26 | BD20: 6.2 | BK20: 0 | BL20: 0 | BM20: 3 | BN20: 0 | BO20: 9 | BR20: 2 | BT20: 47 | BV20: 55 | BW20: 0 | BZ20: 113 | CF20: 0.04 | CG20: 0 | CO20: 0 | CP20: 0 | CT20: 0.1 | CU20: 0.035 | CV20: 0 | CX20: 0 | CZ20: 0 | DB20: 0 | DD20: 0 | DF20: 0 | DH20: 0.035 | DJ20: 0 | DP20: 0.05 | DU20: 0.005 | DY20: 0.045 | EA20: 0 | EC20: 0 | EH20: 0.06 | EI20: 0.045 | EN20: 0.015 | ER20: 0 | FA20: 0 | FD20: 0 | FH20: 0 | FJ20: 0 | FX20: 0 | GT20: 0 | GU20: 0 | GV20: 0
A21: 171711 | B21: Blueberries, raw | D21: SR Legacy | E21: 100 | F21: =E21/SUM($E$3:$E$82) -> 0.013025803 | G21: 84.21 | H21: 63.89 | I21: 267.31576 | K21: 0.74 | L21: 0.33 | M21: 0.33 | N21: 0.24 | O21: 14.49 | P21: 2.4 | V21: 9.96 | W21: 0.11 | X21: 4.88 | Y21: 4.97 | Z21: 0 | AA21: 0 | AB21: 0 | AC21: 0.03 | AF21: 6 | AG21: 0.28 | AH21: 6 | AI21: 12 | AJ21: 77 | AK21: 1 | AL21: 0.16 | AM21: 0.057 | AN21: 0.336 | AP21: 0.1 | AS21: 9.7 | AT21: 0.037 | AU21: 0.041 | AV21: 0.418 | AW21: 0.124 | AX21: 0.052 | AZ21: 6 | BA21: 0 | BB21: 6 | BC21: 6 | BD21: 6 | BJ21: 0.2 | BK21: 0 | BL21: 0 | BM21: 3 | BN21: 0 | BO21: 32 | BR21: 0 | BT21: 0 | BV21: 54 | BW21: 0 | BZ21: 80 | CF21: 0.57 | CG21: 0 | CH21: 0.01 | CI21: 0.36 | CJ21: 0.03 | CK21: 0 | CL21: 0 | CM21: 0.07 | CN21: 0 | CO21: 0 | CP21: 0 | CT21: 19.3 | CU21: 0.028 | CV21: 0 | CX21: 0 | CZ21: 0 | DB21: 0 | DD21: 0 | DF21: 0 | DH21: 0.017 | DJ21: 0.005 | DP21: 0.047 | DU21: 0.002 | DY21: 0.047 | EA21: 0 | EC21: 0 | EH21: 0.146 | EI21: 0.088 | EN21: 0.058 | ER21: 0 | FA21: 0 | FD21: 0 | FH21: 0 | FJ21: 0 | FK21: 0 | FX21: 0 | FZ21: 0.003 | GA21: 0.02 | GB21: 0.023 | GC21: 0.044 | GD21: 0.013 | GE21: 0.012 | GF21: 0.008 | GG21: 0.026 | GH21: 0.009 | GI21: 0.031 | GJ21: 0.037 | GK21: 0.011 | GL21: 0.031 | GM21: 0.057 | GN21: 0.091 | GO21: 0.031 | GP21: 0.028 | GQ21: 0.022 | GT21: 0 | GU21: 0 | GV21: 0 | GW21: 0
A22: 171722 | B22: Cranberries, raw | D22: SR Legacy | E22: 100 | F22: =E22/SUM($E$3:$E$82) -> 0.013025803 | G22: 87.32 | H22: 50.89 | I22: 212.92376 | K22: 0.46 | L22: 0.13 | M22: 0.13 | N22: 0.12 | O22: 11.97 | P22: 3.6 | V22: 4.27 | W22: 0.16 | X22: 3.44 | Y22: 0.67 | Z22: 0 | AA22: 0 | AB22: 0 | AC22: 0 | AF22: 8 | AG22: 0.23 | AH22: 6 | AI22: 11 | AJ22: 80 | AK22: 2 | AL22: 0.09 | AM22: 0.056 | AN22: 0.267 | AP22: 0.1 | AS22: 14 | AT22: 0.012 | AU22: 0.02 | AV22: 0.101 | AW22: 0.295 | AX22: 0.057 | AZ22: 1 | BA22: 0 | BB22: 1 | BC22: 1 | BD22: 5.5 | BJ22: 0.2 | BK22: 0 | BL22: 0 | BM22: 3 | BN22: 0 | BO22: 38 | BR22: 0 | BT22: 0 | BV22: 63 | BW22: 0 | BZ22: 91 | CF22: 1.32 | CG22: 0 | CH22: 0 | CI22: 0.04 | CJ22: 0 | CK22: 0 | CL22: 0 | CM22: 0.29 | CN22: 0 | CO22: 0 | CP22: 0 | CT22: 5 | CU22: 0.008 | CV22: 0 | CX22: 0 | CZ22: 0 | DB22: 0 | DD22: 0 | DF22: 0 | DH22: 0.006 | DJ22: 0.002 | DP22: 0.018 | DU22: 0.001 | DY22: 0.018 | EA22: 0 | EC22: 0 | EH22: 0.055 | EI22: 0.033 | EN22: 0.022 | ER22: 0 | FA22: 0 | FD22: 0 | FH22: 0 | FJ22: 0 | FK22: 0 | FX22: 0 | FZ22: 0.003 | GA22: 0.028 | GB22: 0.033 | GC22: 0.053 | GD22: 0.039 | GE22: 0.003 | GF22: 0.003 | GG22: 0.036 | GH22: 0.032 | GI22: 0.045 | GJ22: 0.056 | GK22: 0.018 | GL22: 0.049 | GM22: 0.188 | GN22: 0.146 | GO22: 0.048 | GP22: 0.031 | GQ22: 0.051 | GT22: 0 | GU22: 0 | GV22: 0 | GW22: 0
A23: 172336 | B23: Oil, canola | D23: SR Legacy | E23: 30 | F23: =E23/SUM($E$3:$E$82) -> 0.0039077409 | G23: 0 | H23: 900 | I23: 3765.6 | K23: 0 | L23: 100 | M23: 100 | N23: 0 | O23: 0 | P23: 0 | V23: 0 | AF23: 0 | AG23: 0 | AH23: 0 | AI23: 0 | AJ23: 0 | AK23: 0 | AL23: 0 | AM23: 0 | AN23: 0 | AP23: 0 | AS23: 0 | AT23: 0 | AU23: 0 | AV23: 0 | AW23: 0 | AX23: 0 | AZ23: 0 | BA23: 0 | BB23: 0 | BC23: 0 | BD23: 0.2 | BJ23: 0 | BK23: 0 | BL23: 0 | BM23: 0 | BN23: 0 | BO23: 0 | BR23: 0 | BT23: 0 | BV23: 0 | BW23: 0 | BZ23: 0 | CF23: 17.46 | CG23: 0 | CH23: 0.01 | CI23: 27.34 | CJ23: 0.99 | CK23: 0.03 | CL23: 0 | CM23: 0 | CN23: 0.01 | CO23: 0 | CP23: 0 | CT23: 71.3 | CU23: 7.365 | CV23: 0 | CX23: 0 | CZ23: 0 | DB23: 0 | DD23: 0 | DF23: 0 | DG23: 0 | DH23: 4.298 | DI23: 0 | DJ23: 2.087 | DK23: 0.65 | DM23: 0.33 | DP23: 63.276 | DR23: 0 | DT23: 0 | DU23: 0.214 | DW23: 0 | DY23: 61.744 | DZ23: 61.714 | EA23: 1.317 | EC23: 0 | EH23: 28.142 | EI23: 19.005 | EK23: 18.64 | EN23: 9.137 | EP23: 9.137 | EQ23: 0 | ER23: 0 | ET23: 0 | EU23: 0 | FA23: 0 | FD23: 0 | FH23: 0 | FJ23: 0 | FK23: 0.395 | FL23: 0.03 | FO23: 0.03 | FU23: 0.365 | FV23: 0.365 | FX23: 0 | GT23: 0 | GU23: 0 | GV23: 0 | GW23: 0 | GX23: 0 | GY23: 3 | GZ23: 241 | HB23: 413
A24: 173410 | B24: Butter, salted | D24: SR Legacy | E24: 100 | F24: =E24/SUM($E$3:$E$82) -> 0.013025803 | G24: 16.17 | H24: 733.63 | I24: 3069.5079 | K24: 0.85 | L24: 81.11 | M24: 81.11 | N24: 2.11 | O24: 0.06 | P24: 0 | V24: 0.06 | AF24: 24 | AG24: 0.02 | AH24: 2 | AI24: 24 | AJ24: 24 | AK24: 643 | AL24: 0.09 | AM24: 0 | AN24: 0 | AP24: 1 | AQ24: 2.8 | AS24: 0 | AT24: 0.005 | AU24: 0.034 | AV24: 0.042 | AW24: 0.11 | AX24: 0.003 | AZ24: 3 | BA24: 0 | BB24: 3 | BC24: 3 | BD24: 18.8 | BJ24: 0.3 | BK24: 0.17 | BL24: 0 | BM24: 684 | BN24: 671 | BO24: 158 | BR24: 0 | BT24: 0 | BV24: 2499 | BW24: 0 | BZ24: 0 | CF24: 2.32 | CG24: 0 | CH24: 0 | CI24: 0 | CJ24: 0 | CK24: 0 | CL24: 0 | CM24: 0 | CN24: 0 | CO24: 0 | CP24: 0 | CQ24: 0 | CR24: 0 | CT24: 7 | CU24: 51.368 | CV24: 3.226 | CX24: 2.007 | CZ24: 1.19 | DB24: 2.529 | DD24: 2.587 | DF24: 7.436 | DH24: 21.697 | DI24: 0.56 | DJ24: 9.999 | DK24: 0.138 | DP24: 21.021 | DU24: 0.961 | DV24: 0.961 | DY24: 19.961 | DZ24: 16.978 | EA24: 0.1 | EC24: 0 | EH24: 3.043 | EI24: 2.728 | EK24: 2.166 | EL24: 0.267 | EM24: 0.296 | EN24: 0.315 | EP24: 0.315 | ER24: 0 | FA24: 0 | FD24: 0 | FH24: 0 | FJ24: 0 | FK24: 3.278 | FL24: 2.982 | FO24: 2.982 | FV24: 0.296 | FX24: 215 | FZ24: 0.012 | GA24: 0.038 | GB24: 0.051 | GC24: 0.083 | GD24: 0.067 | GE24: 0.021 | GF24: 0.008 | GG24: 0.041 | GH24: 0.041 | GI24: 0.057 | GJ24: 0.031 | GK24: 0.023 | GL24: 0.029 | GM24: 0.064 | GN24: 0.178 | GO24: 0.018 | GP24: 0.082 | GQ24: 0.046 | GT24: 0 | GU24: 0 | GV24: 0 | GY24: 0 | GZ24: 0 | HB24: 4
A25: 173468 | B25: Salt, table | D25: SR Legacy | E25: 3.1301472 | F25: =E25/SUM($E$3:$E$82) -> 0.00040772681 | G25: 0.2 | H25: 0 | I25: 0 | K25: 0 | L25: 0 | M25: 0 | N25: 99.8 | O25: 0 | P25: 0 | V25: 0 | AF25: 24 | AG25: 0.33 | AH25: 1 | AI25: 0 | AJ25: 8 | AK25: 38758 | AL25: 0.1 | AM25: 0.03 | AN25: 0.1 | AP25: 0.1 | AQ25: 2 | AS25: 0 | AT25: 0 | AU25: 0 | AV25: 0 | AW25: 0 | AX25: 0 | AZ25: 0 | BA25: 0 | BB25: 0 | BC25: 0 | BD25: 0 | BK25: 0 | BL25: 0 | BM25: 0 | BN25: 0 | BO25: 0 | BR25: 0 | BT25: 0 | BV25: 0 | BW25: 0 | BZ25: 0 | CF25: 0 | CG25: 0 | CO25: 0 | CP25: 0 | CT25: 0 | CU25: 0 | CV25: 0 | CX25: 0 | CZ25: 0 | DB25: 0 | DD25: 0 | DF25: 0 | DH25: 0 | DJ25: 0 | DP25: 0 | DU25: 0 | DY25: 0 | EA25: 0 | EC25: 0 | EH25: 0 | EI25: 0 | EN25: 0 | ER25: 0 | FA25: 0 | FD25: 0 | FH25: 0 | FJ25: 0 | FK25: 0 | FX25: 0 | FY25: 0 | FZ25: 0 | GA25: 0 | GB25: 0 | GC25: 0 | GD25: 0 | GE25: 0 | GF25: 0 | GG25: 0 | GH25: 0 | GI25: 0 | GJ25: 0 | GK25: 0 | GL25: 0 | GM25: 0 | GN25: 0 | GO25: 0 | GP25: 0 | GQ25: 0 | GT25: 0 | GU25: 0 | GV25: 0
A26: 173532 | B26: Babyfood, cereal, mixed, with honey, prepared with whole milk | D26: SR Legacy | E26: 100 | F26: =E26/SUM($E$3:$E$82) -> 0.013025803 | G26: 74.2 | H26: 116 | I26: 485.344 | K26: 5 | L26: 3.6 | M26: 3.6 | N26: 1.2 | O26: 15.9 | AF26: 294 | AG26: 11.27 | AH26: 28 | AI26: 184 | AJ26: 171 | AK26: 48 | AL26: 0.72 | AM26: 0.064 | AT26: 0.447 | AU26: 0.583 | AV26: 6.26 | AW26: 0.443 | AX26: 0.067 | AZ26: 11 | BA26: 0 | BB26: 11 | BC26: 11 | BK26: 0.3
A27: 173534 | B27: Babyfood, cereal, rice, with bananas, prepared with whole milk | D27: SR Legacy | E27: 100 | F27: =E27/SUM($E$3:$E$82) -> 0.013025803 | G27: 81.81 | H27: 86.12 | I27: 360.32608 | K27: 3.57 | L27: 3.32 | M27: 3.32 | N27: 0.81 | O27: 10.49 | P27: 0.1 | V27: 6.13 | W27: 0 | X27: 0 | Y27: 0 | Z27: 4.67 | AA27: 0 | AB27: 0 | AF27: 156 | AG27: 3.63 | AH27: 20 | AI27: 109 | AJ27: 180 | AK27: 47 | AL27: 0.46 | AM27: 0.042 | AN27: 0.004 | AP27: 4.3 | AS27: 0.2 | AT27: 0.684 | AU27: 0.444 | AV27: 1.849 | AW27: 0.345 | AX27: 0.085 | AZ27: 6 | BA27: 0 | BB27: 6 | BC27: 6 | BD27: 15.2 | BJ27: 0.6 | BK27: 0.43 | BL27: 0 | BM27: 43 | BN27: 42 | BO27: 7 | BR27: 1 | BT27: 0 | BV27: 152 | BW27: 0 | BZ27: 3 | CF27: 0.09 | CG27: 0 | CH27: 0 | CI27: 0 | CJ27: 0 | CK27: 0 | CL27: 0 | CM27: 0 | CN27: 0 | CO27: 47 | CP27: 1.2 | CR27: 1.2 | CT27: 0.5 | CU27: 1.798 | CV27: 0.069 | CX27: 0.069 | CZ27: 0.069 | DB27: 0.069 | DD27: 0.071 | DE27: 0 | DF27: 0.276 | DG27: 0 | DH27: 0.826 | DI27: 0 | DJ27: 0.345 | DK27: 0 | DM27: 0 | DO27: 0 | DP27: 0.826 | DR27: 0 | DU27: 0.002 | DY27: 0.823 | EA27: 0 | EC27: 0 | EH27: 0.294 | EI27: 0.209 | EN27: 0.085 | ER27: 0 | FA27: 0 | FD27: 0 | FH27: 0 | FJ27: 0 | FX27: 10 | FZ27: 0.079 | GA27: 0.163 | GB27: 0.184 | GC27: 0.302 | GD27: 0.161 | GE27: 0.085 | GF27: 0.029 | GG27: 0.163 | GH27: 0.165 | GI27: 0.215 | GJ27: 0.113 | GK27: 0.088 | GL27: 0.131 | GM27: 0.28 | GN27: 0.702 | GO27: 0.095 | GP27: 0.341 | GQ27: 0.132 | GT27: 0 | GU27: 0 | GV27: 0 | GW27: 0 | GX27: 0.9
A28: 173944 | B28: Bananas, raw | D28: SR Legacy | E28: 100 | F28: =E28/SUM($E$3:$E$82) -> 0.013025803 | G28: 74.91 | H28: 98.69 | I28: 412.91896 | K28: 1.09 | L28: 0.33 | M28: 0.33 | N28: 0.82 | O28: 22.84 | P28: 2.6 | V28: 12.23 | W28: 2.39 | X28: 4.98 | Y28: 4.85 | Z28: 0 | AA28: 0.01 | AB28: 0 | AC28: 5.38 | AF28: 5 | AG28: 0.26 | AH28: 27 | AI28: 22 | AJ28: 358 | AK28: 1 | AL28: 0.15 | AM28: 0.078 | AN28: 0.27 | AP28: 1 | AQ28: 2.2 | AS28: 8.7 | AT28: 0.031 | AU28: 0.073 | AV28: 0.665 | AW28: 0.334 | AX28: 0.367 | AZ28: 20 | BA28: 0 | BB28: 20 | BC28: 20 | BD28: 9.8 | BJ28: 0.1 | BK28: 0 | BL28: 0 | BM28: 3 | BN28: 0 | BO28: 26 | BR28: 25 | BT28: 0 | BV28: 64 | BW28: 0 | BZ28: 22 | CF28: 0.1 | CG28: 0 | CH28: 0 | CI28: 0.02 | CJ28: 0.01 | CK28: 0.06 | CL28: 0 | CM28: 0 | CN28: 0 | CO28: 0 | CP28: 0 | CT28: 0.5 | CU28: 0.112 | CV28: 0 | CX28: 0 | CZ28: 0 | DB28: 0.001 | DD28: 0.002 | DF28: 0.002 | DH28: 0.102 | DJ28: 0.005 | DP28: 0.032 | DU28: 0.01 | DY28: 0.022 | EA28: 0 | EC28: 0 | EH28: 0.073 | EI28: 0.046 | EN28: 0.027 | ER28: 0 | FA28: 0 | FD28: 0 | FH28: 0 | FJ28: 0 | FK28: 0 | FX28: 0 | FY28: 16 | FZ28: 0.009 | GA28: 0.028 | GB28: 0.028 | GC28: 0.068 | GD28: 0.05 | GE28: 0.008 | GF28: 0.009 | GG28: 0.049 | GH28: 0.009 | GI28: 0.047 | GJ28: 0.049 | GK28: 0.077 | GL28: 0.04 | GM28: 0.124 | GN28: 0.152 | GO28: 0.038 | GP28: 0.028 | GQ28: 0.04 | GT28: 0 | GU28: 0 | GV28: 0 | GW28: 0
A29: 174158 | B29: Water, bottled, generic | D29: SR Legacy | E29: 116.47304 | F29: =E29/SUM($E$3:$E$82) -> 0.015171549 | G29: 99.98 | H29: 0 | I29: 0 | K29: 0 | L29: 0 | M29: 0 | N29: 0.07 | O29: 0 | P29: 0 | V29: 0 | AF29: 10 | AG29: 0 | AH29: 2 | AI29: 0 | AJ29: 0 | AK29: 2 | AL29: 0 | AM29: 0.007 | AP29: 0 | AS29: 0 | AT29: 0 | AU29: 0 | AV29: 0 | AW29: 0 | AX29: 0 | AZ29: 0 | BA29: 0 | BB29: 0 | BC29: 0 | BD29: 0 | BK29: 0 | BL29: 0 | BM29: 0 | BN29: 0 | BO29: 0 | BR29: 0 | BT29: 0 | BV29: 0 | BW29: 0 | BZ29: 0 | CF29: 0 | CG29: 0 | CO29: 0 | CP29: 0 | CT29: 0 | CU29: 0 | CV29: 0 | CX29: 0 | CZ29: 0 | DB29: 0 | DD29: 0 | DF29: 0 | DH29: 0 | DJ29: 0 | DP29: 0 | DU29: 0 | DY29: 0 | EA29: 0 | EC29: 0 | EH29: 0 | EI29: 0 | EN29: 0 | ER29: 0 | FA29: 0 | FD29: 0 | FH29: 0 | FJ29: 0 | FK29: 0 | FX29: 0 | GT29: 0 | GU29: 0 | GV29: 0
A30: 175138 | B30: Fish, salmon, pink, raw | D30: SR Legacy | E30: 100 | F30: =E30/SUM($E$3:$E$82) -> 0.013025803 | G30: 75.52 | H30: 121.6 | I30: 508.7744 | K30: 20.5 | L30: 4.4 | M30: 4.4 | N30: 1.52 | O30: 0 | P30: 0 | V30: 0 | AF30: 7 | AG30: 0.38 | AH30: 27 | AI30: 261 | AJ30: 366 | AK30: 75 | AL30: 0.39 | AM30: 0.063 | AN30: 0.011 | AP30: 31.4 | AS30: 0 | AT30: 0.08 | AU30: 0.105 | AV30: 7.995 | AW30: 1.03 | AX30: 0.611 | AZ30: 4 | BA30: 0 | BB30: 4 | BC30: 4 | BD30: 94.6 | BK30: 4.15 | BL30: 0 | BM30: 35 | BN30: 35 | BO30: 0 | BR30: 0 | BT30: 0 | BV30: 117 | BW30: 0 | BZ30: 0 | CF30: 0.4 | CG30: 0 | CH30: 0 | CI30: 0 | CJ30: 0 | CK30: 0 | CL30: 0 | CM30: 0 | CN30: 0 | CO30: 435 | CP30: 10.9 | CR30: 10.9 | CT30: 0.4 | CU30: 0.81 | CV30: 0 | CX30: 0 | CZ30: 0 | DB30: 0 | DD30: 0.003 | DF30: 0.203 | DG30: 0.013 | DH30: 0.472 | DI30: 0.01 | DJ30: 0.102 | DK30: 0.006 | DM30: 0.002 | DO30: 0.001 | DP30: 1.348 | DR30: 0.003 | DT30: 0.002 | DU30: 0.18 | DV30: 0.175 | DW30: 0.004 | DY30: 0.63 | DZ30: 0.622 | EA30: 0.449 | EC30: 0.047 | ED30: 0.045 | EG30: 0.034 | EH30: 0.811 | EI30: 0.081 | EK30: 0.057 | EL30: 0.005 | EN30: 0.047 | EP30: 0.045 | EQ30: 0.002 | ER30: 0.072 | ET30: 0.018 | EU30: 0.013 | EW30: 0.008 | EX30: 0.004 | FA30: 0.014 | FD30: 0.182 | FG30: 0.001 | FH30: 0.047 | FJ30: 0.333 | FK30: 0.034 | FL30: 0.015 | FN30: 0.005 | FO30: 0.009 | FQ30: 0.001 | FS30: 0.019 | FV30: 0.019 | FX30: 46 | FZ30: 0.221 | GA30: 1.066 | GB30: 0.954 | GC30: 1.562 | GD30: 1.759 | GE30: 0.577 | GF30: 0.159 | GG30: 0.845 | GH30: 0.742 | GI30: 1.1 | GJ30: 1.287 | GK30: 0.543 | GL30: 1.308 | GM30: 2.575 | GN30: 2.903 | GO30: 1.263 | GP30: 0.867 | GQ30: 0.905 | GT30: 0 | GU30: 0 | GV30: 0
A31: 175156 | B31: Fish, tuna, fresh, skipjack, raw | D31: SR Legacy | E31: 100 | F31: =E31/SUM($E$3:$E$82) -> 0.013025803 | G31: 70.58 | H31: 97.09 | I31: 406.22456 | K31: 22 | L31: 1.01 | M31: 1.01 | N31: 1.3 | O31: 0 | P31: 0 | AF31: 29 | AG31: 1.25 | AH31: 34 | AI31: 222 | AJ31: 407 | AK31: 37 | AL31: 0.82 | AM31: 0.086 | AN31: 0.015 | AP31: 36.5 | AS31: 1 | AT31: 0.033 | AU31: 0.1 | AV31: 15.4 | AW31: 0.42 | AX31: 0.85 | AZ31: 9 | BA31: 0 | BB31: 9 | BC31: 9 | BK31: 1.9 | BM31: 16 | BN31: 16 | BV31: 52 | CU31: 0.328 | DF31: 0.04 | DH31: 0.233 | DJ31: 0.055 | DP31: 0.19 | DU31: 0.036 | DY31: 0.131 | EA31: 0.017 | EC31: 0.006 | EH31: 0.315 | EI31: 0.016 | ER31: 0.004 | FA31: 0.026 | FD31: 0.071 | FH31: 0.013 | FJ31: 0.185 | FX31: 47 | FZ31: 0.246 | GA31: 0.964 | GB31: 1.014 | GC31: 1.788 | GD31: 2.02 | GE31: 0.651 | GF31: 0.236 | GG31: 0.859 | GH31: 0.743 | GI31: 1.133 | GJ31: 1.316 | GK31: 0.648 | GL31: 1.331 | GM31: 2.253 | GN31: 3.284 | GO31: 1.056 | GP31: 0.778 | GQ31: 0.898
A32: 175167 | B32: Fish, salmon, Atlantic, farmed, raw | D32: SR Legacy | E32: 100 | F32: =E32/SUM($E$3:$E$82) -> 0.013025803 | G32: 64.89 | H32: 202.46 | I32: 847.09264 | K32: 20.42 | L32: 13.42 | M32: 13.42 | N32: 1.13 | O32: 0 | P32: 0 | V32: 0 | AF32: 9 | AG32: 0.34 | AH32: 27 | AI32: 240 | AJ32: 363 | AK32: 59 | AL32: 0.36 | AM32: 0.045 | AN32: 0.011 | AP32: 24 | AS32: 3.9 | AT32: 0.207 | AU32: 0.155 | AV32: 8.672 | AW32: 1.547 | AX32: 0.636 | AZ32: 26 | BA32: 0 | BB32: 26 | BC32: 26 | BD32: 78.5 | BJ32: 3 | BK32: 3.23 | BL32: 0 | BM32: 58 | BN32: 58 | BO32: 0 | BR32: 0 | BT32: 0 | BV32: 193 | BW32: 0 | BZ32: 0 | CF32: 3.55 | CG32: 0 | CH32: 0.01 | CI32: 0.3 | CJ32: 0.05 | CK32: 0.06 | CL32: 0 | CM32: 0 | CN32: 0 | CO32: 441 | CP32: 11 | CT32: 0.5 | CU32: 3.05 | CV32: 0 | CX32: 0 | CZ32: 0 | DB32: 0 | DD32: 0 | DF32: 0.556 | DG32: 0.046 | DH32: 1.877 | DI32: 0.043 | DJ32: 0.495 | DK32: 0.022 | DM32: 0.011 | DO32: 0 | DP32: 3.77 | DR32: 0 | DT32: 0 | DU32: 0.791 | DW32: 0 | DY32: 2.715 | EA32: 0.265 | EC32: 0 | EH32: 3.886 | EI32: 0.9 | EN32: 0.167 | EP32: 0.148 | EQ32: 0.02 | ER32: 0.121 | ET32: 0.062 | EU32: 0.018 | FA32: 0.092 | FD32: 0.862 | FH32: 0.393 | FJ32: 1.104 | FX32: 55 | FZ32: 0.209 | GA32: 0.86 | GB32: 0.968 | GC32: 1.615 | GD32: 1.87 | GE32: 0.626 | GF32: 0.219 | GG32: 0.845 | GH32: 0.759 | GI32: 1.107 | GJ32: 1.221 | GK32: 0.549 | GL32: 1.271 | GM32: 2.025 | GN32: 2.83 | GO32: 0.96 | GP32: 0.721 | GQ32: 0.896 | GR32: 0.042 | GT32: 0 | GU32: 0 | GV32: 0 | GW32: 0 | GX32: 0
A33: 323294 | B33: Nuts, almonds, dry roasted, with salt added | D33: Foundation | E33: 100 | F33: =E33/SUM($E$3:$E$82) -> 0.013025803 | G33: 2.2 | H33: 666.6 | I33: 2789.0544 | J33: 3.94 | K33: 20.4 | L33: 53.4 | M33: 57.8 | N33: 3.47 | O33: 16.2 | P33: 11 | V33: 4.17 | W33: 4.17 | X33: 0 | Y33: 0 | Z33: 0 | AA33: 0 | AB33: 0 | AF33: 273 | AG33: 3.17 | AH33: 258 | AI33: 456 | AJ33: 684 | AK33: 256 | AL33: 2.8 | AM33: 0.87 | AN33: 2.02 | AP33: 0 | AS33: 0 | AT33: 0.079 | AU33: 1.57 | AV33: 3.1 | AW33: 0.237 | AX33: 0.075 | AZ33: 35 | BD33: 60.8 | BE33: 4.3 | BF33: 56.1 | BG33: 0 | BH33: 0.4 | BI33: 0 | BJ33: 0 | BM33: 2 | BO33: 17 | BR33: 0 | BT33: 9 | BW33: 0 | BZ33: 25 | CF33: 19 | CH33: 0.18 | CI33: 0.92 | CJ33: 0 | CK33: 0.28 | CL33: 0 | CM33: 0 | CN33: 0 | CT33: 0 | CU33: 4.56 | CV33: 0.001 | CX33: 0 | CZ33: 0 | DB33: 0 | DC33: 0 | DD33: 0 | DF33: 0.027 | DG33: 0.008 | DH33: 3.54 | DI33: 0.028 | DJ33: 0.828 | DK33: 0.059 | DM33: 0.042 | DO33: 0.024 | DP33: 34.2 | DS33: 0 | DT33: 0 | DV33: 0.259 | DW33: 0.061 | DX33: 0.061 | DZ33: 33.8 | EB33: 0.076 | ED33: 0.001 | EE33: 0.001 | EG33: 0.001 | EH33: 14.5 | EJ33: 14.5 | EK33: 14.5 | EL33: 0.006 | EO33: 0.052 | EP33: 0.05 | EQ33: 0.002 | ER33: 0 | ES33: 0 | ET33: 0 | EV33: 0 | EW33: 0 | EX33: 0 | EY33: 0 | FA33: 0.005 | FB33: 0.005 | FC33: 0.002 | FD33: 0.002 | FE33: 0 | FF33: 0 | FG33: 0 | FH33: 0 | FI33: 0 | FJ33: 0 | FK33: 0.032 | FL33: 0.016 | FN33: 0 | FO33: 0.016 | FQ33: 0 | FR33: 0.016 | FS33: 0.016 | FV33: 0 | FW33: 0 | GW33: 0 | GX33: 0
A34: 746766 | B34: Cheese, ricotta, whole milk | D34: Foundation | E34: 100 | F34: =E34/SUM($E$3:$E$82) -> 0.013025803 | G34: 72.9 | H34: 157.68 | I34: 659.73312 | J34: 1.22 | K34: 7.81 | L34: 10.3 | M34: 11 | N34: 1.36 | O34: 6.86 | AF34: 224 | AG34: 0.1 | AH34: 19.7 | AI34: 162 | AJ34: 230 | AK34: 105 | AL34: 0.56 | AM34: 0 | AN34: 0 | AP34: 5.5 | AT34: 0.043 | AU34: 0.327 | AV34: 0.168 | AW34: 0.673 | AX34: 0.099 | AZ34: 4 | BK34: 0.78 | BM34: 127 | BN34: 127 | CF34: 0.27 | CH34: 0 | CI34: 0 | CJ34: 0 | CK34: 0 | CL34: 0 | CM34: 0 | CN34: 0 | CT34: 0.6 | CU34: 6.97 | CV34: 0.251 | CX34: 0.199 | CZ34: 0.125 | DB34: 0.306 | DC34: 0 | DD34: 0.36 | DF34: 1.15 | DG34: 0.116 | DH34: 3.36 | DI34: 0.067 | DJ34: 1.02 | DK34: 0.014 | DM34: 0.006 | DO34: 0.004 | DP34: 2.56 | DS34: 0.117 | DT34: 0 | DV34: 0.184 | DW34: 0.021 | DX34: 0.021 | DZ34: 2.22 | EB34: 0.02 | ED34: 0.002 | EE34: 0.002 | EG34: 0 | EH34: 0.389 | EJ34: 0.308 | EK34: 0.259 | EL34: 0.049 | EO34: 0.042 | EP34: 0.042 | EQ34: 0 | ER34: 0.001 | ES34: 0.001 | ET34: 0.001 | EV34: 0.012 | EW34: 0 | EX34: 0.012 | EY34: 0 | FA34: 0.015 | FB34: 0.015 | FC34: 0.005 | FD34: 0.005 | FE34: 0 | FF34: 0.007 | FG34: 0.003 | FH34: 0.007 | FI34: 0 | FJ34: 0 | FK34: 0.351 | FL34: 0.283 | FN34: 0.032 | FO34: 0.251 | FQ34: 0 | FR34: 0.068 | FS34: 0.068 | FV34: 0.001 | FW34: 0.001 | FX34: 48 | FZ34: 0.115 | GA34: 0.395 | GB34: 0.365 | GC34: 0.785 | GD34: 0.655 | GE34: 0.17 | GG34: 0.27 | GH34: 0.25 | GI34: 0.325 | GJ34: 0.21 | GK34: 0.175 | GL34: 0.325 | GM34: 0.735 | GN34: 1.3 | GO34: 0.135 | GP34: 0.565 | GQ34: 0.365 | GR34: 0 | GS34: 0.18 | GW34: 0 | GX34: 3.1
A35: 746772 | B35: Milk, lowfat, fluid, 1% milkfat, with added vitamin A and vitamin D | D35: Foundation | E35: 100 | F35: =E35/SUM($E$3:$E$82) -> 0.013025803 | G35: 89.7 | H35: 42.79 | I35: 179.03336 | J35: 0.53 | K35: 3.38 | L35: 0.85 | M35: 0.95 | N35: 0.8 | O35: 5.18 | V35: 4.96 | W35: 0 | X35: 0 | Y35: 0 | Z35: 4.96 | AA35: 0 | AB35: 0 | AF35: 126 | AG35: 0 | AH35: 12 | AI35: 103 | AJ35: 159 | AK35: 39 | AL35: 0.43 | AM35: 0.001 | AN35: 0 | AO35: 36.2 | AP35: 2.1 | AT35: 0.057 | AU35: 0.14 | AV35: 0.113 | AW35: 0.368 | AX35: 0.06 | AZ35: 2 | BD35: 17.4 | BE35: 3 | BF35: 0.9 | BG35: 1.8 | BH35: 10.9 | BI35: 0.8 | BJ35: 0.9 | BK35: 0.61 | BM35: 58 | BN35: 58 | BO35: 1 | BP35: 0 | BQ35: 1 | BR35: 0 | BT35: 0 | BU35: 0 | BW35: 0 | BX35: 0 | BY35: 0 | CA35: 0 | CB35: 0 | CC35: 0 | CF35: 0.02 | CH35: 0 | CI35: 0 | CJ35: 0 | CK35: 0 | CL35: 0 | CM35: 0 | CN35: 0 | CO35: 42.4 | CP35: 1.06 | CQ35: 0 | CR35: 1.06 | CS35: 0 | CU35: 0.568 | CV35: 0.022 | CW35: 0 | CX35: 0.015 | CY35: 0 | CZ35: 0.011 | DA35: 0 | DB35: 0.023 | DC35: 0 | DD35: 0.026 | DF35: 0.093 | DG35: 0.01 | DH35: 0.265 | DI35: 0.006 | DJ35: 0.096 | DK35: 0.001 | DL35: 0 | DM35: 0 | DN35: 0 | DO35: 0 | DP35: 0.21 | DQ35: 0 | DS35: 0.007 | DT35: 0 | DV35: 0.012 | DW35: 0.002 | DX35: 0.002 | DZ35: 0.187 | EB35: 0.001 | ED35: 0 | EE35: 0 | EF35: 0 | EG35: 0 | EH35: 0.032 | EJ35: 0.029 | EK35: 0.026 | EL35: 0.004 | EO35: 0.004 | EP35: 0.004 | EQ35: 0 | ER35: 0 | ES35: 0 | ET35: 0 | EV35: 0.001 | EW35: 0 | EX35: 0.001 | EY35: 0 | EZ35: 0 | FA35: 0.001 | FB35: 0.001 | FC35: 0 | FD35: 0 | FE35: 0 | FF35: 0 | FG35: 0 | FH35: 0 | FI35: 0 | FJ35: 0 | FK35: 0.036 | FL35: 0.031 | FM35: 0.001 | FN35: 0.002 | FO35: 0.027 | FP35: 0 | FQ35: 0 | FR35: 0.004 | FS35: 0.004 | FV35: 0 | FW35: 0 | FX35: 5 | FZ35: 0.045 | GA35: 0.158 | GB35: 0.174 | GC35: 0.342 | GD35: 0.308 | GE35: 0.092 | GG35: 0.168 | GH35: 0.167 | GI35: 0.21 | GJ35: 0.128 | GK35: 0.099 | GL35: 0.111 | GM35: 0.286 | GN35: 0.809 | GO35: 0.069 | GP35: 0.349 | GQ35: 0.194 | GR35: 0 | GS35: 0.036
A36: 746776 | B36: Milk, nonfat, fluid, with added vitamin A and vitamin D (fat free or skim) | D36: Foundation | E36: 100 | F36: =E36/SUM($E$3:$E$82) -> 0.013025803 | G36: 90.8 | H36: 34.12 | I36: 142.75808 | J36: 0.54 | K36: 3.43 | L36: 0.07 | M36: 0.08 | N36: 0.77 | O36: 4.92 | V36: 5.05 | W36: 0 | X36: 0 | Y36: 0 | Z36: 5.05 | AA36: 0 | AB36: 0 | AF36: 132 | AG36: 0 | AH36: 12.5 | AI36: 107 | AJ36: 167 | AK36: 41 | AL36: 0.45 | AM36: 0.002 | AN36: 0.001 | AO36: 35.7 | AP36: 2 | AT36: 0.056 | AU36: 0.131 | AV36: 0.118 | AW36: 0.388 | AX36: 0.058 | AZ36: 2 | BD36: 18.2 | BE36: 3.1 | BF36: 0.8 | BG36: 2 | BH36: 11.5 | BI36: 0.9 | BJ36: 0.9 | BK36: 0.58 | BM36: 64 | BN36: 64 | BO36: 2 | BP36: 1 | BQ36: 1 | BR36: 0 | BT36: 0 | BU36: 0 | BW36: 0 | BX36: 0 | BY36: 0 | CA36: 0 | CB36: 1 | CC36: 0 | CF36: 0 | CH36: 0 | CI36: 0 | CJ36: 0 | CK36: 0 | CL36: 0 | CM36: 0 | CN36: 0 | CO36: 44 | CP36: 1.1 | CQ36: 0 | CR36: 1.1 | CS36: 0 | CU36: 0.049 | CV36: 0.003 | CW36: 0 | CX36: 0.001 | CY36: 0 | CZ36: 0.001 | DA36: 0 | DB36: 0.002 | DC36: 0 | DD36: 0.002 | DF36: 0.008 | DG36: 0.001 | DH36: 0.021 | DI36: 0.001 | DJ36: 0.009 | DK36: 0 | DL36: 0 | DM36: 0 | DN36: 0 | DO36: 0 | DP36: 0.017 | DQ36: 0 | DS36: 0 | DT36: 0 | DV36: 0.001 | DW36: 0 | DX36: 0 | DZ36: 0.017 | EB36: 0 | ED36: 0 | EE36: 0 | EF36: 0 | EG36: 0 | EH36: 0.006 | EJ36: 0.005 | EK36: 0.005 | EL36: 0 | EO36: 0 | EP36: 0 | EQ36: 0 | ER36: 0 | ES36: 0 | ET36: 0 | EV36: 0 | EW36: 0 | EX36: 0 | EY36: 0 | EZ36: 0 | FA36: 0 | FB36: 0 | FC36: 0 | FD36: 0 | FE36: 0 | FF36: 0 | FG36: 0 | FH36: 0 | FI36: 0 | FJ36: 0 | FK36: 0 | FL36: 0.001 | FM36: 0 | FN36: 0 | FO36: 0.001 | FP36: 0 | FQ36: 0 | FR36: 0 | FS36: 0 | FV36: 0 | FW36: 0 | FX36: 3 | FZ36: 0.048 | GA36: 0.166 | GB36: 0.182 | GC36: 0.347 | GD36: 0.302 | GE36: 0.093 | GG36: 0.168 | GH36: 0.168 | GI36: 0.222 | GJ36: 0.131 | GK36: 0.101 | GL36: 0.118 | GM36: 0.299 | GN36: 0.832 | GO36: 0.071 | GP36: 0.348 | GQ36: 0.202 | GR36: 0 | GS36: 0.038
A37: 746778 | B37: Milk, reduced fat, fluid, 2% milkfat, with added vitamin A and vitamin D | D37: Foundation | E37: 100 | F37: =E37/SUM($E$3:$E$82) -> 0.013025803 | G37: 89.1 | H37: 50.14 | I37: 209.78576 | J37: 0.53 | K37: 3.36 | L37: 1.64 | M37: 1.9 | N37: 0.75 | O37: 4.9 | V37: 4.89 | W37: 0 | X37: 0 | Y37: 0 | Z37: 4.89 | AA37: 0 | AB37: 0 | AF37: 126 | AG37: 0 | AH37: 12 | AI37: 103 | AJ37: 159 | AK37: 39 | AL37: 0.43 | AM37: 0.001 | AN37: 0.001 | AO37: 39.6 | AP37: 1.8 | AT37: 0.059 | AU37: 0.137 | AV37: 0.112 | AW37: 0.39 | AX37: 0.061 | AZ37: 2 | BD37: 18.2 | BE37: 3.1 | BF37: 1.1 | BG37: 1.9 | BH37: 11 | BI37: 1.2 | BJ37: 0.7 | BK37: 0.55 | BM37: 83 | BN37: 83 | BO37: 3 | BP37: 1 | BQ37: 2 | BR37: 0 | BT37: 0 | BU37: 0 | BW37: 0 | BX37: 0 | BY37: 0 | CA37: 0 | CB37: 0 | CC37: 0 | CF37: 0.03 | CH37: 0 | CI37: 0 | CJ37: 0 | CK37: 0 | CL37: 0 | CM37: 0 | CN37: 0 | CO37: 45.2 | CP37: 1.13 | CQ37: 0 | CR37: 1.13 | CS37: 0 | CU37: 1.11 | CV37: 0.041 | CW37: 0 | CX37: 0.032 | CY37: 0 | CZ37: 0.021 | DA37: 0 | DB37: 0.049 | DC37: 0 | DD37: 0.058 | DF37: 0.181 | DG37: 0.019 | DH37: 0.512 | DI37: 0.011 | DJ37: 0.184 | DK37: 0.002 | DL37: 0 | DM37: 0.001 | DN37: 0 | DO37: 0 | DP37: 0.4 | DQ37: 0.001 | DS37: 0.014 | DT37: 0 | DV37: 0.024 | DW37: 0.003 | DX37: 0.003 | DZ37: 0.358 | EB37: 0.002 | ED37: 0 | EE37: 0 | EF37: 0 | EG37: 0 | EH37: 0.058 | EJ37: 0.052 | EK37: 0.045 | EL37: 0.007 | EO37: 0.007 | EP37: 0.007 | EQ37: 0 | ER37: 0 | ES37: 0 | ET37: 0 | EV37: 0.002 | EW37: 0 | EX37: 0.002 | EY37: 0 | EZ37: 0 | FA37: 0.003 | FB37: 0.003 | FC37: 0 | FD37: 0 | FE37: 0 | FF37: 0.001 | FG37: 0 | FH37: 0.001 | FI37: 0 | FJ37: 0 | FK37: 0.07 | FL37: 0.06 | FM37: 0.003 | FN37: 0.005 | FO37: 0.052 | FP37: 0 | FQ37: 0 | FR37: 0.009 | FS37: 0.009 | FV37: 0 | FW37: 0 | FX37: 8 | FZ37: 0.042 | GA37: 0.162 | GB37: 0.173 | GC37: 0.335 | GD37: 0.293 | GE37: 0.089 | GG37: 0.163 | GH37: 0.165 | GI37: 0.213 | GJ37: 0.125 | GK37: 0.099 | GL37: 0.113 | GM37: 0.291 | GN37: 0.801 | GO37: 0.068 | GP37: 0.332 | GQ37: 0.197 | GR37: 0 | GS37: 0.035
A38: 746782 | B38: Milk, whole, 3.25% milkfat, with added vitamin D | D38: Foundation | E38: 100 | F38: =E38/SUM($E$3:$E$82) -> 0.013025803 | G38: 88.1 | H38: 60.4 | I38: 252.7136 | J38: 0.51 | K38: 3.27 | L38: 2.77 | M38: 3.2 | N38: 0.8 | O38: 4.63 | V38: 4.81 | W38: 0 | X38: 0 | Y38: 0 | Z38: 4.81 | AA38: 0 | AB38: 0 | AF38: 123 | AG38: 0 | AH38: 11.9 | AI38: 101 | AJ38: 150 | AK38: 38 | AL38: 0.42 | AM38: 0.001 | AN38: 0 | AO38: 37.9 | AP38: 1.9 | AT38: 0.056 | AU38: 0.138 | AV38: 0.105 | AW38: 0.362 | AX38: 0.061 | AZ38: 0 | BD38: 17.8 | BE38: 3 | BF38: 1.3 | BG38: 1.8 | BH38: 10.3 | BI38: 1.4 | BJ38: 0.7 | BK38: 0.54 | BM38: 32 | BN38: 31 | BO38: 7 | BP38: 2 | BQ38: 5 | BR38: 0 | BT38: 0 | BU38: 0 | BW38: 0 | BX38: 0 | BY38: 0 | CA38: 0 | CB38: 5 | CC38: 1 | CF38: 0.05 | CH38: 0 | CI38: 0 | CJ38: 0 | CK38: 0 | CL38: 0 | CM38: 0 | CN38: 0 | CO38: 38.4 | CP38: 0.96 | CQ38: 0 | CR38: 0.96 | CS38: 0 | CU38: 1.86 | CV38: 0.067 | CW38: 0 | CX38: 0.054 | CY38: 0 | CZ38: 0.034 | DA38: 0 | DB38: 0.084 | DC38: 0 | DD38: 0.097 | DF38: 0.303 | DG38: 0.032 | DH38: 0.857 | DI38: 0.018 | DJ38: 0.309 | DK38: 0.004 | DL38: 0 | DM38: 0.002 | DN38: 0 | DO38: 0.001 | DP38: 0.688 | DQ38: 0.001 | DS38: 0.024 | DT38: 0 | DV38: 0.039 | DW38: 0.005 | DX38: 0.005 | DZ38: 0.612 | EB38: 0.004 | ED38: 0 | EE38: 0 | EF38: 0 | EG38: 0 | EH38: 0.108 | EJ38: 0.097 | EK38: 0.084 | EL38: 0.013 | EO38: 0.013 | EP38: 0.012 | EQ38: 0.001 | ER38: 0 | ES38: 0.001 | ET38: 0.001 | EV38: 0.004 | EW38: 0 | EX38: 0.004 | EY38: 0 | EZ38: 0 | FA38: 0.004 | FB38: 0.004 | FC38: 0.001 | FD38: 0.001 | FE38: 0 | FF38: 0.002 | FG38: 0.001 | FH38: 0.002 | FI38: 0 | FJ38: 0 | FK38: 0.112 | FL38: 0.095 | FM38: 0.005 | FN38: 0.008 | FO38: 0.082 | FP38: 0 | FQ38: 0 | FR38: 0.018 | FS38: 0.018 | FV38: 0 | FW38: 0 | FX38: 12 | FZ38: 0.043 | GA38: 0.154 | GB38: 0.173 | GC38: 0.333 | GD38: 0.298 | GE38: 0.09 | GG38: 0.161 | GH38: 0.162 | GI38: 0.207 | GJ38: 0.127 | GK38: 0.097 | GL38: 0.11 | GM38: 0.279 | GN38: 0.788 | GO38: 0.069 | GP38: 0.333 | GQ38: 0.188 | GR38: 0 | GS38: 0.038
A39: 747447 | B39: Broccoli, raw | D39: Foundation | E39: 100 | F39: =E39/SUM($E$3:$E$82) -> 0.013025803 | G39: 90 | H39: 38.42 | I39: 160.74928 | J39: 0.41 | K39: 2.57 | L39: 0.07 | M39: 0.34 | N39: 0.83 | O39: 6.27 | P39: 2.4 | Q39: 0 | R39: 2.4 | V39: 1.4 | W39: 0.01 | X39: 0.58 | Y39: 0.82 | Z39: 0 | AA39: 0 | AB39: 0 | AC39: 0 | AF39: 46 | AG39: 0.69 | AH39: 21 | AI39: 67 | AJ39: 303 | AK39: 36 | AL39: 0.42 | AM39: 0.059 | AN39: 0.197 | AP39: 1.6 | AS39: 91.3 | AT39: 0.077 | AU39: 0.114 | AV39: 0.639 | AW39: 0.61 | AX39: 0.191 | AZ39: 65 | BM39: 8 | BO39: 93 | BR39: 0 | BT39: 0 | BW39: 0 | BZ39: 745 | CD39: 0 | CE39: 0 | CF39: 0.15 | CH39: 0 | CI39: 0.04 | CJ39: 0 | CK39: 0.01 | CL39: 0 | CM39: 0 | CN39: 0 | CT39: 102 | CU39: 0.039 | CZ39: 0 | DB39: 0 | DD39: 0 | DF39: 0.001 | DG39: 0 | DH39: 0.029 | DI39: 0 | DJ39: 0.006 | DK39: 0.002 | DM39: 0.002 | DP39: 0.011 | DS39: 0 | DT39: 0 | DV39: 0 | DW39: 0.001 | DX39: 0.001 | DY39: 0.01 | DZ39: 0.01 | EA39: 0 | EB39: 0 | EH39: 0.017 | EI39: 0.017 | EJ39: 0.017 | EN39: 0.021 | EO39: 0 | EQ39: 0 | ES39: 0 | ET39: 0 | EU39: 0 | EV39: 0 | FA39: 0 | FB39: 0 | FZ39: 0.033 | GA39: 0.088 | GB39: 0.079 | GC39: 0.129 | GD39: 0.135 | GE39: 0.038 | GF39: 0.028 | GG39: 0.117 | GH39: 0.05 | GI39: 0.125 | GJ39: 0.191 | GK39: 0.059 | GL39: 0.104 | GM39: 0.325 | GN39: 0.542 | GO39: 0.089 | GP39: 0.11 | GQ39: 0.121 | GW39: 0
A40: 747448 | B40: Strawberries, raw | D40: Foundation | E40: 100 | F40: =E40/SUM($E$3:$E$82) -> 0.013025803 | G40: 91.1 | H40: 35.06 | I40: 146.69104 | J40: 0.1 | K40: 0.64 | L40: 0.17 | M40: 0.22 | N40: 0.41 | O40: 7.63 | P40: 1.8 | Q40: 0.7 | R40: 0.9 | V40: 5.34 | W40: 0.11 | X40: 2.39 | Y40: 2.84 | Z40: 0 | AA40: 0 | AB40: 0 | AC40: 0.04 | AF40: 12 | AG40: 0.28 | AH40: 11.8 | AI40: 20 | AJ40: 89 | AK40: 10 | AL40: 0.18 | AM40: 0.119 | AN40: 0.28 | AP40: 0.4 | AS40: 56 | AT40: 0.025 | AU40: 0.016 | AV40: 0.386 | AW40: 0.122 | AX40: 0.035 | AZ40: 8 | BM40: 1 | BO40: 7 | BR40: 0 | BT40: 0 | BW40: 0 | BZ40: 22 | CT40: 2.1 | CU40: 0 | CV40: 0 | CX40: 0 | CZ40: 0 | DB40: 0 | DD40: 0 | DF40: 0 | DG40: 0 | DH40: 0 | DI40: 0 | DJ40: 0 | DK40: 0 | DM40: 0 | DO40: 0 | DP40: 0 | DS40: 0 | DV40: 0 | DY40: 0 | DZ40: 0 | EA40: 0 | EB40: 0 | EC40: 0 | ED40: 0 | EH40: 0 | EI40: 0 | EJ40: 0 | EN40: 0 | EO40: 0 | ER40: 0 | FA40: 0 | FB40: 0 | FC40: 0 | FD40: 0 | FE40: 0 | FI40: 0 | FJ40: 0 | FZ40: 0 | GA40: 0 | GB40: 0 | GC40: 0 | GD40: 0 | GE40: 0 | GF40: 0 | GG40: 0 | GH40: 0 | GI40: 0 | GJ40: 0 | GK40: 0 | GL40: 0 | GM40: 0.136 | GN40: 0.126 | GO40: 0 | GP40: 0 | GQ40: 0 | GW40: 0
...

Sheet Totales
A1: Nutriente | B1: Total | C1: Unidad
A2: Water | B2: =Ingredientes!G83 -> 67.725627 | C2: g
A3: Energy (Atwater General Factors) | B3: =Ingredientes!#REF! -> #REF! | C3: kcal
A4: Energy (Atwater Specific Factors) | B4: =Ingredientes!#REF! -> #REF! | C4: kcal
A5: Energy | B5: =Ingredientes!H83 -> 168.9656 | C5: kcal
A6: Energy | B6: =Ingredientes!I83 -> 706.95205 | C6: kJ
A7: Nitrogen | B7: =Ingredientes!J83 -> 0.32740927 | C7: g
A8: Protein | B8: =Ingredientes!K83 -> 4.8227871 | C8: g
A9: Total fat (NLEA) | B9: =Ingredientes!L83 -> 8.8942732 | C9: g
A10: Total lipid (fat) | B10: =Ingredientes!M83 -> 9.0225513 | C10: g
A11: Ash | B11: =Ingredientes!N83 -> 0.75773923 | C11: g
A12: Carbohydrate, by difference | B12: =Ingredientes!O83 -> 17.117871 | C12: g
A13: Fiber, total dietary | B13: =Ingredientes!P83 -> 1.9550662 | C13: g
A14: Fiber, soluble | B14: =Ingredientes!Q83 -> 0.10980752 | C14: g
A15: Fiber, insoluble | B15: =Ingredientes!R83 -> 0.04298515 | C15: g
A16: Total dietary fiber (AOAC 2011.25) | B16: =Ingredientes!S83 -> 0.087806938 | C16: g
A17: High Molecular Weight Dietary Fiber (HMWDF) | B17: =Ingredientes!T83 -> 0.025191903 | C17: g
A18: Low Molecular Weight Dietary Fiber (LMWDF) | B18: =Ingredientes!U83 -> 0.0038595454 | C18: g
A19: Sugars, Total | B19: =Ingredientes!V83 -> 6.2223996 | C19: g
A20: Sucrose | B20: =Ingredientes!W83 -> 0.34439446 | C20: g
A21: Glucose | B21: =Ingredientes!X83 -> 0.83904972 | C21: g
A22: Fructose | B22: =Ingredientes!Y83 -> 0.77789184 | C22: g
A23: Lactose | B23: =Ingredientes!Z83 -> 0.32577533 | C23: g
A24: Maltose | B24: =Ingredientes!AA83 -> 0.083638681 | C24: g
A25: Galactose | B25: =Ingredientes!AB83 -> 0.0055932798 | C25: g
A26: Starch | B26: =Ingredientes!AC83 -> 3.2338984 | C26: g
A27: Resistant starch | B27: =Ingredientes!AD83 -> 0.068359414 | C27: g
A28: Sugars, added | B28: =Ingredientes!AE83 -> 0.04168257 | C28: g
A29: Calcium, Ca | B29: =Ingredientes!AF83 -> 64.954513 | C29: mg
A30: Iron, Fe | B30: =Ingredientes!AG83 -> 1.0773851 | C30: mg
A31: Magnesium, Mg | B31: =Ingredientes!AH83 -> 25.447487 | C31: mg
A32: Phosphorus, P | B32: =Ingredientes!AI83 -> 85.885078 | C32: mg
A33: Potassium, K | B33: =Ingredientes!AJ83 -> 225.58962 | C33: mg
A34: Sodium, Na | B34: =Ingredientes!AK83 -> 155.79182 | C34: mg
A35: Zinc, Zn | B35: =Ingredientes!AL83 -> 0.51225891 | C35: mg
A36: Copper, Cu | B36: =Ingredientes!AM83 -> 0.11629678 | C36: mg
A37: Manganese, Mn | B37: =Ingredientes!AN83 -> 0.30396444 | C37: mg
A38: Iodine, I | B38: =Ingredientes!AO83 -> 4.1759422 | C38: µg
A39: Selenium, Se | B39: =Ingredientes!AP83 -> 4.3767323 | C39: µg
A40: Fluoride, F | B40: =Ingredientes!AQ83 -> 1.696775 | C40: µg
...
