Workbook

Sheet Ingredientes
A1: Detalles de formulación | G1: Proximates | P1: Carbohydrates | Y1: Minerals | AK1: Vitamins and Other Components | CM1: Lipids | FN1: Amino acids | GG1: Phytosterols | GK1: Organic acids | GO1: Nutrientes
A2: FDC ID | B2: Ingrediente | C2: Marca / Origen | D2: Tipo de dato | E2: Cantidad (g) | F2: Cantidad (%) | G2: Water (g) | H2: Energy (kcal) | I2: Energy (kJ) | J2: Nitrogen (g) | K2: Protein (g) | L2: Total fat (NLEA) (g) | M2: Total lipid (fat) (g) | N2: Ash (g) | O2: Carbohydrate, by difference (g) | P2: Fiber, total dietary (g) | Q2: Sugars, Total (g) | R2: Sucrose (g) | S2: Glucose (g) | T2: Fructose (g) | U2: Lactose (g) | V2: Maltose (g) | W2: Galactose (g) | X2: Starch (g) | Y2: Calcium, Ca (mg) | Z2: Iron, Fe (mg) | AA2: Magnesium, Mg (mg) | AB2: Phosphorus, P (mg) | AC2: Potassium, K (mg) | AD2: Sodium, Na (mg) | AE2: Zinc, Zn (mg) | AF2: Copper, Cu (mg) | AG2: Manganese, Mn (mg) | AH2: Iodine, I (µg) | AI2: Selenium, Se (µg) | AJ2: Fluoride, F (µg) | AK2: Folate, food (µg) | AL2: Thiamin (mg) | AM2: Riboflavin (mg) | AN2: Niacin (mg) | AO2: Vitamin B-6 (mg) | AP2: Folate, total (µg) | AQ2: Folic acid (µg) | AR2: Folate, DFE (µg) | AS2: Choline, total (mg) | AT2: Choline, free (mg) | AU2: Choline, from phosphocholine (mg) | AV2: Choline, from phosphatidyl choline (mg) | AW2: Choline, from glycerophosphocholine (mg) | AX2: Choline, from sphingomyelin (mg) | AY2: Betaine (mg) | AZ2: Vitamin B-12 (µg) | BA2: Vitamin B-12, added (µg) | BB2: Vitamin A, RAE (µg) | BC2: Retinol (µg) | BD2: Carotene, beta (µg) | BE2: cis-beta-Carotene (µg) | BF2: trans-beta-Carotene (µg) | BG2: Carotene, alpha (µg) | BH2: Cryptoxanthin, beta (µg) | BI2: Cryptoxanthin, alpha (µg) | BJ2: Vitamin A, IU (iu) | BK2: Lycopene (µg) | BL2: cis-Lycopene (µg) | BM2: trans-Lycopene (µg) | BN2: Lutein + zeaxanthin (µg) | BO2: cis-Lutein/Zeaxanthin (µg) | BP2: Lutein (µg) | BQ2: Zeaxanthin (µg) | BR2: Vitamin D (D2 + D3), International Units (iu) | BS2: Vitamin D (D2 + D3) (µg) | BT2: Vitamin D2 (ergocalciferol) (µg) | BU2: Vitamin D3 (cholecalciferol) (µg) | BV2: 25-hydroxycholecalciferol (µg) | BW2: Vitamin K (phylloquinone) (µg) | BX2: Vitamin K (Dihydrophylloquinone) (µg) | BY2: Vitamin K (Menaquinone-4) (µg) | BZ2: Vitamin E (alpha-tocopherol) (mg) | CA2: Vitamin E, added (mg) | CB2: Tocopherol, beta (mg) | CC2: Tocopherol, gamma (mg) | CD2: Tocopherol, delta (mg) | CE2: Tocotrienol, alpha (mg) | CF2: Tocotrienol, beta (mg) | CG2: Tocotrienol, gamma (mg) | CH2: Tocotrienol, delta (mg) | CI2: Vitamin C, total ascorbic acid (mg) | CJ2: Pantothenic acid (mg) | CK2: Caffeine (mg) | CL2: Theobromine (mg) | CM2: Fatty acids, total saturated (g) | CN2: SFA 4:0 (g) | CO2: SFA 5:0 (g) | CP2: SFA 6:0 (g) | CQ2: SFA 7:0 (g) | CR2: SFA 8:0 (g) | CS2: SFA 9:0 (g) | CT2: SFA 10:0 (g) | CU2: SFA 11:0 (g) | CV2: SFA 12:0 (g) | CW2: SFA 14:0 (g) | CX2: SFA 15:0 (g) | CY2: SFA 16:0 (g) | CZ2: SFA 17:0 (g) | DA2: SFA 18:0 (g) | DB2: SFA 20:0 (g) | DC2: SFA 21:0 (g) | DD2: SFA 22:0 (g) | DE2: SFA 23:0 (g) | DF2: SFA 24:0 (g) | DG2: Fatty acids, total monounsaturated (g) | DH2: MUFA 12:1 (g) | DI2: MUFA 14:1 (g) | DJ2: MUFA 14:1 c (g) | DK2: MUFA 15:1 (g) | DL2: MUFA 16:1 (g) | DM2: MUFA 16:1 c (g) | DN2: MUFA 17:1 (g) | DO2: MUFA 17:1 c (g) | DP2: MUFA 18:1 (g) | DQ2: MUFA 18:1 c (g) | DR2: MUFA 20:1 (g) | DS2: MUFA 20:1 c (g) | DT2: MUFA 22:1 (g) | DU2: MUFA 22:1 c (g) | DV2: MUFA 22:1 n-9 (g) | DW2: MUFA 22:1 n-11 (g) | DX2: MUFA 24:1 c (g) | DY2: Fatty acids, total polyunsaturated (g) | DZ2: PUFA 18:2 (g) | EA2: PUFA 18:2 c (g) | EB2: PUFA 18:2 n-6 c,c (g) | EC2: PUFA 18:2 CLAs (g) | ED2: PUFA 18:3 (g) | EE2: PUFA 18:3 c (g) | EF2: PUFA 18:3 n-3 c,c,c (ALA) (g) | EG2: PUFA 18:3 n-6 c,c,c (g) | EH2: PUFA 18:4 (g) | EI2: PUFA 20:2 c (g) | EJ2: PUFA 20:2 n-6 c,c (g) | EK2: PUFA 20:3 (g) | EL2: PUFA 20:3 c (g) | EM2: PUFA 20:3 n-3 (g) | EN2: PUFA 20:3 n-6 (g) | EO2: PUFA 20:3 n-9 (g) | EP2: PUFA 20:4 (g) | EQ2: PUFA 20:4c (g) | ER2: PUFA 20:5c (g) | ES2: PUFA 20:5 n-3 (EPA) (g) | ET2: PUFA 22:2 (g) | EU2: PUFA 22:3 (g) | EV2: PUFA 22:4 (g) | EW2: PUFA 22:5 c (g) | EX2: PUFA 22:5 n-3 (DPA) (g) | EY2: PUFA 22:6 c (g) | EZ2: PUFA 22:6 n-3 (DHA) (g) | FA2: Fatty acids, total trans (g) | FB2: Fatty acids, total trans-monoenoic (g) | FC2: Fatty acids, total trans-dienoic (g) | FD2: Fatty acids, total trans-polyenoic (g) | FE2: TFA 14:1 t (g) | FF2: TFA 16:1 t (g) | FG2: TFA 18:1 t (g) | FH2: TFA 18:2 t,t (g) | FI2: TFA 18:2 t not further defined (g) | FJ2: TFA 18:3 t (g) | FK2: TFA 20:1 t (g) | FL2: TFA 22:1 t (g) | FM2: Cholesterol (mg) | FN2: Tryptophan (g) | FO2: Threonine (g) | FP2: Isoleucine (g) | FQ2: Leucine (g) | FR2: Lysine (g) | FS2: Methionine (g) | FT2: Phenylalanine (g) | FU2: Tyrosine (g) | FV2: Valine (g) | FW2: Arginine (g) | FX2: Histidine (g) | FY2: Alanine (g) | FZ2: Aspartic acid (g) | GA2: Glutamic acid (g) | GB2: Glycine (g) | GC2: Proline (g) | GD2: Serine (g) | GE2: Hydroxyproline (g) | GF2: Cysteine (g) | GG2: Phytosterols (mg) | GH2: Beta-sitosterol (mg) | GI2: Campesterol (mg) | GJ2: Stigmasterol (mg) | GK2: Citric acid (mg) | GL2: Malic acid (mg) | GM2: Oxalic acid (mg) | GN2: Quinic acid (mg) | GO2: Alcohol, ethyl (g)
A3: 172336 | B3: Oil, canola | D3: SR Legacy | E3: 30 | F3: =E3/SUM($E$3:$E$8) | G3: 0 | H3: 900 | I3: 3765.6 | J3: 0 | K3: 0 | L3: 100 | M3: 100 | N3: 0 | O3: 0 | P3: 0 | Q3: 0 | Y3: 0 | Z3: 0 | AA3: 0 | AB3: 0 | AC3: 0 | AD3: 0 | AE3: 0 | AF3: 0 | AG3: 0 | AI3: 0 | AK3: 0 | AL3: 0 | AM3: 0 | AN3: 0 | AO3: 0 | AP3: 0 | AQ3: 0 | AR3: 0 | AS3: 0.2 | AY3: 0 | AZ3: 0 | BA3: 0 | BB3: 0 | BC3: 0 | BD3: 0 | BG3: 0 | BH3: 0 | BJ3: 0 | BK3: 0 | BN3: 0 | BR3: 0 | BS3: 0 | BW3: 71.3 | BX3: 0 | BY3: 0 | BZ3: 17.5 | CA3: 0 | CB3: 0.01 | CC3: 27.3 | CD3: 0.99 | CE3: 0.03 | CF3: 0 | CG3: 0 | CH3: 0.01 | CI3: 0 | CJ3: 0 | CK3: 0 | CL3: 0 | CM3: 7.36 | CN3: 0 | CP3: 0 | CR3: 0 | CT3: 0 | CV3: 0 | CW3: 0 | CX3: 0 | CY3: 4.3 | CZ3: 0 | DA3: 2.09 | DB3: 0.65 | DD3: 0.33 | DG3: 63.3 | DI3: 0 | DK3: 0 | DL3: 0.214 | DN3: 0 | DP3: 61.7 | DQ3: 61.7 | DR3: 1.32 | DT3: 0 | DY3: 28.1 | DZ3: 19 | EB3: 18.6 | ED3: 9.14 | EF3: 9.14 | EG3: 0 | EH3: 0 | EJ3: 0 | EK3: 0 | EP3: 0 | ES3: 0 | EX3: 0 | EZ3: 0 | FA3: 0.395 | FB3: 0.03 | FD3: 0.365 | FG3: 0.03 | FH3: 0.365 | FM3: 0 | GH3: 413 | GI3: 241 | GJ3: 3 | GO3: 0
A4: 173468 | B4: Salt, table | D4: SR Legacy | E4: 3.1301472 | F4: =E4/SUM($E$3:$E$8) | G4: 0.2 | H4: 0 | I4: 0 | J4: 0 | K4: 0 | L4: 0 | M4: 0 | N4: 99.8 | O4: 0 | P4: 0 | Q4: 0 | Y4: 24 | Z4: 0.33 | AA4: 1 | AB4: 0 | AC4: 8 | AD4: 38800 | AE4: 0.1 | AF4: 0.03 | AG4: 0.1 | AI4: 0.1 | AJ4: 2 | AK4: 0 | AL4: 0 | AM4: 0 | AN4: 0 | AO4: 0 | AP4: 0 | AQ4: 0 | AR4: 0 | AS4: 0 | AZ4: 0 | BA4: 0 | BB4: 0 | BC4: 0 | BD4: 0 | BG4: 0 | BH4: 0 | BJ4: 0 | BK4: 0 | BN4: 0 | BR4: 0 | BS4: 0 | BW4: 0 | BZ4: 0 | CA4: 0 | CI4: 0 | CJ4: 0 | CK4: 0 | CL4: 0 | CM4: 0 | CN4: 0 | CP4: 0 | CR4: 0 | CT4: 0 | CV4: 0 | CW4: 0 | CY4: 0 | DA4: 0 | DG4: 0 | DL4: 0 | DP4: 0 | DR4: 0 | DT4: 0 | DY4: 0 | DZ4: 0 | ED4: 0 | EH4: 0 | EP4: 0 | ES4: 0 | EX4: 0 | EZ4: 0 | FA4: 0 | FM4: 0 | FN4: 0 | FO4: 0 | FP4: 0 | FQ4: 0 | FR4: 0 | FS4: 0 | FT4: 0 | FU4: 0 | FV4: 0 | FW4: 0 | FX4: 0 | FY4: 0 | FZ4: 0 | GA4: 0 | GB4: 0 | GC4: 0 | GD4: 0 | GF4: 0 | GG4: 0 | GO4: 0
A5: 748967 | B5: Eggs, Grade A, Large, egg whole | D5: Foundation | E5: 150 | F5: =E5/SUM($E$3:$E$8) | G5: 75.8 | H5: 143.08 | I5: 598.64672 | J5: 1.99 | K5: 12.4 | L5: 8.65 | M5: 9.96 | N5: 0.85 | O5: 0.96 | P5: 0 | Q5: 0.2 | R5: 0 | S5: 0.2 | T5: 0 | U5: 0 | V5: 0 | X5: 0 | Y5: 48 | Z5: 1.67 | AA5: 11.4 | AB5: 184 | AC5: 132 | AD5: 129 | AE5: 1.24 | AF5: 0 | AG5: 0 | AH5: 49.1 | AI5: 31.1 | AL5: 0.077 | AM5: 0.419 | AN5: 0 | AO5: 0.063 | AP5: 71 | AS5: 335 | AT5: 0.6 | AU5: 309 | AV5: 0.2 | AW5: 0.2 | AX5: 25.1 | AY5: 0.3 | AZ5: 1.02 | BB5: 180 | BC5: 179 | BD5: 0 | BE5: 0 | BF5: 0 | BG5: 0 | BH5: 13 | BI5: 13 | BK5: 0 | BL5: 0 | BM5: 0 | BO5: 57 | BP5: 230 | BQ5: 229 | BR5: 98.4 | BS5: 2.46 | BT5: 0 | BU5: 2.46 | BV5: 0.56 | CM5: 3.2 | CW5: 0.032 | CY5: 2.32 | DA5: 0.813 | DG5: 3.63 | DM5: 0.238 | DQ5: 3.35 | DY5: 1.82 | EA5: 1.46 | EB5: 1.46 | EE5: 0.011 | EG5: 0.011 | EL5: 0.02 | EN5: 0.02 | FM5: 411 | FN5: 0.166 | FO5: 0.594 | FP5: 0.616 | FQ5: 1.05 | FR5: 0.832 | FS5: 0.418 | FT5: 0.66 | FU5: 0.512 | FV5: 0.734 | FW5: 0.787 | FX5: 0.283 | FY5: 0.667 | FZ5: 1.27 | GA5: 1.63 | GB5: 0.408 | GC5: 0.56 | GD5: 0.919 | GE5: 0 | GF5: 0.385
A6: 2345190 | B6: Carrots, glazed, cooked | D6: Survey (FNDDS) | E6: 100 | F6: =E6/SUM($E$3:$E$8) | G6: 78.49 | H6: 94.44 | I6: 395.13696 | J6: 0.144 | K6: 0.9 | L6: 2.68 | M6: 2.68 | O6: 16.68 | P6: 2.6 | Q6: 12.14 | Y6: 38 | Z6: 0.34 | AA6: 12 | AB6: 33 | AC6: 307 | AD6: 197 | AE6: 0.23 | AF6: 0.046 | AI6: 0.2 | AK6: 15 | AL6: 0.055 | AM6: 0.051 | AN6: 0.872 | AO6: 0.118 | AP6: 15 | AQ6: 0 | AR6: 15 | AS6: 8.9 | AZ6: 0 | BA6: 0 | BB6: 756 | BC6: 22 | BD6: 7280 | BG6: 3053 | BH6: 0 | BK6: 1 | BN6: 225 | BS6: 0 | BW6: 12.4 | BZ6: 0.61 | CA6: 0 | CI6: 4.6 | CK6: 0 | CL6: 0 | CM6: 1.393 | CN6: 0.061 | CP6: 0.043 | CR6: 0.025 | CT6: 0.057 | CV6: 0.066 | CW6: 0.214 | CY6: 0.662 | DA6: 0.224 | DG6: 0.516 | DL6: 0.032 | DP6: 0.458 | DR6: 0.003 | DT6: 0 | DY6: 0.169 | DZ6: 0.16 | ED6: 0.012 | EH6: 0 | EP6: 0.003 | ES6: 0.001 | EX6: 0.001 | EZ6: 0 | FM6: 7 | GO6: 0
A7: 746782 | B7: Milk, whole, 3.25% milkfat, with added vitamin D | D7: Foundation | E7: 100 | F7: =E7/SUM($E$3:$E$8) | G7: 88.1 | H7: 60.4 | I7: 252.7136 | J7: 0.51 | K7: 3.27 | L7: 2.77 | M7: 3.2 | N7: 0.8 | O7: 4.63 | Q7: 4.81 | R7: 0 | S7: 0 | T7: 0 | U7: 4.81 | V7: 0 | W7: 0 | Y7: 123 | Z7: 0 | AA7: 11.9 | AB7: 101 | AC7: 150 | AD7: 38 | AE7: 0.42 | AF7: 0.001 | AG7: 0 | AH7: 37.9 | AI7: 1.9 | AL7: 0.056 | AM7: 0.138 | AN7: 0.105 | AO7: 0.061 | AP7: 0 | AS7: 17.8 | AT7: 3 | AU7: 1.3 | AV7: 1.8 | AW7: 10.3 | AX7: 1.4 | AY7: 0.7 | AZ7: 0.54 | BB7: 32 | BC7: 31 | BD7: 7 | BE7: 2 | BF7: 5 | BG7: 0 | BH7: 0 | BI7: 0 | BK7: 0 | BL7: 0 | BM7: 0 | BO7: 0 | BP7: 5 | BQ7: 1 | BR7: 38.4 | BS7: 0.96 | BT7: 0 | BU7: 0.96 | BV7: 0 | BZ7: 0.05 | CB7: 0 | CC7: 0 | CD7: 0 | CE7: 0 | CF7: 0 | CG7: 0 | CH7: 0 | CJ7: 0.362 | CM7: 1.86 | CN7: 0.067 | CO7: 0 | CP7: 0.054 | CQ7: 0 | CR7: 0.034 | CS7: 0 | CT7: 0.084 | CU7: 0 | CV7: 0.097 | CW7: 0.303 | CX7: 0.032 | CY7: 0.857 | CZ7: 0.018 | DA7: 0.309 | DB7: 0.004 | DC7: 0 | DD7: 0.002 | DE7: 0 | DF7: 0.001 | DG7: 0.688 | DH7: 0.001 | DJ7: 0.024 | DK7: 0 | DM7: 0.039 | DN7: 0.005 | DO7: 0.005 | DQ7: 0.612 | DS7: 0.004 | DU7: 0 | DV7: 0 | DW7: 0 | DX7: 0 | DY7: 0.108 | EA7: 0.097 | EB7: 0.084 | EC7: 0.013 | EE7: 0.013 | EF7: 0.012 | EG7: 0.001 | EH7: 0 | EI7: 0.001 | EJ7: 0.001 | EL7: 0.004 | EM7: 0 | EN7: 0.004 | EO7: 0 | EP7: 0.004 | EQ7: 0.004 | ER7: 0.001 | ES7: 0.001 | ET7: 0 | EU7: 0 | EV7: 0.001 | EW7: 0.002 | EX7: 0.002 | EY7: 0 | EZ7: 0 | FA7: 0.112 | FB7: 0.095 | FC7: 0.018 | FD7: 0 | FE7: 0.005 | FF7: 0.008 | FG7: 0.082 | FI7: 0.018 | FJ7: 0 | FK7: 0 | FL7: 0 | FM7: 12 | FN7: 0.043 | FO7: 0.154 | FP7: 0.173 | FQ7: 0.333 | FR7: 0.298 | FS7: 0.09 | FT7: 0.161 | FU7: 0.162 | FV7: 0.207 | FW7: 0.127 | FX7: 0.097 | FY7: 0.11 | FZ7: 0.279 | GA7: 0.788 | GB7: 0.069 | GC7: 0.333 | GD7: 0.188 | GE7: 0 | GF7: 0.038
A8: 2003591 | B8: Orange juice, no pulp, not fortified, from concentrate, refrigerated | D8: Foundation | E8: 100 | F8: =E8/SUM($E$3:$E$8) | G8: 88.2 | H8: 47.061 | I8: 196.90322 | J8: 0.118 | K8: 0.734 | L8: 0.325 | M8: 0.325 | N8: 0.35 | O8: 10.3 | Q8: 8.28 | R8: 4.39 | S8: 1.79 | T8: 2.1 | U8: 0 | V8: 0 | W8: 0 | Y8: 12.8 | Z8: 0.0646 | AA8: 10.6 | AB8: 18.2 | AC8: 180 | AD8: 5.23 | AE8: 0.0319 | AF8: 0.0322 | AG8: 0.0299 | AL8: 0.0701 | AN8: 0.0403 | AO8: 0.0429 | AP8: 29.8 | CI8: 26.9 | GK8: 706 | GL8: 161 | GM8: 0 | GN8: 12.3
A9: Total | B9: Formulado | C9: Formulado | D9: Formulado | E9: =SUBTOTAL(9,E3:E8) | F9: 100% | G9: =SUMPRODUCT($F$3:$F$8,$G$3:$G$8) | H9: =SUMPRODUCT($F$3:$F$8,$H$3:$H$8) | I9: =SUMPRODUCT($F$3:$F$8,$I$3:$I$8) | J9: =SUMPRODUCT($F$3:$F$8,$J$3:$J$8) | K9: =SUMPRODUCT($F$3:$F$8,$K$3:$K$8) | L9: =SUMPRODUCT($F$3:$F$8,$L$3:$L$8) | M9: =SUMPRODUCT($F$3:$F$8,$M$3:$M$8) | N9: =SUMPRODUCT($F$3:$F$8,$N$3:$N$8) | O9: =SUMPRODUCT($F$3:$F$8,$O$3:$O$8) | P9: =SUMPRODUCT($F$3:$F$8,$P$3:$P$8) | Q9: =SUMPRODUCT($F$3:$F$8,$Q$3:$Q$8) | R9: =SUMPRODUCT($F$3:$F$8,$R$3:$R$8) | S9: =SUMPRODUCT($F$3:$F$8,$S$3:$S$8) | T9: =SUMPRODUCT($F$3:$F$8,$T$3:$T$8) | U9: =SUMPRODUCT($F$3:$F$8,$U$3:$U$8) | V9: =SUMPRODUCT($F$3:$F$8,$V$3:$V$8) | W9: =SUMPRODUCT($F$3:$F$8,$W$3:$W$8) | X9: =SUMPRODUCT($F$3:$F$8,$X$3:$X$8) | Y9: =SUMPRODUCT($F$3:$F$8,$Y$3:$Y$8) | Z9: =SUMPRODUCT($F$3:$F$8,$Z$3:$Z$8) | AA9: =SUMPRODUCT($F$3:$F$8,$AA$3:$AA$8) | AB9: =SUMPRODUCT($F$3:$F$8,$AB$3:$AB$8) | AC9: =SUMPRODUCT($F$3:$F$8,$AC$3:$AC$8) | AD9: =SUMPRODUCT($F$3:$F$8,$AD$3:$AD$8) | AE9: =SUMPRODUCT($F$3:$F$8,$AE$3:$AE$8) | AF9: =SUMPRODUCT($F$3:$F$8,$AF$3:$AF$8) | AG9: =SUMPRODUCT($F$3:$F$8,$AG$3:$AG$8) | AH9: =SUMPRODUCT($F$3:$F$8,$AH$3:$AH$8) | AI9: =SUMPRODUCT($F$3:$F$8,$AI$3:$AI$8) | AJ9: =SUMPRODUCT($F$3:$F$8,$AJ$3:$AJ$8) | AK9: =SUMPRODUCT($F$3:$F$8,$AK$3:$AK$8) | AL9: =SUMPRODUCT($F$3:$F$8,$AL$3:$AL$8) | AM9: =SUMPRODUCT($F$3:$F$8,$AM$3:$AM$8) | AN9: =SUMPRODUCT($F$3:$F$8,$AN$3:$AN$8) | AO9: =SUMPRODUCT($F$3:$F$8,$AO$3:$AO$8) | AP9: =SUMPRODUCT($F$3:$F$8,$AP$3:$AP$8) | AQ9: =SUMPRODUCT($F$3:$F$8,$AQ$3:$AQ$8) | AR9: =SUMPRODUCT($F$3:$F$8,$AR$3:$AR$8) | AS9: =SUMPRODUCT($F$3:$F$8,$AS$3:$AS$8) | AT9: =SUMPRODUCT($F$3:$F$8,$AT$3:$AT$8) | AU9: =SUMPRODUCT($F$3:$F$8,$AU$3:$AU$8) | AV9: =SUMPRODUCT($F$3:$F$8,$AV$3:$AV$8) | AW9: =SUMPRODUCT($F$3:$F$8,$AW$3:$AW$8) | AX9: =SUMPRODUCT($F$3:$F$8,$AX$3:$AX$8) | AY9: =SUMPRODUCT($F$3:$F$8,$AY$3:$AY$8) | AZ9: =SUMPRODUCT($F$3:$F$8,$AZ$3:$AZ$8) | BA9: =SUMPRODUCT($F$3:$F$8,$BA$3:$BA$8) | BB9: =SUMPRODUCT($F$3:$F$8,$BB$3:$BB$8) | BC9: =SUMPRODUCT($F$3:$F$8,$BC$3:$BC$8) | BD9: =SUMPRODUCT($F$3:$F$8,$BD$3:$BD$8) | BE9: =SUMPRODUCT($F$3:$F$8,$BE$3:$BE$8) | BF9: =SUMPRODUCT($F$3:$F$8,$BF$3:$BF$8) | BG9: =SUMPRODUCT($F$3:$F$8,$BG$3:$BG$8) | BH9: =SUMPRODUCT($F$3:$F$8,$BH$3:$BH$8) | BI9: =SUMPRODUCT($F$3:$F$8,$BI$3:$BI$8) | BJ9: =SUMPRODUCT($F$3:$F$8,$BJ$3:$BJ$8) | BK9: =SUMPRODUCT($F$3:$F$8,$BK$3:$BK$8) | BL9: =SUMPRODUCT($F$3:$F$8,$BL$3:$BL$8) | BM9: =SUMPRODUCT($F$3:$F$8,$BM$3:$BM$8) | BN9: =SUMPRODUCT($F$3:$F$8,$BN$3:$BN$8) | BO9: =SUMPRODUCT($F$3:$F$8,$BO$3:$BO$8) | BP9: =SUMPRODUCT($F$3:$F$8,$BP$3:$BP$8) | BQ9: =SUMPRODUCT($F$3:$F$8,$BQ$3:$BQ$8) | BR9: =SUMPRODUCT($F$3:$F$8,$BR$3:$BR$8) | BS9: =SUMPRODUCT($F$3:$F$8,$BS$3:$BS$8) | BT9: =SUMPRODUCT($F$3:$F$8,$BT$3:$BT$8) | BU9: =SUMPRODUCT($F$3:$F$8,$BU$3:$BU$8) | BV9: =SUMPRODUCT($F$3:$F$8,$BV$3:$BV$8) | BW9: =SUMPRODUCT($F$3:$F$8,$BW$3:$BW$8) | BX9: =SUMPRODUCT($F$3:$F$8,$BX$3:$BX$8) | BY9: =SUMPRODUCT($F$3:$F$8,$BY$3:$BY$8) | BZ9: =SUMPRODUCT($F$3:$F$8,$BZ$3:$BZ$8) | CA9: =SUMPRODUCT($F$3:$F$8,$CA$3:$CA$8) | CB9: =SUMPRODUCT($F$3:$F$8,$CB$3:$CB$8) | CC9: =SUMPRODUCT($F$3:$F$8,$CC$3:$CC$8) | CD9: =SUMPRODUCT($F$3:$F$8,$CD$3:$CD$8) | CE9: =SUMPRODUCT($F$3:$F$8,$CE$3:$CE$8) | CF9: =SUMPRODUCT($F$3:$F$8,$CF$3:$CF$8) | CG9: =SUMPRODUCT($F$3:$F$8,$CG$3:$CG$8) | CH9: =SUMPRODUCT($F$3:$F$8,$CH$3:$CH$8) | CI9: =SUMPRODUCT($F$3:$F$8,$CI$3:$CI$8) | CJ9: =SUMPRODUCT($F$3:$F$8,$CJ$3:$CJ$8) | CK9: =SUMPRODUCT($F$3:$F$8,$CK$3:$CK$8) | CL9: =SUMPRODUCT($F$3:$F$8,$CL$3:$CL$8) | CM9: =SUMPRODUCT($F$3:$F$8,$CM$3:$CM$8) | CN9: =SUMPRODUCT($F$3:$F$8,$CN$3:$CN$8) | CO9: =SUMPRODUCT($F$3:$F$8,$CO$3:$CO$8) | CP9: =SUMPRODUCT($F$3:$F$8,$CP$3:$CP$8) | CQ9: =SUMPRODUCT($F$3:$F$8,$CQ$3:$CQ$8) | CR9: =SUMPRODUCT($F$3:$F$8,$CR$3:$CR$8) | CS9: =SUMPRODUCT($F$3:$F$8,$CS$3:$CS$8) | CT9: =SUMPRODUCT($F$3:$F$8,$CT$3:$CT$8) | CU9: =SUMPRODUCT($F$3:$F$8,$CU$3:$CU$8) | CV9: =SUMPRODUCT($F$3:$F$8,$CV$3:$CV$8) | CW9: =SUMPRODUCT($F$3:$F$8,$CW$3:$CW$8) | CX9: =SUMPRODUCT($F$3:$F$8,$CX$3:$CX$8) | CY9: =SUMPRODUCT($F$3:$F$8,$CY$3:$CY$8) | CZ9: =SUMPRODUCT($F$3:$F$8,$CZ$3:$CZ$8) | DA9: =SUMPRODUCT($F$3:$F$8,$DA$3:$DA$8) | DB9: =SUMPRODUCT($F$3:$F$8,$DB$3:$DB$8) | DC9: =SUMPRODUCT($F$3:$F$8,$DC$3:$DC$8) | DD9: =SUMPRODUCT($F$3:$F$8,$DD$3:$DD$8) | DE9: =SUMPRODUCT($F$3:$F$8,$DE$3:$DE$8) | DF9: =SUMPRODUCT($F$3:$F$8,$DF$3:$DF$8) | DG9: =SUMPRODUCT($F$3:$F$8,$DG$3:$DG$8) | DH9: =SUMPRODUCT($F$3:$F$8,$DH$3:$DH$8) | DI9: =SUMPRODUCT($F$3:$F$8,$DI$3:$DI$8) | DJ9: =SUMPRODUCT($F$3:$F$8,$DJ$3:$DJ$8) | DK9: =SUMPRODUCT($F$3:$F$8,$DK$3:$DK$8) | DL9: =SUMPRODUCT($F$3:$F$8,$DL$3:$DL$8) | DM9: =SUMPRODUCT($F$3:$F$8,$DM$3:$DM$8) | DN9: =SUMPRODUCT($F$3:$F$8,$DN$3:$DN$8) | DO9: =SUMPRODUCT($F$3:$F$8,$DO$3:$DO$8) | DP9: =SUMPRODUCT($F$3:$F$8,$DP$3:$DP$8) | DQ9: =SUMPRODUCT($F$3:$F$8,$DQ$3:$DQ$8) | DR9: =SUMPRODUCT($F$3:$F$8,$DR$3:$DR$8) | DS9: =SUMPRODUCT($F$3:$F$8,$DS$3:$DS$8) | DT9: =SUMPRODUCT($F$3:$F$8,$DT$3:$DT$8) | DU9: =SUMPRODUCT($F$3:$F$8,$DU$3:$DU$8) | DV9: =SUMPRODUCT($F$3:$F$8,$DV$3:$DV$8) | DW9: =SUMPRODUCT($F$3:$F$8,$DW$3:$DW$8) | DX9: =SUMPRODUCT($F$3:$F$8,$DX$3:$DX$8) | DY9: =SUMPRODUCT($F$3:$F$8,$DY$3:$DY$8) | DZ9: =SUMPRODUCT($F$3:$F$8,$DZ$3:$DZ$8) | EA9: =SUMPRODUCT($F$3:$F$8,$EA$3:$EA$8) | EB9: =SUMPRODUCT($F$3:$F$8,$EB$3:$EB$8) | EC9: =SUMPRODUCT($F$3:$F$8,$EC$3:$EC$8) | ED9: =SUMPRODUCT($F$3:$F$8,$ED$3:$ED$8) | EE9: =SUMPRODUCT($F$3:$F$8,$EE$3:$EE$8) | EF9: =SUMPRODUCT($F$3:$F$8,$EF$3:$EF$8) | EG9: =SUMPRODUCT($F$3:$F$8,$EG$3:$EG$8) | EH9: =SUMPRODUCT($F$3:$F$8,$EH$3:$EH$8) | EI9: =SUMPRODUCT($F$3:$F$8,$EI$3:$EI$8) | EJ9: =SUMPRODUCT($F$3:$F$8,$EJ$3:$EJ$8) | EK9: =SUMPRODUCT($F$3:$F$8,$EK$3:$EK$8) | EL9: =SUMPRODUCT($F$3:$F$8,$EL$3:$EL$8) | EM9: =SUMPRODUCT($F$3:$F$8,$EM$3:$EM$8) | EN9: =SUMPRODUCT($F$3:$F$8,$EN$3:$EN$8) | EO9: =SUMPRODUCT($F$3:$F$8,$EO$3:$EO$8) | EP9: =SUMPRODUCT($F$3:$F$8,$EP$3:$EP$8) | EQ9: =SUMPRODUCT($F$3:$F$8,$EQ$3:$EQ$8) | ER9: =SUMPRODUCT($F$3:$F$8,$ER$3:$ER$8) | ES9: =SUMPRODUCT($F$3:$F$8,$ES$3:$ES$8) | ET9: =SUMPRODUCT($F$3:$F$8,$ET$3:$ET$8) | EU9: =SUMPRODUCT($F$3:$F$8,$EU$3:$EU$8) | EV9: =SUMPRODUCT($F$3:$F$8,$EV$3:$EV$8) | EW9: =SUMPRODUCT($F$3:$F$8,$EW$3:$EW$8) | EX9: =SUMPRODUCT($F$3:$F$8,$EX$3:$EX$8) | EY9: =SUMPRODUCT($F$3:$F$8,$EY$3:$EY$8) | EZ9: =SUMPRODUCT($F$3:$F$8,$EZ$3:$EZ$8) | FA9: =SUMPRODUCT($F$3:$F$8,$FA$3:$FA$8) | FB9: =SUMPRODUCT($F$3:$F$8,$FB$3:$FB$8) | FC9: =SUMPRODUCT($F$3:$F$8,$FC$3:$FC$8) | FD9: =SUMPRODUCT($F$3:$F$8,$FD$3:$FD$8) | FE9: =SUMPRODUCT($F$3:$F$8,$FE$3:$FE$8) | FF9: =SUMPRODUCT($F$3:$F$8,$FF$3:$FF$8) | FG9: =SUMPRODUCT($F$3:$F$8,$FG$3:$FG$8) | FH9: =SUMPRODUCT($F$3:$F$8,$FH$3:$FH$8) | FI9: =SUMPRODUCT($F$3:$F$8,$FI$3:$FI$8) | FJ9: =SUMPRODUCT($F$3:$F$8,$FJ$3:$FJ$8) | FK9: =SUMPRODUCT($F$3:$F$8,$FK$3:$FK$8) | FL9: =SUMPRODUCT($F$3:$F$8,$FL$3:$FL$8) | FM9: =SUMPRODUCT($F$3:$F$8,$FM$3:$FM$8) | FN9: =SUMPRODUCT($F$3:$F$8,$FN$3:$FN$8) | FO9: =SUMPRODUCT($F$3:$F$8,$FO$3:$FO$8) | FP9: =SUMPRODUCT($F$3:$F$8,$FP$3:$FP$8) | FQ9: =SUMPRODUCT($F$3:$F$8,$FQ$3:$FQ$8) | FR9: =SUMPRODUCT($F$3:$F$8,$FR$3:$FR$8) | FS9: =SUMPRODUCT($F$3:$F$8,$FS$3:$FS$8) | FT9: =SUMPRODUCT($F$3:$F$8,$FT$3:$FT$8) | FU9: =SUMPRODUCT($F$3:$F$8,$FU$3:$FU$8) | FV9: =SUMPRODUCT($F$3:$F$8,$FV$3:$FV$8) | FW9: =SUMPRODUCT($F$3:$F$8,$FW$3:$FW$8) | FX9: =SUMPRODUCT($F$3:$F$8,$FX$3:$FX$8) | FY9: =SUMPRODUCT($F$3:$F$8,$FY$3:$FY$8) | FZ9: =SUMPRODUCT($F$3:$F$8,$FZ$3:$FZ$8) | GA9: =SUMPRODUCT($F$3:$F$8,$GA$3:$GA$8) | GB9: =SUMPRODUCT($F$3:$F$8,$GB$3:$GB$8) | GC9: =SUMPRODUCT($F$3:$F$8,$GC$3:$GC$8) | GD9: =SUMPRODUCT($F$3:$F$8,$GD$3:$GD$8) | GE9: =SUMPRODUCT($F$3:$F$8,$GE$3:$GE$8) | GF9: =SUMPRODUCT($F$3:$F$8,$GF$3:$GF$8) | GG9: =SUMPRODUCT($F$3:$F$8,$GG$3:$GG$8) | GH9: =SUMPRODUCT($F$3:$F$8,$GH$3:$GH$8) | GI9: =SUMPRODUCT($F$3:$F$8,$GI$3:$GI$8) | GJ9: =SUMPRODUCT($F$3:$F$8,$GJ$3:$GJ$8) | GK9: =SUMPRODUCT($F$3:$F$8,$GK$3:$GK$8) | GL9: =SUMPRODUCT($F$3:$F$8,$GL$3:$GL$8) | GM9: =SUMPRODUCT($F$3:$F$8,$GM$3:$GM$8) | GN9: =SUMPRODUCT($F$3:$F$8,$GN$3:$GN$8) | GO9: =SUMPRODUCT($F$3:$F$8,$GO$3:$GO$8)

Sheet Totales
A1: Nutriente | B1: Total | C1: Unidad
A2: Water | B2: =Ingredientes!G9 | C2: g
A3: Energy | B3: =Ingredientes!H9 | C3: kcal
A4: Energy | B4: =Ingredientes!I9 | C4: kJ
A5: Nitrogen | B5: =Ingredientes!J9 | C5: g
A6: Protein | B6: =Ingredientes!K9 | C6: g
A7: Total fat (NLEA) | B7: =Ingredientes!L9 | C7: g
A8: Total lipid (fat) | B8: =Ingredientes!M9 | C8: g
A9: Ash | B9: =Ingredientes!N9 | C9: g
A10: Carbohydrate, by difference | B10: =Ingredientes!O9 | C10: g
A11: Fiber, total dietary | B11: =Ingredientes!P9 | C11: g
A12: Sugars, Total | B12: =Ingredientes!Q9 | C12: g
A13: Sucrose | B13: =Ingredientes!R9 | C13: g
A14: Glucose | B14: =Ingredientes!S9 | C14: g
A15: Fructose | B15: =Ingredientes!T9 | C15: g
A16: Lactose | B16: =Ingredientes!U9 | C16: g
A17: Maltose | B17: =Ingredientes!V9 | C17: g
A18: Galactose | B18: =Ingredientes!W9 | C18: g
A19: Starch | B19: =Ingredientes!X9 | C19: g
A20: Calcium, Ca | B20: =Ingredientes!Y9 | C20: mg
A21: Iron, Fe | B21: =Ingredientes!Z9 | C21: mg
A22: Magnesium, Mg | B22: =Ingredientes!AA9 | C22: mg
A23: Phosphorus, P | B23: =Ingredientes!AB9 | C23: mg
A24: Potassium, K | B24: =Ingredientes!AC9 | C24: mg
A25: Sodium, Na | B25: =Ingredientes!AD9 | C25: mg
A26: Zinc, Zn | B26: =Ingredientes!AE9 | C26: mg
A27: Copper, Cu | B27: =Ingredientes!AF9 | C27: mg
A28: Manganese, Mn | B28: =Ingredientes!AG9 | C28: mg
A29: Iodine, I | B29: =Ingredientes!AH9 | C29: µg
A30: Selenium, Se | B30: =Ingredientes!AI9 | C30: µg
A31: Fluoride, F | B31: =Ingredientes!AJ9 | C31: µg
A32: Folate, food | B32: =Ingredientes!AK9 | C32: µg
A33: Thiamin | B33: =Ingredientes!AL9 | C33: mg
A34: Riboflavin | B34: =Ingredientes!AM9 | C34: mg
A35: Niacin | B35: =Ingredientes!AN9 | C35: mg
A36: Vitamin B-6 | B36: =Ingredientes!AO9 | C36: mg
A37: Folate, total | B37: =Ingredientes!AP9 | C37: µg
A38: Folic acid | B38: =Ingredientes!AQ9 | C38: µg
A39: Folate, DFE | B39: =Ingredientes!AR9 | C39: µg
A40: Choline, total | B40: =Ingredientes!AS9 | C40: mg
...
