Workbook

Sheet Ingredientes
A1: Detalles de formulación | G1: Proximates | P1: Carbohydrates | AD1: Minerals | AQ1: Vitamins and Other Components | CU1: Lipids | FX1: Amino acids | GQ1: Phytosterols | GZ1: Organic acids | HD1: Oligosaccharides | HG1: Isoflavones | HL1: Nutrientes
A2: FDC ID | B2: Ingrediente | C2: Marca / Origen | D2: Tipo de dato | E2: Cantidad (g) | F2: Cantidad (%) | G2: Water (g) | H2: Energy (kcal) | I2: Energy (kJ) | J2: Nitrogen (g) | K2: Protein (g) | L2: Total fat (NLEA) (g) | M2: Total lipid (fat) (g) | N2: Ash (g) | O2: Carbohydrate, by difference (g) | P2: Fiber, total dietary (g) | Q2: Total dietary fiber (AOAC 2011.25) (g) | R2: High Molecular Weight Dietary Fiber (HMWDF) (g) | S2: Low Molecular Weight Dietary Fiber (LMWDF) (g) | T2: Sugars, Total (g) | U2: Sucrose (g) | V2: Glucose (g) | W2: Fructose (g) | X2: Lactose (g) | Y2: Maltose (g) | Z2: Galactose (g) | AA2: Starch (g) | AB2: Resistant starch (g) | AC2: Sugars, added (g) | AD2: Calcium, Ca (mg) | AE2: Iron, Fe (mg) | AF2: Magnesium, Mg (mg) | AG2: Phosphorus, P (mg) | AH2: Potassium, K (mg) | AI2: Sodium, Na (mg) | AJ2: Zinc, Zn (mg) | AK2: Copper, Cu (mg) | AL2: Manganese, Mn (mg) | AM2: Iodine, I (µg) | AN2: Selenium, Se (µg) | AO2: Molybdenum, Mo (µg) | AP2: Fluoride, F (µg) | AQ2: Folate, food (µg) | AR2: Thiamin (mg) | AS2: Riboflavin (mg) | AT2: Niacin (mg) | AU2: Vitamin B-6 (mg) | AV2: Folate, total (µg) | AW2: Folic acid (µg) | AX2: Folate, DFE (µg) | AY2: Choline, total (mg) | AZ2: Choline, free (mg) | BA2: Choline, from phosphocholine (mg) | BB2: Choline, from phosphatidyl choline (mg) | BC2: Choline, from glycerophosphocholine (mg) | BD2: Choline, from sphingomyelin (mg) | BE2: Betaine (mg) | BF2: Vitamin B-12 (µg) | BG2: Vitamin B-12, added (µg) | BH2: Vitamin A, RAE (µg) | BI2: Retinol (µg) | BJ2: Carotene, beta (µg) | BK2: cis-beta-Carotene (µg) | BL2: trans-beta-Carotene (µg) | BM2: Carotene, alpha (µg) | BN2: Carotene, gamma (µg) | BO2: Cryptoxanthin, beta (µg) | BP2: Cryptoxanthin, alpha (µg) | BQ2: Vitamin A, IU (iu) | BR2: Lycopene (µg) | BS2: cis-Lycopene (µg) | BT2: trans-Lycopene (µg) | BU2: Lutein + zeaxanthin (µg) | BV2: cis-Lutein/Zeaxanthin (µg) | BW2: Lutein (µg) | BX2: Zeaxanthin (µg) | BY2: Vitamin D (D2 + D3), International Units (iu) | BZ2: Vitamin D (D2 + D3) (µg) | CA2: Vitamin D2 (ergocalciferol) (µg) | CB2: Vitamin D3 (cholecalciferol) (µg) | CC2: 25-hydroxycholecalciferol (µg) | CD2: Vitamin K (phylloquinone) (µg) | CE2: Vitamin K (Dihydrophylloquinone) (µg) | CF2: Vitamin K (Menaquinone-4) (µg) | CG2: Vitamin E (alpha-tocopherol) (mg) | CH2: Vitamin E, added (mg) | CI2: Tocopherol, beta (mg) | CJ2: Tocopherol, gamma (mg) | CK2: Tocopherol, delta (mg) | CL2: Tocotrienol, alpha (mg) | CM2: Tocotrienol, beta (mg) | CN2: Tocotrienol, gamma (mg) | CO2: Tocotrienol, delta (mg) | CP2: Vitamin C, total ascorbic acid (mg) | CQ2: Pantothenic acid (mg) | CR2: Biotin (µg) | CS2: Caffeine (mg) | CT2: Theobromine (mg) | CU2: Fatty acids, total saturated (g) | CV2: SFA 4:0 (g) | CW2: SFA 5:0 (g) | CX2: SFA 6:0 (g) | CY2: SFA 7:0 (g) | CZ2: SFA 8:0 (g) | DA2: SFA 9:0 (g) | DB2: SFA 10:0 (g) | DC2: SFA 11:0 (g) | DD2: SFA 12:0 (g) | DE2: SFA 13:0 (g) | DF2: SFA 14:0 (g) | DG2: SFA 15:0 (g) | DH2: SFA 16:0 (g) | DI2: SFA 17:0 (g) | DJ2: SFA 18:0 (g) | DK2: SFA 20:0 (g) | DL2: SFA 21:0 (g) | DM2: SFA 22:0 (g) | DN2: SFA 23:0 (g) | DO2: SFA 24:0 (g) | DP2: Fatty acids, total monounsaturated (g) | DQ2: MUFA 12:1 (g) | DR2: MUFA 14:1 (g) | DS2: MUFA 14:1 c (g) | DT2: MUFA 15:1 (g) | DU2: MUFA 16:1 (g) | DV2: MUFA 16:1 c (g) | DW2: MUFA 17:1 (g) | DX2: MUFA 17:1 c (g) | DY2: MUFA 18:1 (g) | DZ2: MUFA 18:1 c (g) | EA2: MUFA 20:1 (g) | EB2: MUFA 20:1 c (g) | EC2: MUFA 22:1 (g) | ED2: MUFA 22:1 c (g) | EE2: MUFA 22:1 n-9 (g) | EF2: MUFA 22:1 n-11 (g) | EG2: MUFA 24:1 c (g) | EH2: Fatty acids, total polyunsaturated (g) | EI2: PUFA 18:2 (g) | EJ2: PUFA 18:2 c (g) | EK2: PUFA 18:2 n-6 c,c (g) | EL2: PUFA 18:2 CLAs (g) | EM2: PUFA 18:3 (g) | EN2: PUFA 18:3 c (g) | EO2: PUFA 18:3 n-3 c,c,c (ALA) (g) | EP2: PUFA 18:3 n-6 c,c,c (g) | EQ2: PUFA 18:4 (g) | ER2: PUFA 20:2 c (g) | ES2: PUFA 20:2 n-6 c,c (g) | ET2: PUFA 20:3 (g) | EU2: PUFA 20:3 c (g) | EV2: PUFA 20:3 n-3 (g) | EW2: PUFA 20:3 n-6 (g) | EX2: PUFA 20:3 n-9 (g) | EY2: PUFA 20:4 (g) | EZ2: PUFA 20:4c (g) | FA2: PUFA 20:5c (g) | FB2: PUFA 20:5 n-3 (EPA) (g) | FC2: PUFA 22:2 (g) | FD2: PUFA 22:3 (g) | FE2: PUFA 22:4 (g) | FF2: PUFA 22:5 c (g) | FG2: PUFA 22:5 n-3 (DPA) (g) | FH2: PUFA 22:6 c (g) | FI2: PUFA 22:6 n-3 (DHA) (g) | FJ2: Fatty acids, total trans (g) | FK2: Fatty acids, total trans-monoenoic (g) | FL2: Fatty acids, total trans-dienoic (g) | FM2: Fatty acids, total trans-polyenoic (g) | FN2: TFA 14:1 t (g) | FO2: TFA 16:1 t (g) | FP2: TFA 18:1 t (g) | FQ2: TFA 18:2 t (g) | FR2: TFA 18:2 t,t (g) | FS2: TFA 18:2 t not further defined (g) | FT2: TFA 18:3 t (g) | FU2: TFA 20:1 t (g) | FV2: TFA 22:1 t (g) | FW2: Cholesterol (mg) | FX2: Tryptophan (g) | FY2: Threonine (g) | FZ2: Isoleucine (g) | GA2: Leucine (g) | GB2: Lysine (g) | GC2: Methionine (g) | GD2: Phenylalanine (g) | GE2: Tyrosine (g) | GF2: Valine (g) | GG2: Arginine (g) | GH2: Histidine (g) | GI2: Alanine (g) | GJ2: Aspartic acid (g) | GK2: Glutamic acid (g) | GL2: Glycine (g) | GM2: Proline (g) | GN2: Serine (g) | GO2: Hydroxyproline (g) | GP2: Cysteine (g) | GQ2: Phytosterols (mg) | GR2: Beta-sitosterol (mg) | GS2: Brassicasterol (mg) | GT2: Campesterol (mg) | GU2: Campestanol (mg) | GV2: Delta-5-avenasterol (mg) | GW2: Phytosterols, other (mg) | GX2: Stigmasterol (mg) | GY2: Beta-sitostanol (mg) | GZ2: Citric acid (mg) | HA2: Malic acid (mg) | HB2: Oxalic acid (mg) | HC2: Quinic acid (mg) | HD2: Verbascose (g) | HE2: Raffinose (g) | HF2: Stachyose (g) | HG2: Daidzin (mg) | HH2: Genistin (mg) | HI2: Glycitin (mg) | HJ2: Daidzein (mg) | HK2: Genistein (mg) | HL2: Alcohol, ethyl (g)
A3: 748967 | B3: Eggs, Grade A, Large, egg whole | D3: Foundation | E3: 150 | F3: =E3/SUM($E$3:$E$33) | G3: 75.8 | H3: 143.08 | I3: 598.64672 | J3: 1.99 | K3: 12.4 | L3: 8.65 | M3: 9.96 | N3: 0.85 | O3: 0.96 | P3: 0 | T3: 0.2 | U3: 0 | V3: 0.2 | W3: 0 | X3: 0 | Y3: 0 | AA3: 0 | AD3: 48 | AE3: 1.67 | AF3: 11.4 | AG3: 184 | AH3: 132 | AI3: 129 | AJ3: 1.24 | AK3: 0 | AL3: 0 | AM3: 49.1 | AN3: 31.1 | AR3: 0.077 | AS3: 0.419 | AT3: 0 | AU3: 0.063 | AV3: 71 | AY3: 335 | AZ3: 0.6 | BA3: 309 | BB3: 0.2 | BC3: 0.2 | BD3: 25.1 | BE3: 0.3 | BF3: 1.02 | BH3: 180 | BI3: 179 | BJ3: 0 | BK3: 0 | BL3: 0 | BM3: 0 | BO3: 13 | BP3: 13 | BR3: 0 | BS3: 0 | BT3: 0 | BV3: 57 | BW3: 230 | BX3: 229 | BY3: 98.4 | BZ3: 2.46 | CA3: 0 | CB3: 2.46 | CC3: 0.56 | CU3: 3.2 | DF3: 0.032 | DH3: 2.32 | DJ3: 0.813 | DP3: 3.63 | DV3: 0.238 | DZ3: 3.35 | EH3: 1.82 | EJ3: 1.46 | EK3: 1.46 | EN3: 0.011 | EP3: 0.011 | EU3: 0.02 | EW3: 0.02 | FW3: 411 | FX3: 0.166 | FY3: 0.594 | FZ3: 0.616 | GA3: 1.05 | GB3: 0.832 | GC3: 0.418 | GD3: 0.66 | GE3: 0.512 | GF3: 0.734 | GG3: 0.787 | GH3: 0.283 | GI3: 0.667 | GJ3: 1.27 | GK3: 1.63 | GL3: 0.408 | GM3: 0.56 | GN3: 0.919 | GO3: 0 | GP3: 0.385
A4: 174158 | B4: Water, bottled, generic | D4: SR Legacy | E4: 116.47304 | F4: =E4/SUM($E$3:$E$33) | G4: 100 | H4: 0 | I4: 0 | J4: 0 | K4: 0 | L4: 0 | M4: 0 | N4: 0.07 | O4: 0 | P4: 0 | T4: 0 | AD4: 10 | AE4: 0 | AF4: 2 | AG4: 0 | AH4: 0 | AI4: 2 | AJ4: 0 | AK4: 0.007 | AN4: 0 | AQ4: 0 | AR4: 0 | AS4: 0 | AT4: 0 | AU4: 0 | AV4: 0 | AW4: 0 | AX4: 0 | AY4: 0 | BF4: 0 | BG4: 0 | BH4: 0 | BI4: 0 | BJ4: 0 | BM4: 0 | BO4: 0 | BQ4: 0 | BR4: 0 | BU4: 0 | BY4: 0 | BZ4: 0 | CD4: 0 | CG4: 0 | CH4: 0 | CP4: 0 | CQ4: 0 | CS4: 0 | CT4: 0 | CU4: 0 | CV4: 0 | CX4: 0 | CZ4: 0 | DB4: 0 | DD4: 0 | DF4: 0 | DH4: 0 | DJ4: 0 | DP4: 0 | DU4: 0 | DY4: 0 | EA4: 0 | EC4: 0 | EH4: 0 | EI4: 0 | EM4: 0 | EQ4: 0 | EY4: 0 | FB4: 0 | FG4: 0 | FI4: 0 | FJ4: 0 | FW4: 0 | HL4: 0
A5: 171320 | B5: Spices, cinnamon, ground | D5: SR Legacy | E5: 39.666667 | F5: =E5/SUM($E$3:$E$33) | G5: 10.6 | H5: 349.52 | I5: 1462.3917 | J5: 0.6384 | K5: 3.99 | L5: 1.24 | M5: 1.24 | N5: 3.6 | O5: 80.6 | P5: 53.1 | T5: 2.17 | U5: 0.02 | V5: 1.04 | W5: 1.11 | X5: 0 | Y5: 0 | Z5: 0 | AD5: 1000 | AE5: 8.32 | AF5: 60 | AG5: 64 | AH5: 431 | AI5: 10 | AJ5: 1.83 | AK5: 0.339 | AL5: 17.5 | AN5: 3.1 | AQ5: 6 | AR5: 0.022 | AS5: 0.041 | AT5: 1.33 | AU5: 0.158 | AV5: 6 | AW5: 0 | AX5: 6 | AY5: 11 | BE5: 3.9 | BF5: 0 | BG5: 0 | BH5: 15 | BI5: 0 | BJ5: 112 | BM5: 1 | BO5: 129 | BQ5: 295 | BR5: 15 | BU5: 222 | BY5: 0 | BZ5: 0 | CD5: 31.2 | CE5: 0 | CG5: 2.32 | CH5: 0 | CI5: 0 | CJ5: 10.4 | CK5: 0.26 | CL5: 0 | CM5: 0 | CN5: 0 | CO5: 0 | CP5: 3.8 | CQ5: 0.358 | CS5: 0 | CT5: 0 | CU5: 0.345 | CV5: 0 | CX5: 0 | CZ5: 0 | DB5: 0.003 | DD5: 0.006 | DE5: 0 | DF5: 0.009 | DG5: 0 | DH5: 0.104 | DI5: 0.136 | DJ5: 0.082 | DK5: 0 | DM5: 0 | DO5: 0 | DP5: 0.246 | DR5: 0 | DT5: 0 | DU5: 0.001 | DW5: 0 | DY5: 0.246 | DZ5: 0.246 | EA5: 0 | EC5: 0 | EG5: 0 | EH5: 0.068 | EI5: 0.044 | EM5: 0.011 | EO5: 0.011 | EP5: 0 | EQ5: 0 | ES5: 0 | ET5: 0 | EY5: 0 | FB5: 0 | FG5: 0 | FI5: 0 | FJ5: 0 | FK5: 0 | FP5: 0 | FW5: 0 | FX5: 0.049 | FY5: 0.136 | FZ5: 0.146 | GA5: 0.253 | GB5: 0.243 | GC5: 0.078 | GD5: 0.146 | GE5: 0.136 | GF5: 0.224 | GG5: 0.166 | GH5: 0.117 | GI5: 0.166 | GJ5: 0.438 | GK5: 0.37 | GL5: 0.195 | GM5: 0.419 | GN5: 0.195 | GO5: 0 | GP5: 0.058 | GQ5: 26 | HL5: 0
A6: 172336 | B6: Oil, canola | D6: SR Legacy | E6: 30 | F6: =E6/SUM($E$3:$E$33) | G6: 0 | H6: 900 | I6: 3765.6 | J6: 0 | K6: 0 | L6: 100 | M6: 100 | N6: 0 | O6: 0 | P6: 0 | T6: 0 | AD6: 0 | AE6: 0 | AF6: 0 | AG6: 0 | AH6: 0 | AI6: 0 | AJ6: 0 | AK6: 0 | AL6: 0 | AN6: 0 | AQ6: 0 | AR6: 0 | AS6: 0 | AT6: 0 | AU6: 0 | AV6: 0 | AW6: 0 | AX6: 0 | AY6: 0.2 | BE6: 0 | BF6: 0 | BG6: 0 | BH6: 0 | BI6: 0 | BJ6: 0 | BM6: 0 | BO6: 0 | BQ6: 0 | BR6: 0 | BU6: 0 | BY6: 0 | BZ6: 0 | CD6: 71.3 | CE6: 0 | CF6: 0 | CG6: 17.5 | CH6: 0 | CI6: 0.01 | CJ6: 27.3 | CK6: 0.99 | CL6: 0.03 | CM6: 0 | CN6: 0 | CO6: 0.01 | CP6: 0 | CQ6: 0 | CS6: 0 | CT6: 0 | CU6: 7.36 | CV6: 0 | CX6: 0 | CZ6: 0 | DB6: 0 | DD6: 0 | DF6: 0 | DG6: 0 | DH6: 4.3 | DI6: 0 | DJ6: 2.09 | DK6: 0.65 | DM6: 0.33 | DP6: 63.3 | DR6: 0 | DT6: 0 | DU6: 0.214 | DW6: 0 | DY6: 61.7 | DZ6: 61.7 | EA6: 1.32 | EC6: 0 | EH6: 28.1 | EI6: 19 | EK6: 18.6 | EM6: 9.14 | EO6: 9.14 | EP6: 0 | EQ6: 0 | ES6: 0 | ET6: 0 | EY6: 0 | FB6: 0 | FG6: 0 | FI6: 0 | FJ6: 0.395 | FK6: 0.03 | FM6: 0.365 | FP6: 0.03 | FR6: 0.365 | FW6: 0 | GR6: 413 | GT6: 241 | GX6: 3 | HL6: 0
A7: 748366 | B7: Oil, soybean | D7: Foundation | E7: 5 | F7: =E7/SUM($E$3:$E$33) | H7: 851.4 | I7: 3562.2576 | L7: 94.6 | M7: 94.6 | CG7: 12.2 | CI7: 1.8 | CJ7: 70.4 | CK7: 22 | CL7: 0 | CM7: 1.6 | CN7: 0 | CO7: 0 | CU7: 14.9 | DF7: 0.075 | DG7: 0.014 | DH7: 10.3 | DI7: 0.086 | DJ7: 3.71 | DK7: 0.294 | DL7: 0.025 | DM7: 0.306 | DO7: 0.124 | DP7: 22.1 | DV7: 0.08 | DZ7: 21.4 | EB7: 0.6 | EH7: 57.6 | EJ7: 50.9 | EK7: 50.9 | EN7: 6.62 | EO7: 6.62 | EU7: 0 | EW7: 0 | GR7: 153 | GS7: 0 | GT7: 58 | GU7: 2.15 | GV7: 10.5 | GW7: 20.8 | GX7: 55.4 | GY7: 5.62
A8: 173468 | B8: Salt, table | D8: SR Legacy | E8: 3.1301472 | F8: =E8/SUM($E$3:$E$33) | G8: 0.2 | H8: 0 | I8: 0 | J8: 0 | K8: 0 | L8: 0 | M8: 0 | N8: 99.8 | O8: 0 | P8: 0 | T8: 0 | AD8: 24 | AE8: 0.33 | AF8: 1 | AG8: 0 | AH8: 8 | AI8: 38800 | AJ8: 0.1 | AK8: 0.03 | AL8: 0.1 | AN8: 0.1 | AP8: 2 | AQ8: 0 | AR8: 0 | AS8: 0 | AT8: 0 | AU8: 0 | AV8: 0 | AW8: 0 | AX8: 0 | AY8: 0 | BF8: 0 | BG8: 0 | BH8: 0 | BI8: 0 | BJ8: 0 | BM8: 0 | BO8: 0 | BQ8: 0 | BR8: 0 | BU8: 0 | BY8: 0 | BZ8: 0 | CD8: 0 | CG8: 0 | CH8: 0 | CP8: 0 | CQ8: 0 | CS8: 0 | CT8: 0 | CU8: 0 | CV8: 0 | CX8: 0 | CZ8: 0 | DB8: 0 | DD8: 0 | DF8: 0 | DH8: 0 | DJ8: 0 | DP8: 0 | DU8: 0 | DY8: 0 | EA8: 0 | EC8: 0 | EH8: 0 | EI8: 0 | EM8: 0 | EQ8: 0 | EY8: 0 | FB8: 0 | FG8: 0 | FI8: 0 | FJ8: 0 | FW8: 0 | FX8: 0 | FY8: 0 | FZ8: 0 | GA8: 0 | GB8: 0 | GC8: 0 | GD8: 0 | GE8: 0 | GF8: 0 | GG8: 0 | GH8: 0 | GI8: 0 | GJ8: 0 | GK8: 0 | GL8: 0 | GM8: 0 | GN8: 0 | GP8: 0 | GQ8: 0 | HL8: 0
A9: 2644283 | B9: Lentils, dry | D9: Foundation | E9: 32.8 | F9: =E9/SUM($E$3:$E$33) | G9: 9.45 | H9: 360.48 | I9: 1508.2483 | J9: 3.77 | K9: 23.6 | L9: 1.92 | M9: 1.92 | N9: 2.88 | O9: 62.2 | AA9: 37.1 | AB9: 16 | AD9: 61.8 | AE9: 7.16 | AF9: 107 | AG9: 374 | AH9: 949 | AI9: 0 | AJ9: 3.86 | AK9: 0.838 | AL9: 1.57
A10: 2707920 | B10: Cookie, chocolate sandwich | D10: Survey (FNDDS) | E10: 100 | F10: =E10/SUM($E$3:$E$33) | G10: 3.11 | H10: 476.74 | I10: 1994.6802 | J10: 0.8336 | K10: 5.21 | L10: 19.1 | M10: 19.1 | O10: 71 | P10: 2.9 | T10: 40.7 | AD10: 21 | AE10: 12.1 | AF10: 47 | AG10: 93 | AH10: 234 | AI10: 388 | AJ10: 0.74 | AK10: 0.334 | AN10: 5.2 | AQ10: 3 | AR10: 0.197 | AS10: 0.238 | AT10: 2.6 | AU10: 0.023 | AV10: 61 | AW10: 58 | AX10: 102 | AY10: 19.2 | BF10: 0 | BG10: 0 | BH10: 1 | BI10: 0 | BJ10: 0 | BM10: 0 | BO10: 0 | BR10: 0 | BU10: 4 | BZ10: 0 | CD10: 27.4 | CG10: 2.47 | CH10: 0 | CP10: 0 | CS10: 5 | CT10: 184 | CU10: 5.65 | CV10: 0 | CX10: 0 | CZ10: 0.003 | DB10: 0.011 | DD10: 0.045 | DF10: 0.111 | DH10: 4.45 | DJ10: 0.857 | DP10: 9.28 | DU10: 0.036 | DY10: 9.11 | EA10: 0.12 | EC10: 0.003 | EH10: 3.56 | EI10: 3.25 | EM10: 0.298 | EQ10: 0 | EY10: 0.004 | FB10: 0 | FG10: 0 | FI10: 0 | FW10: 0 | HL10: 0
A11: 746782 | B11: Milk, whole, 3.25% milkfat, with added vitamin D | D11: Foundation | E11: 100 | F11: =E11/SUM($E$3:$E$33) | G11: 88.1 | H11: 60.4 | I11: 252.7136 | J11: 0.51 | K11: 3.27 | L11: 2.77 | M11: 3.2 | N11: 0.8 | O11: 4.63 | T11: 4.81 | U11: 0 | V11: 0 | W11: 0 | X11: 4.81 | Y11: 0 | Z11: 0 | AD11: 123 | AE11: 0 | AF11: 11.9 | AG11: 101 | AH11: 150 | AI11: 38 | AJ11: 0.42 | AK11: 0.001 | AL11: 0 | AM11: 37.9 | AN11: 1.9 | AR11: 0.056 | AS11: 0.138 | AT11: 0.105 | AU11: 0.061 | AV11: 0 | AY11: 17.8 | AZ11: 3 | BA11: 1.3 | BB11: 1.8 | BC11: 10.3 | BD11: 1.4 | BE11: 0.7 | BF11: 0.54 | BH11: 32 | BI11: 31 | BJ11: 7 | BK11: 2 | BL11: 5 | BM11: 0 | BO11: 0 | BP11: 0 | BR11: 0 | BS11: 0 | BT11: 0 | BV11: 0 | BW11: 5 | BX11: 1 | BY11: 38.4 | BZ11: 0.96 | CA11: 0 | CB11: 0.96 | CC11: 0 | CG11: 0.05 | CI11: 0 | CJ11: 0 | CK11: 0 | CL11: 0 | CM11: 0 | CN11: 0 | CO11: 0 | CQ11: 0.362 | CU11: 1.86 | CV11: 0.067 | CW11: 0 | CX11: 0.054 | CY11: 0 | CZ11: 0.034 | DA11: 0 | DB11: 0.084 | DC11: 0 | DD11: 0.097 | DF11: 0.303 | DG11: 0.032 | DH11: 0.857 | DI11: 0.018 | DJ11: 0.309 | DK11: 0.004 | DL11: 0 | DM11: 0.002 | DN11: 0 | DO11: 0.001 | DP11: 0.688 | DQ11: 0.001 | DS11: 0.024 | DT11: 0 | DV11: 0.039 | DW11: 0.005 | DX11: 0.005 | DZ11: 0.612 | EB11: 0.004 | ED11: 0 | EE11: 0 | EF11: 0 | EG11: 0 | EH11: 0.108 | EJ11: 0.097 | EK11: 0.084 | EL11: 0.013 | EN11: 0.013 | EO11: 0.012 | EP11: 0.001 | EQ11: 0 | ER11: 0.001 | ES11: 0.001 | EU11: 0.004 | EV11: 0 | EW11: 0.004 | EX11: 0 | EY11: 0.004 | EZ11: 0.004 | FA11: 0.001 | FB11: 0.001 | FC11: 0 | FD11: 0 | FE11: 0.001 | FF11: 0.002 | FG11: 0.002 | FH11: 0 | FI11: 0 | FJ11: 0.112 | FK11: 0.095 | FL11: 0.018 | FM11: 0 | FN11: 0.005 | FO11: 0.008 | FP11: 0.082 | FS11: 0.018 | FT11: 0 | FU11: 0 | FV11: 0 | FW11: 12 | FX11: 0.043 | FY11: 0.154 | FZ11: 0.173 | GA11: 0.333 | GB11: 0.298 | GC11: 0.09 | GD11: 0.161 | GE11: 0.162 | GF11: 0.207 | GG11: 0.127 | GH11: 0.097 | GI11: 0.11 | GJ11: 0.279 | GK11: 0.788 | GL11: 0.069 | GM11: 0.333 | GN11: 0.188 | GO11: 0 | GP11: 0.038
A12: 2720960 | B12: Pringles Crisps Bbq 16.9oz | C12: Kellogg Company US | D12: Branded | E12: 100 | F12: =E12/SUM($E$3:$E$33) | G12: 4.3 | H12: 529.2 | I12: 2214.1728 | J12: 0.72 | K12: 4.5 | L12: 31.2 | M12: 31.2 | O12: 57.6 | P12: 2.4 | T12: 4.3 | AC12: 3.2 | AD12: 9.7 | AE12: 0.6 | AH12: 412 | AI12: 482 | BZ12: 0 | CU12: 8.6 | FJ12: 0 | FW12: 0
A13: 2257045 | B13: Almond milk, unsweetened, plain, refrigerated | D13: Foundation | E13: 100 | F13: =E13/SUM($E$3:$E$33) | G13: 96.5 | H13: 19.348 | I13: 80.952032 | J13: 0.105 | K13: 0.656 | L13: 1.56 | M13: 1.56 | N13: 0.595 | O13: 0.671 | P13: 0 | U13: 0.0386 | V13: 0 | W13: 0 | X13: 0 | Y13: 0 | Z13: 0 | AD13: 158 | AE13: 0.125 | AF13: 8.25 | AG13: 19.1 | AH13: 49.3 | AI13: 59.2 | AJ13: 0.0766 | AK13: 0.0269 | AL13: 0.0564 | AR13: 0.005 | AS13: 0.0833 | AT13: 0.0888 | AU13: 0 | AV13: 0 | BF13: 0.449 | BI13: 60.9 | BY13: 63.6 | BZ13: 1.59 | CA13: 1.58 | CB13: 0.0102 | CD13: 0 | CE13: 0 | CF13: 0 | CR13: 1.42 | FX13: 0.00125 | FY13: 0.01 | FZ13: 0.0262 | GA13: 0.0462 | GB13: 0.0312 | GC13: 0.00125 | GD13: 0.0425 | GE13: 0.0188 | GF13: 0.0175 | GG13: 0.0925 | GH13: 0.0138 | GI13: 0.0288 | GJ13: 0.0775 | GK13: 0.138 | GL13: 0.045 | GM13: 0.0312 | GN13: 0.02 | GO13: 0 | GP13: 0.00125
A14: 1999631 | B14: Almond milk, unsweetened, plain, shelf stable | D14: Foundation | E14: 100 | F14: =E14/SUM($E$3:$E$33) | G14: 97.4 | H14: 14.548 | I14: 60.868832 | J14: 0.0888 | K14: 0.555 | L14: 1.11 | M14: 1.22 | N14: 0.487 | O14: 0.337 | P14: 0 | T14: 0 | U14: 0 | V14: 0 | W14: 0 | X14: 0 | Y14: 0 | Z14: 0 | AD14: 173 | AE14: 0.29 | AF14: 6.78 | AG14: 29.8 | AH14: 30.8 | AI14: 59.6 | AJ14: 0.172 | AK14: 0.0213 | AL14: 0.045 | AM14: 0 | AN14: 0 | AO14: 0 | AR14: 0 | AS14: 0.0334 | AT14: 0.0744 | AU14: 0 | AV14: 0 | BF14: 0.338 | BH14: 41.4 | BI14: 41.4 | BY14: 37.1 | BZ14: 0.927 | CA14: 0.927 | CB14: 0 | CG14: 3.32 | CI14: 0 | CJ14: 0.0275 | CK14: 0 | CL14: 0 | CM14: 0 | CN14: 0 | CO14: 0 | CR14: 1.02 | CU14: 0.104 | CV14: 0.00369 | CW14: 0 | CX14: 0 | CY14: 0 | CZ14: 0 | DA14: 0 | DB14: 0 | DC14: 0 | DD14: 0 | DF14: 0.00238 | DG14: 0.00125 | DH14: 0.0778 | DI14: 0.000875 | DJ14: 0.0195 | DK14: 0 | DL14: 0 | DM14: 0 | DN14: 0 | DO14: 0 | DP14: 0.729 | DQ14: 0 | DS14: 0 | DT14: 0 | DV14: 0.00581 | DW14: 0.00125 | DX14: 0.00125 | DZ14: 0.721 | EB14: 0.000875 | ED14: 0 | EE14: 0 | EF14: 0 | EG14: 0 | EH14: 0.276 | EJ14: 0.276 | EK14: 0.276 | EL14: 0 | EN14: 0.000625 | EO14: 0.000625 | EP14: 0 | EQ14: 0 | ER14: 0 | ES14: 0 | EU14: 0 | EV14: 0 | EW14: 0 | EX14: 0 | EY14: 0 | EZ14: 0 | FA14: 0 | FB14: 0 | FC14: 0 | FD14: 0 | FE14: 0 | FF14: 0 | FG14: 0 | FH14: 0 | FI14: 0 | FJ14: 0 | FK14: 0 | FM14: 0 | FN14: 0 | FO14: 0 | FP14: 0 | FQ14: 0.000125 | FS14: 0.000125 | FT14: 0 | FU14: 0 | FV14: 0 | HD14: 0 | HE14: 0.00788 | HF14: 0.0075
A15: 2259796 | B15: Cheese, feta, whole milk, crumbled | D15: Foundation | E15: 100 | F15: =E15/SUM($E$3:$E$33) | G15: 51.9 | H15: 273.02 | I15: 1142.3157 | J15: 3.09 | K15: 19.7 | L15: 19.1 | M15: 19.1 | N15: 3.74 | O15: 5.58 | T15: 1.63 | U15: 0 | V15: 0.586 | W15: 0 | X15: 0.61 | Y15: 0 | Z15: 0.429 | AD15: 371 | AE15: 0.0675 | AF15: 17.7 | AG15: 328 | AH15: 105 | AI15: 1030 | AJ15: 2.35 | AK15: 0.0316 | AL15: 0.02 | AM15: 48.4 | AR15: 0.0564 | AS15: 0.444 | AT15: 0.264 | AU15: 0.0383 | BI15: 147 | BY15: 0 | BZ15: 0 | CA15: 0 | CB15: 0 | CD15: 1.2 | CE15: 0 | CF15: 4.8 | CR15: 0.464 | CU15: 11.2 | CV15: 0.404 | CX15: 0.334 | DB15: 0.481 | DD15: 0.545 | DF15: 1.8 | DH15: 5.31 | DJ15: 1.74 | DP15: 4.18 | DV15: 0.285 | DZ15: 3.66 | EK15: 0.424 | FW15: 57.5
A16: 746766 | B16: Cheese, ricotta, whole milk | D16: Foundation | E16: 100 | F16: =E16/SUM($E$3:$E$33) | G16: 72.9 | H16: 157.68 | I16: 659.73312 | J16: 1.22 | K16: 7.81 | L16: 10.3 | M16: 11 | N16: 1.36 | O16: 6.86 | AD16: 224 | AE16: 0.1 | AF16: 19.7 | AG16: 162 | AH16: 230 | AI16: 105 | AJ16: 0.56 | AK16: 0 | AL16: 0 | AN16: 5.5 | AR16: 0.043 | AS16: 0.327 | AT16: 0.168 | AU16: 0.099 | AV16: 4 | BF16: 0.78 | BH16: 127 | BI16: 127 | CD16: 0.6 | CE16: 0 | CF16: 3.1 | CG16: 0.27 | CI16: 0 | CJ16: 0 | CK16: 0 | CL16: 0 | CM16: 0 | CN16: 0 | CO16: 0 | CQ16: 0.673 | CU16: 6.97 | CV16: 0.251 | CX16: 0.199 | CZ16: 0.125 | DB16: 0.306 | DC16: 0 | DD16: 0.36 | DF16: 1.15 | DG16: 0.116 | DH16: 3.36 | DI16: 0.067 | DJ16: 1.02 | DK16: 0.014 | DM16: 0.006 | DO16: 0.004 | DP16: 2.56 | DS16: 0.117 | DT16: 0 | DV16: 0.184 | DW16: 0.021 | DX16: 0.021 | DZ16: 2.22 | EB16: 0.02 | ED16: 0.002 | EE16: 0.002 | EG16: 0 | EH16: 0.389 | EJ16: 0.308 | EK16: 0.259 | EL16: 0.049 | EN16: 0.042 | EO16: 0.042 | EP16: 0 | EQ16: 0.001 | ER16: 0.001 | ES16: 0.001 | EU16: 0.012 | EV16: 0 | EW16: 0.012 | EX16: 0 | EY16: 0.015 | EZ16: 0.015 | FA16: 0.005 | FB16: 0.005 | FC16: 0 | FE16: 0.003 | FF16: 0.007 | FG16: 0.007 | FH16: 0 | FI16: 0 | FJ16: 0.351 | FK16: 0.283 | FL16: 0.068 | FM16: 0.001 | FO16: 0.032 | FP16: 0.251 | FS16: 0.068 | FT16: 0.001 | FV16: 0 | FW16: 48 | FX16: 0.115 | FY16: 0.395 | FZ16: 0.365 | GA16: 0.785 | GB16: 0.655 | GC16: 0.17 | GD16: 0.27 | GE16: 0.25 | GF16: 0.325 | GG16: 0.21 | GH16: 0.175 | GI16: 0.325 | GJ16: 0.735 | GK16: 1.3 | GL16: 0.135 | GM16: 0.565 | GN16: 0.365 | GO16: 0 | GP16: 0.18
A17: 746772 | B17: Milk, lowfat, fluid, 1% milkfat, with added vitamin A and vitamin D | D17: Foundation | E17: 100 | F17: =E17/SUM($E$3:$E$33) | G17: 89.7 | H17: 42.79 | I17: 179.03336 | J17: 0.53 | K17: 3.38 | L17: 0.85 | M17: 0.95 | N17: 0.8 | O17: 5.18 | T17: 4.96 | U17: 0 | V17: 0 | W17: 0 | X17: 4.96 | Y17: 0 | Z17: 0 | AD17: 126 | AE17: 0 | AF17: 12 | AG17: 103 | AH17: 159 | AI17: 39 | AJ17: 0.43 | AK17: 0.001 | AL17: 0 | AM17: 36.2 | AN17: 2.1 | AR17: 0.057 | AS17: 0.14 | AT17: 0.113 | AU17: 0.06 | AV17: 2 | AY17: 17.4 | AZ17: 3 | BA17: 0.9 | BB17: 1.8 | BC17: 10.9 | BD17: 0.8 | BE17: 0.9 | BF17: 0.61 | BH17: 58 | BI17: 58 | BJ17: 1 | BK17: 0 | BL17: 1 | BM17: 0 | BO17: 0 | BP17: 0 | BR17: 0 | BS17: 0 | BT17: 0 | BV17: 0 | BW17: 0 | BX17: 0 | BY17: 42.4 | BZ17: 1.06 | CA17: 0 | CB17: 1.06 | CC17: 0 | CG17: 0.02 | CI17: 0 | CJ17: 0 | CK17: 0 | CL17: 0 | CM17: 0 | CN17: 0 | CO17: 0 | CQ17: 0.368 | CU17: 0.568 | CV17: 0.022 | CW17: 0 | CX17: 0.015 | CY17: 0 | CZ17: 0.011 | DA17: 0 | DB17: 0.023 | DC17: 0 | DD17: 0.026 | DF17: 0.093 | DG17: 0.01 | DH17: 0.265 | DI17: 0.006 | DJ17: 0.096 | DK17: 0.001 | DL17: 0 | DM17: 0 | DN17: 0 | DO17: 0 | DP17: 0.21 | DQ17: 0 | DS17: 0.007 | DT17: 0 | DV17: 0.012 | DW17: 0.002 | DX17: 0.002 | DZ17: 0.187 | EB17: 0.001 | ED17: 0 | EE17: 0 | EF17: 0 | EG17: 0 | EH17: 0.032 | EJ17: 0.029 | EK17: 0.026 | EL17: 0.004 | EN17: 0.004 | EO17: 0.004 | EP17: 0 | EQ17: 0 | ER17: 0 | ES17: 0 | EU17: 0.001 | EV17: 0 | EW17: 0.001 | EX17: 0 | EY17: 0.001 | EZ17: 0.001 | FA17: 0 | FB17: 0 | FC17: 0 | FD17: 0 | FE17: 0 | FF17: 0 | FG17: 0 | FH17: 0 | FI17: 0 | FJ17: 0.036 | FK17: 0.031 | FL17: 0.004 | FM17: 0 | FN17: 0.001 | FO17: 0.002 | FP17: 0.027 | FS17: 0.004 | FT17: 0 | FU17: 0 | FV17: 0 | FW17: 5 | FX17: 0.045 | FY17: 0.158 | FZ17: 0.174 | GA17: 0.342 | GB17: 0.308 | GC17: 0.092 | GD17: 0.168 | GE17: 0.167 | GF17: 0.21 | GG17: 0.128 | GH17: 0.099 | GI17: 0.111 | GJ17: 0.286 | GK17: 0.809 | GL17: 0.069 | GM17: 0.349 | GN17: 0.194 | GO17: 0 | GP17: 0.036
A18: 746776 | B18: Milk, nonfat, fluid, with added vitamin A and vitamin D (fat free or skim) | D18: Foundation | E18: 100 | F18: =E18/SUM($E$3:$E$33) | G18: 90.8 | H18: 34.12 | I18: 142.75808 | J18: 0.54 | K18: 3.43 | L18: 0.07 | M18: 0.08 | N18: 0.77 | O18: 4.92 | T18: 5.05 | U18: 0 | V18: 0 | W18: 0 | X18: 5.05 | Y18: 0 | Z18: 0 | AD18: 132 | AE18: 0 | AF18: 12.5 | AG18: 107 | AH18: 167 | AI18: 41 | AJ18: 0.45 | AK18: 0.002 | AL18: 0.001 | AM18: 35.7 | AN18: 2 | AR18: 0.056 | AS18: 0.131 | AT18: 0.118 | AU18: 0.058 | AV18: 2 | AY18: 18.2 | AZ18: 3.1 | BA18: 0.8 | BB18: 2 | BC18: 11.5 | BD18: 0.9 | BE18: 0.9 | BF18: 0.58 | BH18: 64 | BI18: 64 | BJ18: 2 | BK18: 1 | BL18: 1 | BM18: 0 | BO18: 0 | BP18: 0 | BR18: 0 | BS18: 0 | BT18: 0 | BV18: 0 | BW18: 1 | BX18: 0 | BY18: 44 | BZ18: 1.1 | CA18: 0 | CB18: 1.1 | CC18: 0 | CG18: 0 | CI18: 0 | CJ18: 0 | CK18: 0 | CL18: 0 | CM18: 0 | CN18: 0 | CO18: 0 | CQ18: 0.388 | CU18: 0.049 | CV18: 0.003 | CW18: 0 | CX18: 0.001 | CY18: 0 | CZ18: 0.001 | DA18: 0 | DB18: 0.002 | DC18: 0 | DD18: 0.002 | DF18: 0.008 | DG18: 0.001 | DH18: 0.021 | DI18: 0.001 | DJ18: 0.009 | DK18: 0 | DL18: 0 | DM18: 0 | DN18: 0 | DO18: 0 | DP18: 0.017 | DQ18: 0 | DS18: 0 | DT18: 0 | DV18: 0.001 | DW18: 0 | DX18: 0 | DZ18: 0.017 | EB18: 0 | ED18: 0 | EE18: 0 | EF18: 0 | EG18: 0 | EH18: 0.006 | EJ18: 0.005 | EK18: 0.005 | EL18: 0 | EN18: 0 | EO18: 0 | EP18: 0 | EQ18: 0 | ER18: 0 | ES18: 0 | EU18: 0 | EV18: 0 | EW18: 0 | EX18: 0 | EY18: 0 | EZ18: 0 | FA18: 0 | FB18: 0 | FC18: 0 | FD18: 0 | FE18: 0 | FF18: 0 | FG18: 0 | FH18: 0 | FI18: 0 | FJ18: 0 | FK18: 0.001 | FL18: 0 | FM18: 0 | FN18: 0 | FO18: 0 | FP18: 0.001 | FS18: 0 | FT18: 0 | FU18: 0 | FV18: 0 | FW18: 3 | FX18: 0.048 | FY18: 0.166 | FZ18: 0.182 | GA18: 0.347 | GB18: 0.302 | GC18: 0.093 | GD18: 0.168 | GE18: 0.168 | GF18: 0.222 | GG18: 0.131 | GH18: 0.101 | GI18: 0.118 | GJ18: 0.299 | GK18: 0.832 | GL18: 0.071 | GM18: 0.348 | GN18: 0.202 | GO18: 0 | GP18: 0.038
A19: 746778 | B19: Milk, reduced fat, fluid, 2% milkfat, with added vitamin A and vitamin D | D19: Foundation | E19: 100 | F19: =E19/SUM($E$3:$E$33) | G19: 89.1 | H19: 50.14 | I19: 209.78576 | J19: 0.53 | K19: 3.36 | L19: 1.64 | M19: 1.9 | N19: 0.75 | O19: 4.9 | T19: 4.89 | U19: 0 | V19: 0 | W19: 0 | X19: 4.89 | Y19: 0 | Z19: 0 | AD19: 126 | AE19: 0 | AF19: 12 | AG19: 103 | AH19: 159 | AI19: 39 | AJ19: 0.43 | AK19: 0.001 | AL19: 0.001 | AM19: 39.6 | AN19: 1.8 | AR19: 0.059 | AS19: 0.137 | AT19: 0.112 | AU19: 0.061 | AV19: 2 | AY19: 18.2 | AZ19: 3.1 | BA19: 1.1 | BB19: 1.9 | BC19: 11 | BD19: 1.2 | BE19: 0.7 | BF19: 0.55 | BH19: 83 | BI19: 83 | BJ19: 3 | BK19: 1 | BL19: 2 | BM19: 0 | BO19: 0 | BP19: 0 | BR19: 0 | BS19: 0 | BT19: 0 | BV19: 0 | BW19: 0 | BX19: 0 | BY19: 45.2 | BZ19: 1.13 | CA19: 0 | CB19: 1.13 | CC19: 0 | CG19: 0.03 | CI19: 0 | CJ19: 0 | CK19: 0 | CL19: 0 | CM19: 0 | CN19: 0 | CO19: 0 | CQ19: 0.39 | CU19: 1.11 | CV19: 0.041 | CW19: 0 | CX19: 0.032 | CY19: 0 | CZ19: 0.021 | DA19: 0 | DB19: 0.049 | DC19: 0 | DD19: 0.058 | DF19: 0.181 | DG19: 0.019 | DH19: 0.512 | DI19: 0.011 | DJ19: 0.184 | DK19: 0.002 | DL19: 0 | DM19: 0.001 | DN19: 0 | DO19: 0 | DP19: 0.4 | DQ19: 0.001 | DS19: 0.014 | DT19: 0 | DV19: 0.024 | DW19: 0.003 | DX19: 0.003 | DZ19: 0.358 | EB19: 0.002 | ED19: 0 | EE19: 0 | EF19: 0 | EG19: 0 | EH19: 0.058 | EJ19: 0.052 | EK19: 0.045 | EL19: 0.007 | EN19: 0.007 | EO19: 0.007 | EP19: 0 | EQ19: 0 | ER19: 0 | ES19: 0 | EU19: 0.002 | EV19: 0 | EW19: 0.002 | EX19: 0 | EY19: 0.003 | EZ19: 0.003 | FA19: 0 | FB19: 0 | FC19: 0 | FD19: 0 | FE19: 0 | FF19: 0.001 | FG19: 0.001 | FH19: 0 | FI19: 0 | FJ19: 0.07 | FK19: 0.06 | FL19: 0.009 | FM19: 0 | FN19: 0.003 | FO19: 0.005 | FP19: 0.052 | FS19: 0.009 | FT19: 0 | FU19: 0 | FV19: 0 | FW19: 8 | FX19: 0.042 | FY19: 0.162 | FZ19: 0.173 | GA19: 0.335 | GB19: 0.293 | GC19: 0.089 | GD19: 0.163 | GE19: 0.165 | GF19: 0.213 | GG19: 0.125 | GH19: 0.099 | GI19: 0.113 | GJ19: 0.291 | GK19: 0.801 | GL19: 0.068 | GM19: 0.332 | GN19: 0.197 | GO19: 0 | GP19: 0.035
A20: 2257046 | B20: Oat milk, unsweetened, plain, refrigerated | D20: Foundation | E20: 100 | F20: =E20/SUM($E$3:$E$33) | G20: 90.6 | H20: 48.338 | I20: 202.24619 | J20: 0.128 | K20: 0.797 | L20: 2.75 | M20: 2.75 | N20: 0.794 | O20: 5.1 | P20: 0 | T20: 2.32 | U20: 0 | V20: 0.771 | W20: 0 | X20: 0 | Y20: 1.55 | Z20: 0 | AD20: 148 | AE20: 0.261 | AF20: 5.91 | AG20: 89.2 | AH20: 148 | AI20: 42 | AJ20: 0.0906 | AK20: 0.0271 | AL20: 0.126 | AN20: 0 | AO20: 10.1 | AR20: 0.04 | AS20: 0.281 | AT20: 0.0962 | AU20: 0.0065 | AV20: 0 | BF20: 0.506 | BI20: 84.7 | BY20: 68 | BZ20: 1.7 | CA20: 1.69 | CB20: 0.00769 | CD20: 0.4 | CE20: 0 | CF20: 0 | CR20: 1.41 | FX20: 0.00875 | FY20: 0.0225 | FZ20: 0.025 | GA20: 0.0812 | GB20: 0.0612 | GC20: 0.01 | GD20: 0.0725 | GE20: 0.0412 | GF20: 0.0325 | GG20: 0.0825 | GH20: 0.0175 | GI20: 0.0375 | GJ20: 0.0825 | GK20: 0.15 | GL20: 0.0562 | GM20: 0.0725 | GN20: 0.0562 | GO20: 0 | GP20: 0.025
A21: 2257044 | B21: Soy milk, sweetened, plain, refrigerated | D21: Foundation | E21: 100 | F21: =E21/SUM($E$3:$E$33) | G21: 91.5 | H21: 40.76 | I21: 170.53984 | J21: 0.444 | K21: 2.78 | L21: 1.96 | M21: 1.96 | N21: 0.75 | O21: 3 | P21: 0 | U21: 2.58 | V21: 0 | W21: 0 | X21: 0 | Y21: 0 | Z21: 0 | AD21: 155 | AE21: 0.367 | AF21: 17.5 | AG21: 46 | AH21: 118 | AI21: 39.4 | AJ21: 0.264 | AK21: 0.0956 | AL21: 0.16 | AN21: 0 | AO21: 32.3 | AR21: 0.0436 | AS21: 0.331 | AT21: 0.133 | AU21: 0.0364 | AV21: 15.8 | BF21: 1.33 | BI21: 89.4 | BY21: 185 | BZ21: 4.63 | CA21: 4.61 | CB21: 0.0201 | CD21: 2.8 | CE21: 0 | CF21: 0 | CR21: 2.16 | FX21: 0.0343 | FY21: 0.1 | FZ21: 0.1 | GA21: 0.2 | GB21: 0.2 | GC21: 0.0329 | GD21: 0.157 | GE21: 0.1 | GF21: 0.101 | GG21: 0.2 | GH21: 0.1 | GI21: 0.1 | GJ21: 0.329 | GK21: 0.486 | GL21: 0.1 | GM21: 0.114 | GN21: 0.171 | GO21: 0 | GP21: 0.0486 | HG21: 7.96 | HH21: 14.7 | HI21: 0.364 | HJ21: 0.139 | HK21: 0.236
A22: 1999630 | B22: Soy milk, unsweetened, plain, shelf stable | D22: Foundation | E22: 100 | F22: =E22/SUM($E$3:$E$33) | G22: 92.4 | H22: 38.44 | I22: 160.83296 | J22: 0.568 | K22: 3.55 | L22: 1.88 | M22: 2.12 | N22: 0.635 | O22: 1.29 | P22: 0 | T22: 0.557 | U22: 0.557 | V22: 0 | W22: 0 | X22: 0 | Y22: 0 | Z22: 0 | AD22: 101 | AE22: 0.542 | AF22: 21.5 | AG22: 68.6 | AH22: 158 | AI22: 34.3 | AJ22: 0.312 | AK22: 0.108 | AL22: 0.208 | AM22: 0 | AN22: 1.94 | AO22: 58.4 | AR22: 0.0632 | AS22: 0.084 | AT22: 0.236 | AU22: 0.0552 | AV22: 19.7 | BF22: 0.393 | BH22: 58.2 | BI22: 58.2 | BJ22: 0 | BK22: 0 | BL22: 0 | BM22: 0 | BN22: 0 | BO22: 0 | BP22: 0 | BR22: 0 | BS22: 0 | BT22: 0 | BU22: 8.22 | BV22: 0.966 | BX22: 7.26 | BY22: 27.2 | BZ22: 0.681 | CA22: 0.681 | CB22: 0 | CG22: 0.156 | CI22: 0 | CJ22: 1.42 | CK22: 0.874 | CL22: 0 | CM22: 0 | CN22: 0 | CO22: 0 | CR22: 3.34 | CU22: 0.314 | CV22: 0 | CW22: 0 | CX22: 0 | CY22: 0 | CZ22: 0 | DA22: 0 | DB22: 0 | DC22: 0 | DD22: 0 | DF22: 0.00381 | DG22: 0.00169 | DH22: 0.218 | DI22: 0.002 | DJ22: 0.0728 | DK22: 0.00562 | DL22: 0 | DM22: 0.00675 | DN22: 0 | DO22: 0.00231 | DP22: 0.416 | DQ22: 0 | DS22: 0 | DT22: 0 | DV22: 0.00194 | DW22: 0.001 | DX22: 0.001 | DZ22: 0.409 | EB22: 0.00481 | ED22: 0 | EE22: 0 | EF22: 0 | EG22: 0 | EH22: 1.15 | EJ22: 0.988 | EK22: 0.988 | EL22: 0 | EN22: 0.166 | EO22: 0.166 | EP22: 0 | EQ22: 0 | ER22: 0.000562 | ES22: 0.000562 | EU22: 0 | EV22: 0 | EW22: 0 | EX22: 0 | EY22: 0 | EZ22: 0 | FA22: 0 | FB22: 0 | FC22: 0 | FD22: 0 | FE22: 0 | FF22: 0 | FG22: 0 | FH22: 0 | FI22: 0 | FJ22: 0 | FK22: 0.000812 | FM22: 0 | FN22: 0 | FO22: 0 | FP22: 0.000812 | FQ22: 0.00112 | FS22: 0.00112 | FT22: 0 | FU22: 0 | FV22: 0 | FX22: 0.0462 | FY22: 0.128 | FZ22: 0.145 | GA22: 0.249 | GB22: 0.221 | GC22: 0.0462 | GD22: 0.175 | GE22: 0.124 | GF22: 0.142 | GG22: 0.269 | GH22: 0.0975 | GI22: 0.139 | GJ22: 0.396 | GK22: 0.619 | GL22: 0.141 | GM22: 0.137 | GN22: 0.168 | GO22: 0 | GP22: 0.0575 | HD22: 0.0262 | HE22: 0.0665 | HF22: 0.434 | HG22: 12.9 | HH22: 18.8 | HI22: 1.36 | HJ22: 0.457 | HK22: 0.38
A23: 173532 | B23: Babyfood, cereal, mixed, with honey, prepared with whole milk | D23: SR Legacy | E23: 100 | F23: =E23/SUM($E$3:$E$33) | G23: 74.2 | H23: 116 | I23: 485.344 | J23: 0.8 | K23: 5 | L23: 3.6 | M23: 3.6 | N23: 1.2 | O23: 15.9 | AD23: 294 | AE23: 11.3 | AF23: 28 | AG23: 184 | AH23: 171 | AI23: 48 | AJ23: 0.72 | AK23: 0.064 | AQ23: 11 | AR23: 0.447 | AS23: 0.583 | AT23: 6.26 | AU23: 0.067 | AV23: 11 | AW23: 0 | AX23: 11 | BF23: 0.3 | CQ23: 0.443
A24: 173534 | B24: Babyfood, cereal, rice, with bananas, prepared with whole milk | D24: SR Legacy | E24: 100 | F24: =E24/SUM($E$3:$E$33) | G24: 81.8 | H24: 86.16 | I24: 360.49344 | J24: 0.5712 | K24: 3.57 | L24: 3.32 | M24: 3.32 | N24: 0.81 | O24: 10.5 | P24: 0.1 | T24: 6.13 | U24: 0 | V24: 0 | W24: 0 | X24: 4.67 | Y24: 0 | Z24: 0 | AD24: 156 | AE24: 3.63 | AF24: 20 | AG24: 109 | AH24: 180 | AI24: 47 | AJ24: 0.46 | AK24: 0.042 | AL24: 0.004 | AN24: 4.3 | AQ24: 6 | AR24: 0.684 | AS24: 0.444 | AT24: 1.85 | AU24: 0.085 | AV24: 6 | AW24: 0 | AX24: 6 | AY24: 15.2 | BE24: 0.6 | BF24: 0.43 | BG24: 0 | BH24: 43 | BI24: 42 | BJ24: 7 | BM24: 1 | BO24: 0 | BQ24: 152 | BR24: 0 | BU24: 3 | BY24: 47 | BZ24: 1.2 | CB24: 1.2 | CD24: 0.5 | CE24: 0 | CF24: 0.9 | CG24: 0.09 | CH24: 0 | CI24: 0 | CJ24: 0 | CK24: 0 | CL24: 0 | CM24: 0 | CN24: 0 | CO24: 0 | CP24: 0.2 | CQ24: 0.345 | CS24: 0 | CT24: 0 | CU24: 1.8 | CV24: 0.069 | CX24: 0.069 | CZ24: 0.069 | DB24: 0.069 | DD24: 0.071 | DE24: 0 | DF24: 0.276 | DG24: 0 | DH24: 0.826 | DI24: 0 | DJ24: 0.345 | DK24: 0 | DM24: 0 | DO24: 0 | DP24: 0.826 | DR24: 0 | DU24: 0.002 | DY24: 0.823 | EA24: 0 | EC24: 0 | EH24: 0.294 | EI24: 0.209 | EM24: 0.085 | EQ24: 0 | EY24: 0 | FB24: 0 | FG24: 0 | FI24: 0 | FW24: 10 | FX24: 0.079 | FY24: 0.163 | FZ24: 0.184 | GA24: 0.302 | GB24: 0.161 | GC24: 0.085 | GD24: 0.163 | GE24: 0.165 | GF24: 0.215 | GG24: 0.113 | GH24: 0.088 | GI24: 0.131 | GJ24: 0.28 | GK24: 0.702 | GL24: 0.095 | GM24: 0.341 | GN24: 0.132 | GP24: 0.029 | HL24: 0
A25: 2003591 | B25: Orange juice, no pulp, not fortified, from concentrate, refrigerated | D25: Foundation | E25: 100 | F25: =E25/SUM($E$3:$E$33) | G25: 88.2 | H25: 47.061 | I25: 196.90322 | J25: 0.118 | K25: 0.734 | L25: 0.325 | M25: 0.325 | N25: 0.35 | O25: 10.3 | T25: 8.28 | U25: 4.39 | V25: 1.79 | W25: 2.1 | X25: 0 | Y25: 0 | Z25: 0 | AD25: 12.8 | AE25: 0.0646 | AF25: 10.6 | AG25: 18.2 | AH25: 180 | AI25: 5.23 | AJ25: 0.0319 | AK25: 0.0322 | AL25: 0.0299 | AR25: 0.0701 | AT25: 0.0403 | AU25: 0.0429 | AV25: 29.8 | CP25: 26.9 | GZ25: 706 | HA25: 161 | HB25: 0 | HC25: 12.3
A26: 2003597 | B26: Orange juice, no pulp, not fortified, not from concentrate, refrigerated | D26: Foundation | E26: 100 | F26: =E26/SUM($E$3:$E$33) | G26: 88.5 | H26: 46.452 | I26: 194.35517 | J26: 0.13 | K26: 0.812 | L26: 0.356 | M26: 0.356 | N26: 0.339 | O26: 10 | T26: 8.08 | U26: 4.14 | V26: 1.81 | W26: 2.12 | X26: 0 | Y26: 0 | Z26: 0 | AD26: 9.29 | AE26: 0.0706 | AF26: 10.3 | AG26: 19 | AH26: 183 | AI26: 0.075 | AJ26: 0.0321 | AK26: 0.0353 | AL26: 0.0277 | AR26: 0.0746 | AT26: 0.0291 | AU26: 0.0411 | AV26: 29 | CP26: 30.5 | GZ26: 757 | HA26: 160 | HB26: 0 | HC26: 0
A27: 169102 | B27: Orange juice, frozen concentrate, unsweetened, diluted with 3 volume water | D27: SR Legacy | E27: 100 | F27: =E27/SUM($E$3:$E$33) | G27: 90.1 | H27: 38.14 | I27: 159.57776 | J27: 0.096 | K27: 0.6 | L27: 0.06 | M27: 0.06 | N27: 0.47 | O27: 8.8 | P27: 0.2 | T27: 7.42 | AD27: 12 | AE27: 0.08 | AF27: 10 | AG27: 15 | AH27: 158 | AI27: 4 | AJ27: 0.04 | AK27: 0.021 | AN27: 0.1 | AQ27: 19 | AR27: 0.069 | AS27: 0.044 | AT27: 0.273 | AU27: 0.065 | AV27: 19 | AW27: 0 | AX27: 19 | AY27: 5 | BF27: 0 | BG27: 0 | BH27: 3 | BI27: 0 | BJ27: 13 | BM27: 5 | BO27: 48 | BQ27: 66 | BR27: 0 | BU27: 83 | BY27: 0 | BZ27: 0 | CD27: 0.1 | CG27: 0.15 | CH27: 0 | CP27: 36.2 | CS27: 0 | CT27: 0 | CU27: 0.015 | CV27: 0 | CX27: 0 | CZ27: 0 | DB27: 0 | DD27: 0.001 | DF27: 0.001 | DH27: 0.011 | DJ27: 0.002 | DP27: 0.012 | DU27: 0.002 | DY27: 0.011 | EA27: 0 | EC27: 0 | EH27: 0.016 | EI27: 0.012 | EM27: 0.004 | EQ27: 0 | EY27: 0 | FB27: 0 | FG27: 0 | FI27: 0 | FJ27: 0 | FW27: 0 | HL27: 0
A28: 168113 | B28: Frozen novelties, juice type, orange | D28: SR Legacy | E28: 100 | F28: =E28/SUM($E$3:$E$33) | G28: 76.1 | H28: 94.8 | I28: 396.6432 | J28: 0.08 | K28: 0.5 | L28: 0 | M28: 0 | N28: 0.23 | O28: 23.2 | P28: 0.1 | T28: 20 | AD28: 9 | AE28: 0.47 | AF28: 8 | AG28: 13 | AH28: 100 | AI28: 8 | AJ28: 0.02 | AK28: 0.022 | AL28: 0.008 | AN28: 0.1 | AP28: 77 | AQ28: 18 | AR28: 0.01 | AS28: 0.03 | AT28: 0.16 | AU28: 0.018 | AV28: 18 | AW28: 0 | AX28: 18 | AY28: 2.9 | BF28: 0 | BG28: 0 | BH28: 1 | BI28: 0 | BJ28: 12 | BM28: 0 | BO28: 0 | BQ28: 21 | BR28: 0 | BU28: 39 | BY28: 0 | BZ28: 0 | CD28: 0.1 | CG28: 0.04 | CH28: 0 | CP28: 25.7 | CQ28: 0.065 | CS28: 0 | CT28: 0 | CU28: 0 | CV28: 0 | CX28: 0 | CZ28: 0 | DB28: 0 | DD28: 0 | DF28: 0 | DH28: 0 | DJ28: 0 | DP28: 0 | DU28: 0 | DY28: 0 | EA28: 0 | EC28: 0 | EH28: 0 | EI28: 0 | EM28: 0 | EQ28: 0 | EY28: 0 | FB28: 0 | FG28: 0 | FI28: 0 | FW28: 0 | HL28: 0
A29: 171354 | B29: Babyfood, juice, orange | D29: SR Legacy | E29: 100 | F29: =E29/SUM($E$3:$E$33) | G29: 88.5 | H29: 45.9 | I29: 192.0456 | J29: 0.096 | K29: 0.6 | L29: 0.3 | M29: 0.3 | N29: 0.4 | O29: 10.2 | P29: 0.1 | T29: 8.26 | AD29: 12 | AE29: 0.17 | AF29: 9 | AG29: 11 | AH29: 184 | AI29: 0 | AJ29: 0.06 | AK29: 0.046 | AN29: 0.1 | AQ29: 26 | AR29: 0.045 | AS29: 0.028 | AT29: 0.239 | AU29: 0.054 | AV29: 26 | AW29: 0 | AX29: 26 | AY29: 6.2 | BF29: 0 | BG29: 0 | BH29: 3 | BI29: 0 | BJ29: 9 | BM29: 2 | BO29: 47 | BQ29: 55 | BR29: 0 | BU29: 113 | BY29: 0 | BZ29: 0 | CD29: 0.1 | CG29: 0.04 | CH29: 0 | CP29: 62.5 | CQ29: 0.137 | CS29: 0 | CT29: 0 | CU29: 0.035 | CV29: 0 | CX29: 0 | CZ29: 0 | DB29: 0 | DD29: 0 | DF29: 0 | DH29: 0.035 | DJ29: 0 | DP29: 0.05 | DU29: 0.005 | DY29: 0.045 | EA29: 0 | EC29: 0 | EH29: 0.06 | EI29: 0.045 | EM29: 0.015 | EQ29: 0 | EY29: 0 | FB29: 0 | FG29: 0 | FI29: 0 | FW29: 0 | HL29: 0
A30: 1104812 | B30: Flour, rice, brown | D30: Foundation | E30: 100 | F30: =E30/SUM($E$3:$E$33) | G30: 12.1 | H30: 365.41 | I30: 1528.8754 | J30: 1.15 | K30: 7.19 | L30: 3.85 | M30: 3.85 | N30: 1.4 | O30: 75.5 | AD30: 10 | AE30: 1.5 | AF30: 124 | AG30: 319 | AH30: 265 | AI30: 1 | AJ30: 1.91 | AK30: 0.286 | AL30: 2.84 | AN30: 9.68 | AO30: 56.2 | AR30: 0.322 | AS30: 0.008 | AT30: 5.99 | AU30: 0.132
A31: 169707 | B31: Rice, white, long-grain, parboiled, enriched, dry | D31: SR Legacy | E31: 100 | F31: =E31/SUM($E$3:$E$33) | G31: 9.86 | H31: 362.91 | I31: 1518.4154 | J31: 1.2016 | K31: 7.51 | L31: 1.03 | M31: 1.03 | N31: 0.71 | O31: 80.9 | P31: 1.8 | T31: 0.33 | U31: 0.21 | V31: 0.11 | W31: 0.02 | X31: 0 | Y31: 0 | Z31: 0 | AA31: 68.3 | AD31: 71 | AE31: 3.33 | AF31: 27 | AG31: 153 | AH31: 174 | AI31: 2 | AJ31: 1.02 | AK31: 0.284 | AL31: 1.04 | AN31: 19.9 | AQ31: 8 | AR31: 0.603 | AS31: 0.05 | AT31: 5.05 | AU31: 0.452 | AV31: 257 | AW31: 249 | AX31: 431 | AY31: 6 | BF31: 0 | BG31: 0 | BH31: 0 | BI31: 0 | BJ31: 0 | BM31: 0 | BO31: 0 | BQ31: 0 | BR31: 0 | BU31: 0 | BY31: 0 | BZ31: 0 | CD31: 0.1 | CG31: 0.03 | CH31: 0 | CI31: 0.02 | CJ31: 0.17 | CK31: 0 | CL31: 0.05 | CM31: 0 | CN31: 0 | CO31: 0 | CP31: 0 | CQ31: 0.672 | CS31: 0 | CT31: 0 | CU31: 0.294 | CV31: 0 | CX31: 0 | CZ31: 0 | DB31: 0 | DD31: 0 | DF31: 0 | DG31: 0 | DH31: 0.277 | DI31: 0 | DJ31: 0.017 | DK31: 0 | DM31: 0 | DO31: 0 | DP31: 0.258 | DR31: 0 | DU31: 0 | DY31: 0.258 | EA31: 0 | EC31: 0 | EH31: 0.322 | EI31: 0.305 | EM31: 0.017 | EQ31: 0 | EY31: 0 | FB31: 0 | FG31: 0 | FI31: 0 | FW31: 0 | FX31: 0.103 | FY31: 0.271 | FZ31: 0.339 | GA31: 0.656 | GB31: 0.215 | GC31: 0.183 | GD31: 0.398 | GE31: 0.216 | GF31: 0.47 | GG31: 0.651 | GH31: 0.185 | GI31: 0.433 | GJ31: 0.795 | GK31: 1.4 | GL31: 0.358 | GM31: 0.484 | GN31: 0.366 | GP31: 0.153 | HL31: 0
A32: 169758 | B32: Rice, white, long-grain, parboiled, unenriched, dry | D32: SR Legacy | E32: 100 | F32: =E32/SUM($E$3:$E$33) | G32: 9.86 | H32: 362.91 | I32: 1518.4154 | J32: 1.2016 | K32: 7.51 | L32: 1.03 | M32: 1.03 | N32: 0.71 | O32: 80.9 | P32: 1.8 | T32: 0.33 | U32: 0.21 | V32: 0.11 | W32: 0.02 | X32: 0 | Y32: 0 | Z32: 0 | AA32: 68.3 | AD32: 71 | AE32: 0.74 | AF32: 27 | AG32: 153 | AH32: 174 | AI32: 2 | AJ32: 1.02 | AK32: 0.284 | AL32: 1.04 | AN32: 19.9 | AQ32: 8 | AR32: 0.224 | AS32: 0.05 | AT32: 5.05 | AU32: 0.452 | AV32: 8 | AW32: 0 | AX32: 8 | BF32: 0 | BG32: 0 | BI32: 0 | BQ32: 0 | BY32: 0 | BZ32: 0 | CD32: 0.1 | CG32: 0.03 | CH32: 0 | CI32: 0.02 | CJ32: 0.17 | CK32: 0 | CL32: 0.05 | CM32: 0 | CN32: 0 | CO32: 0 | CP32: 0 | CQ32: 0.672 | CU32: 0.294 | CV32: 0 | CX32: 0 | CZ32: 0 | DB32: 0 | DD32: 0 | DF32: 0 | DG32: 0 | DH32: 0.277 | DI32: 0 | DJ32: 0.017 | DK32: 0 | DM32: 0 | DO32: 0 | DP32: 0.258 | DR32: 0 | DU32: 0 | DY32: 0.258 | EA32: 0 | EC32: 0 | EH32: 0.322 | EI32: 0.305 | EM32: 0.017 | EQ32: 0 | EY32: 0 | FB32: 0 | FG32: 0 | FI32: 0 | FW32: 0 | FX32: 0.103 | FY32: 0.271 | FZ32: 0.339 | GA32: 0.656 | GB32: 0.215 | GC32: 0.183 | GD32: 0.398 | GE32: 0.216 | GF32: 0.47 | GG32: 0.651 | GH32: 0.185 | GI32: 0.433 | GJ32: 0.795 | GK32: 1.4 | GL32: 0.358 | GM32: 0.484 | GN32: 0.366 | GP32: 0.153 | HL32: 0
A33: 2512381 | B33: Rice, white, long grain, unenriched, raw | D33: Foundation | E33: 100 | F33: =E33/SUM($E$3:$E$33) | G33: 11.2 | H33: 358.63 | I33: 1500.5079 | J33: 1.18 | K33: 7.04 | L33: 1.03 | M33: 1.03 | N33: 0.425 | O33: 80.3 | P33: 0.149 | Q33: 2.77 | R33: 1.93 | S33: 0.296 | AA33: 74.4 | AD33: 4.46 | AE33: 0.14 | AF33: 26.5 | AG33: 108 | AH33: 82.3 | AI33: 0.462 | AJ33: 1.35 | AK33: 0.214 | AL33: 0.981 | AN33: 6.6 | AO33: 64.2 | AR33: 0.065 | AS33: 0.08 | AT33: 1.43 | AU33: 0.0579 | CR33: 0
A34: Total | B34: Formulado | C34: Formulado | D34: Formulado | E34: =SUBTOTAL(9,E3:E33) | F34: 100% | G34: =SUMPRODUCT($F$3:$F$33,$G$3:$G$33) | H34: =SUMPRODUCT($F$3:$F$33,$H$3:$H$33) | I34: =SUMPRODUCT($F$3:$F$33,$I$3:$I$33) | J34: =SUMPRODUCT($F$3:$F$33,$J$3:$J$33) | K34: =SUMPRODUCT($F$3:$F$33,$K$3:$K$33) | L34: =SUMPRODUCT($F$3:$F$33,$L$3:$L$33) | M34: =SUMPRODUCT($F$3:$F$33,$M$3:$M$33) | N34: =SUMPRODUCT($F$3:$F$33,$N$3:$N$33) | O34: =SUMPRODUCT($F$3:$F$33,$O$3:$O$33) | P34: =SUMPRODUCT($F$3:$F$33,$P$3:$P$33) | Q34: =SUMPRODUCT($F$3:$F$33,$Q$3:$Q$33) | R34: =SUMPRODUCT($F$3:$F$33,$R$3:$R$33) | S34: =SUMPRODUCT($F$3:$F$33,$S$3:$S$33) | T34: =SUMPRODUCT($F$3:$F$33,$T$3:$T$33) | U34: =SUMPRODUCT($F$3:$F$33,$U$3:$U$33) | V34: =SUMPRODUCT($F$3:$F$33,$V$3:$V$33) | W34: =SUMPRODUCT($F$3:$F$33,$W$3:$W$33) | X34: =SUMPRODUCT($F$3:$F$33,$X$3:$X$33) | Y34: =SUMPRODUCT($F$3:$F$33,$Y$3:$Y$33) | Z34: =SUMPRODUCT($F$3:$F$33,$Z$3:$Z$33) | AA34: =SUMPRODUCT($F$3:$F$33,$AA$3:$AA$33) | AB34: =SUMPRODUCT($F$3:$F$33,$AB$3:$AB$33) | AC34: =SUMPRODUCT($F$3:$F$33,$AC$3:$AC$33) | AD34: =SUMPRODUCT($F$3:$F$33,$AD$3:$AD$33) | AE34: =SUMPRODUCT($F$3:$F$33,$AE$3:$AE$33) | AF34: =SUMPRODUCT($F$3:$F$33,$AF$3:$AF$33) | AG34: =SUMPRODUCT($F$3:$F$33,$AG$3:$AG$33) | AH34: =SUMPRODUCT($F$3:$F$33,$AH$3:$AH$33) | AI34: =SUMPRODUCT($F$3:$F$33,$AI$3:$AI$33) | AJ34: =SUMPRODUCT($F$3:$F$33,$AJ$3:$AJ$33) | AK34: =SUMPRODUCT($F$3:$F$33,$AK$3:$AK$33) | AL34: =SUMPRODUCT($F$3:$F$33,$AL$3:$AL$33) | AM34: =SUMPRODUCT($F$3:$F$33,$AM$3:$AM$33) | AN34: =SUMPRODUCT($F$3:$F$33,$AN$3:$AN$33) | AO34: =SUMPRODUCT($F$3:$F$33,$AO$3:$AO$33) | AP34: =SUMPRODUCT($F$3:$F$33,$AP$3:$AP$33) | AQ34: =SUMPRODUCT($F$3:$F$33,$AQ$3:$AQ$33) | AR34: =SUMPRODUCT($F$3:$F$33,$AR$3:$AR$33) | AS34: =SUMPRODUCT($F$3:$F$33,$AS$3:$AS$33) | AT34: =SUMPRODUCT($F$3:$F$33,$AT$3:$AT$33) | AU34: =SUMPRODUCT($F$3:$F$33,$AU$3:$AU$33) | AV34: =SUMPRODUCT($F$3:$F$33,$AV$3:$AV$33) | AW34: =SUMPRODUCT($F$3:$F$33,$AW$3:$AW$33) | AX34: =SUMPRODUCT($F$3:$F$33,$AX$3:$AX$33) | AY34: =SUMPRODUCT($F$3:$F$33,$AY$3:$AY$33) | AZ34: =SUMPRODUCT($F$3:$F$33,$AZ$3:$AZ$33) | BA34: =SUMPRODUCT($F$3:$F$33,$BA$3:$BA$33) | BB34: =SUMPRODUCT($F$3:$F$33,$BB$3:$BB$33) | BC34: =SUMPRODUCT($F$3:$F$33,$BC$3:$BC$33) | BD34: =SUMPRODUCT($F$3:$F$33,$BD$3:$BD$33) | BE34: =SUMPRODUCT($F$3:$F$33,$BE$3:$BE$33) | BF34: =SUMPRODUCT($F$3:$F$33,$BF$3:$BF$33) | BG34: =SUMPRODUCT($F$3:$F$33,$BG$3:$BG$33) | BH34: =SUMPRODUCT($F$3:$F$33,$BH$3:$BH$33) | BI34: =SUMPRODUCT($F$3:$F$33,$BI$3:$BI$33) | BJ34: =SUMPRODUCT($F$3:$F$33,$BJ$3:$BJ$33) | BK34: =SUMPRODUCT($F$3:$F$33,$BK$3:$BK$33) | BL34: =SUMPRODUCT($F$3:$F$33,$BL$3:$BL$33) | BM34: =SUMPRODUCT($F$3:$F$33,$BM$3:$BM$33) | BN34: =SUMPRODUCT($F$3:$F$33,$BN$3:$BN$33) | BO34: =SUMPRODUCT($F$3:$F$33,$BO$3:$BO$33) | BP34: =SUMPRODUCT($F$3:$F$33,$BP$3:$BP$33) | BQ34: =SUMPRODUCT($F$3:$F$33,$BQ$3:$BQ$33) | BR34: =SUMPRODUCT($F$3:$F$33,$BR$3:$BR$33) | BS34: =SUMPRODUCT($F$3:$F$33,$BS$3:$BS$33) | BT34: =SUMPRODUCT($F$3:$F$33,$BT$3:$BT$33) | BU34: =SUMPRODUCT($F$3:$F$33,$BU$3:$BU$33) | BV34: =SUMPRODUCT($F$3:$F$33,$BV$3:$BV$33) | BW34: =SUMPRODUCT($F$3:$F$33,$BW$3:$BW$33) | BX34: =SUMPRODUCT($F$3:$F$33,$BX$3:$BX$33) | BY34: =SUMPRODUCT($F$3:$F$33,$BY$3:$BY$33) | BZ34: =SUMPRODUCT($F$3:$F$33,$BZ$3:$BZ$33) | CA34: =SUMPRODUCT($F$3:$F$33,$CA$3:$CA$33) | CB34: =SUMPRODUCT($F$3:$F$33,$CB$3:$CB$33) | CC34: =SUMPRODUCT($F$3:$F$33,$CC$3:$CC$33) | CD34: =SUMPRODUCT($F$3:$F$33,$CD$3:$CD$33) | CE34: =SUMPRODUCT($F$3:$F$33,$CE$3:$CE$33) | CF34: =SUMPRODUCT($F$3:$F$33,$CF$3:$CF$33) | CG34: =SUMPRODUCT($F$3:$F$33,$CG$3:$CG$33) | CH34: =SUMPRODUCT($F$3:$F$33,$CH$3:$CH$33) | CI34: =SUMPRODUCT($F$3:$F$33,$CI$3:$CI$33) | CJ34: =SUMPRODUCT($F$3:$F$33,$CJ$3:$CJ$33) | CK34: =SUMPRODUCT($F$3:$F$33,$CK$3:$CK$33) | CL34: =SUMPRODUCT($F$3:$F$33,$CL$3:$CL$33) | CM34: =SUMPRODUCT($F$3:$F$33,$CM$3:$CM$33) | CN34: =SUMPRODUCT($F$3:$F$33,$CN$3:$CN$33) | CO34: =SUMPRODUCT($F$3:$F$33,$CO$3:$CO$33) | CP34: =SUMPRODUCT($F$3:$F$33,$CP$3:$CP$33) | CQ34: =SUMPRODUCT($F$3:$F$33,$CQ$3:$CQ$33) | CR34: =SUMPRODUCT($F$3:$F$33,$CR$3:$CR$33) | CS34: =SUMPRODUCT($F$3:$F$33,$CS$3:$CS$33) | CT34: =SUMPRODUCT($F$3:$F$33,$CT$3:$CT$33) | CU34: =SUMPRODUCT($F$3:$F$33,$CU$3:$CU$33) | CV34: =SUMPRODUCT($F$3:$F$33,$CV$3:$CV$33) | CW34: =SUMPRODUCT($F$3:$F$33,$CW$3:$CW$33) | CX34: =SUMPRODUCT($F$3:$F$33,$CX$3:$CX$33) | CY34: =SUMPRODUCT($F$3:$F$33,$CY$3:$CY$33) | CZ34: =SUMPRODUCT($F$3:$F$33,$CZ$3:$CZ$33) | DA34: =SUMPRODUCT($F$3:$F$33,$DA$3:$DA$33) | DB34: =SUMPRODUCT($F$3:$F$33,$DB$3:$DB$33) | DC34: =SUMPRODUCT($F$3:$F$33,$DC$3:$DC$33) | DD34: =SUMPRODUCT($F$3:$F$33,$DD$3:$DD$33) | DE34: =SUMPRODUCT($F$3:$F$33,$DE$3:$DE$33) | DF34: =SUMPRODUCT($F$3:$F$33,$DF$3:$DF$33) | DG34: =SUMPRODUCT($F$3:$F$33,$DG$3:$DG$33) | DH34: =SUMPRODUCT($F$3:$F$33,$DH$3:$DH$33) | DI34: =SUMPRODUCT($F$3:$F$33,$DI$3:$DI$33) | DJ34: =SUMPRODUCT($F$3:$F$33,$DJ$3:$DJ$33) | DK34: =SUMPRODUCT($F$3:$F$33,$DK$3:$DK$33) | DL34: =SUMPRODUCT($F$3:$F$33,$DL$3:$DL$33) | DM34: =SUMPRODUCT($F$3:$F$33,$DM$3:$DM$33) | DN34: =SUMPRODUCT($F$3:$F$33,$DN$3:$DN$33) | DO34: =SUMPRODUCT($F$3:$F$33,$DO$3:$DO$33) | DP34: =SUMPRODUCT($F$3:$F$33,$DP$3:$DP$33) | DQ34: =SUMPRODUCT($F$3:$F$33,$DQ$3:$DQ$33) | DR34: =SUMPRODUCT($F$3:$F$33,$DR$3:$DR$33) | DS34: =SUMPRODUCT($F$3:$F$33,$DS$3:$DS$33) | DT34: =SUMPRODUCT($F$3:$F$33,$DT$3:$DT$33) | DU34: =SUMPRODUCT($F$3:$F$33,$DU$3:$DU$33) | DV34: =SUMPRODUCT($F$3:$F$33,$DV$3:$DV$33) | DW34: =SUMPRODUCT($F$3:$F$33,$DW$3:$DW$33) | DX34: =SUMPRODUCT($F$3:$F$33,$DX$3:$DX$33) | DY34: =SUMPRODUCT($F$3:$F$33,$DY$3:$DY$33) | DZ34: =SUMPRODUCT($F$3:$F$33,$DZ$3:$DZ$33) | EA34: =SUMPRODUCT($F$3:$F$33,$EA$3:$EA$33) | EB34: =SUMPRODUCT($F$3:$F$33,$EB$3:$EB$33) | EC34: =SUMPRODUCT($F$3:$F$33,$EC$3:$EC$33) | ED34: =SUMPRODUCT($F$3:$F$33,$ED$3:$ED$33) | EE34: =SUMPRODUCT($F$3:$F$33,$EE$3:$EE$33) | EF34: =SUMPRODUCT($F$3:$F$33,$EF$3:$EF$33) | EG34: =SUMPRODUCT($F$3:$F$33,$EG$3:$EG$33) | EH34: =SUMPRODUCT($F$3:$F$33,$EH$3:$EH$33) | EI34: =SUMPRODUCT($F$3:$F$33,$EI$3:$EI$33) | EJ34: =SUMPRODUCT($F$3:$F$33,$EJ$3:$EJ$33) | EK34: =SUMPRODUCT($F$3:$F$33,$EK$3:$EK$33) | EL34: =SUMPRODUCT($F$3:$F$33,$EL$3:$EL$33) | EM34: =SUMPRODUCT($F$3:$F$33,$EM$3:$EM$33) | EN34: =SUMPRODUCT($F$3:$F$33,$EN$3:$EN$33) | EO34: =SUMPRODUCT($F$3:$F$33,$EO$3:$EO$33) | EP34: =SUMPRODUCT($F$3:$F$33,$EP$3:$EP$33) | EQ34: =SUMPRODUCT($F$3:$F$33,$EQ$3:$EQ$33) | ER34: =SUMPRODUCT($F$3:$F$33,$ER$3:$ER$33) | ES34: =SUMPRODUCT($F$3:$F$33,$ES$3:$ES$33) | ET34: =SUMPRODUCT($F$3:$F$33,$ET$3:$ET$33) | EU34: =SUMPRODUCT($F$3:$F$33,$EU$3:$EU$33) | EV34: =SUMPRODUCT($F$3:$F$33,$EV$3:$EV$33) | EW34: =SUMPRODUCT($F$3:$F$33,$EW$3:$EW$33) | EX34: =SUMPRODUCT($F$3:$F$33,$EX$3:$EX$33) | EY34: =SUMPRODUCT($F$3:$F$33,$EY$3:$EY$33) | EZ34: =SUMPRODUCT($F$3:$F$33,$EZ$3:$EZ$33) | FA34: =SUMPRODUCT($F$3:$F$33,$FA$3:$FA$33) | FB34: =SUMPRODUCT($F$3:$F$33,$FB$3:$FB$33) | FC34: =SUMPRODUCT($F$3:$F$33,$FC$3:$FC$33) | FD34: =SUMPRODUCT($F$3:$F$33,$FD$3:$FD$33) | FE34: =SUMPRODUCT($F$3:$F$33,$FE$3:$FE$33) | FF34: =SUMPRODUCT($F$3:$F$33,$FF$3:$FF$33) | FG34: =SUMPRODUCT($F$3:$F$33,$FG$3:$FG$33) | FH34: =SUMPRODUCT($F$3:$F$33,$FH$3:$FH$33) | FI34: =SUMPRODUCT($F$3:$F$33,$FI$3:$FI$33) | FJ34: =SUMPRODUCT($F$3:$F$33,$FJ$3:$FJ$33) | FK34: =SUMPRODUCT($F$3:$F$33,$FK$3:$FK$33) | FL34: =SUMPRODUCT($F$3:$F$33,$FL$3:$FL$33) | FM34: =SUMPRODUCT($F$3:$F$33,$FM$3:$FM$33) | FN34: =SUMPRODUCT($F$3:$F$33,$FN$3:$FN$33) | FO34: =SUMPRODUCT($F$3:$F$33,$FO$3:$FO$33) | FP34: =SUMPRODUCT($F$3:$F$33,$FP$3:$FP$33) | FQ34: =SUMPRODUCT($F$3:$F$33,$FQ$3:$FQ$33) | FR34: =SUMPRODUCT($F$3:$F$33,$FR$3:$FR$33) | FS34: =SUMPRODUCT($F$3:$F$33,$FS$3:$FS$33) | FT34: =SUMPRODUCT($F$3:$F$33,$FT$3:$FT$33) | FU34: =SUMPRODUCT($F$3:$F$33,$FU$3:$FU$33) | FV34: =SUMPRODUCT($F$3:$F$33,$FV$3:$FV$33) | FW34: =SUMPRODUCT($F$3:$F$33,$FW$3:$FW$33) | FX34: =SUMPRODUCT($F$3:$F$33,$FX$3:$FX$33) | FY34: =SUMPRODUCT($F$3:$F$33,$FY$3:$FY$33) | FZ34: =SUMPRODUCT($F$3:$F$33,$FZ$3:$FZ$33) | GA34: =SUMPRODUCT($F$3:$F$33,$GA$3:$GA$33) | GB34: =SUMPRODUCT($F$3:$F$33,$GB$3:$GB$33) | GC34: =SUMPRODUCT($F$3:$F$33,$GC$3:$GC$33) | GD34: =SUMPRODUCT($F$3:$F$33,$GD$3:$GD$33) | GE34: =SUMPRODUCT($F$3:$F$33,$GE$3:$GE$33) | GF34: =SUMPRODUCT($F$3:$F$33,$GF$3:$GF$33) | GG34: =SUMPRODUCT($F$3:$F$33,$GG$3:$GG$33) | GH34: =SUMPRODUCT($F$3:$F$33,$GH$3:$GH$33) | GI34: =SUMPRODUCT($F$3:$F$33,$GI$3:$GI$33) | GJ34: =SUMPRODUCT($F$3:$F$33,$GJ$3:$GJ$33) | GK34: =SUMPRODUCT($F$3:$F$33,$GK$3:$GK$33) | GL34: =SUMPRODUCT($F$3:$F$33,$GL$3:$GL$33) | GM34: =SUMPRODUCT($F$3:$F$33,$GM$3:$GM$33) | GN34: =SUMPRODUCT($F$3:$F$33,$GN$3:$GN$33) | GO34: =SUMPRODUCT($F$3:$F$33,$GO$3:$GO$33) | GP34: =SUMPRODUCT($F$3:$F$33,$GP$3:$GP$33) | GQ34: =SUMPRODUCT($F$3:$F$33,$GQ$3:$GQ$33) | GR34: =SUMPRODUCT($F$3:$F$33,$GR$3:$GR$33) | GS34: =SUMPRODUCT($F$3:$F$33,$GS$3:$GS$33) | GT34: =SUMPRODUCT($F$3:$F$33,$GT$3:$GT$33) | GU34: =SUMPRODUCT($F$3:$F$33,$GU$3:$GU$33) | GV34: =SUMPRODUCT($F$3:$F$33,$GV$3:$GV$33) | GW34: =SUMPRODUCT($F$3:$F$33,$GW$3:$GW$33) | GX34: =SUMPRODUCT($F$3:$F$33,$GX$3:$GX$33) | GY34: =SUMPRODUCT($F$3:$F$33,$GY$3:$GY$33) | GZ34: =SUMPRODUCT($F$3:$F$33,$GZ$3:$GZ$33) | HA34: =SUMPRODUCT($F$3:$F$33,$HA$3:$HA$33) | HB34: =SUMPRODUCT($F$3:$F$33,$HB$3:$HB$33) | HC34: =SUMPRODUCT($F$3:$F$33,$HC$3:$HC$33) | HD34: =SUMPRODUCT($F$3:$F$33,$HD$3:$HD$33) | HE34: =SUMPRODUCT($F$3:$F$33,$HE$3:$HE$33) | HF34: =SUMPRODUCT($F$3:$F$33,$HF$3:$HF$33) | HG34: =SUMPRODUCT($F$3:$F$33,$HG$3:$HG$33) | HH34: =SUMPRODUCT($F$3:$F$33,$HH$3:$HH$33) | HI34: =SUMPRODUCT($F$3:$F$33,$HI$3:$HI$33) | HJ34: =SUMPRODUCT($F$3:$F$33,$HJ$3:$HJ$33) | HK34: =SUMPRODUCT($F$3:$F$33,$HK$3:$HK$33) | HL34: =SUMPRODUCT($F$3:$F$33,$HL$3:$HL$33)

Sheet Totales
A1: Nutriente | B1: Total | C1: Unidad
A2: Water | B2: =Ingredientes!G34 | C2: g
A3: Energy | B3: =Ingredientes!H34 | C3: kcal
A4: Energy | B4: =Ingredientes!I34 | C4: kJ
A5: Nitrogen | B5: =Ingredientes!J34 | C5: g
A6: Protein | B6: =Ingredientes!K34 | C6: g
A7: Total fat (NLEA) | B7: =Ingredientes!L34 | C7: g
A8: Total lipid (fat) | B8: =Ingredientes!M34 | C8: g
A9: Ash | B9: =Ingredientes!N34 | C9: g
A10: Carbohydrate, by difference | B10: =Ingredientes!O34 | C10: g
A11: Fiber, total dietary | B11: =Ingredientes!P34 | C11: g
A12: Total dietary fiber (AOAC 2011.25) | B12: =Ingredientes!Q34 | C12: g
A13: High Molecular Weight Dietary Fiber (HMWDF) | B13: =Ingredientes!R34 | C13: g
A14: Low Molecular Weight Dietary Fiber (LMWDF) | B14: =Ingredientes!S34 | C14: g
A15: Sugars, Total | B15: =Ingredientes!T34 | C15: g
A16: Sucrose | B16: =Ingredientes!U34 | C16: g
A17: Glucose | B17: =Ingredientes!V34 | C17: g
A18: Fructose | B18: =Ingredientes!W34 | C18: g
A19: Lactose | B19: =Ingredientes!X34 | C19: g
A20: Maltose | B20: =Ingredientes!Y34 | C20: g
A21: Galactose | B21: =Ingredientes!Z34 | C21: g
A22: Starch | B22: =Ingredientes!AA34 | C22: g
A23: Resistant starch | B23: =Ingredientes!AB34 | C23: g
A24: Sugars, added | B24: =Ingredientes!AC34 | C24: g
A25: Calcium, Ca | B25: =Ingredientes!AD34 | C25: mg
A26: Iron, Fe | B26: =Ingredientes!AE34 | C26: mg
A27: Magnesium, Mg | B27: =Ingredientes!AF34 | C27: mg
A28: Phosphorus, P | B28: =Ingredientes!AG34 | C28: mg
A29: Potassium, K | B29: =Ingredientes!AH34 | C29: mg
A30: Sodium, Na | B30: =Ingredientes!AI34 | C30: mg
A31: Zinc, Zn | B31: =Ingredientes!AJ34 | C31: mg
A32: Copper, Cu | B32: =Ingredientes!AK34 | C32: mg
A33: Manganese, Mn | B33: =Ingredientes!AL34 | C33: mg
A34: Iodine, I | B34: =Ingredientes!AM34 | C34: µg
A35: Selenium, Se | B35: =Ingredientes!AN34 | C35: µg
A36: Molybdenum, Mo | B36: =Ingredientes!AO34 | C36: µg
A37: Fluoride, F | B37: =Ingredientes!AP34 | C37: µg
A38: Folate, food | B38: =Ingredientes!AQ34 | C38: µg
A39: Thiamin | B39: =Ingredientes!AR34 | C39: mg
A40: Riboflavin | B40: =Ingredientes!AS34 | C40: mg
...
