Workbook

Sheet Ingredientes
A1: Detalles de formulación | G1: Proximates | Q1: Carbohydrates | AD1: Minerals | AP1: Vitamins and Other Components | CP1: Lipids | EP1: Amino acids | FM1: Phytosterols
A2: FDC ID | B2: Ingrediente | C2: Marca / Origen | D2: Tipo de dato | E2: Cantidad (g) | F2: Cantidad (%) | G2: Water (g) | H2: Energy (kcal) | I2: Energy (kJ) | J2: Nitrogen (g) | K2: Protein (g) | L2: Total lipid (fat) (g) | M2: Total fat (NLEA) (g) | N2: Ash (g) | O2: Energy (Atwater General Factors) (kcal) | P2: Energy (Atwater Specific Factors) (kcal) | Q2: Carbohydrate, by difference (g) | R2: Carbohydrate, by summation (g) | S2: Fiber, total dietary (g) | T2: Sugars, Total (g) | U2: Sucrose (g) | V2: Glucose (g) | W2: Fructose (g) | X2: Lactose (g) | Y2: Maltose (g) | Z2: Starch (g) | AA2: Total Sugars (g) | AB2: Galactose (g) | AC2: Resistant starch (g) | AD2: Calcium, Ca (mg) | AE2: Iron, Fe (mg) | AF2: Magnesium, Mg (mg) | AG2: Phosphorus, P (mg) | AH2: Potassium, K (mg) | AI2: Sodium, Na (mg) | AJ2: Zinc, Zn (mg) | AK2: Copper, Cu (mg) | AL2: Manganese, Mn (mg) | AM2: Iodine, I (µg) | AN2: Selenium, Se (µg) | AO2: Fluoride, F (µg) | AP2: Thiamin (mg) | AQ2: Riboflavin (mg) | AR2: Niacin (mg) | AS2: Vitamin B-6 (mg) | AT2: Folate, total (µg) | AU2: Choline, total (mg) | AV2: Choline, free (mg) | AW2: Choline, from phosphocholine (mg) | AX2: Choline, from phosphotidyl choline (mg) | AY2: Choline, from glycerophosphocholine (mg) | AZ2: Choline, from sphingomyelin (mg) | BA2: Betaine (mg) | BB2: Vitamin B-12 (µg) | BC2: Vitamin A, RAE (µg) | BD2: Retinol (µg) | BE2: Carotene, beta (µg) | BF2: cis-beta-Carotene (µg) | BG2: trans-beta-Carotene (µg) | BH2: Carotene, alpha (µg) | BI2: Cryptoxanthin, beta (µg) | BJ2: Cryptoxanthin, alpha (µg) | BK2: Lycopene (µg) | BL2: cis-Lycopene (µg) | BM2: trans-Lycopene (µg) | BN2: cis-Lutein/Zeaxanthin (µg) | BO2: Lutein (µg) | BP2: Zeaxanthin (µg) | BQ2: Vitamin D (D2 + D3), International Units (IU) | BR2: Vitamin D (D2 + D3) (µg) | BS2: Vitamin D2 (ergocalciferol) (µg) | BT2: Vitamin D3 (cholecalciferol) (µg) | BU2: 25-hydroxycholecalciferol (µg) | BV2: Vitamin C, total ascorbic acid (mg) | BW2: Pantothenic acid (mg) | BX2: Folic acid (µg) | BY2: Folate, food (µg) | BZ2: Folate, DFE (µg) | CA2: Vitamin B-12, added (µg) | CB2: Vitamin A, IU (IU) | CC2: Lutein + zeaxanthin (µg) | CD2: Vitamin E (alpha-tocopherol) (mg) | CE2: Vitamin E, added (mg) | CF2: Vitamin K (phylloquinone) (µg) | CG2: Tocopherol, beta (mg) | CH2: Tocopherol, gamma (mg) | CI2: Tocopherol, delta (mg) | CJ2: Tocotrienol, alpha (mg) | CK2: Tocotrienol, beta (mg) | CL2: Tocotrienol, gamma (mg) | CM2: Tocotrienol, delta (mg) | CN2: Vitamin K (Dihydrophylloquinone) (µg) | CO2: Vitamin K (Menaquinone-4) (µg) | CP2: Fatty acids, total saturated (g) | CQ2: SFA 14:0 (g) | CR2: SFA 16:0 (g) | CS2: SFA 18:0 (g) | CT2: Fatty acids, total monounsaturated (g) | CU2: MUFA 16:1 c (g) | CV2: MUFA 18:1 c (g) | CW2: Fatty acids, total polyunsaturated (g) | CX2: PUFA 18:2 c (g) | CY2: PUFA 18:2 n-6 c,c (g) | CZ2: PUFA 18:3 c (g) | DA2: PUFA 18:3 n-6 c,c,c (g) | DB2: PUFA 20:3 c (g) | DC2: PUFA 20:3 n-6 (g) | DD2: Cholesterol (mg) | DE2: SFA 4:0 (g) | DF2: SFA 6:0 (g) | DG2: SFA 8:0 (g) | DH2: SFA 10:0 (g) | DI2: SFA 12:0 (g) | DJ2: MUFA 16:1 (g) | DK2: MUFA 18:1 (g) | DL2: MUFA 20:1 (g) | DM2: MUFA 22:1 (g) | DN2: PUFA 18:2 (g) | DO2: PUFA 18:3 (g) | DP2: PUFA 18:4 (g) | DQ2: PUFA 20:4 (g) | DR2: PUFA 20:5 n-3 (EPA) (g) | DS2: PUFA 22:5 n-3 (DPA) (g) | DT2: PUFA 22:6 n-3 (DHA) (g) | DU2: Fatty acids, total trans (g) | DV2: SFA 13:0 (g) | DW2: SFA 15:0 (g) | DX2: SFA 17:0 (g) | DY2: SFA 20:0 (g) | DZ2: SFA 22:0 (g) | EA2: SFA 24:0 (g) | EB2: MUFA 14:1 (g) | EC2: MUFA 15:1 (g) | ED2: MUFA 17:1 (g) | EE2: MUFA 24:1 c (g) | EF2: PUFA 18:3 n-3 c,c,c (ALA) (g) | EG2: PUFA 20:2 n-6 c,c (g) | EH2: PUFA 20:3 (g) | EI2: Fatty acids, total trans-monoenoic (g) | EJ2: TFA 18:1 t (g) | EK2: Phytosterols (mg) | EL2: TFA 18:2 t,t (g) | EM2: Fatty acids, total trans-polyenoic (g) | EN2: SFA 21:0 (g) | EO2: MUFA 20:1 c (g) | EP2: Tryptophan (g) | EQ2: Threonine (g) | ER2: Isoleucine (g) | ES2: Leucine (g) | ET2: Lysine (g) | EU2: Methionine (g) | EV2: Phenylalanine (g) | EW2: Tyrosine (g) | EX2: Valine (g) | EY2: Arginine (g) | EZ2: Histidine (g) | FA2: Alanine (g) | FB2: Aspartic acid (g) | FC2: Glutamic acid (g) | FD2: Glycine (g) | FE2: Proline (g) | FF2: Serine (g) | FG2: Hydroxyproline (g) | FH2: Cysteine (g) | FI2: Alcohol, ethyl (g) | FJ2: Caffeine (mg) | FK2: Theobromine (mg) | FL2: Cystine (g) | FM2: Stigmasterol (mg) | FN2: Campesterol (mg) | FO2: Beta-sitosterol (mg) | FP2: Brassicasterol (mg) | FQ2: Campestanol (mg) | FR2: Beta-sitostanol (mg) | FS2: Delta-5-avenasterol (mg) | FT2: Phytosterols, other (mg)
A3: 748967 | B3: Eggs, Grade A, Large, egg whole | D3: Foundation | E3: 1 | F3: =E3/SUM($E$3:$E$9) -> 0.0043846216 | G3: 75.8 | H3: 148 | I3: 617 | J3: 1.99 | K3: 12.4 | L3: 9.96 | M3: 8.65 | N3: 0.85 | Q3: 0.96 | R3: 0.2 | S3: 0 | T3: 0.2 | U3: 0 | V3: 0.2 | W3: 0 | X3: 0 | Y3: 0 | Z3: 0 | AD3: 48 | AE3: 1.67 | AF3: 11.4 | AG3: 184 | AH3: 132 | AI3: 129 | AJ3: 1.24 | AK3: 0 | AL3: 0 | AM3: 49.1 | AN3: 31.1 | AP3: 0.077 | AQ3: 0.419 | AR3: 0 | AS3: 0.063 | AT3: 71 | AU3: 335 | AV3: 0.6 | AW3: 309 | AX3: 0.2 | AY3: 0.2 | AZ3: 25.1 | BA3: 0.3 | BB3: 1.02 | BC3: 180 | BD3: 179 | BE3: 0 | BF3: 0 | BG3: 0 | BH3: 0 | BI3: 13 | BJ3: 13 | BK3: 0 | BL3: 0 | BM3: 0 | BN3: 57 | BO3: 230 | BP3: 229 | BQ3: 98.4 | BR3: 2.46 | BS3: 0 | BT3: 2.46 | BU3: 0.56 | CP3: 3.2 | CQ3: 0.032 | CR3: 2.32 | CS3: 0.813 | CT3: 3.63 | CU3: 0.238 | CV3: 3.35 | CW3: 1.82 | CX3: 1.46 | CY3: 1.46 | CZ3: 0.011 | DA3: 0.011 | DB3: 0.02 | DC3: 0.02 | DD3: 411 | EP3: 0.166 | EQ3: 0.594 | ER3: 0.616 | ES3: 1.05 | ET3: 0.832 | EU3: 0.418 | EV3: 0.66 | EW3: 0.512 | EX3: 0.734 | EY3: 0.787 | EZ3: 0.283 | FA3: 0.667 | FB3: 1.27 | FC3: 1.63 | FD3: 0.408 | FE3: 0.56 | FF3: 0.919 | FG3: 0 | FH3: 0.385
A4: 174158 | B4: Water, bottled, generic | D4: SR Legacy | E4: 116.47304 | F4: =E4/SUM($E$3:$E$9) -> 0.5106902 | G4: 99.98 | H4: 0 | I4: 0 | K4: 0 | L4: 0 | N4: 0.07 | Q4: 0 | S4: 0 | AA4: 0 | AD4: 10 | AE4: 0 | AF4: 2 | AG4: 0 | AH4: 0 | AI4: 2 | AJ4: 0 | AK4: 0.007 | AN4: 0 | AP4: 0 | AQ4: 0 | AR4: 0 | AS4: 0 | AT4: 0 | AU4: 0 | BB4: 0 | BC4: 0 | BD4: 0 | BE4: 0 | BH4: 0 | BI4: 0 | BK4: 0 | BQ4: 0 | BR4: 0 | BV4: 0 | BW4: 0 | BX4: 0 | BY4: 0 | BZ4: 0 | CA4: 0 | CB4: 0 | CC4: 0 | CD4: 0 | CE4: 0 | CF4: 0 | CP4: 0 | CQ4: 0 | CR4: 0 | CS4: 0 | CT4: 0 | CW4: 0 | DD4: 0 | DE4: 0 | DF4: 0 | DG4: 0 | DH4: 0 | DI4: 0 | DJ4: 0 | DK4: 0 | DL4: 0 | DM4: 0 | DN4: 0 | DO4: 0 | DP4: 0 | DQ4: 0 | DR4: 0 | DS4: 0 | DT4: 0 | DU4: 0 | FI4: 0 | FJ4: 0 | FK4: 0
A5: 171320 | B5: Spices, cinnamon, ground | D5: SR Legacy | E5: 39.666667 | F5: =E5/SUM($E$3:$E$9) -> 0.17392332 | G5: 10.58 | H5: 247 | I5: 1035 | K5: 3.99 | L5: 1.24 | N5: 3.6 | Q5: 80.59 | S5: 53.1 | U5: 0.02 | V5: 1.04 | W5: 1.11 | X5: 0 | Y5: 0 | AA5: 2.17 | AB5: 0 | AD5: 1002 | AE5: 8.32 | AF5: 60 | AG5: 64 | AH5: 431 | AI5: 10 | AJ5: 1.83 | AK5: 0.339 | AL5: 17.466 | AN5: 3.1 | AP5: 0.022 | AQ5: 0.041 | AR5: 1.332 | AS5: 0.158 | AT5: 6 | AU5: 11 | BA5: 3.9 | BB5: 0 | BC5: 15 | BD5: 0 | BE5: 112 | BH5: 1 | BI5: 129 | BK5: 15 | BQ5: 0 | BR5: 0 | BV5: 3.8 | BW5: 0.358 | BX5: 0 | BY5: 6 | BZ5: 6 | CA5: 0 | CB5: 295 | CC5: 222 | CD5: 2.32 | CE5: 0 | CF5: 31.2 | CG5: 0 | CH5: 10.44 | CI5: 0.26 | CJ5: 0 | CK5: 0 | CL5: 0 | CM5: 0 | CN5: 0 | CP5: 0.345 | CQ5: 0.009 | CR5: 0.104 | CS5: 0.082 | CT5: 0.246 | CV5: 0.246 | CW5: 0.068 | DA5: 0 | DD5: 0 | DE5: 0 | DF5: 0 | DG5: 0 | DH5: 0.003 | DI5: 0.006 | DJ5: 0.001 | DK5: 0.246 | DL5: 0 | DM5: 0 | DN5: 0.044 | DO5: 0.011 | DP5: 0 | DQ5: 0 | DR5: 0 | DS5: 0 | DT5: 0 | DU5: 0 | DV5: 0 | DW5: 0 | DX5: 0.136 | DY5: 0 | DZ5: 0 | EA5: 0 | EB5: 0 | EC5: 0 | ED5: 0 | EE5: 0 | EF5: 0.011 | EG5: 0 | EH5: 0 | EI5: 0 | EJ5: 0 | EK5: 26 | EP5: 0.049 | EQ5: 0.136 | ER5: 0.146 | ES5: 0.253 | ET5: 0.243 | EU5: 0.078 | EV5: 0.146 | EW5: 0.136 | EX5: 0.224 | EY5: 0.166 | EZ5: 0.117 | FA5: 0.166 | FB5: 0.438 | FC5: 0.37 | FD5: 0.195 | FE5: 0.419 | FF5: 0.195 | FG5: 0 | FI5: 0 | FJ5: 0 | FK5: 0 | FL5: 0.058
A6: 172336 | B6: Oil, canola | D6: SR Legacy | E6: 30 | F6: =E6/SUM($E$3:$E$9) -> 0.13153865 | G6: 0 | H6: 884 | I6: 3699 | K6: 0 | L6: 100 | N6: 0 | Q6: 0 | S6: 0 | AA6: 0 | AD6: 0 | AE6: 0 | AF6: 0 | AG6: 0 | AH6: 0 | AI6: 0 | AJ6: 0 | AK6: 0 | AL6: 0 | AN6: 0 | AP6: 0 | AQ6: 0 | AR6: 0 | AS6: 0 | AT6: 0 | AU6: 0.2 | BA6: 0 | BB6: 0 | BC6: 0 | BD6: 0 | BE6: 0 | BH6: 0 | BI6: 0 | BK6: 0 | BQ6: 0 | BR6: 0 | BV6: 0 | BW6: 0 | BX6: 0 | BY6: 0 | BZ6: 0 | CA6: 0 | CB6: 0 | CC6: 0 | CD6: 17.46 | CE6: 0 | CF6: 71.3 | CG6: 0.01 | CH6: 27.34 | CI6: 0.99 | CJ6: 0.03 | CK6: 0 | CL6: 0 | CM6: 0.01 | CN6: 0 | CO6: 0 | CP6: 7.365 | CQ6: 0 | CR6: 4.298 | CS6: 2.087 | CT6: 63.276 | CV6: 61.714 | CW6: 28.142 | CY6: 18.64 | DA6: 0 | DD6: 0 | DE6: 0 | DF6: 0 | DG6: 0 | DH6: 0 | DI6: 0 | DJ6: 0.214 | DK6: 61.744 | DL6: 1.317 | DM6: 0 | DN6: 19.005 | DO6: 9.137 | DP6: 0 | DQ6: 0 | DR6: 0 | DS6: 0 | DT6: 0 | DU6: 0.395 | DW6: 0 | DX6: 0 | DY6: 0.65 | DZ6: 0.33 | EB6: 0 | EC6: 0 | ED6: 0 | EF6: 9.137 | EG6: 0 | EH6: 0 | EI6: 0.03 | EJ6: 0.03 | EL6: 0.365 | EM6: 0.365 | FI6: 0 | FJ6: 0 | FK6: 0 | FM6: 3 | FN6: 241 | FO6: 413
A7: 748366 | B7: Oil, soybean | D7: Foundation | E7: 5 | F7: =E7/SUM($E$3:$E$9) -> 0.021923108 | M7: 94.6 | CD7: 12.2 | CG7: 1.8 | CH7: 70.4 | CI7: 22 | CJ7: 0 | CK7: 1.6 | CL7: 0 | CM7: 0 | CP7: 14.9 | CQ7: 0.075 | CR7: 10.3 | CS7: 3.71 | CT7: 22.1 | CU7: 0.08 | CV7: 21.4 | CW7: 57.6 | CX7: 50.9 | CY7: 50.9 | CZ7: 6.62 | DB7: 0 | DC7: 0 | DW7: 0.014 | DX7: 0.086 | DY7: 0.294 | DZ7: 0.306 | EA7: 0.124 | EF7: 6.62 | EN7: 0.025 | EO7: 0.6 | FM7: 55.4 | FN7: 58 | FO7: 153 | FP7: 0 | FQ7: 2.15 | FR7: 5.62 | FS7: 10.5 | FT7: 20.8
A8: 173468 | B8: Salt, table | D8: SR Legacy | E8: 3.1301472 | F8: =E8/SUM($E$3:$E$9) -> 0.013724511 | G8: 0.2 | H8: 0 | I8: 0 | K8: 0 | L8: 0 | N8: 99.8 | Q8: 0 | S8: 0 | AA8: 0 | AD8: 24 | AE8: 0.33 | AF8: 1 | AG8: 0 | AH8: 8 | AI8: 38758 | AJ8: 0.1 | AK8: 0.03 | AL8: 0.1 | AN8: 0.1 | AO8: 2 | AP8: 0 | AQ8: 0 | AR8: 0 | AS8: 0 | AT8: 0 | AU8: 0 | BB8: 0 | BC8: 0 | BD8: 0 | BE8: 0 | BH8: 0 | BI8: 0 | BK8: 0 | BQ8: 0 | BR8: 0 | BV8: 0 | BW8: 0 | BX8: 0 | BY8: 0 | BZ8: 0 | CA8: 0 | CB8: 0 | CC8: 0 | CD8: 0 | CE8: 0 | CF8: 0 | CP8: 0 | CQ8: 0 | CR8: 0 | CS8: 0 | CT8: 0 | CW8: 0 | DD8: 0 | DE8: 0 | DF8: 0 | DG8: 0 | DH8: 0 | DI8: 0 | DJ8: 0 | DK8: 0 | DL8: 0 | DM8: 0 | DN8: 0 | DO8: 0 | DP8: 0 | DQ8: 0 | DR8: 0 | DS8: 0 | DT8: 0 | DU8: 0 | EK8: 0 | EP8: 0 | EQ8: 0 | ER8: 0 | ES8: 0 | ET8: 0 | EU8: 0 | EV8: 0 | EW8: 0 | EX8: 0 | EY8: 0 | EZ8: 0 | FA8: 0 | FB8: 0 | FC8: 0 | FD8: 0 | FE8: 0 | FF8: 0 | FI8: 0 | FJ8: 0 | FK8: 0 | FL8: 0
A9: 2644283 | B9: Lentils, dry | D9: Foundation | E9: 32.8 | F9: =E9/SUM($E$3:$E$9) -> 0.14381559 | G9: 9.451 | J9: 3.771 | K9: 23.56875 | L9: 1.925 | N9: 2.884 | O9: 360.285 | P9: 350.9328 | Q9: 62.17125 | Z9: 37.13 | AC9: 16 | AD9: 61.85 | AE9: 7.158 | AF9: 106.7 | AG9: 373.6 | AH9: 948.9 | AI9: 0 | AJ9: 3.863 | AK9: 0.8376 | AL9: 1.569
A10: Total | B10: Formulado | C10: Formulado | D10: Formulado | E10: =SUBTOTAL(9,E3:E9) -> 228.06985 | F10: 100% | G10: =SUMPRODUCT($F$3:$F$9,$G$3:$G$9) -> 54.593215 | H10: =SUMPRODUCT($F$3:$F$9,$H$3:$H$9) -> 159.88815 | I10: =SUMPRODUCT($F$3:$F$9,$I$3:$I$9) -> 669.27741 | J10: =SUMPRODUCT($F$3:$F$9,$J$3:$J$9) -> 0.55105398 | K10: =SUMPRODUCT($F$3:$F$9,$K$3:$K$9) -> 4.137877 | L10: =SUMPRODUCT($F$3:$F$9,$L$3:$L$9) -> 13.690046 | M10: =SUMPRODUCT($F$3:$F$9,$M$3:$M$9) -> 2.111853 | N10: =SUMPRODUCT($F$3:$F$9,$N$3:$N$9) -> 2.4500695 | O10: =SUMPRODUCT($F$3:$F$9,$O$3:$O$9) -> 51.814599 | P10: =SUMPRODUCT($F$3:$F$9,$P$3:$P$9) -> 50.469607 | Q10: =SUMPRODUCT($F$3:$F$9,$Q$3:$Q$9) -> 22.961885 | R10: =SUMPRODUCT($F$3:$F$9,$R$3:$R$9) -> 0.00087692432 | S10: =SUMPRODUCT($F$3:$F$9,$S$3:$S$9) -> 9.2353284 | T10: =SUMPRODUCT($F$3:$F$9,$T$3:$T$9) -> 0.00087692432 | U10: =SUMPRODUCT($F$3:$F$9,$U$3:$U$9) -> 0.0034784665 | V10: =SUMPRODUCT($F$3:$F$9,$V$3:$V$9) -> 0.18175718 | W10: =SUMPRODUCT($F$3:$F$9,$W$3:$W$9) -> 0.19305489 | X10: =SUMPRODUCT($F$3:$F$9,$X$3:$X$9) -> 0 | Y10: =SUMPRODUCT($F$3:$F$9,$Y$3:$Y$9) -> 0 | Z10: =SUMPRODUCT($F$3:$F$9,$Z$3:$Z$9) -> 5.3398728 | AA10: =SUMPRODUCT($F$3:$F$9,$AA$3:$AA$9) -> 0.37741361 | AB10: =SUMPRODUCT($F$3:$F$9,$AB$3:$AB$9) -> 0 | AC10: =SUMPRODUCT($F$3:$F$9,$AC$3:$AC$9) -> 2.3010494 | AD10: =SUMPRODUCT($F$3:$F$9,$AD$3:$AD$9) -> 188.81292 | AE10: =SUMPRODUCT($F$3:$F$9,$AE$3:$AE$9) -> 2.4883254 | AF10: =SUMPRODUCT($F$3:$F$9,$AF$3:$AF$9) -> 26.865612 | AG10: =SUMPRODUCT($F$3:$F$9,$AG$3:$AG$9) -> 65.667367 | AH10: =SUMPRODUCT($F$3:$F$9,$AH$3:$AH$9) -> 212.11613 | AI10: =SUMPRODUCT($F$3:$F$9,$AI$3:$AI$9) -> 535.26082 | AJ10: =SUMPRODUCT($F$3:$F$9,$AJ$3:$AJ$9) -> 0.88064868 | AK10: =SUMPRODUCT($F$3:$F$9,$AK$3:$AK$9) -> 0.18340651 | AL10: =SUMPRODUCT($F$3:$F$9,$AL$3:$AL$9) -> 3.2647639 | AM10: =SUMPRODUCT($F$3:$F$9,$AM$3:$AM$9) -> 0.21528492 | AN10: =SUMPRODUCT($F$3:$F$9,$AN$3:$AN$9) -> 0.67689648 | AO10: =SUMPRODUCT($F$3:$F$9,$AO$3:$AO$9) -> 0.027449022 | AP10: =SUMPRODUCT($F$3:$F$9,$AP$3:$AP$9) -> 0.004163929 | AQ10: =SUMPRODUCT($F$3:$F$9,$AQ$3:$AQ$9) -> 0.0089680127 | AR10: =SUMPRODUCT($F$3:$F$9,$AR$3:$AR$9) -> 0.23166587 | AS10: =SUMPRODUCT($F$3:$F$9,$AS$3:$AS$9) -> 0.027756116 | AT10: =SUMPRODUCT($F$3:$F$9,$AT$3:$AT$9) -> 1.3548481 | AU10: =SUMPRODUCT($F$3:$F$9,$AU$3:$AU$9) -> 3.4083125 | AV10: =SUMPRODUCT($F$3:$F$9,$AV$3:$AV$9) -> 0.002630773 | AW10: =SUMPRODUCT($F$3:$F$9,$AW$3:$AW$9) -> 1.3548481 | AX10: =SUMPRODUCT($F$3:$F$9,$AX$3:$AX$9) -> 0.00087692432 | AY10: =SUMPRODUCT($F$3:$F$9,$AY$3:$AY$9) -> 0.00087692432 | AZ10: =SUMPRODUCT($F$3:$F$9,$AZ$3:$AZ$9) -> 0.110054 | BA10: =SUMPRODUCT($F$3:$F$9,$BA$3:$BA$9) -> 0.67961635 | BB10: =SUMPRODUCT($F$3:$F$9,$BB$3:$BB$9) -> 0.004472314 | BC10: =SUMPRODUCT($F$3:$F$9,$BC$3:$BC$9) -> 3.3980817 | BD10: =SUMPRODUCT($F$3:$F$9,$BD$3:$BD$9) -> 0.78484726 | BE10: =SUMPRODUCT($F$3:$F$9,$BE$3:$BE$9) -> 19.479412 | BF10: =SUMPRODUCT($F$3:$F$9,$BF$3:$BF$9) -> 0 | BG10: =SUMPRODUCT($F$3:$F$9,$BG$3:$BG$9) -> 0 | BH10: =SUMPRODUCT($F$3:$F$9,$BH$3:$BH$9) -> 0.17392332 | BI10: =SUMPRODUCT($F$3:$F$9,$BI$3:$BI$9) -> 22.493109 | BJ10: =SUMPRODUCT($F$3:$F$9,$BJ$3:$BJ$9) -> 0.057000081 | BK10: =SUMPRODUCT($F$3:$F$9,$BK$3:$BK$9) -> 2.6088498 | BL10: =SUMPRODUCT($F$3:$F$9,$BL$3:$BL$9) -> 0 | BM10: =SUMPRODUCT($F$3:$F$9,$BM$3:$BM$9) -> 0 | BN10: =SUMPRODUCT($F$3:$F$9,$BN$3:$BN$9) -> 0.24992343 | BO10: =SUMPRODUCT($F$3:$F$9,$BO$3:$BO$9) -> 1.008463 | BP10: =SUMPRODUCT($F$3:$F$9,$BP$3:$BP$9) -> 1.0040783 | BQ10: =SUMPRODUCT($F$3:$F$9,$BQ$3:$BQ$9) -> 0.43144676 | BR10: =SUMPRODUCT($F$3:$F$9,$BR$3:$BR$9) -> 0.010786169 | BS10: =SUMPRODUCT($F$3:$F$9,$BS$3:$BS$9) -> 0 | BT10: =SUMPRODUCT($F$3:$F$9,$BT$3:$BT$9) -> 0.010786169 | BU10: =SUMPRODUCT($F$3:$F$9,$BU$3:$BU$9) -> 0.0024553881 | BV10: =SUMPRODUCT($F$3:$F$9,$BV$3:$BV$9) -> 0.66090863 | BW10: =SUMPRODUCT($F$3:$F$9,$BW$3:$BW$9) -> 0.06226455 | BX10: =SUMPRODUCT($F$3:$F$9,$BX$3:$BX$9) -> 0 | BY10: =SUMPRODUCT($F$3:$F$9,$BY$3:$BY$9) -> 1.0435399 | BZ10: =SUMPRODUCT($F$3:$F$9,$BZ$3:$BZ$9) -> 1.0435399 | CA10: =SUMPRODUCT($F$3:$F$9,$CA$3:$CA$9) -> 0 | CB10: =SUMPRODUCT($F$3:$F$9,$CB$3:$CB$9) -> 51.30738 | CC10: =SUMPRODUCT($F$3:$F$9,$CC$3:$CC$9) -> 38.610978 | CD10: =SUMPRODUCT($F$3:$F$9,$CD$3:$CD$9) -> 2.9676288 | CE10: =SUMPRODUCT($F$3:$F$9,$CE$3:$CE$9) -> 0 | CF10: =SUMPRODUCT($F$3:$F$9,$CF$3:$CF$9) -> 14.805113 | CG10: =SUMPRODUCT($F$3:$F$9,$CG$3:$CG$9) -> 0.040776981 | CH10: =SUMPRODUCT($F$3:$F$9,$CH$3:$CH$9) -> 6.9554129 | CI10: =SUMPRODUCT($F$3:$F$9,$CI$3:$CI$9) -> 0.6577517 | CJ10: =SUMPRODUCT($F$3:$F$9,$CJ$3:$CJ$9) -> 0.0039461594 | CK10: =SUMPRODUCT($F$3:$F$9,$CK$3:$CK$9) -> 0.035076973 | CL10: =SUMPRODUCT($F$3:$F$9,$CL$3:$CL$9) -> 0 | CM10: =SUMPRODUCT($F$3:$F$9,$CM$3:$CM$9) -> 0.0013153865 | CN10: =SUMPRODUCT($F$3:$F$9,$CN$3:$CN$9) -> 0 | CO10: =SUMPRODUCT($F$3:$F$9,$CO$3:$CO$9) -> 0 | CP10: =SUMPRODUCT($F$3:$F$9,$CP$3:$CP$9) -> 1.3694708 | CQ10: =SUMPRODUCT($F$3:$F$9,$CQ$3:$CQ$9) -> 0.0033498509 | CR10: =SUMPRODUCT($F$3:$F$9,$CR$3:$CR$9) -> 0.81942147 | CS10: =SUMPRODUCT($F$3:$F$9,$CS$3:$CS$9) -> 0.3736823 | CT10: =SUMPRODUCT($F$3:$F$9,$CT$3:$CT$9) -> 8.8664415 | CU10: =SUMPRODUCT($F$3:$F$9,$CU$3:$CU$9) -> 0.0027973886 | CV10: =SUMPRODUCT($F$3:$F$9,$CV$3:$CV$9) -> 8.6444042 | CW10: =SUMPRODUCT($F$3:$F$9,$CW$3:$CW$9) -> 4.9843384 | CX10: =SUMPRODUCT($F$3:$F$9,$CX$3:$CX$9) -> 1.1222877 | CY10: =SUMPRODUCT($F$3:$F$9,$CY$3:$CY$9) -> 3.5741681 | CZ10: =SUMPRODUCT($F$3:$F$9,$CZ$3:$CZ$9) -> 0.14517921 | DA10: =SUMPRODUCT($F$3:$F$9,$DA$3:$DA$9) -> 4.8230837e-05 | DB10: =SUMPRODUCT($F$3:$F$9,$DB$3:$DB$9) -> 8.7692432e-05 | DC10: =SUMPRODUCT($F$3:$F$9,$DC$3:$DC$9) -> 8.7692432e-05 | DD10: =SUMPRODUCT($F$3:$F$9,$DD$3:$DD$9) -> 1.8020795 | DE10: =SUMPRODUCT($F$3:$F$9,$DE$3:$DE$9) -> 0 | DF10: =SUMPRODUCT($F$3:$F$9,$DF$3:$DF$9) -> 0 | DG10: =SUMPRODUCT($F$3:$F$9,$DG$3:$DG$9) -> 0 | DH10: =SUMPRODUCT($F$3:$F$9,$DH$3:$DH$9) -> 0.00052176997 | DI10: =SUMPRODUCT($F$3:$F$9,$DI$3:$DI$9) -> 0.0010435399 | DJ10: =SUMPRODUCT($F$3:$F$9,$DJ$3:$DJ$9) -> 0.028323194 | DK10: =SUMPRODUCT($F$3:$F$9,$DK$3:$DK$9) -> 8.1645074 | DL10: =SUMPRODUCT($F$3:$F$9,$DL$3:$DL$9) -> 0.1732364 | DM10: =SUMPRODUCT($F$3:$F$9,$DM$3:$DM$9) -> 0 | DN10: =SUMPRODUCT($F$3:$F$9,$DN$3:$DN$9) -> 2.5075446 | DO10: =SUMPRODUCT($F$3:$F$9,$DO$3:$DO$9) -> 1.2037818 | DP10: =SUMPRODUCT($F$3:$F$9,$DP$3:$DP$9) -> 0 | DQ10: =SUMPRODUCT($F$3:$F$9,$DQ$3:$DQ$9) -> 0 | DR10: =SUMPRODUCT($F$3:$F$9,$DR$3:$DR$9) -> 0 | DS10: =SUMPRODUCT($F$3:$F$9,$DS$3:$DS$9) -> 0 | DT10: =SUMPRODUCT($F$3:$F$9,$DT$3:$DT$9) -> 0 | DU10: =SUMPRODUCT($F$3:$F$9,$DU$3:$DU$9) -> 0.051957766 | DV10: =SUMPRODUCT($F$3:$F$9,$DV$3:$DV$9) -> 0 | DW10: =SUMPRODUCT($F$3:$F$9,$DW$3:$DW$9) -> 0.00030692351 | DX10: =SUMPRODUCT($F$3:$F$9,$DX$3:$DX$9) -> 0.025538959 | DY10: =SUMPRODUCT($F$3:$F$9,$DY$3:$DY$9) -> 0.091945515 | DZ10: =SUMPRODUCT($F$3:$F$9,$DZ$3:$DZ$9) -> 0.050116225 | EA10: =SUMPRODUCT($F$3:$F$9,$EA$3:$EA$9) -> 0.0027184654 | EB10: =SUMPRODUCT($F$3:$F$9,$EB$3:$EB$9) -> 0 | EC10: =SUMPRODUCT($F$3:$F$9,$EC$3:$EC$9) -> 0 | ED10: =SUMPRODUCT($F$3:$F$9,$ED$3:$ED$9) -> 0 | EE10: =SUMPRODUCT($F$3:$F$9,$EE$3:$EE$9) -> 0 | EF10: =SUMPRODUCT($F$3:$F$9,$EF$3:$EF$9) -> 1.3489128 | EG10: =SUMPRODUCT($F$3:$F$9,$EG$3:$EG$9) -> 0 | EH10: =SUMPRODUCT($F$3:$F$9,$EH$3:$EH$9) -> 0 | EI10: =SUMPRODUCT($F$3:$F$9,$EI$3:$EI$9) -> 0.0039461594 | EJ10: =SUMPRODUCT($F$3:$F$9,$EJ$3:$EJ$9) -> 0.0039461594 | EK10: =SUMPRODUCT($F$3:$F$9,$EK$3:$EK$9) -> 4.5220064 | EL10: =SUMPRODUCT($F$3:$F$9,$EL$3:$EL$9) -> 0.048011606 | EM10: =SUMPRODUCT($F$3:$F$9,$EM$3:$EM$9) -> 0.048011606 | EN10: =SUMPRODUCT($F$3:$F$9,$EN$3:$EN$9) -> 0.0005480777 | EO10: =SUMPRODUCT($F$3:$F$9,$EO$3:$EO$9) -> 0.013153865 | EP10: =SUMPRODUCT($F$3:$F$9,$EP$3:$EP$9) -> 0.00925009 | EQ10: =SUMPRODUCT($F$3:$F$9,$EQ$3:$EQ$9) -> 0.026258037 | ER10: =SUMPRODUCT($F$3:$F$9,$ER$3:$ER$9) -> 0.028093732 | ES10: =SUMPRODUCT($F$3:$F$9,$ES$3:$ES$9) -> 0.048606453 | ET10: =SUMPRODUCT($F$3:$F$9,$ET$3:$ET$9) -> 0.045911373 | EU10: =SUMPRODUCT($F$3:$F$9,$EU$3:$EU$9) -> 0.015398791 | EV10: =SUMPRODUCT($F$3:$F$9,$EV$3:$EV$9) -> 0.028286655 | EW10: =SUMPRODUCT($F$3:$F$9,$EW$3:$EW$9) -> 0.025898498 | EX10: =SUMPRODUCT($F$3:$F$9,$EX$3:$EX$9) -> 0.042177137 | EY10: =SUMPRODUCT($F$3:$F$9,$EY$3:$EY$9) -> 0.032321969 | EZ10: =SUMPRODUCT($F$3:$F$9,$EZ$3:$EZ$9) -> 0.021589877 | FA10: =SUMPRODUCT($F$3:$F$9,$FA$3:$FA$9) -> 0.031795814 | FB10: =SUMPRODUCT($F$3:$F$9,$FB$3:$FB$9) -> 0.081746885 | FC10: =SUMPRODUCT($F$3:$F$9,$FC$3:$FC$9) -> 0.071498563 | FD10: =SUMPRODUCT($F$3:$F$9,$FD$3:$FD$9) -> 0.035703974 | FE10: =SUMPRODUCT($F$3:$F$9,$FE$3:$FE$9) -> 0.07532926 | FF10: =SUMPRODUCT($F$3:$F$9,$FF$3:$FF$9) -> 0.037944515 | FG10: =SUMPRODUCT($F$3:$F$9,$FG$3:$FG$9) -> 0 | FH10: =SUMPRODUCT($F$3:$F$9,$FH$3:$FH$9) -> 0.0016880793 | FI10: =SUMPRODUCT($F$3:$F$9,$FI$3:$FI$9) -> 0 | FJ10: =SUMPRODUCT($F$3:$F$9,$FJ$3:$FJ$9) -> 0 | FK10: =SUMPRODUCT($F$3:$F$9,$FK$3:$FK$9) -> 0 | FL10: =SUMPRODUCT($F$3:$F$9,$FL$3:$FL$9) -> 0.010087553 | FM10: =SUMPRODUCT($F$3:$F$9,$FM$3:$FM$9) -> 1.6091561 | FN10: =SUMPRODUCT($F$3:$F$9,$FN$3:$FN$9) -> 32.972354 | FO10: =SUMPRODUCT($F$3:$F$9,$FO$3:$FO$9) -> 57.679697 | FP10: =SUMPRODUCT($F$3:$F$9,$FP$3:$FP$9) -> 0 | FQ10: =SUMPRODUCT($F$3:$F$9,$FQ$3:$FQ$9) -> 0.047134682 | FR10: =SUMPRODUCT($F$3:$F$9,$FR$3:$FR$9) -> 0.12320787 | FS10: =SUMPRODUCT($F$3:$F$9,$FS$3:$FS$9) -> 0.23019263 | FT10: =SUMPRODUCT($F$3:$F$9,$FT$3:$FT$9) -> 0.45600065

Sheet Totales
A1: Nutriente | B1: Total | C1: Unidad
A2: Water | B2: =Ingredientes!G10 -> 54.593215 | C2: g
A3: Energy | B3: =Ingredientes!H10 -> 159.88815 | C3: kcal
A4: Energy | B4: =Ingredientes!I10 -> 669.27741 | C4: kJ
A5: Nitrogen | B5: =Ingredientes!J10 -> 0.55105398 | C5: g
A6: Protein | B6: =Ingredientes!K10 -> 4.137877 | C6: g
A7: Total lipid (fat) | B7: =Ingredientes!L10 -> 13.690046 | C7: g
A8: Total fat (NLEA) | B8: =Ingredientes!M10 -> 2.111853 | C8: g
A9: Ash | B9: =Ingredientes!N10 -> 2.4500695 | C9: g
A10: Energy (Atwater General Factors) | B10: =Ingredientes!O10 -> 51.814599 | C10: kcal
A11: Energy (Atwater Specific Factors) | B11: =Ingredientes!P10 -> 50.469607 | C11: kcal
A12: Carbohydrate, by difference | B12: =Ingredientes!Q10 -> 22.961885 | C12: g
A13: Carbohydrate, by summation | B13: =Ingredientes!R10 -> 0.00087692432 | C13: g
A14: Fiber, total dietary | B14: =Ingredientes!S10 -> 9.2353284 | C14: g
A15: Sugars, Total | B15: =Ingredientes!T10 -> 0.00087692432 | C15: g
A16: Sucrose | B16: =Ingredientes!U10 -> 0.0034784665 | C16: g
A17: Glucose | B17: =Ingredientes!V10 -> 0.18175718 | C17: g
A18: Fructose | B18: =Ingredientes!W10 -> 0.19305489 | C18: g
A19: Lactose | B19: =Ingredientes!X10 -> 0 | C19: g
A20: Maltose | B20: =Ingredientes!Y10 -> 0 | C20: g
A21: Starch | B21: =Ingredientes!Z10 -> 5.3398728 | C21: g
A22: Total Sugars | B22: =Ingredientes!AA10 -> 0.37741361 | C22: g
A23: Galactose | B23: =Ingredientes!AB10 -> 0 | C23: g
A24: Resistant starch | B24: =Ingredientes!AC10 -> 2.3010494 | C24: g
A25: Calcium, Ca | B25: =Ingredientes!AD10 -> 188.81292 | C25: mg
A26: Iron, Fe | B26: =Ingredientes!AE10 -> 2.4883254 | C26: mg
A27: Magnesium, Mg | B27: =Ingredientes!AF10 -> 26.865612 | C27: mg
A28: Phosphorus, P | B28: =Ingredientes!AG10 -> 65.667367 | C28: mg
A29: Potassium, K | B29: =Ingredientes!AH10 -> 212.11613 | C29: mg
A30: Sodium, Na | B30: =Ingredientes!AI10 -> 535.26082 | C30: mg
A31: Zinc, Zn | B31: =Ingredientes!AJ10 -> 0.88064868 | C31: mg
A32: Copper, Cu | B32: =Ingredientes!AK10 -> 0.18340651 | C32: mg
A33: Manganese, Mn | B33: =Ingredientes!AL10 -> 3.2647639 | C33: mg
A34: Iodine, I | B34: =Ingredientes!AM10 -> 0.21528492 | C34: µg
A35: Selenium, Se | B35: =Ingredientes!AN10 -> 0.67689648 | C35: µg
A36: Fluoride, F | B36: =Ingredientes!AO10 -> 0.027449022 | C36: µg
A37: Thiamin | B37: =Ingredientes!AP10 -> 0.004163929 | C37: mg
A38: Riboflavin | B38: =Ingredientes!AQ10 -> 0.0089680127 | C38: mg
A39: Niacin | B39: =Ingredientes!AR10 -> 0.23166587 | C39: mg
A40: Vitamin B-6 | B40: =Ingredientes!AS10 -> 0.027756116 | C40: mg
...
