Workbook

Sheet Ingredientes
A1: Detalles de formulación | G1: Proximates | P1: Carbohydrates | Z1: Minerals | AL1: Vitamins and Other Components | CN1: Lipids | FP1: Amino acids | GI1: Phytosterols | GR1: Nutrientes
A2: FDC ID | B2: Ingrediente | C2: Marca / Origen | D2: Tipo de dato | E2: Cantidad (g) | F2: Cantidad (%) | G2: Water (g) | H2: Energy (kcal) | I2: Energy (kJ) | J2: Nitrogen (g) | K2: Protein (g) | L2: Total fat (NLEA) (g) | M2: Total lipid (fat) (g) | N2: Ash (g) | O2: Carbohydrate, by difference (g) | P2: Fiber, total dietary (g) | Q2: Sugars, Total (g) | R2: Sucrose (g) | S2: Glucose (g) | T2: Fructose (g) | U2: Lactose (g) | V2: Maltose (g) | W2: Galactose (g) | X2: Starch (g) | Y2: Resistant starch (g) | Z2: Calcium, Ca (mg) | AA2: Iron, Fe (mg) | AB2: Magnesium, Mg (mg) | AC2: Phosphorus, P (mg) | AD2: Potassium, K (mg) | AE2: Sodium, Na (mg) | AF2: Zinc, Zn (mg) | AG2: Copper, Cu (mg) | AH2: Manganese, Mn (mg) | AI2: Iodine, I (µg) | AJ2: Selenium, Se (µg) | AK2: Fluoride, F (µg) | AL2: Folate, food (µg) | AM2: Thiamin (mg) | AN2: Riboflavin (mg) | AO2: Niacin (mg) | AP2: Vitamin B-6 (mg) | AQ2: Folate, total (µg) | AR2: Folic acid (µg) | AS2: Folate, DFE (µg) | AT2: Choline, total (mg) | AU2: Choline, free (mg) | AV2: Choline, from phosphocholine (mg) | AW2: Choline, from phosphatidyl choline (mg) | AX2: Choline, from glycerophosphocholine (mg) | AY2: Choline, from sphingomyelin (mg) | AZ2: Betaine (mg) | BA2: Vitamin B-12 (µg) | BB2: Vitamin B-12, added (µg) | BC2: Vitamin A, RAE (µg) | BD2: Retinol (µg) | BE2: Carotene, beta (µg) | BF2: cis-beta-Carotene (µg) | BG2: trans-beta-Carotene (µg) | BH2: Carotene, alpha (µg) | BI2: Cryptoxanthin, beta (µg) | BJ2: Cryptoxanthin, alpha (µg) | BK2: Vitamin A, IU (iu) | BL2: Lycopene (µg) | BM2: cis-Lycopene (µg) | BN2: trans-Lycopene (µg) | BO2: Lutein + zeaxanthin (µg) | BP2: cis-Lutein/Zeaxanthin (µg) | BQ2: Lutein (µg) | BR2: Zeaxanthin (µg) | BS2: Vitamin D (D2 + D3), International Units (iu) | BT2: Vitamin D (D2 + D3) (µg) | BU2: Vitamin D2 (ergocalciferol) (µg) | BV2: Vitamin D3 (cholecalciferol) (µg) | BW2: 25-hydroxycholecalciferol (µg) | BX2: Vitamin K (phylloquinone) (µg) | BY2: Vitamin K (Dihydrophylloquinone) (µg) | BZ2: Vitamin K (Menaquinone-4) (µg) | CA2: Vitamin E (alpha-tocopherol) (mg) | CB2: Vitamin E, added (mg) | CC2: Tocopherol, beta (mg) | CD2: Tocopherol, gamma (mg) | CE2: Tocopherol, delta (mg) | CF2: Tocotrienol, alpha (mg) | CG2: Tocotrienol, beta (mg) | CH2: Tocotrienol, gamma (mg) | CI2: Tocotrienol, delta (mg) | CJ2: Vitamin C, total ascorbic acid (mg) | CK2: Pantothenic acid (mg) | CL2: Caffeine (mg) | CM2: Theobromine (mg) | CN2: Fatty acids, total saturated (g) | CO2: SFA 4:0 (g) | CP2: SFA 5:0 (g) | CQ2: SFA 6:0 (g) | CR2: SFA 7:0 (g) | CS2: SFA 8:0 (g) | CT2: SFA 9:0 (g) | CU2: SFA 10:0 (g) | CV2: SFA 11:0 (g) | CW2: SFA 12:0 (g) | CX2: SFA 13:0 (g) | CY2: SFA 14:0 (g) | CZ2: SFA 15:0 (g) | DA2: SFA 16:0 (g) | DB2: SFA 17:0 (g) | DC2: SFA 18:0 (g) | DD2: SFA 20:0 (g) | DE2: SFA 21:0 (g) | DF2: SFA 22:0 (g) | DG2: SFA 23:0 (g) | DH2: SFA 24:0 (g) | DI2: Fatty acids, total monounsaturated (g) | DJ2: MUFA 12:1 (g) | DK2: MUFA 14:1 (g) | DL2: MUFA 14:1 c (g) | DM2: MUFA 15:1 (g) | DN2: MUFA 16:1 (g) | DO2: MUFA 16:1 c (g) | DP2: MUFA 17:1 (g) | DQ2: MUFA 17:1 c (g) | DR2: MUFA 18:1 (g) | DS2: MUFA 18:1 c (g) | DT2: MUFA 20:1 (g) | DU2: MUFA 20:1 c (g) | DV2: MUFA 22:1 (g) | DW2: MUFA 22:1 c (g) | DX2: MUFA 22:1 n-9 (g) | DY2: MUFA 22:1 n-11 (g) | DZ2: MUFA 24:1 c (g) | EA2: Fatty acids, total polyunsaturated (g) | EB2: PUFA 18:2 (g) | EC2: PUFA 18:2 c (g) | ED2: PUFA 18:2 n-6 c,c (g) | EE2: PUFA 18:2 CLAs (g) | EF2: PUFA 18:3 (g) | EG2: PUFA 18:3 c (g) | EH2: PUFA 18:3 n-3 c,c,c (ALA) (g) | EI2: PUFA 18:3 n-6 c,c,c (g) | EJ2: PUFA 18:4 (g) | EK2: PUFA 20:2 c (g) | EL2: PUFA 20:2 n-6 c,c (g) | EM2: PUFA 20:3 (g) | EN2: PUFA 20:3 c (g) | EO2: PUFA 20:3 n-3 (g) | EP2: PUFA 20:3 n-6 (g) | EQ2: PUFA 20:3 n-9 (g) | ER2: PUFA 20:4 (g) | ES2: PUFA 20:4c (g) | ET2: PUFA 20:5c (g) | EU2: PUFA 20:5 n-3 (EPA) (g) | EV2: PUFA 22:2 (g) | EW2: PUFA 22:3 (g) | EX2: PUFA 22:4 (g) | EY2: PUFA 22:5 c (g) | EZ2: PUFA 22:5 n-3 (DPA) (g) | FA2: PUFA 22:6 c (g) | FB2: PUFA 22:6 n-3 (DHA) (g) | FC2: Fatty acids, total trans (g) | FD2: Fatty acids, total trans-monoenoic (g) | FE2: Fatty acids, total trans-dienoic (g) | FF2: Fatty acids, total trans-polyenoic (g) | FG2: TFA 14:1 t (g) | FH2: TFA 16:1 t (g) | FI2: TFA 18:1 t (g) | FJ2: TFA 18:2 t,t (g) | FK2: TFA 18:2 t not further defined (g) | FL2: TFA 18:3 t (g) | FM2: TFA 20:1 t (g) | FN2: TFA 22:1 t (g) | FO2: Cholesterol (mg) | FP2: Tryptophan (g) | FQ2: Threonine (g) | FR2: Isoleucine (g) | FS2: Leucine (g) | FT2: Lysine (g) | FU2: Methionine (g) | FV2: Phenylalanine (g) | FW2: Tyrosine (g) | FX2: Valine (g) | FY2: Arginine (g) | FZ2: Histidine (g) | GA2: Alanine (g) | GB2: Aspartic acid (g) | GC2: Glutamic acid (g) | GD2: Glycine (g) | GE2: Proline (g) | GF2: Serine (g) | GG2: Hydroxyproline (g) | GH2: Cysteine (g) | GI2: Phytosterols (mg) | GJ2: Beta-sitosterol (mg) | GK2: Brassicasterol (mg) | GL2: Campesterol (mg) | GM2: Campestanol (mg) | GN2: Delta-5-avenasterol (mg) | GO2: Phytosterols, other (mg) | GP2: Stigmasterol (mg) | GQ2: Beta-sitostanol (mg) | GR2: Alcohol, ethyl (g)
A3: 748967 | B3: Eggs, Grade A, Large, egg whole | D3: Foundation | E3: 136.59072 | F3: =E3/SUM($E$3:$E$11) | G3: 75.8 | H3: 143.08 | I3: 598.64672 | J3: 1.99 | K3: 12.4 | L3: 8.65 | M3: 9.96 | N3: 0.85 | O3: 0.96 | P3: 0 | Q3: 0.2 | R3: 0 | S3: 0.2 | T3: 0 | U3: 0 | V3: 0 | X3: 0 | Z3: 48 | AA3: 1.67 | AB3: 11.4 | AC3: 184 | AD3: 132 | AE3: 129 | AF3: 1.24 | AG3: 0 | AH3: 0 | AI3: 49.1 | AJ3: 31.1 | AM3: 0.077 | AN3: 0.419 | AO3: 0 | AP3: 0.063 | AQ3: 71 | AT3: 335 | AU3: 0.6 | AV3: 309 | AW3: 0.2 | AX3: 0.2 | AY3: 25.1 | AZ3: 0.3 | BA3: 1.02 | BC3: 180 | BD3: 179 | BE3: 0 | BF3: 0 | BG3: 0 | BH3: 0 | BI3: 13 | BJ3: 13 | BL3: 0 | BM3: 0 | BN3: 0 | BP3: 57 | BQ3: 230 | BR3: 229 | BS3: 98.4 | BT3: 2.46 | BU3: 0 | BV3: 2.46 | BW3: 0.56 | CN3: 3.2 | CY3: 0.032 | DA3: 2.32 | DC3: 0.813 | DI3: 3.63 | DO3: 0.238 | DS3: 3.35 | EA3: 1.82 | EC3: 1.46 | ED3: 1.46 | EG3: 0.011 | EI3: 0.011 | EN3: 0.02 | EP3: 0.02 | FO3: 411 | FP3: 0.166 | FQ3: 0.594 | FR3: 0.616 | FS3: 1.05 | FT3: 0.832 | FU3: 0.418 | FV3: 0.66 | FW3: 0.512 | FX3: 0.734 | FY3: 0.787 | FZ3: 0.283 | GA3: 0.667 | GB3: 1.27 | GC3: 1.63 | GD3: 0.408 | GE3: 0.56 | GF3: 0.919 | GG3: 0 | GH3: 0.385
A4: 174158 | B4: Water, bottled, generic | D4: SR Legacy | E4: 600 | F4: =E4/SUM($E$3:$E$11) | G4: 100 | H4: 0 | I4: 0 | J4: 0 | K4: 0 | L4: 0 | M4: 0 | N4: 0.07 | O4: 0 | P4: 0 | Q4: 0 | Z4: 10 | AA4: 0 | AB4: 2 | AC4: 0 | AD4: 0 | AE4: 2 | AF4: 0 | AG4: 0.007 | AJ4: 0 | AL4: 0 | AM4: 0 | AN4: 0 | AO4: 0 | AP4: 0 | AQ4: 0 | AR4: 0 | AS4: 0 | AT4: 0 | BA4: 0 | BB4: 0 | BC4: 0 | BD4: 0 | BE4: 0 | BH4: 0 | BI4: 0 | BK4: 0 | BL4: 0 | BO4: 0 | BS4: 0 | BT4: 0 | BX4: 0 | CA4: 0 | CB4: 0 | CJ4: 0 | CK4: 0 | CL4: 0 | CM4: 0 | CN4: 0 | CO4: 0 | CQ4: 0 | CS4: 0 | CU4: 0 | CW4: 0 | CY4: 0 | DA4: 0 | DC4: 0 | DI4: 0 | DN4: 0 | DR4: 0 | DT4: 0 | DV4: 0 | EA4: 0 | EB4: 0 | EF4: 0 | EJ4: 0 | ER4: 0 | EU4: 0 | EZ4: 0 | FB4: 0 | FC4: 0 | FO4: 0 | GR4: 0
A5: 171320 | B5: Spices, cinnamon, ground | D5: SR Legacy | E5: 60.706985 | F5: =E5/SUM($E$3:$E$11) | G5: 10.6 | H5: 349.52 | I5: 1462.3917 | J5: 0.6384 | K5: 3.99 | L5: 1.24 | M5: 1.24 | N5: 3.6 | O5: 80.6 | P5: 53.1 | Q5: 2.17 | R5: 0.02 | S5: 1.04 | T5: 1.11 | U5: 0 | V5: 0 | W5: 0 | Z5: 1000 | AA5: 8.32 | AB5: 60 | AC5: 64 | AD5: 431 | AE5: 10 | AF5: 1.83 | AG5: 0.339 | AH5: 17.5 | AJ5: 3.1 | AL5: 6 | AM5: 0.022 | AN5: 0.041 | AO5: 1.33 | AP5: 0.158 | AQ5: 6 | AR5: 0 | AS5: 6 | AT5: 11 | AZ5: 3.9 | BA5: 0 | BB5: 0 | BC5: 15 | BD5: 0 | BE5: 112 | BH5: 1 | BI5: 129 | BK5: 295 | BL5: 15 | BO5: 222 | BS5: 0 | BT5: 0 | BX5: 31.2 | BY5: 0 | CA5: 2.32 | CB5: 0 | CC5: 0 | CD5: 10.4 | CE5: 0.26 | CF5: 0 | CG5: 0 | CH5: 0 | CI5: 0 | CJ5: 3.8 | CK5: 0.358 | CL5: 0 | CM5: 0 | CN5: 0.345 | CO5: 0 | CQ5: 0 | CS5: 0 | CU5: 0.003 | CW5: 0.006 | CX5: 0 | CY5: 0.009 | CZ5: 0 | DA5: 0.104 | DB5: 0.136 | DC5: 0.082 | DD5: 0 | DF5: 0 | DH5: 0 | DI5: 0.246 | DK5: 0 | DM5: 0 | DN5: 0.001 | DP5: 0 | DR5: 0.246 | DS5: 0.246 | DT5: 0 | DV5: 0 | DZ5: 0 | EA5: 0.068 | EB5: 0.044 | EF5: 0.011 | EH5: 0.011 | EI5: 0 | EJ5: 0 | EL5: 0 | EM5: 0 | ER5: 0 | EU5: 0 | EZ5: 0 | FB5: 0 | FC5: 0 | FD5: 0 | FI5: 0 | FO5: 0 | FP5: 0.049 | FQ5: 0.136 | FR5: 0.146 | FS5: 0.253 | FT5: 0.243 | FU5: 0.078 | FV5: 0.146 | FW5: 0.136 | FX5: 0.224 | FY5: 0.166 | FZ5: 0.117 | GA5: 0.166 | GB5: 0.438 | GC5: 0.37 | GD5: 0.195 | GE5: 0.419 | GF5: 0.195 | GG5: 0 | GH5: 0.058 | GI5: 26 | GR5: 0
A6: 172336 | B6: Oil, canola | D6: SR Legacy | E6: 0 | F6: =E6/SUM($E$3:$E$11) | G6: 0 | H6: 900 | I6: 3765.6 | J6: 0 | K6: 0 | L6: 100 | M6: 100 | N6: 0 | O6: 0 | P6: 0 | Q6: 0 | Z6: 0 | AA6: 0 | AB6: 0 | AC6: 0 | AD6: 0 | AE6: 0 | AF6: 0 | AG6: 0 | AH6: 0 | AJ6: 0 | AL6: 0 | AM6: 0 | AN6: 0 | AO6: 0 | AP6: 0 | AQ6: 0 | AR6: 0 | AS6: 0 | AT6: 0.2 | AZ6: 0 | BA6: 0 | BB6: 0 | BC6: 0 | BD6: 0 | BE6: 0 | BH6: 0 | BI6: 0 | BK6: 0 | BL6: 0 | BO6: 0 | BS6: 0 | BT6: 0 | BX6: 71.3 | BY6: 0 | BZ6: 0 | CA6: 17.5 | CB6: 0 | CC6: 0.01 | CD6: 27.3 | CE6: 0.99 | CF6: 0.03 | CG6: 0 | CH6: 0 | CI6: 0.01 | CJ6: 0 | CK6: 0 | CL6: 0 | CM6: 0 | CN6: 7.36 | CO6: 0 | CQ6: 0 | CS6: 0 | CU6: 0 | CW6: 0 | CY6: 0 | CZ6: 0 | DA6: 4.3 | DB6: 0 | DC6: 2.09 | DD6: 0.65 | DF6: 0.33 | DI6: 63.3 | DK6: 0 | DM6: 0 | DN6: 0.214 | DP6: 0 | DR6: 61.7 | DS6: 61.7 | DT6: 1.32 | DV6: 0 | EA6: 28.1 | EB6: 19 | ED6: 18.6 | EF6: 9.14 | EH6: 9.14 | EI6: 0 | EJ6: 0 | EL6: 0 | EM6: 0 | ER6: 0 | EU6: 0 | EZ6: 0 | FB6: 0 | FC6: 0.395 | FD6: 0.03 | FF6: 0.365 | FI6: 0.03 | FJ6: 0.365 | FO6: 0 | GJ6: 413 | GL6: 241 | GP6: 3 | GR6: 0
A7: 748366 | B7: Oil, soybean | D7: Foundation | E7: 0 | F7: =E7/SUM($E$3:$E$11) | H7: 851.4 | I7: 3562.2576 | L7: 94.6 | M7: 94.6 | CA7: 12.2 | CC7: 1.8 | CD7: 70.4 | CE7: 22 | CF7: 0 | CG7: 1.6 | CH7: 0 | CI7: 0 | CN7: 14.9 | CY7: 0.075 | CZ7: 0.014 | DA7: 10.3 | DB7: 0.086 | DC7: 3.71 | DD7: 0.294 | DE7: 0.025 | DF7: 0.306 | DH7: 0.124 | DI7: 22.1 | DO7: 0.08 | DS7: 21.4 | DU7: 0.6 | EA7: 57.6 | EC7: 50.9 | ED7: 50.9 | EG7: 6.62 | EH7: 6.62 | EN7: 0 | EP7: 0 | GJ7: 153 | GK7: 0 | GL7: 58 | GM7: 2.15 | GN7: 10.5 | GO7: 20.8 | GP7: 55.4 | GQ7: 5.62
A8: 173468 | B8: Salt, table | D8: SR Legacy | E8: 0 | F8: =E8/SUM($E$3:$E$11) | G8: 0.2 | H8: 0 | I8: 0 | J8: 0 | K8: 0 | L8: 0 | M8: 0 | N8: 99.8 | O8: 0 | P8: 0 | Q8: 0 | Z8: 24 | AA8: 0.33 | AB8: 1 | AC8: 0 | AD8: 8 | AE8: 38800 | AF8: 0.1 | AG8: 0.03 | AH8: 0.1 | AJ8: 0.1 | AK8: 2 | AL8: 0 | AM8: 0 | AN8: 0 | AO8: 0 | AP8: 0 | AQ8: 0 | AR8: 0 | AS8: 0 | AT8: 0 | BA8: 0 | BB8: 0 | BC8: 0 | BD8: 0 | BE8: 0 | BH8: 0 | BI8: 0 | BK8: 0 | BL8: 0 | BO8: 0 | BS8: 0 | BT8: 0 | BX8: 0 | CA8: 0 | CB8: 0 | CJ8: 0 | CK8: 0 | CL8: 0 | CM8: 0 | CN8: 0 | CO8: 0 | CQ8: 0 | CS8: 0 | CU8: 0 | CW8: 0 | CY8: 0 | DA8: 0 | DC8: 0 | DI8: 0 | DN8: 0 | DR8: 0 | DT8: 0 | DV8: 0 | EA8: 0 | EB8: 0 | EF8: 0 | EJ8: 0 | ER8: 0 | EU8: 0 | EZ8: 0 | FB8: 0 | FC8: 0 | FO8: 0 | FP8: 0 | FQ8: 0 | FR8: 0 | FS8: 0 | FT8: 0 | FU8: 0 | FV8: 0 | FW8: 0 | FX8: 0 | FY8: 0 | FZ8: 0 | GA8: 0 | GB8: 0 | GC8: 0 | GD8: 0 | GE8: 0 | GF8: 0 | GH8: 0 | GI8: 0 | GR8: 0
A9: 2644283 | B9: Lentils, dry | D9: Foundation | E9: 0 | F9: =E9/SUM($E$3:$E$11) | G9: 9.45 | H9: 360.48 | I9: 1508.2483 | J9: 3.77 | K9: 23.6 | L9: 1.92 | M9: 1.92 | N9: 2.88 | O9: 62.2 | X9: 37.1 | Y9: 16 | Z9: 61.8 | AA9: 7.16 | AB9: 107 | AC9: 374 | AD9: 949 | AE9: 0 | AF9: 3.86 | AG9: 0.838 | AH9: 1.57
A10: 2707920 | B10: Cookie, chocolate sandwich | D10: Survey (FNDDS) | E10: 0 | F10: =E10/SUM($E$3:$E$11) | G10: 3.11 | H10: 476.74 | I10: 1994.6802 | J10: 0.8336 | K10: 5.21 | L10: 19.1 | M10: 19.1 | O10: 71 | P10: 2.9 | Q10: 40.7 | Z10: 21 | AA10: 12.1 | AB10: 47 | AC10: 93 | AD10: 234 | AE10: 388 | AF10: 0.74 | AG10: 0.334 | AJ10: 5.2 | AL10: 3 | AM10: 0.197 | AN10: 0.238 | AO10: 2.6 | AP10: 0.023 | AQ10: 61 | AR10: 58 | AS10: 102 | AT10: 19.2 | BA10: 0 | BB10: 0 | BC10: 1 | BD10: 0 | BE10: 0 | BH10: 0 | BI10: 0 | BL10: 0 | BO10: 4 | BT10: 0 | BX10: 27.4 | CA10: 2.47 | CB10: 0 | CJ10: 0 | CL10: 5 | CM10: 184 | CN10: 5.65 | CO10: 0 | CQ10: 0 | CS10: 0.003 | CU10: 0.011 | CW10: 0.045 | CY10: 0.111 | DA10: 4.45 | DC10: 0.857 | DI10: 9.28 | DN10: 0.036 | DR10: 9.11 | DT10: 0.12 | DV10: 0.003 | EA10: 3.56 | EB10: 3.25 | EF10: 0.298 | EJ10: 0 | ER10: 0.004 | EU10: 0 | EZ10: 0 | FB10: 0 | FO10: 0 | GR10: 0
A11: 746782 | B11: Milk, whole, 3.25% milkfat, with added vitamin D | D11: Foundation | E11: 0 | F11: =E11/SUM($E$3:$E$11) | G11: 88.1 | H11: 60.4 | I11: 252.7136 | J11: 0.51 | K11: 3.27 | L11: 2.77 | M11: 3.2 | N11: 0.8 | O11: 4.63 | Q11: 4.81 | R11: 0 | S11: 0 | T11: 0 | U11: 4.81 | V11: 0 | W11: 0 | Z11: 123 | AA11: 0 | AB11: 11.9 | AC11: 101 | AD11: 150 | AE11: 38 | AF11: 0.42 | AG11: 0.001 | AH11: 0 | AI11: 37.9 | AJ11: 1.9 | AM11: 0.056 | AN11: 0.138 | AO11: 0.105 | AP11: 0.061 | AQ11: 0 | AT11: 17.8 | AU11: 3 | AV11: 1.3 | AW11: 1.8 | AX11: 10.3 | AY11: 1.4 | AZ11: 0.7 | BA11: 0.54 | BC11: 32 | BD11: 31 | BE11: 7 | BF11: 2 | BG11: 5 | BH11: 0 | BI11: 0 | BJ11: 0 | BL11: 0 | BM11: 0 | BN11: 0 | BP11: 0 | BQ11: 5 | BR11: 1 | BS11: 38.4 | BT11: 0.96 | BU11: 0 | BV11: 0.96 | BW11: 0 | CA11: 0.05 | CC11: 0 | CD11: 0 | CE11: 0 | CF11: 0 | CG11: 0 | CH11: 0 | CI11: 0 | CK11: 0.362 | CN11: 1.86 | CO11: 0.067 | CP11: 0 | CQ11: 0.054 | CR11: 0 | CS11: 0.034 | CT11: 0 | CU11: 0.084 | CV11: 0 | CW11: 0.097 | CY11: 0.303 | CZ11: 0.032 | DA11: 0.857 | DB11: 0.018 | DC11: 0.309 | DD11: 0.004 | DE11: 0 | DF11: 0.002 | DG11: 0 | DH11: 0.001 | DI11: 0.688 | DJ11: 0.001 | DL11: 0.024 | DM11: 0 | DO11: 0.039 | DP11: 0.005 | DQ11: 0.005 | DS11: 0.612 | DU11: 0.004 | DW11: 0 | DX11: 0 | DY11: 0 | DZ11: 0 | EA11: 0.108 | EC11: 0.097 | ED11: 0.084 | EE11: 0.013 | EG11: 0.013 | EH11: 0.012 | EI11: 0.001 | EJ11: 0 | EK11: 0.001 | EL11: 0.001 | EN11: 0.004 | EO11: 0 | EP11: 0.004 | EQ11: 0 | ER11: 0.004 | ES11: 0.004 | ET11: 0.001 | EU11: 0.001 | EV11: 0 | EW11: 0 | EX11: 0.001 | EY11: 0.002 | EZ11: 0.002 | FA11: 0 | FB11: 0 | FC11: 0.112 | FD11: 0.095 | FE11: 0.018 | FF11: 0 | FG11: 0.005 | FH11: 0.008 | FI11: 0.082 | FK11: 0.018 | FL11: 0 | FM11: 0 | FN11: 0 | FO11: 12 | FP11: 0.043 | FQ11: 0.154 | FR11: 0.173 | FS11: 0.333 | FT11: 0.298 | FU11: 0.09 | FV11: 0.161 | FW11: 0.162 | FX11: 0.207 | FY11: 0.127 | FZ11: 0.097 | GA11: 0.11 | GB11: 0.279 | GC11: 0.788 | GD11: 0.069 | GE11: 0.333 | GF11: 0.188 | GG11: 0 | GH11: 0.038
A12: Total | B12: Formulado | C12: Formulado | D12: Formulado | E12: =SUBTOTAL(9,E3:E11) | F12: 100% | G12: =SUMPRODUCT($F$3:$F$11,$G$3:$G$11) | H12: =SUMPRODUCT($F$3:$F$11,$H$3:$H$11) | I12: =SUMPRODUCT($F$3:$F$11,$I$3:$I$11) | J12: =SUMPRODUCT($F$3:$F$11,$J$3:$J$11) | K12: =SUMPRODUCT($F$3:$F$11,$K$3:$K$11) | L12: =SUMPRODUCT($F$3:$F$11,$L$3:$L$11) | M12: =SUMPRODUCT($F$3:$F$11,$M$3:$M$11) | N12: =SUMPRODUCT($F$3:$F$11,$N$3:$N$11) | O12: =SUMPRODUCT($F$3:$F$11,$O$3:$O$11) | P12: =SUMPRODUCT($F$3:$F$11,$P$3:$P$11) | Q12: =SUMPRODUCT($F$3:$F$11,$Q$3:$Q$11) | R12: =SUMPRODUCT($F$3:$F$11,$R$3:$R$11) | S12: =SUMPRODUCT($F$3:$F$11,$S$3:$S$11) | T12: =SUMPRODUCT($F$3:$F$11,$T$3:$T$11) | U12: =SUMPRODUCT($F$3:$F$11,$U$3:$U$11) | V12: =SUMPRODUCT($F$3:$F$11,$V$3:$V$11) | W12: =SUMPRODUCT($F$3:$F$11,$W$3:$W$11) | X12: =SUMPRODUCT($F$3:$F$11,$X$3:$X$11) | Y12: =SUMPRODUCT($F$3:$F$11,$Y$3:$Y$11) | Z12: =SUMPRODUCT($F$3:$F$11,$Z$3:$Z$11) | AA12: =SUMPRODUCT($F$3:$F$11,$AA$3:$AA$11) | AB12: =SUMPRODUCT($F$3:$F$11,$AB$3:$AB$11) | AC12: =SUMPRODUCT($F$3:$F$11,$AC$3:$AC$11) | AD12: =SUMPRODUCT($F$3:$F$11,$AD$3:$AD$11) | AE12: =SUMPRODUCT($F$3:$F$11,$AE$3:$AE$11) | AF12: =SUMPRODUCT($F$3:$F$11,$AF$3:$AF$11) | AG12: =SUMPRODUCT($F$3:$F$11,$AG$3:$AG$11) | AH12: =SUMPRODUCT($F$3:$F$11,$AH$3:$AH$11) | AI12: =SUMPRODUCT($F$3:$F$11,$AI$3:$AI$11) | AJ12: =SUMPRODUCT($F$3:$F$11,$AJ$3:$AJ$11) | AK12: =SUMPRODUCT($F$3:$F$11,$AK$3:$AK$11) | AL12: =SUMPRODUCT($F$3:$F$11,$AL$3:$AL$11) | AM12: =SUMPRODUCT($F$3:$F$11,$AM$3:$AM$11) | AN12: =SUMPRODUCT($F$3:$F$11,$AN$3:$AN$11) | AO12: =SUMPRODUCT($F$3:$F$11,$AO$3:$AO$11) | AP12: =SUMPRODUCT($F$3:$F$11,$AP$3:$AP$11) | AQ12: =SUMPRODUCT($F$3:$F$11,$AQ$3:$AQ$11) | AR12: =SUMPRODUCT($F$3:$F$11,$AR$3:$AR$11) | AS12: =SUMPRODUCT($F$3:$F$11,$AS$3:$AS$11) | AT12: =SUMPRODUCT($F$3:$F$11,$AT$3:$AT$11) | AU12: =SUMPRODUCT($F$3:$F$11,$AU$3:$AU$11) | AV12: =SUMPRODUCT($F$3:$F$11,$AV$3:$AV$11) | AW12: =SUMPRODUCT($F$3:$F$11,$AW$3:$AW$11) | AX12: =SUMPRODUCT($F$3:$F$11,$AX$3:$AX$11) | AY12: =SUMPRODUCT($F$3:$F$11,$AY$3:$AY$11) | AZ12: =SUMPRODUCT($F$3:$F$11,$AZ$3:$AZ$11) | BA12: =SUMPRODUCT($F$3:$F$11,$BA$3:$BA$11) | BB12: =SUMPRODUCT($F$3:$F$11,$BB$3:$BB$11) | BC12: =SUMPRODUCT($F$3:$F$11,$BC$3:$BC$11) | BD12: =SUMPRODUCT($F$3:$F$11,$BD$3:$BD$11) | BE12: =SUMPRODUCT($F$3:$F$11,$BE$3:$BE$11) | BF12: =SUMPRODUCT($F$3:$F$11,$BF$3:$BF$11) | BG12: =SUMPRODUCT($F$3:$F$11,$BG$3:$BG$11) | BH12: =SUMPRODUCT($F$3:$F$11,$BH$3:$BH$11) | BI12: =SUMPRODUCT($F$3:$F$11,$BI$3:$BI$11) | BJ12: =SUMPRODUCT($F$3:$F$11,$BJ$3:$BJ$11) | BK12: =SUMPRODUCT($F$3:$F$11,$BK$3:$BK$11) | BL12: =SUMPRODUCT($F$3:$F$11,$BL$3:$BL$11) | BM12: =SUMPRODUCT($F$3:$F$11,$BM$3:$BM$11) | BN12: =SUMPRODUCT($F$3:$F$11,$BN$3:$BN$11) | BO12: =SUMPRODUCT($F$3:$F$11,$BO$3:$BO$11) | BP12: =SUMPRODUCT($F$3:$F$11,$BP$3:$BP$11) | BQ12: =SUMPRODUCT($F$3:$F$11,$BQ$3:$BQ$11) | BR12: =SUMPRODUCT($F$3:$F$11,$BR$3:$BR$11) | BS12: =SUMPRODUCT($F$3:$F$11,$BS$3:$BS$11) | BT12: =SUMPRODUCT($F$3:$F$11,$BT$3:$BT$11) | BU12: =SUMPRODUCT($F$3:$F$11,$BU$3:$BU$11) | BV12: =SUMPRODUCT($F$3:$F$11,$BV$3:$BV$11) | BW12: =SUMPRODUCT($F$3:$F$11,$BW$3:$BW$11) | BX12: =SUMPRODUCT($F$3:$F$11,$BX$3:$BX$11) | BY12: =SUMPRODUCT($F$3:$F$11,$BY$3:$BY$11) | BZ12: =SUMPRODUCT($F$3:$F$11,$BZ$3:$BZ$11) | CA12: =SUMPRODUCT($F$3:$F$11,$CA$3:$CA$11) | CB12: =SUMPRODUCT($F$3:$F$11,$CB$3:$CB$11) | CC12: =SUMPRODUCT($F$3:$F$11,$CC$3:$CC$11) | CD12: =SUMPRODUCT($F$3:$F$11,$CD$3:$CD$11) | CE12: =SUMPRODUCT($F$3:$F$11,$CE$3:$CE$11) | CF12: =SUMPRODUCT($F$3:$F$11,$CF$3:$CF$11) | CG12: =SUMPRODUCT($F$3:$F$11,$CG$3:$CG$11) | CH12: =SUMPRODUCT($F$3:$F$11,$CH$3:$CH$11) | CI12: =SUMPRODUCT($F$3:$F$11,$CI$3:$CI$11) | CJ12: =SUMPRODUCT($F$3:$F$11,$CJ$3:$CJ$11) | CK12: =SUMPRODUCT($F$3:$F$11,$CK$3:$CK$11) | CL12: =SUMPRODUCT($F$3:$F$11,$CL$3:$CL$11) | CM12: =SUMPRODUCT($F$3:$F$11,$CM$3:$CM$11) | CN12: =SUMPRODUCT($F$3:$F$11,$CN$3:$CN$11) | CO12: =SUMPRODUCT($F$3:$F$11,$CO$3:$CO$11) | CP12: =SUMPRODUCT($F$3:$F$11,$CP$3:$CP$11) | CQ12: =SUMPRODUCT($F$3:$F$11,$CQ$3:$CQ$11) | CR12: =SUMPRODUCT($F$3:$F$11,$CR$3:$CR$11) | CS12: =SUMPRODUCT($F$3:$F$11,$CS$3:$CS$11) | CT12: =SUMPRODUCT($F$3:$F$11,$CT$3:$CT$11) | CU12: =SUMPRODUCT($F$3:$F$11,$CU$3:$CU$11) | CV12: =SUMPRODUCT($F$3:$F$11,$CV$3:$CV$11) | CW12: =SUMPRODUCT($F$3:$F$11,$CW$3:$CW$11) | CX12: =SUMPRODUCT($F$3:$F$11,$CX$3:$CX$11) | CY12: =SUMPRODUCT($F$3:$F$11,$CY$3:$CY$11) | CZ12: =SUMPRODUCT($F$3:$F$11,$CZ$3:$CZ$11) | DA12: =SUMPRODUCT($F$3:$F$11,$DA$3:$DA$11) | DB12: =SUMPRODUCT($F$3:$F$11,$DB$3:$DB$11) | DC12: =SUMPRODUCT($F$3:$F$11,$DC$3:$DC$11) | DD12: =SUMPRODUCT($F$3:$F$11,$DD$3:$DD$11) | DE12: =SUMPRODUCT($F$3:$F$11,$DE$3:$DE$11) | DF12: =SUMPRODUCT($F$3:$F$11,$DF$3:$DF$11) | DG12: =SUMPRODUCT($F$3:$F$11,$DG$3:$DG$11) | DH12: =SUMPRODUCT($F$3:$F$11,$DH$3:$DH$11) | DI12: =SUMPRODUCT($F$3:$F$11,$DI$3:$DI$11) | DJ12: =SUMPRODUCT($F$3:$F$11,$DJ$3:$DJ$11) | DK12: =SUMPRODUCT($F$3:$F$11,$DK$3:$DK$11) | DL12: =SUMPRODUCT($F$3:$F$11,$DL$3:$DL$11) | DM12: =SUMPRODUCT($F$3:$F$11,$DM$3:$DM$11) | DN12: =SUMPRODUCT($F$3:$F$11,$DN$3:$DN$11) | DO12: =SUMPRODUCT($F$3:$F$11,$DO$3:$DO$11) | DP12: =SUMPRODUCT($F$3:$F$11,$DP$3:$DP$11) | DQ12: =SUMPRODUCT($F$3:$F$11,$DQ$3:$DQ$11) | DR12: =SUMPRODUCT($F$3:$F$11,$DR$3:$DR$11) | DS12: =SUMPRODUCT($F$3:$F$11,$DS$3:$DS$11) | DT12: =SUMPRODUCT($F$3:$F$11,$DT$3:$DT$11) | DU12: =SUMPRODUCT($F$3:$F$11,$DU$3:$DU$11) | DV12: =SUMPRODUCT($F$3:$F$11,$DV$3:$DV$11) | DW12: =SUMPRODUCT($F$3:$F$11,$DW$3:$DW$11) | DX12: =SUMPRODUCT($F$3:$F$11,$DX$3:$DX$11) | DY12: =SUMPRODUCT($F$3:$F$11,$DY$3:$DY$11) | DZ12: =SUMPRODUCT($F$3:$F$11,$DZ$3:$DZ$11) | EA12: =SUMPRODUCT($F$3:$F$11,$EA$3:$EA$11) | EB12: =SUMPRODUCT($F$3:$F$11,$EB$3:$EB$11) | EC12: =SUMPRODUCT($F$3:$F$11,$EC$3:$EC$11) | ED12: =SUMPRODUCT($F$3:$F$11,$ED$3:$ED$11) | EE12: =SUMPRODUCT($F$3:$F$11,$EE$3:$EE$11) | EF12: =SUMPRODUCT($F$3:$F$11,$EF$3:$EF$11) | EG12: =SUMPRODUCT($F$3:$F$11,$EG$3:$EG$11) | EH12: =SUMPRODUCT($F$3:$F$11,$EH$3:$EH$11) | EI12: =SUMPRODUCT($F$3:$F$11,$EI$3:$EI$11) | EJ12: =SUMPRODUCT($F$3:$F$11,$EJ$3:$EJ$11) | EK12: =SUMPRODUCT($F$3:$F$11,$EK$3:$EK$11) | EL12: =SUMPRODUCT($F$3:$F$11,$EL$3:$EL$11) | EM12: =SUMPRODUCT($F$3:$F$11,$EM$3:$EM$11) | EN12: =SUMPRODUCT($F$3:$F$11,$EN$3:$EN$11) | EO12: =SUMPRODUCT($F$3:$F$11,$EO$3:$EO$11) | EP12: =SUMPRODUCT($F$3:$F$11,$EP$3:$EP$11) | EQ12: =SUMPRODUCT($F$3:$F$11,$EQ$3:$EQ$11) | ER12: =SUMPRODUCT($F$3:$F$11,$ER$3:$ER$11) | ES12: =SUMPRODUCT($F$3:$F$11,$ES$3:$ES$11) | ET12: =SUMPRODUCT($F$3:$F$11,$ET$3:$ET$11) | EU12: =SUMPRODUCT($F$3:$F$11,$EU$3:$EU$11) | EV12: =SUMPRODUCT($F$3:$F$11,$EV$3:$EV$11) | EW12: =SUMPRODUCT($F$3:$F$11,$EW$3:$EW$11) | EX12: =SUMPRODUCT($F$3:$F$11,$EX$3:$EX$11) | EY12: =SUMPRODUCT($F$3:$F$11,$EY$3:$EY$11) | EZ12: =SUMPRODUCT($F$3:$F$11,$EZ$3:$EZ$11) | FA12: =SUMPRODUCT($F$3:$F$11,$FA$3:$FA$11) | FB12: =SUMPRODUCT($F$3:$F$11,$FB$3:$FB$11) | FC12: =SUMPRODUCT($F$3:$F$11,$FC$3:$FC$11) | FD12: =SUMPRODUCT($F$3:$F$11,$FD$3:$FD$11) | FE12: =SUMPRODUCT($F$3:$F$11,$FE$3:$FE$11) | FF12: =SUMPRODUCT($F$3:$F$11,$FF$3:$FF$11) | FG12: =SUMPRODUCT($F$3:$F$11,$FG$3:$FG$11) | FH12: =SUMPRODUCT($F$3:$F$11,$FH$3:$FH$11) | FI12: =SUMPRODUCT($F$3:$F$11,$FI$3:$FI$11) | FJ12: =SUMPRODUCT($F$3:$F$11,$FJ$3:$FJ$11) | FK12: =SUMPRODUCT($F$3:$F$11,$FK$3:$FK$11) | FL12: =SUMPRODUCT($F$3:$F$11,$FL$3:$FL$11) | FM12: =SUMPRODUCT($F$3:$F$11,$FM$3:$FM$11) | FN12: =SUMPRODUCT($F$3:$F$11,$FN$3:$FN$11) | FO12: =SUMPRODUCT($F$3:$F$11,$FO$3:$FO$11) | FP12: =SUMPRODUCT($F$3:$F$11,$FP$3:$FP$11) | FQ12: =SUMPRODUCT($F$3:$F$11,$FQ$3:$FQ$11) | FR12: =SUMPRODUCT($F$3:$F$11,$FR$3:$FR$11) | FS12: =SUMPRODUCT($F$3:$F$11,$FS$3:$FS$11) | FT12: =SUMPRODUCT($F$3:$F$11,$FT$3:$FT$11) | FU12: =SUMPRODUCT($F$3:$F$11,$FU$3:$FU$11) | FV12: =SUMPRODUCT($F$3:$F$11,$FV$3:$FV$11) | FW12: =SUMPRODUCT($F$3:$F$11,$FW$3:$FW$11) | FX12: =SUMPRODUCT($F$3:$F$11,$FX$3:$FX$11) | FY12: =SUMPRODUCT($F$3:$F$11,$FY$3:$FY$11) | FZ12: =SUMPRODUCT($F$3:$F$11,$FZ$3:$FZ$11) | GA12: =SUMPRODUCT($F$3:$F$11,$GA$3:$GA$11) | GB12: =SUMPRODUCT($F$3:$F$11,$GB$3:$GB$11) | GC12: =SUMPRODUCT($F$3:$F$11,$GC$3:$GC$11) | GD12: =SUMPRODUCT($F$3:$F$11,$GD$3:$GD$11) | GE12: =SUMPRODUCT($F$3:$F$11,$GE$3:$GE$11) | GF12: =SUMPRODUCT($F$3:$F$11,$GF$3:$GF$11) | GG12: =SUMPRODUCT($F$3:$F$11,$GG$3:$GG$11) | GH12: =SUMPRODUCT($F$3:$F$11,$GH$3:$GH$11) | GI12: =SUMPRODUCT($F$3:$F$11,$GI$3:$GI$11) | GJ12: =SUMPRODUCT($F$3:$F$11,$GJ$3:$GJ$11) | GK12: =SUMPRODUCT($F$3:$F$11,$GK$3:$GK$11) | GL12: =SUMPRODUCT($F$3:$F$11,$GL$3:$GL$11) | GM12: =SUMPRODUCT($F$3:$F$11,$GM$3:$GM$11) | GN12: =SUMPRODUCT($F$3:$F$11,$GN$3:$GN$11) | GO12: =SUMPRODUCT($F$3:$F$11,$GO$3:$GO$11) | GP12: =SUMPRODUCT($F$3:$F$11,$GP$3:$GP$11) | GQ12: =SUMPRODUCT($F$3:$F$11,$GQ$3:$GQ$11) | GR12: =SUMPRODUCT($F$3:$F$11,$GR$3:$GR$11)

Sheet Totales
A1: Nutriente | B1: Total | C1: Unidad
A2: Water | B2: =Ingredientes!G12 | C2: g
A3: Energy | B3: =Ingredientes!H12 | C3: kcal
A4: Energy | B4: =Ingredientes!I12 | C4: kJ
A5: Nitrogen | B5: =Ingredientes!J12 | C5: g
A6: Protein | B6: =Ingredientes!K12 | C6: g
A7: Total fat (NLEA) | B7: =Ingredientes!L12 | C7: g
A8: Total lipid (fat) | B8: =Ingredientes!M12 | C8: g
A9: Ash | B9: =Ingredientes!N12 | C9: g
A10: Carbohydrate, by difference | B10: =Ingredientes!O12 | C10: g
A11: Fiber, total dietary | B11: =Ingredientes!P12 | C11: g
A12: Sugars, Total | B12: =Ingredientes!Q12 | C12: g
A13: Sucrose | B13: =Ingredientes!R12 | C13: g
A14: Glucose | B14: =Ingredientes!S12 | C14: g
A15: Fructose | B15: =Ingredientes!T12 | C15: g
A16: Lactose | B16: =Ingredientes!U12 | C16: g
A17: Maltose | B17: =Ingredientes!V12 | C17: g
A18: Galactose | B18: =Ingredientes!W12 | C18: g
A19: Starch | B19: =Ingredientes!X12 | C19: g
A20: Resistant starch | B20: =Ingredientes!Y12 | C20: g
A21: Calcium, Ca | B21: =Ingredientes!Z12 | C21: mg
A22: Iron, Fe | B22: =Ingredientes!AA12 | C22: mg
A23: Magnesium, Mg | B23: =Ingredientes!AB12 | C23: mg
A24: Phosphorus, P | B24: =Ingredientes!AC12 | C24: mg
A25: Potassium, K | B25: =Ingredientes!AD12 | C25: mg
A26: Sodium, Na | B26: =Ingredientes!AE12 | C26: mg
A27: Zinc, Zn | B27: =Ingredientes!AF12 | C27: mg
A28: Copper, Cu | B28: =Ingredientes!AG12 | C28: mg
A29: Manganese, Mn | B29: =Ingredientes!AH12 | C29: mg
A30: Iodine, I | B30: =Ingredientes!AI12 | C30: µg
A31: Selenium, Se | B31: =Ingredientes!AJ12 | C31: µg
A32: Fluoride, F | B32: =Ingredientes!AK12 | C32: µg
A33: Folate, food | B33: =Ingredientes!AL12 | C33: µg
A34: Thiamin | B34: =Ingredientes!AM12 | C34: mg
A35: Riboflavin | B35: =Ingredientes!AN12 | C35: mg
A36: Niacin | B36: =Ingredientes!AO12 | C36: mg
A37: Vitamin B-6 | B37: =Ingredientes!AP12 | C37: mg
A38: Folate, total | B38: =Ingredientes!AQ12 | C38: µg
A39: Folic acid | B39: =Ingredientes!AR12 | C39: µg
A40: Folate, DFE | B40: =Ingredientes!AS12 | C40: µg
...
