Workbook

Sheet Ingredientes
A1: Detalles de formulación | G1: Proximates | Q1: Carbohydrates | AB1: Minerals | AN1: Vitamins and Other Components | CN1: Lipids | EN1: Amino acids | FK1: Nutrientes | FL1: Phytosterols
A2: FDC ID | B2: Ingrediente | C2: Marca / Origen | D2: Tipo de dato | E2: Cantidad (g) | F2: Cantidad (%) | G2: Water (g) | H2: Energy (kcal) | I2: Energy (kJ) | J2: Energy (Atwater General Factors) (kcal) | K2: Energy (Atwater Specific Factors) (kcal) | L2: Nitrogen (g) | M2: Protein (g) | N2: Total fat (NLEA) (g) | O2: Total lipid (fat) (g) | P2: Ash (g) | Q2: Carbohydrate, by difference (g) | R2: Fiber, total dietary (g) | S2: Sugars, Total (g) | T2: Sucrose (g) | U2: Glucose (g) | V2: Fructose (g) | W2: Lactose (g) | X2: Maltose (g) | Y2: Galactose (g) | Z2: Starch (g) | AA2: Resistant starch (g) | AB2: Calcium, Ca (mg) | AC2: Iron, Fe (mg) | AD2: Magnesium, Mg (mg) | AE2: Phosphorus, P (mg) | AF2: Potassium, K (mg) | AG2: Sodium, Na (mg) | AH2: Zinc, Zn (mg) | AI2: Copper, Cu (mg) | AJ2: Manganese, Mn (mg) | AK2: Iodine, I (µg) | AL2: Selenium, Se (µg) | AM2: Fluoride, F (µg) | AN2: Vitamin C, total ascorbic acid (mg) | AO2: Thiamin (mg) | AP2: Riboflavin (mg) | AQ2: Niacin (mg) | AR2: Pantothenic acid (mg) | AS2: Vitamin B-6 (mg) | AT2: Folate, total (µg) | AU2: Folic acid (µg) | AV2: Folate, food (µg) | AW2: Folate, DFE (µg) | AX2: Choline, total (mg) | AY2: Choline, free (mg) | AZ2: Choline, from phosphocholine (mg) | BA2: Choline, from phosphotidyl choline (mg) | BB2: Choline, from glycerophosphocholine (mg) | BC2: Choline, from sphingomyelin (mg) | BD2: Betaine (mg) | BE2: Vitamin B-12 (µg) | BF2: Vitamin B-12, added (µg) | BG2: Vitamin A, RAE (µg) | BH2: Retinol (µg) | BI2: Carotene, beta (µg) | BJ2: cis-beta-Carotene (µg) | BK2: trans-beta-Carotene (µg) | BL2: Carotene, alpha (µg) | BM2: Cryptoxanthin, beta (µg) | BN2: Cryptoxanthin, alpha (µg) | BO2: Vitamin A, IU (IU) | BP2: Lycopene (µg) | BQ2: cis-Lycopene (µg) | BR2: trans-Lycopene (µg) | BS2: Lutein + zeaxanthin (µg) | BT2: cis-Lutein/Zeaxanthin (µg) | BU2: Lutein (µg) | BV2: Zeaxanthin (µg) | BW2: Vitamin E (alpha-tocopherol) (mg) | BX2: Vitamin E, added (mg) | BY2: Tocopherol, beta (mg) | BZ2: Tocopherol, gamma (mg) | CA2: Tocopherol, delta (mg) | CB2: Tocotrienol, alpha (mg) | CC2: Tocotrienol, beta (mg) | CD2: Tocotrienol, gamma (mg) | CE2: Tocotrienol, delta (mg) | CF2: Vitamin D (D2 + D3), International Units (IU) | CG2: Vitamin D (D2 + D3) (µg) | CH2: Vitamin D2 (ergocalciferol) (µg) | CI2: Vitamin D3 (cholecalciferol) (µg) | CJ2: 25-hydroxycholecalciferol (µg) | CK2: Vitamin K (phylloquinone) (µg) | CL2: Vitamin K (Dihydrophylloquinone) (µg) | CM2: Vitamin K (Menaquinone-4) (µg) | CN2: Fatty acids, total saturated (g) | CO2: SFA 4:0 (g) | CP2: SFA 6:0 (g) | CQ2: SFA 8:0 (g) | CR2: SFA 10:0 (g) | CS2: SFA 12:0 (g) | CT2: SFA 13:0 (g) | CU2: SFA 14:0 (g) | CV2: SFA 15:0 (g) | CW2: SFA 16:0 (g) | CX2: SFA 17:0 (g) | CY2: SFA 18:0 (g) | CZ2: SFA 20:0 (g) | DA2: SFA 21:0 (g) | DB2: SFA 22:0 (g) | DC2: SFA 24:0 (g) | DD2: Fatty acids, total monounsaturated (g) | DE2: MUFA 14:1 (g) | DF2: MUFA 15:1 (g) | DG2: MUFA 16:1 (g) | DH2: MUFA 16:1 c (g) | DI2: MUFA 17:1 (g) | DJ2: MUFA 18:1 (g) | DK2: MUFA 18:1 c (g) | DL2: MUFA 20:1 (g) | DM2: MUFA 20:1 c (g) | DN2: MUFA 22:1 (g) | DO2: MUFA 24:1 c (g) | DP2: Fatty acids, total polyunsaturated (g) | DQ2: PUFA 18:2 (g) | DR2: PUFA 18:2 c (g) | DS2: PUFA 18:2 n-6 c,c (g) | DT2: PUFA 18:3 (g) | DU2: PUFA 18:3 c (g) | DV2: PUFA 18:3 n-3 c,c,c (ALA) (g) | DW2: PUFA 18:3 n-6 c,c,c (g) | DX2: PUFA 18:4 (g) | DY2: PUFA 20:2 n-6 c,c (g) | DZ2: PUFA 20:3 (g) | EA2: PUFA 20:3 c (g) | EB2: PUFA 20:3 n-6 (g) | EC2: PUFA 20:4 (g) | ED2: PUFA 20:5 n-3 (EPA) (g) | EE2: PUFA 22:5 n-3 (DPA) (g) | EF2: PUFA 22:6 n-3 (DHA) (g) | EG2: Fatty acids, total trans (g) | EH2: Fatty acids, total trans-monoenoic (g) | EI2: TFA 18:1 t (g) | EJ2: TFA 18:2 t,t (g) | EK2: Fatty acids, total trans-polyenoic (g) | EL2: Cholesterol (mg) | EM2: Phytosterols (mg) | EN2: Tryptophan (g) | EO2: Threonine (g) | EP2: Isoleucine (g) | EQ2: Leucine (g) | ER2: Lysine (g) | ES2: Methionine (g) | ET2: Cystine (g) | EU2: Phenylalanine (g) | EV2: Tyrosine (g) | EW2: Valine (g) | EX2: Arginine (g) | EY2: Histidine (g) | EZ2: Alanine (g) | FA2: Aspartic acid (g) | FB2: Glutamic acid (g) | FC2: Glycine (g) | FD2: Proline (g) | FE2: Serine (g) | FF2: Hydroxyproline (g) | FG2: Cysteine (g) | FH2: Alcohol, ethyl (g) | FI2: Caffeine (mg) | FJ2: Theobromine (mg) | FK2: Sugars, added (g) | FL2: Stigmasterol (mg) | FM2: Campesterol (mg) | FN2: Brassicasterol (mg) | FO2: Beta-sitosterol (mg) | FP2: Campestanol (mg) | FQ2: Beta-sitostanol (mg) | FR2: Delta-5-avenasterol (mg) | FS2: Phytosterols, other (mg)
A3: 748967 | B3: Eggs, Grade A, Large, egg whole | D3: Foundation | E3: 150 | F3: =E3/SUM($E$3:$E$11) -> 0.3512306 | G3: 75.8 | H3: 148 | I3: 617 | L3: 1.99 | M3: 12.4 | N3: 8.65 | O3: 9.96 | P3: 0.85 | Q3: 0.96 | R3: 0 | S3: 0.2 | T3: 0 | U3: 0.2 | V3: 0 | W3: 0 | X3: 0 | Z3: 0 | AB3: 48 | AC3: 1.67 | AD3: 11.4 | AE3: 184 | AF3: 132 | AG3: 129 | AH3: 1.24 | AI3: 0 | AJ3: 0 | AK3: 49.1 | AL3: 31.1 | AO3: 0.077 | AP3: 0.419 | AQ3: 0 | AS3: 0.063 | AT3: 71 | AX3: 335 | AY3: 0.6 | AZ3: 309 | BA3: 0.2 | BB3: 0.2 | BC3: 25.1 | BD3: 0.3 | BE3: 1.02 | BG3: 180 | BH3: 179 | BI3: 0 | BJ3: 0 | BK3: 0 | BL3: 0 | BM3: 13 | BN3: 13 | BP3: 0 | BQ3: 0 | BR3: 0 | BT3: 57 | BU3: 230 | BV3: 229 | CF3: 98.4 | CG3: 2.46 | CH3: 0 | CI3: 2.46 | CJ3: 0.56 | CN3: 3.2 | CU3: 0.032 | CW3: 2.32 | CY3: 0.813 | DD3: 3.63 | DH3: 0.238 | DK3: 3.35 | DP3: 1.82 | DR3: 1.46 | DS3: 1.46 | DU3: 0.011 | DW3: 0.011 | EA3: 0.02 | EB3: 0.02 | EL3: 411 | EN3: 0.166 | EO3: 0.594 | EP3: 0.616 | EQ3: 1.05 | ER3: 0.832 | ES3: 0.418 | EU3: 0.66 | EV3: 0.512 | EW3: 0.734 | EX3: 0.787 | EY3: 0.283 | EZ3: 0.667 | FA3: 1.27 | FB3: 1.63 | FC3: 0.408 | FD3: 0.56 | FE3: 0.919 | FF3: 0 | FG3: 0.385
A4: 174158 | B4: Water, bottled, generic | D4: SR Legacy | E4: 116.47304 | F4: =E4/SUM($E$3:$E$11) -> 0.27272597 | G4: 99.98 | H4: 0 | I4: 0 | M4: 0 | N4: 0 | O4: 0 | P4: 0.07 | Q4: 0 | R4: 0 | S4: 0 | AB4: 10 | AC4: 0 | AD4: 2 | AE4: 0 | AF4: 0 | AG4: 2 | AH4: 0 | AI4: 0.007 | AL4: 0 | AN4: 0 | AO4: 0 | AP4: 0 | AQ4: 0 | AR4: 0 | AS4: 0 | AT4: 0 | AU4: 0 | AV4: 0 | AW4: 0 | AX4: 0 | BE4: 0 | BF4: 0 | BG4: 0 | BH4: 0 | BI4: 0 | BL4: 0 | BM4: 0 | BO4: 0 | BP4: 0 | BS4: 0 | BW4: 0 | BX4: 0 | CF4: 0 | CG4: 0 | CK4: 0 | CN4: 0 | CO4: 0 | CP4: 0 | CQ4: 0 | CR4: 0 | CS4: 0 | CU4: 0 | CW4: 0 | CY4: 0 | DD4: 0 | DG4: 0 | DJ4: 0 | DL4: 0 | DN4: 0 | DP4: 0 | DQ4: 0 | DT4: 0 | DX4: 0 | EC4: 0 | ED4: 0 | EE4: 0 | EF4: 0 | EG4: 0 | EL4: 0 | FH4: 0 | FI4: 0 | FJ4: 0
A5: 171320 | B5: Spices, cinnamon, ground | D5: SR Legacy | E5: 39.666667 | F5: =E5/SUM($E$3:$E$11) -> 0.09288098 | G5: 10.58 | H5: 247 | I5: 1035 | M5: 3.99 | N5: 1.24 | O5: 1.24 | P5: 3.6 | Q5: 80.59 | R5: 53.1 | S5: 2.17 | T5: 0.02 | U5: 1.04 | V5: 1.11 | W5: 0 | X5: 0 | Y5: 0 | AB5: 1002 | AC5: 8.32 | AD5: 60 | AE5: 64 | AF5: 431 | AG5: 10 | AH5: 1.83 | AI5: 0.339 | AJ5: 17.466 | AL5: 3.1 | AN5: 3.8 | AO5: 0.022 | AP5: 0.041 | AQ5: 1.332 | AR5: 0.358 | AS5: 0.158 | AT5: 6 | AU5: 0 | AV5: 6 | AW5: 6 | AX5: 11 | BD5: 3.9 | BE5: 0 | BF5: 0 | BG5: 15 | BH5: 0 | BI5: 112 | BL5: 1 | BM5: 129 | BO5: 295 | BP5: 15 | BS5: 222 | BW5: 2.32 | BX5: 0 | BY5: 0 | BZ5: 10.44 | CA5: 0.26 | CB5: 0 | CC5: 0 | CD5: 0 | CE5: 0 | CF5: 0 | CG5: 0 | CK5: 31.2 | CL5: 0 | CN5: 0.345 | CO5: 0 | CP5: 0 | CQ5: 0 | CR5: 0.003 | CS5: 0.006 | CT5: 0 | CU5: 0.009 | CV5: 0 | CW5: 0.104 | CX5: 0.136 | CY5: 0.082 | CZ5: 0 | DB5: 0 | DC5: 0 | DD5: 0.246 | DE5: 0 | DF5: 0 | DG5: 0.001 | DI5: 0 | DJ5: 0.246 | DK5: 0.246 | DL5: 0 | DN5: 0 | DO5: 0 | DP5: 0.068 | DQ5: 0.044 | DT5: 0.011 | DV5: 0.011 | DW5: 0 | DX5: 0 | DY5: 0 | DZ5: 0 | EC5: 0 | ED5: 0 | EE5: 0 | EF5: 0 | EG5: 0 | EH5: 0 | EI5: 0 | EL5: 0 | EM5: 26 | EN5: 0.049 | EO5: 0.136 | EP5: 0.146 | EQ5: 0.253 | ER5: 0.243 | ES5: 0.078 | ET5: 0.058 | EU5: 0.146 | EV5: 0.136 | EW5: 0.224 | EX5: 0.166 | EY5: 0.117 | EZ5: 0.166 | FA5: 0.438 | FB5: 0.37 | FC5: 0.195 | FD5: 0.419 | FE5: 0.195 | FF5: 0 | FH5: 0 | FI5: 0 | FJ5: 0
A6: 172336 | B6: Oil, canola | D6: SR Legacy | E6: 30 | F6: =E6/SUM($E$3:$E$11) -> 0.07024612 | G6: 0 | H6: 884 | I6: 3699 | M6: 0 | N6: 100 | O6: 100 | P6: 0 | Q6: 0 | R6: 0 | S6: 0 | AB6: 0 | AC6: 0 | AD6: 0 | AE6: 0 | AF6: 0 | AG6: 0 | AH6: 0 | AI6: 0 | AJ6: 0 | AL6: 0 | AN6: 0 | AO6: 0 | AP6: 0 | AQ6: 0 | AR6: 0 | AS6: 0 | AT6: 0 | AU6: 0 | AV6: 0 | AW6: 0 | AX6: 0.2 | BD6: 0 | BE6: 0 | BF6: 0 | BG6: 0 | BH6: 0 | BI6: 0 | BL6: 0 | BM6: 0 | BO6: 0 | BP6: 0 | BS6: 0 | BW6: 17.46 | BX6: 0 | BY6: 0.01 | BZ6: 27.34 | CA6: 0.99 | CB6: 0.03 | CC6: 0 | CD6: 0 | CE6: 0.01 | CF6: 0 | CG6: 0 | CK6: 71.3 | CL6: 0 | CM6: 0 | CN6: 7.365 | CO6: 0 | CP6: 0 | CQ6: 0 | CR6: 0 | CS6: 0 | CU6: 0 | CV6: 0 | CW6: 4.298 | CX6: 0 | CY6: 2.087 | CZ6: 0.65 | DB6: 0.33 | DD6: 63.276 | DE6: 0 | DF6: 0 | DG6: 0.214 | DI6: 0 | DJ6: 61.744 | DK6: 61.714 | DL6: 1.317 | DN6: 0 | DP6: 28.142 | DQ6: 19.005 | DS6: 18.64 | DT6: 9.137 | DV6: 9.137 | DW6: 0 | DX6: 0 | DY6: 0 | DZ6: 0 | EC6: 0 | ED6: 0 | EE6: 0 | EF6: 0 | EG6: 0.395 | EH6: 0.03 | EI6: 0.03 | EJ6: 0.365 | EK6: 0.365 | EL6: 0 | FH6: 0 | FI6: 0 | FJ6: 0 | FL6: 3 | FM6: 241 | FO6: 413
A7: 748366 | B7: Oil, soybean | D7: Foundation | E7: 5 | F7: =E7/SUM($E$3:$E$11) -> 0.011707687 | H7: 851.4 | I7: 3562.2576 | N7: 94.6 | O7: 94.6 | BW7: 12.2 | BY7: 1.8 | BZ7: 70.4 | CA7: 22 | CB7: 0 | CC7: 1.6 | CD7: 0 | CE7: 0 | CN7: 14.9 | CU7: 0.075 | CV7: 0.014 | CW7: 10.3 | CX7: 0.086 | CY7: 3.71 | CZ7: 0.294 | DA7: 0.025 | DB7: 0.306 | DC7: 0.124 | DD7: 22.1 | DH7: 0.08 | DK7: 21.4 | DM7: 0.6 | DP7: 57.6 | DR7: 50.9 | DS7: 50.9 | DU7: 6.62 | DV7: 6.62 | EA7: 0 | EB7: 0 | FL7: 55.4 | FM7: 58 | FN7: 0 | FO7: 153 | FP7: 2.15 | FQ7: 5.62 | FR7: 10.5 | FS7: 20.8
A8: 173468 | B8: Salt, table | D8: SR Legacy | E8: 3.1301472 | F8: =E8/SUM($E$3:$E$11) -> 0.0073293564 | G8: 0.2 | H8: 0 | I8: 0 | M8: 0 | N8: 0 | O8: 0 | P8: 99.8 | Q8: 0 | R8: 0 | S8: 0 | AB8: 24 | AC8: 0.33 | AD8: 1 | AE8: 0 | AF8: 8 | AG8: 38758 | AH8: 0.1 | AI8: 0.03 | AJ8: 0.1 | AL8: 0.1 | AM8: 2 | AN8: 0 | AO8: 0 | AP8: 0 | AQ8: 0 | AR8: 0 | AS8: 0 | AT8: 0 | AU8: 0 | AV8: 0 | AW8: 0 | AX8: 0 | BE8: 0 | BF8: 0 | BG8: 0 | BH8: 0 | BI8: 0 | BL8: 0 | BM8: 0 | BO8: 0 | BP8: 0 | BS8: 0 | BW8: 0 | BX8: 0 | CF8: 0 | CG8: 0 | CK8: 0 | CN8: 0 | CO8: 0 | CP8: 0 | CQ8: 0 | CR8: 0 | CS8: 0 | CU8: 0 | CW8: 0 | CY8: 0 | DD8: 0 | DG8: 0 | DJ8: 0 | DL8: 0 | DN8: 0 | DP8: 0 | DQ8: 0 | DT8: 0 | DX8: 0 | EC8: 0 | ED8: 0 | EE8: 0 | EF8: 0 | EG8: 0 | EL8: 0 | EM8: 0 | EN8: 0 | EO8: 0 | EP8: 0 | EQ8: 0 | ER8: 0 | ES8: 0 | ET8: 0 | EU8: 0 | EV8: 0 | EW8: 0 | EX8: 0 | EY8: 0 | EZ8: 0 | FA8: 0 | FB8: 0 | FC8: 0 | FD8: 0 | FE8: 0 | FH8: 0 | FI8: 0 | FJ8: 0
A9: 2644283 | B9: Lentils, dry | D9: Foundation | E9: 32.8 | F9: =E9/SUM($E$3:$E$11) -> 0.076802424 | G9: 9.451 | H9: 360.285 | I9: 1507.4324 | J9: 360.285 | K9: 350.9328 | L9: 3.771 | M9: 23.56875 | N9: 1.925 | O9: 1.925 | P9: 2.884 | Q9: 62.17125 | Z9: 37.13 | AA9: 16 | AB9: 61.85 | AC9: 7.158 | AD9: 106.7 | AE9: 373.6 | AF9: 948.9 | AG9: 0 | AH9: 3.863 | AI9: 0.8376 | AJ9: 1.569
A10: 2707920 | B10: Cookie, chocolate sandwich | D10: Survey (FNDDS) | E10: 25 | F10: =E10/SUM($E$3:$E$11) -> 0.058538433 | G10: 3.11 | H10: 464 | I10: 1994.6802 | M10: 5.21 | N10: 19.1 | O10: 19.1 | Q10: 71 | R10: 2.9 | S10: 40.7 | AB10: 21 | AC10: 12.1 | AD10: 47 | AE10: 93 | AF10: 234 | AG10: 388 | AH10: 0.74 | AI10: 0.334 | AL10: 5.2 | AN10: 0 | AO10: 0.197 | AP10: 0.238 | AQ10: 2.6 | AS10: 0.023 | AT10: 61 | AU10: 58 | AV10: 3 | AW10: 102 | AX10: 19.2 | BE10: 0 | BF10: 0 | BG10: 1 | BH10: 0 | BI10: 0 | BL10: 0 | BM10: 0 | BP10: 0 | BS10: 4 | BW10: 2.47 | BX10: 0 | CG10: 0 | CK10: 27.4 | CN10: 5.65 | CO10: 0 | CP10: 0 | CQ10: 0.003 | CR10: 0.011 | CS10: 0.045 | CU10: 0.111 | CW10: 4.45 | CY10: 0.857 | DD10: 9.28 | DG10: 0.036 | DJ10: 9.11 | DL10: 0.12 | DN10: 0.003 | DP10: 3.56 | DQ10: 3.25 | DT10: 0.298 | DX10: 0 | EC10: 0.004 | ED10: 0 | EE10: 0 | EF10: 0 | EL10: 0 | FH10: 0 | FI10: 5 | FJ10: 184
A11: 2720960 | B11: Pringles Crisps Bbq 16.9oz | C11: Kellogg Company US | D11: Branded | E11: 25 | F11: =E11/SUM($E$3:$E$11) -> 0.058538433 | H11: 527 | I11: 2214.1728 | M11: 4.5 | N11: 31.2 | O11: 31.2 | Q11: 57.6 | R11: 2.4 | S11: 4.3 | AB11: 9.7 | AC11: 0.6 | AF11: 412 | AG11: 482 | CG11: 0 | CN11: 8.6 | EG11: 0 | EL11: 0 | FK11: 3.2
A12: Total | B12: Formulado | C12: Formulado | D12: Formulado | E12: =SUBTOTAL(9,E3:E11) -> 427.06985 | F12: 100% | G12: =SUMPRODUCT($F$3:$F$11,$G$3:$G$11) -> 55.782483 | H12: =SUMPRODUCT($F$3:$F$11,$H$3:$H$11) -> 232.67157 | I12: =SUMPRODUCT($F$3:$F$11,$I$3:$I$11) -> 976.54141 | J12: =SUMPRODUCT($F$3:$F$11,$J$3:$J$11) -> 27.670761 | K12: =SUMPRODUCT($F$3:$F$11,$K$3:$K$11) -> 26.95249 | L12: =SUMPRODUCT($F$3:$F$11,$L$3:$L$11) -> 0.98857083 | M12: =SUMPRODUCT($F$3:$F$11,$M$3:$M$11) -> 7.1043999 | N12: =SUMPRODUCT($F$3:$F$11,$N$3:$N$11) -> 14.377804 | O12: =SUMPRODUCT($F$3:$F$11,$O$3:$O$11) -> 14.837916 | P12: =SUMPRODUCT($F$3:$F$11,$P$3:$P$11) -> 1.6049763 | Q12: =SUMPRODUCT($F$3:$F$11,$Q$3:$Q$11) -> 20.125405 | R12: =SUMPRODUCT($F$3:$F$11,$R$3:$R$11) -> 5.2422338 | S12: =SUMPRODUCT($F$3:$F$11,$S$3:$S$11) -> 2.9060273 | T12: =SUMPRODUCT($F$3:$F$11,$T$3:$T$11) -> 0.0018576196 | U12: =SUMPRODUCT($F$3:$F$11,$U$3:$U$11) -> 0.16684234 | V12: =SUMPRODUCT($F$3:$F$11,$V$3:$V$11) -> 0.10309789 | W12: =SUMPRODUCT($F$3:$F$11,$W$3:$W$11) -> 0 | X12: =SUMPRODUCT($F$3:$F$11,$X$3:$X$11) -> 0 | Y12: =SUMPRODUCT($F$3:$F$11,$Y$3:$Y$11) -> 0 | Z12: =SUMPRODUCT($F$3:$F$11,$Z$3:$Z$11) -> 2.851674 | AA12: =SUMPRODUCT($F$3:$F$11,$AA$3:$AA$11) -> 1.2288388 | AB12: =SUMPRODUCT($F$3:$F$11,$AB$3:$AB$11) -> 119.37634 | AC12: =SUMPRODUCT($F$3:$F$11,$AC$3:$AC$11) -> 2.6549334 | AD12: =SUMPRODUCT($F$3:$F$11,$AD$3:$AD$11) -> 21.075794 | AE12: =SUMPRODUCT($F$3:$F$11,$AE$3:$AE$11) -> 104.70827 | AF12: =SUMPRODUCT($F$3:$F$11,$AF$3:$AF$11) -> 197.14642 | AG12: =SUMPRODUCT($F$3:$F$11,$AG$3:$AG$11) -> 381.78264 | AH12: =SUMPRODUCT($F$3:$F$11,$AH$3:$AH$11) -> 0.94623728 | AI12: =SUMPRODUCT($F$3:$F$11,$AI$3:$AI$11) -> 0.11749716 | AJ12: =SUMPRODUCT($F$3:$F$11,$AJ$3:$AJ$11) -> 1.7434951 | AK12: =SUMPRODUCT($F$3:$F$11,$AK$3:$AK$11) -> 17.245422 | AL12: =SUMPRODUCT($F$3:$F$11,$AL$3:$AL$11) -> 11.516335 | AM12: =SUMPRODUCT($F$3:$F$11,$AM$3:$AM$11) -> 0.014658713 | AN12: =SUMPRODUCT($F$3:$F$11,$AN$3:$AN$11) -> 0.35294773 | AO12: =SUMPRODUCT($F$3:$F$11,$AO$3:$AO$11) -> 0.040620209 | AP12: =SUMPRODUCT($F$3:$F$11,$AP$3:$AP$11) -> 0.16490589 | AQ12: =SUMPRODUCT($F$3:$F$11,$AQ$3:$AQ$11) -> 0.27591739 | AR12: =SUMPRODUCT($F$3:$F$11,$AR$3:$AR$11) -> 0.033251391 | AS12: =SUMPRODUCT($F$3:$F$11,$AS$3:$AS$11) -> 0.038149107 | AT12: =SUMPRODUCT($F$3:$F$11,$AT$3:$AT$11) -> 29.065503 | AU12: =SUMPRODUCT($F$3:$F$11,$AU$3:$AU$11) -> 3.3952291 | AV12: =SUMPRODUCT($F$3:$F$11,$AV$3:$AV$11) -> 0.73290118 | AW12: =SUMPRODUCT($F$3:$F$11,$AW$3:$AW$11) -> 6.5282061 | AX12: =SUMPRODUCT($F$3:$F$11,$AX$3:$AX$11) -> 119.82193 | AY12: =SUMPRODUCT($F$3:$F$11,$AY$3:$AY$11) -> 0.21073836 | AZ12: =SUMPRODUCT($F$3:$F$11,$AZ$3:$AZ$11) -> 108.53025 | BA12: =SUMPRODUCT($F$3:$F$11,$BA$3:$BA$11) -> 0.07024612 | BB12: =SUMPRODUCT($F$3:$F$11,$BB$3:$BB$11) -> 0.07024612 | BC12: =SUMPRODUCT($F$3:$F$11,$BC$3:$BC$11) -> 8.815888 | BD12: =SUMPRODUCT($F$3:$F$11,$BD$3:$BD$11) -> 0.467605 | BE12: =SUMPRODUCT($F$3:$F$11,$BE$3:$BE$11) -> 0.35825521 | BF12: =SUMPRODUCT($F$3:$F$11,$BF$3:$BF$11) -> 0 | BG12: =SUMPRODUCT($F$3:$F$11,$BG$3:$BG$11) -> 64.673261 | BH12: =SUMPRODUCT($F$3:$F$11,$BH$3:$BH$11) -> 62.870277 | BI12: =SUMPRODUCT($F$3:$F$11,$BI$3:$BI$11) -> 10.40267 | BJ12: =SUMPRODUCT($F$3:$F$11,$BJ$3:$BJ$11) -> 0 | BK12: =SUMPRODUCT($F$3:$F$11,$BK$3:$BK$11) -> 0 | BL12: =SUMPRODUCT($F$3:$F$11,$BL$3:$BL$11) -> 0.09288098 | BM12: =SUMPRODUCT($F$3:$F$11,$BM$3:$BM$11) -> 16.547644 | BN12: =SUMPRODUCT($F$3:$F$11,$BN$3:$BN$11) -> 4.5659978 | BO12: =SUMPRODUCT($F$3:$F$11,$BO$3:$BO$11) -> 27.399889 | BP12: =SUMPRODUCT($F$3:$F$11,$BP$3:$BP$11) -> 1.3932147 | BQ12: =SUMPRODUCT($F$3:$F$11,$BQ$3:$BQ$11) -> 0 | BR12: =SUMPRODUCT($F$3:$F$11,$BR$3:$BR$11) -> 0 | BS12: =SUMPRODUCT($F$3:$F$11,$BS$3:$BS$11) -> 20.853731 | BT12: =SUMPRODUCT($F$3:$F$11,$BT$3:$BT$11) -> 20.020144 | BU12: =SUMPRODUCT($F$3:$F$11,$BU$3:$BU$11) -> 80.783038 | BV12: =SUMPRODUCT($F$3:$F$11,$BV$3:$BV$11) -> 80.431807 | BW12: =SUMPRODUCT($F$3:$F$11,$BW$3:$BW$11) -> 1.7294048 | BX12: =SUMPRODUCT($F$3:$F$11,$BX$3:$BX$11) -> 0 | BY12: =SUMPRODUCT($F$3:$F$11,$BY$3:$BY$11) -> 0.021776297 | BZ12: =SUMPRODUCT($F$3:$F$11,$BZ$3:$BZ$11) -> 3.7144275 | CA12: =SUMPRODUCT($F$3:$F$11,$CA$3:$CA$11) -> 0.35126182 | CB12: =SUMPRODUCT($F$3:$F$11,$CB$3:$CB$11) -> 0.0021073836 | CC12: =SUMPRODUCT($F$3:$F$11,$CC$3:$CC$11) -> 0.018732299 | CD12: =SUMPRODUCT($F$3:$F$11,$CD$3:$CD$11) -> 0 | CE12: =SUMPRODUCT($F$3:$F$11,$CE$3:$CE$11) -> 0.0007024612 | CF12: =SUMPRODUCT($F$3:$F$11,$CF$3:$CF$11) -> 34.561091 | CG12: =SUMPRODUCT($F$3:$F$11,$CG$3:$CG$11) -> 0.86402727 | CH12: =SUMPRODUCT($F$3:$F$11,$CH$3:$CH$11) -> 0 | CI12: =SUMPRODUCT($F$3:$F$11,$CI$3:$CI$11) -> 0.86402727 | CJ12: =SUMPRODUCT($F$3:$F$11,$CJ$3:$CJ$11) -> 0.19668914 | CK12: =SUMPRODUCT($F$3:$F$11,$CK$3:$CK$11) -> 9.510388 | CL12: =SUMPRODUCT($F$3:$F$11,$CL$3:$CL$11) -> 0 | CM12: =SUMPRODUCT($F$3:$F$11,$CM$3:$CM$11) -> 0 | CN12: =SUMPRODUCT($F$3:$F$11,$CN$3:$CN$11) -> 2.6819617 | CO12: =SUMPRODUCT($F$3:$F$11,$CO$3:$CO$11) -> 0 | CP12: =SUMPRODUCT($F$3:$F$11,$CP$3:$CP$11) -> 0 | CQ12: =SUMPRODUCT($F$3:$F$11,$CQ$3:$CQ$11) -> 0.0001756153 | CR12: =SUMPRODUCT($F$3:$F$11,$CR$3:$CR$11) -> 0.00092256571 | CS12: =SUMPRODUCT($F$3:$F$11,$CS$3:$CS$11) -> 0.0031915154 | CT12: =SUMPRODUCT($F$3:$F$11,$CT$3:$CT$11) -> 0 | CU12: =SUMPRODUCT($F$3:$F$11,$CU$3:$CU$11) -> 0.019451151 | CV12: =SUMPRODUCT($F$3:$F$11,$CV$3:$CV$11) -> 0.00016390761 | CW12: =SUMPRODUCT($F$3:$F$11,$CW$3:$CW$11) -> 1.5075176 | CX12: =SUMPRODUCT($F$3:$F$11,$CX$3:$CX$11) -> 0.013638674 | CY12: =SUMPRODUCT($F$3:$F$11,$CY$3:$CY$11) -> 0.53337332 | CZ12: =SUMPRODUCT($F$3:$F$11,$CZ$3:$CZ$11) -> 0.049102038 | DA12: =SUMPRODUCT($F$3:$F$11,$DA$3:$DA$11) -> 0.00029269217 | DB12: =SUMPRODUCT($F$3:$F$11,$DB$3:$DB$11) -> 0.026763772 | DC12: =SUMPRODUCT($F$3:$F$11,$DC$3:$DC$11) -> 0.0014517531 | DD12: =SUMPRODUCT($F$3:$F$11,$DD$3:$DD$11) -> 6.5446858 | DE12: =SUMPRODUCT($F$3:$F$11,$DE$3:$DE$11) -> 0 | DF12: =SUMPRODUCT($F$3:$F$11,$DF$3:$DF$11) -> 0 | DG12: =SUMPRODUCT($F$3:$F$11,$DG$3:$DG$11) -> 0.017232934 | DH12: =SUMPRODUCT($F$3:$F$11,$DH$3:$DH$11) -> 0.084529497 | DI12: =SUMPRODUCT($F$3:$F$11,$DI$3:$DI$11) -> 0 | DJ12: =SUMPRODUCT($F$3:$F$11,$DJ$3:$DJ$11) -> 4.8934103 | DK12: =SUMPRODUCT($F$3:$F$11,$DK$3:$DK$11) -> 5.7851848 | DL12: =SUMPRODUCT($F$3:$F$11,$DL$3:$DL$11) -> 0.099538752 | DM12: =SUMPRODUCT($F$3:$F$11,$DM$3:$DM$11) -> 0.007024612 | DN12: =SUMPRODUCT($F$3:$F$11,$DN$3:$DN$11) -> 0.0001756153 | DO12: =SUMPRODUCT($F$3:$F$11,$DO$3:$DO$11) -> 0 | DP12: =SUMPRODUCT($F$3:$F$11,$DP$3:$DP$11) -> 3.5051815 | DQ12: =SUMPRODUCT($F$3:$F$11,$DQ$3:$DQ$11) -> 1.5293642 | DR12: =SUMPRODUCT($F$3:$F$11,$DR$3:$DR$11) -> 1.1087179 | DS12: =SUMPRODUCT($F$3:$F$11,$DS$3:$DS$11) -> 2.4181056 | DT12: =SUMPRODUCT($F$3:$F$11,$DT$3:$DT$11) -> 0.66030494 | DU12: =SUMPRODUCT($F$3:$F$11,$DU$3:$DU$11) -> 0.081368422 | DV12: =SUMPRODUCT($F$3:$F$11,$DV$3:$DV$11) -> 0.72036537 | DW12: =SUMPRODUCT($F$3:$F$11,$DW$3:$DW$11) -> 0.0038635366 | DX12: =SUMPRODUCT($F$3:$F$11,$DX$3:$DX$11) -> 0 | DY12: =SUMPRODUCT($F$3:$F$11,$DY$3:$DY$11) -> 0 | DZ12: =SUMPRODUCT($F$3:$F$11,$DZ$3:$DZ$11) -> 0 | EA12: =SUMPRODUCT($F$3:$F$11,$EA$3:$EA$11) -> 0.007024612 | EB12: =SUMPRODUCT($F$3:$F$11,$EB$3:$EB$11) -> 0.007024612 | EC12: =SUMPRODUCT($F$3:$F$11,$EC$3:$EC$11) -> 0.00023415373 | ED12: =SUMPRODUCT($F$3:$F$11,$ED$3:$ED$11) -> 0 | EE12: =SUMPRODUCT($F$3:$F$11,$EE$3:$EE$11) -> 0 | EF12: =SUMPRODUCT($F$3:$F$11,$EF$3:$EF$11) -> 0 | EG12: =SUMPRODUCT($F$3:$F$11,$EG$3:$EG$11) -> 0.027747217 | EH12: =SUMPRODUCT($F$3:$F$11,$EH$3:$EH$11) -> 0.0021073836 | EI12: =SUMPRODUCT($F$3:$F$11,$EI$3:$EI$11) -> 0.0021073836 | EJ12: =SUMPRODUCT($F$3:$F$11,$EJ$3:$EJ$11) -> 0.025639834 | EK12: =SUMPRODUCT($F$3:$F$11,$EK$3:$EK$11) -> 0.025639834 | EL12: =SUMPRODUCT($F$3:$F$11,$EL$3:$EL$11) -> 144.35578 | EM12: =SUMPRODUCT($F$3:$F$11,$EM$3:$EM$11) -> 2.4149055 | EN12: =SUMPRODUCT($F$3:$F$11,$EN$3:$EN$11) -> 0.062855447 | EO12: =SUMPRODUCT($F$3:$F$11,$EO$3:$EO$11) -> 0.22126279 | EP12: =SUMPRODUCT($F$3:$F$11,$EP$3:$EP$11) -> 0.22991867 | EQ12: =SUMPRODUCT($F$3:$F$11,$EQ$3:$EQ$11) -> 0.39229102 | ER12: =SUMPRODUCT($F$3:$F$11,$ER$3:$ER$11) -> 0.31479394 | ES12: =SUMPRODUCT($F$3:$F$11,$ES$3:$ES$11) -> 0.15405911 | ET12: =SUMPRODUCT($F$3:$F$11,$ET$3:$ET$11) -> 0.0053870969 | EU12: =SUMPRODUCT($F$3:$F$11,$EU$3:$EU$11) -> 0.24537282 | EV12: =SUMPRODUCT($F$3:$F$11,$EV$3:$EV$11) -> 0.19246188 | EW12: =SUMPRODUCT($F$3:$F$11,$EW$3:$EW$11) -> 0.2786086 | EX12: =SUMPRODUCT($F$3:$F$11,$EX$3:$EX$11) -> 0.29183672 | EY12: =SUMPRODUCT($F$3:$F$11,$EY$3:$EY$11) -> 0.11026533 | EZ12: =SUMPRODUCT($F$3:$F$11,$EZ$3:$EZ$11) -> 0.24968905 | FA12: =SUMPRODUCT($F$3:$F$11,$FA$3:$FA$11) -> 0.48674473 | FB12: =SUMPRODUCT($F$3:$F$11,$FB$3:$FB$11) -> 0.60687184 | FC12: =SUMPRODUCT($F$3:$F$11,$FC$3:$FC$11) -> 0.16141388 | FD12: =SUMPRODUCT($F$3:$F$11,$FD$3:$FD$11) -> 0.23560627 | FE12: =SUMPRODUCT($F$3:$F$11,$FE$3:$FE$11) -> 0.34089271 | FF12: =SUMPRODUCT($F$3:$F$11,$FF$3:$FF$11) -> 0 | FG12: =SUMPRODUCT($F$3:$F$11,$FG$3:$FG$11) -> 0.13522378 | FH12: =SUMPRODUCT($F$3:$F$11,$FH$3:$FH$11) -> 0 | FI12: =SUMPRODUCT($F$3:$F$11,$FI$3:$FI$11) -> 0.29269217 | FJ12: =SUMPRODUCT($F$3:$F$11,$FJ$3:$FJ$11) -> 10.771072 | FK12: =SUMPRODUCT($F$3:$F$11,$FK$3:$FK$11) -> 0.18732299 | FL12: =SUMPRODUCT($F$3:$F$11,$FL$3:$FL$11) -> 0.8593442 | FM12: =SUMPRODUCT($F$3:$F$11,$FM$3:$FM$11) -> 17.608361 | FN12: =SUMPRODUCT($F$3:$F$11,$FN$3:$FN$11) -> 0 | FO12: =SUMPRODUCT($F$3:$F$11,$FO$3:$FO$11) -> 30.802923 | FP12: =SUMPRODUCT($F$3:$F$11,$FP$3:$FP$11) -> 0.025171526 | FQ12: =SUMPRODUCT($F$3:$F$11,$FQ$3:$FQ$11) -> 0.065797199 | FR12: =SUMPRODUCT($F$3:$F$11,$FR$3:$FR$11) -> 0.12293071 | FS12: =SUMPRODUCT($F$3:$F$11,$FS$3:$FS$11) -> 0.24351988

Sheet Totales
A1: Nutriente | B1: Total | C1: Unidad
A2: Water | B2: =Ingredientes!G12 -> 55.782483 | C2: g
A3: Energy | B3: =Ingredientes!H12 -> 232.67157 | C3: kcal
A4: Energy | B4: =Ingredientes!I12 -> 976.54141 | C4: kJ
A5: Energy (Atwater General Factors) | B5: =Ingredientes!J12 -> 27.670761 | C5: kcal
A6: Energy (Atwater Specific Factors) | B6: =Ingredientes!K12 -> 26.95249 | C6: kcal
A7: Nitrogen | B7: =Ingredientes!L12 -> 0.98857083 | C7: g
A8: Protein | B8: =Ingredientes!M12 -> 7.1043999 | C8: g
A9: Total fat (NLEA) | B9: =Ingredientes!N12 -> 14.377804 | C9: g
A10: Total lipid (fat) | B10: =Ingredientes!O12 -> 14.837916 | C10: g
A11: Ash | B11: =Ingredientes!P12 -> 1.6049763 | C11: g
A12: Carbohydrate, by difference | B12: =Ingredientes!Q12 -> 20.125405 | C12: g
A13: Fiber, total dietary | B13: =Ingredientes!R12 -> 5.2422338 | C13: g
A14: Sugars, Total | B14: =Ingredientes!S12 -> 2.9060273 | C14: g
A15: Sucrose | B15: =Ingredientes!T12 -> 0.0018576196 | C15: g
A16: Glucose | B16: =Ingredientes!U12 -> 0.16684234 | C16: g
A17: Fructose | B17: =Ingredientes!V12 -> 0.10309789 | C17: g
A18: Lactose | B18: =Ingredientes!W12 -> 0 | C18: g
A19: Maltose | B19: =Ingredientes!X12 -> 0 | C19: g
A20: Galactose | B20: =Ingredientes!Y12 -> 0 | C20: g
A21: Starch | B21: =Ingredientes!Z12 -> 2.851674 | C21: g
A22: Resistant starch | B22: =Ingredientes!AA12 -> 1.2288388 | C22: g
A23: Calcium, Ca | B23: =Ingredientes!AB12 -> 119.37634 | C23: mg
A24: Iron, Fe | B24: =Ingredientes!AC12 -> 2.6549334 | C24: mg
A25: Magnesium, Mg | B25: =Ingredientes!AD12 -> 21.075794 | C25: mg
A26: Phosphorus, P | B26: =Ingredientes!AE12 -> 104.70827 | C26: mg
A27: Potassium, K | B27: =Ingredientes!AF12 -> 197.14642 | C27: mg
A28: Sodium, Na | B28: =Ingredientes!AG12 -> 381.78264 | C28: mg
A29: Zinc, Zn | B29: =Ingredientes!AH12 -> 0.94623728 | C29: mg
A30: Copper, Cu | B30: =Ingredientes!AI12 -> 0.11749716 | C30: mg
A31: Manganese, Mn | B31: =Ingredientes!AJ12 -> 1.7434951 | C31: mg
A32: Iodine, I | B32: =Ingredientes!AK12 -> 17.245422 | C32: µg
A33: Selenium, Se | B33: =Ingredientes!AL12 -> 11.516335 | C33: µg
A34: Fluoride, F | B34: =Ingredientes!AM12 -> 0.014658713 | C34: µg
A35: Vitamin C, total ascorbic acid | B35: =Ingredientes!AN12 -> 0.35294773 | C35: mg
A36: Thiamin | B36: =Ingredientes!AO12 -> 0.040620209 | C36: mg
A37: Riboflavin | B37: =Ingredientes!AP12 -> 0.16490589 | C37: mg
A38: Niacin | B38: =Ingredientes!AQ12 -> 0.27591739 | C38: mg
A39: Pantothenic acid | B39: =Ingredientes!AR12 -> 0.033251391 | C39: mg
A40: Vitamin B-6 | B40: =Ingredientes!AS12 -> 0.038149107 | C40: mg
...
