Workbook

Sheet Ingredientes
A1: Detalles de formulación | G1: Proximates | P1: Carbohydrates | Z1: Minerals | AL1: Vitamins and Other Components | CK1: Lipids | FM1: Amino acids | GF1: Phytosterols | GJ1: Nutrientes
A2: FDC ID | B2: Ingrediente | C2: Marca / Origen | D2: Tipo de dato | E2: Cantidad (g) | F2: Cantidad (%) | G2: Water (g) | H2: Energy (kcal) | I2: Energy (kJ) | J2: Nitrogen (g) | K2: Protein (g) | L2: Total fat (NLEA) (g) | M2: Total lipid (fat) (g) | N2: Ash (g) | O2: Carbohydrate, by difference (g) | P2: Fiber, total dietary (g) | Q2: Sugars, Total (g) | R2: Sucrose (g) | S2: Glucose (g) | T2: Fructose (g) | U2: Lactose (g) | V2: Maltose (g) | W2: Galactose (g) | X2: Starch (g) | Y2: Resistant starch (g) | Z2: Calcium, Ca (mg) | AA2: Iron, Fe (mg) | AB2: Magnesium, Mg (mg) | AC2: Phosphorus, P (mg) | AD2: Potassium, K (mg) | AE2: Sodium, Na (mg) | AF2: Zinc, Zn (mg) | AG2: Copper, Cu (mg) | AH2: Manganese, Mn (mg) | AI2: Iodine, I (μg) | AJ2: Selenium, Se (μg) | AK2: Fluoride, F (μg) | AL2: Thiamin (mg) | AM2: Riboflavin (mg) | AN2: Niacin (mg) | AO2: Vitamin B-6 (mg) | AP2: Folate, total (μg) | AQ2: Folic acid (μg) | AR2: Folate, DFE (μg) | AS2: Choline, total (mg) | AT2: Vitamin B-12 (μg) | AU2: Vitamin A, RAE (μg) | AV2: Vitamin A, IU (iu) | AW2: Vitamin D (D2 + D3) (μg) | AX2: Vitamin K (phylloquinone) (μg) | AY2: Vitamin E (alpha-tocopherol) (mg) | AZ2: Vitamin C, total ascorbic acid (mg) | BA2: Pantothenic acid (mg) | BB2: Caffeine (mg) | BC2: Theobromine (mg) | BD2: Retinol (μg) | BE2: Carotene, beta (μg) | BF2: cis-beta-Carotene (μg) | BG2: trans-beta-Carotene (μg) | BH2: Carotene, alpha (μg) | BI2: Vitamin D (D2 + D3), International Units (iu) | BJ2: Vitamin D2 (ergocalciferol) (μg) | BK2: Vitamin D3 (cholecalciferol) (μg) | BL2: Lycopene (μg) | BM2: cis-Lycopene (μg) | BN2: trans-Lycopene (μg) | BO2: Lutein + zeaxanthin (μg) | BP2: Lutein (μg) | BQ2: Zeaxanthin (μg) | BR2: cis-Lutein/Zeaxanthin (μg) | BS2: Tocopherol, beta (mg) | BT2: Tocopherol, gamma (mg) | BU2: Tocopherol, delta (mg) | BV2: Tocotrienol, alpha (mg) | BW2: Tocotrienol, beta (mg) | BX2: Tocotrienol, gamma (mg) | BY2: Tocotrienol, delta (mg) | BZ2: Vitamin K (Menaquinone-4) (μg) | CA2: Vitamin K (Dihydrophylloquinone) (μg) | CB2: Folate, food (μg) | CC2: Choline, free (mg) | CD2: Choline, from phosphocholine (mg) | CE2: Choline, from phosphatidyl choline (mg) | CF2: Choline, from glycerophosphocholine (mg) | CG2: Betaine (mg) | CH2: Choline, from sphingomyelin (mg) | CI2: Vitamin E, added (mg) | CJ2: Vitamin B-12, added (μg) | CK2: Fatty acids, total saturated (g) | CL2: Fatty acids, total monounsaturated (g) | CM2: Fatty acids, total polyunsaturated (g) | CN2: Fatty acids, total trans (g) | CO2: Cholesterol (mg) | CP2: SFA 4:0 (g) | CQ2: SFA 6:0 (g) | CR2: SFA 8:0 (g) | CS2: SFA 10:0 (g) | CT2: SFA 12:0 (g) | CU2: SFA 14:0 (g) | CV2: SFA 16:0 (g) | CW2: SFA 18:0 (g) | CX2: SFA 20:0 (g) | CY2: MUFA 18:1 (g) | CZ2: PUFA 18:2 (g) | DA2: PUFA 18:3 (g) | DB2: PUFA 20:4 (g) | DC2: PUFA 22:6 n-3 (DHA) (g) | DD2: SFA 22:0 (g) | DE2: MUFA 14:1 (g) | DF2: MUFA 16:1 (g) | DG2: PUFA 18:4 (g) | DH2: MUFA 20:1 (g) | DI2: PUFA 20:5 n-3 (EPA) (g) | DJ2: MUFA 22:1 (g) | DK2: PUFA 22:5 n-3 (DPA) (g) | DL2: SFA 5:0 (g) | DM2: SFA 7:0 (g) | DN2: SFA 9:0 (g) | DO2: MUFA 12:1 (g) | DP2: SFA 15:0 (g) | DQ2: SFA 17:0 (g) | DR2: SFA 24:0 (g) | DS2: TFA 16:1 t (g) | DT2: TFA 18:1 t (g) | DU2: TFA 22:1 t (g) | DV2: TFA 18:2 t not further defined (g) | DW2: TFA 18:2 t,t (g) | DX2: PUFA 18:2 CLAs (g) | DY2: MUFA 24:1 c (g) | DZ2: PUFA 20:2 n-6 c,c (g) | EA2: MUFA 16:1 c (g) | EB2: MUFA 18:1 c (g) | EC2: PUFA 18:2 n-6 c,c (g) | ED2: MUFA 22:1 c (g) | EE2: MUFA 22:1 n-9 (g) | EF2: MUFA 22:1 n-11 (g) | EG2: SFA 21:0 (g) | EH2: SFA 23:0 (g) | EI2: PUFA 22:3 (g) | EJ2: PUFA 18:3 n-6 c,c,c (g) | EK2: MUFA 17:1 (g) | EL2: PUFA 20:3 (g) | EM2: Fatty acids, total trans-monoenoic (g) | EN2: Fatty acids, total trans-dienoic (g) | EO2: Fatty acids, total trans-polyenoic (g) | EP2: SFA 13:0 (g) | EQ2: MUFA 15:1 (g) | ER2: PUFA 22:2 (g) | ES2: SFA 11:0 (g) | ET2: TFA 14:1 t (g) | EU2: MUFA 14:1 c (g) | EV2: MUFA 17:1 c (g) | EW2: MUFA 20:1 c (g) | EX2: TFA 20:1 t (g) | EY2: PUFA 18:2 c (g) | EZ2: PUFA 18:3 c (g) | FA2: TFA 18:3 t (g) | FB2: PUFA 20:3 c (g) | FC2: PUFA 20:4c (g) | FD2: PUFA 20:5c (g) | FE2: PUFA 22:5 c (g) | FF2: PUFA 22:6 c (g) | FG2: PUFA 20:2 c (g) | FH2: PUFA 18:3 n-3 c,c,c (ALA) (g) | FI2: PUFA 20:3 n-3 (g) | FJ2: PUFA 20:3 n-6 (g) | FK2: PUFA 22:4 (g) | FL2: PUFA 20:3 n-9 (g) | FM2: Tryptophan (g) | FN2: Threonine (g) | FO2: Isoleucine (g) | FP2: Leucine (g) | FQ2: Lysine (g) | FR2: Methionine (g) | FS2: Phenylalanine (g) | FT2: Tyrosine (g) | FU2: Valine (g) | FV2: Arginine (g) | FW2: Histidine (g) | FX2: Alanine (g) | FY2: Aspartic acid (g) | FZ2: Glutamic acid (g) | GA2: Glycine (g) | GB2: Proline (g) | GC2: Serine (g) | GD2: Hydroxyproline (g) | GE2: Cysteine (g) | GF2: Phytosterols (mg) | GG2: Beta-sitosterol (mg) | GH2: Campesterol (mg) | GI2: Stigmasterol (mg) | GJ2: Alcohol, ethyl (g) | GK2: 25-hydroxycholecalciferol (μg) | GL2: Cryptoxanthin, beta (μg) | GM2: Cryptoxanthin, alpha (μg)
A3: 748967 | B3: Eggs, Grade A, Large, egg whole | D3: Foundation | E3: 1616.4388 | F3: =E3/SUM($E$3:$E$10) | G3: 75.8 | H3: 143.08 | I3: 598.64672 | J3: 1.99 | K3: 12.4 | L3: 8.65 | M3: 9.96 | N3: 0.85 | O3: 0.96 | P3: 0 | Q3: 0.2 | R3: 0 | S3: 0.2 | T3: 0 | U3: 0 | V3: 0 | X3: 0 | Z3: 48 | AA3: 1.67 | AB3: 11.4 | AC3: 184 | AD3: 132 | AE3: 129 | AF3: 1.24 | AG3: 0 | AH3: 0 | AI3: 49.1 | AJ3: 31.1 | AL3: 0.077 | AM3: 0.419 | AN3: 0 | AO3: 0.063 | AP3: 71 | AS3: 335 | AT3: 1.02 | AU3: 180 | AW3: 2.46 | BD3: 179 | BE3: 0 | BF3: 0 | BG3: 0 | BH3: 0 | BI3: 98.4 | BJ3: 0 | BK3: 2.46 | BL3: 0 | BM3: 0 | BN3: 0 | BP3: 230 | BQ3: 229 | BR3: 57 | CC3: 0.6 | CD3: 309 | CE3: 0.2 | CF3: 0.2 | CG3: 0.3 | CH3: 25.1 | CK3: 3.2 | CL3: 3.63 | CM3: 1.82 | CO3: 411 | CU3: 0.032 | CV3: 2.32 | CW3: 0.813 | EA3: 0.238 | EB3: 3.35 | EC3: 1.46 | EJ3: 0.011 | EY3: 1.46 | EZ3: 0.011 | FB3: 0.02 | FJ3: 0.02 | FM3: 0.166 | FN3: 0.594 | FO3: 0.616 | FP3: 1.05 | FQ3: 0.832 | FR3: 0.418 | FS3: 0.66 | FT3: 0.512 | FU3: 0.734 | FV3: 0.787 | FW3: 0.283 | FX3: 0.667 | FY3: 1.27 | FZ3: 1.63 | GA3: 0.408 | GB3: 0.56 | GC3: 0.919 | GD3: 0 | GE3: 0.385 | GK3: 0.56 | GL3: 13 | GM3: 13
A4: 174158 | B4: Water, bottled, generic | D4: SR Legacy | E4: 1017.9967 | F4: =E4/SUM($E$3:$E$10) | G4: 100 | H4: 0 | I4: 0 | J4: 0 | K4: 0 | L4: 0 | M4: 0 | N4: 0.07 | O4: 0 | P4: 0 | Q4: 0 | Z4: 10 | AA4: 0 | AB4: 2 | AC4: 0 | AD4: 0 | AE4: 2 | AF4: 0 | AG4: 0.007 | AJ4: 0 | AL4: 0 | AM4: 0 | AN4: 0 | AO4: 0 | AP4: 0 | AQ4: 0 | AR4: 0 | AS4: 0 | AT4: 0 | AU4: 0 | AV4: 0 | AW4: 0 | AX4: 0 | AY4: 0 | AZ4: 0 | BA4: 0 | BB4: 0 | BC4: 0 | BD4: 0 | BE4: 0 | BH4: 0 | BI4: 0 | BL4: 0 | BO4: 0 | CB4: 0 | CI4: 0 | CJ4: 0 | CK4: 0 | CL4: 0 | CM4: 0 | CN4: 0 | CO4: 0 | CP4: 0 | CQ4: 0 | CR4: 0 | CS4: 0 | CT4: 0 | CU4: 0 | CV4: 0 | CW4: 0 | CY4: 0 | CZ4: 0 | DA4: 0 | DB4: 0 | DC4: 0 | DF4: 0 | DG4: 0 | DH4: 0 | DI4: 0 | DJ4: 0 | DK4: 0 | GJ4: 0 | GL4: 0
A5: 171320 | B5: Spices, cinnamon, ground | D5: SR Legacy | E5: 427.45827 | F5: =E5/SUM($E$3:$E$10) | G5: 10.6 | H5: 349.52 | I5: 1462.3917 | J5: 0.6384 | K5: 3.99 | L5: 1.24 | M5: 1.24 | N5: 3.6 | O5: 80.6 | P5: 53.1 | Q5: 2.17 | R5: 0.02 | S5: 1.04 | T5: 1.11 | U5: 0 | V5: 0 | W5: 0 | Z5: 1000 | AA5: 8.32 | AB5: 60 | AC5: 64 | AD5: 431 | AE5: 10 | AF5: 1.83 | AG5: 0.339 | AH5: 17.5 | AJ5: 3.1 | AL5: 0.022 | AM5: 0.041 | AN5: 1.33 | AO5: 0.158 | AP5: 6 | AQ5: 0 | AR5: 6 | AS5: 11 | AT5: 0 | AU5: 15 | AV5: 295 | AW5: 0 | AX5: 31.2 | AY5: 2.32 | AZ5: 3.8 | BA5: 0.358 | BB5: 0 | BC5: 0 | BD5: 0 | BE5: 112 | BH5: 1 | BI5: 0 | BL5: 15 | BO5: 222 | BS5: 0 | BT5: 10.4 | BU5: 0.26 | BV5: 0 | BW5: 0 | BX5: 0 | BY5: 0 | CA5: 0 | CB5: 6 | CG5: 3.9 | CI5: 0 | CJ5: 0 | CK5: 0.345 | CL5: 0.246 | CM5: 0.068 | CN5: 0 | CO5: 0 | CP5: 0 | CQ5: 0 | CR5: 0 | CS5: 0.003 | CT5: 0.006 | CU5: 0.009 | CV5: 0.104 | CW5: 0.082 | CX5: 0 | CY5: 0.246 | CZ5: 0.044 | DA5: 0.011 | DB5: 0 | DC5: 0 | DD5: 0 | DE5: 0 | DF5: 0.001 | DG5: 0 | DH5: 0 | DI5: 0 | DJ5: 0 | DK5: 0 | DP5: 0 | DQ5: 0.136 | DR5: 0 | DT5: 0 | DY5: 0 | DZ5: 0 | EB5: 0.246 | EJ5: 0 | EK5: 0 | EL5: 0 | EM5: 0 | EP5: 0 | EQ5: 0 | FH5: 0.011 | FM5: 0.049 | FN5: 0.136 | FO5: 0.146 | FP5: 0.253 | FQ5: 0.243 | FR5: 0.078 | FS5: 0.146 | FT5: 0.136 | FU5: 0.224 | FV5: 0.166 | FW5: 0.117 | FX5: 0.166 | FY5: 0.438 | FZ5: 0.37 | GA5: 0.195 | GB5: 0.419 | GC5: 0.195 | GD5: 0 | GE5: 0.058 | GF5: 26 | GJ5: 0 | GL5: 129
A6: 172336 | B6: Oil, canola | D6: SR Legacy | E6: 323.28777 | F6: =E6/SUM($E$3:$E$10) | G6: 0 | H6: 900 | I6: 3765.6 | J6: 0 | K6: 0 | L6: 100 | M6: 100 | N6: 0 | O6: 0 | P6: 0 | Q6: 0 | Z6: 0 | AA6: 0 | AB6: 0 | AC6: 0 | AD6: 0 | AE6: 0 | AF6: 0 | AG6: 0 | AH6: 0 | AJ6: 0 | AL6: 0 | AM6: 0 | AN6: 0 | AO6: 0 | AP6: 0 | AQ6: 0 | AR6: 0 | AS6: 0.2 | AT6: 0 | AU6: 0 | AV6: 0 | AW6: 0 | AX6: 71.3 | AY6: 17.5 | AZ6: 0 | BA6: 0 | BB6: 0 | BC6: 0 | BD6: 0 | BE6: 0 | BH6: 0 | BI6: 0 | BL6: 0 | BO6: 0 | BS6: 0.01 | BT6: 27.3 | BU6: 0.99 | BV6: 0.03 | BW6: 0 | BX6: 0 | BY6: 0.01 | BZ6: 0 | CA6: 0 | CB6: 0 | CG6: 0 | CI6: 0 | CJ6: 0 | CK6: 7.36 | CL6: 63.3 | CM6: 28.1 | CN6: 0.395 | CO6: 0 | CP6: 0 | CQ6: 0 | CR6: 0 | CS6: 0 | CT6: 0 | CU6: 0 | CV6: 4.3 | CW6: 2.09 | CX6: 0.65 | CY6: 61.7 | CZ6: 19 | DA6: 9.14 | DB6: 0 | DC6: 0 | DD6: 0.33 | DE6: 0 | DF6: 0.214 | DG6: 0 | DH6: 1.32 | DI6: 0 | DJ6: 0 | DK6: 0 | DP6: 0 | DQ6: 0 | DT6: 0.03 | DW6: 0.365 | DZ6: 0 | EB6: 61.7 | EC6: 18.6 | EJ6: 0 | EK6: 0 | EL6: 0 | EM6: 0.03 | EO6: 0.365 | EQ6: 0 | FH6: 9.14 | GG6: 413 | GH6: 241 | GI6: 3 | GJ6: 0 | GL6: 0
A7: 173468 | B7: Salt, table | D7: SR Legacy | E7: 33.731276 | F7: =E7/SUM($E$3:$E$10) | G7: 0.2 | H7: 0 | I7: 0 | J7: 0 | K7: 0 | L7: 0 | M7: 0 | N7: 99.8 | O7: 0 | P7: 0 | Q7: 0 | Z7: 24 | AA7: 0.33 | AB7: 1 | AC7: 0 | AD7: 8 | AE7: 38800 | AF7: 0.1 | AG7: 0.03 | AH7: 0.1 | AJ7: 0.1 | AK7: 2 | AL7: 0 | AM7: 0 | AN7: 0 | AO7: 0 | AP7: 0 | AQ7: 0 | AR7: 0 | AS7: 0 | AT7: 0 | AU7: 0 | AV7: 0 | AW7: 0 | AX7: 0 | AY7: 0 | AZ7: 0 | BA7: 0 | BB7: 0 | BC7: 0 | BD7: 0 | BE7: 0 | BH7: 0 | BI7: 0 | BL7: 0 | BO7: 0 | CB7: 0 | CI7: 0 | CJ7: 0 | CK7: 0 | CL7: 0 | CM7: 0 | CN7: 0 | CO7: 0 | CP7: 0 | CQ7: 0 | CR7: 0 | CS7: 0 | CT7: 0 | CU7: 0 | CV7: 0 | CW7: 0 | CY7: 0 | CZ7: 0 | DA7: 0 | DB7: 0 | DC7: 0 | DF7: 0 | DG7: 0 | DH7: 0 | DI7: 0 | DJ7: 0 | DK7: 0 | FM7: 0 | FN7: 0 | FO7: 0 | FP7: 0 | FQ7: 0 | FR7: 0 | FS7: 0 | FT7: 0 | FU7: 0 | FV7: 0 | FW7: 0 | FX7: 0 | FY7: 0 | FZ7: 0 | GA7: 0 | GB7: 0 | GC7: 0 | GE7: 0 | GF7: 0 | GJ7: 0 | GL7: 0
A8: 2644283 | B8: Lentils, dry | D8: Foundation | E8: 353.46129 | F8: =E8/SUM($E$3:$E$10) | G8: 9.45 | H8: 360.48 | I8: 1508.2483 | J8: 3.77 | K8: 23.6 | L8: 1.92 | M8: 1.92 | N8: 2.88 | O8: 62.2 | X8: 37.1 | Y8: 16 | Z8: 61.8 | AA8: 7.16 | AB8: 107 | AC8: 374 | AD8: 949 | AE8: 0 | AF8: 3.86 | AG8: 0.838 | AH8: 1.57
A9: 2707920 | B9: Cookie, chocolate sandwich | D9: Survey (FNDDS) | E9: 150 | F9: =E9/SUM($E$3:$E$10) | G9: 3.11 | H9: 476.74 | I9: 1994.6802 | J9: 0.8336 | K9: 5.21 | L9: 19.1 | M9: 19.1 | O9: 71 | P9: 2.9 | Q9: 40.7 | Z9: 21 | AA9: 12.1 | AB9: 47 | AC9: 93 | AD9: 234 | AE9: 388 | AF9: 0.74 | AG9: 0.334 | AJ9: 5.2 | AL9: 0.197 | AM9: 0.238 | AN9: 2.6 | AO9: 0.023 | AP9: 61 | AQ9: 58 | AR9: 102 | AS9: 19.2 | AT9: 0 | AU9: 1 | AW9: 0 | AX9: 27.4 | AY9: 2.47 | AZ9: 0 | BB9: 5 | BC9: 184 | BD9: 0 | BE9: 0 | BH9: 0 | BL9: 0 | BO9: 4 | CB9: 3 | CI9: 0 | CJ9: 0 | CK9: 5.65 | CL9: 9.28 | CM9: 3.56 | CO9: 0 | CP9: 0 | CQ9: 0 | CR9: 0.003 | CS9: 0.011 | CT9: 0.045 | CU9: 0.111 | CV9: 4.45 | CW9: 0.857 | CY9: 9.11 | CZ9: 3.25 | DA9: 0.298 | DB9: 0.004 | DC9: 0 | DF9: 0.036 | DG9: 0 | DH9: 0.12 | DI9: 0 | DJ9: 0.003 | DK9: 0 | GJ9: 0 | GL9: 0
A10: 746782 | B10: Milk, whole, 3.25% milkfat, with added vitamin D | D10: Foundation | E10: 1077.6259 | F10: =E10/SUM($E$3:$E$10) | G10: 88.1 | H10: 60.4 | I10: 252.7136 | J10: 0.51 | K10: 3.27 | L10: 2.77 | M10: 3.2 | N10: 0.8 | O10: 4.63 | Q10: 4.81 | R10: 0 | S10: 0 | T10: 0 | U10: 4.81 | V10: 0 | W10: 0 | Z10: 123 | AA10: 0 | AB10: 11.9 | AC10: 101 | AD10: 150 | AE10: 38 | AF10: 0.42 | AG10: 0.001 | AH10: 0 | AI10: 37.9 | AJ10: 1.9 | AL10: 0.056 | AM10: 0.138 | AN10: 0.105 | AO10: 0.061 | AP10: 0 | AS10: 17.8 | AT10: 0.54 | AU10: 32 | AW10: 0.96 | AY10: 0.05 | BA10: 0.362 | BD10: 31 | BE10: 7 | BF10: 2 | BG10: 5 | BH10: 0 | BI10: 38.4 | BJ10: 0 | BK10: 0.96 | BL10: 0 | BM10: 0 | BN10: 0 | BP10: 5 | BQ10: 1 | BR10: 0 | BS10: 0 | BT10: 0 | BU10: 0 | BV10: 0 | BW10: 0 | BX10: 0 | BY10: 0 | CC10: 3 | CD10: 1.3 | CE10: 1.8 | CF10: 10.3 | CG10: 0.7 | CH10: 1.4 | CK10: 1.86 | CL10: 0.688 | CM10: 0.108 | CN10: 0.112 | CO10: 12 | CP10: 0.067 | CQ10: 0.054 | CR10: 0.034 | CS10: 0.084 | CT10: 0.097 | CU10: 0.303 | CV10: 0.857 | CW10: 0.309 | CX10: 0.004 | DB10: 0.004 | DC10: 0 | DD10: 0.002 | DG10: 0 | DI10: 0.001 | DK10: 0.002 | DL10: 0 | DM10: 0 | DN10: 0 | DO10: 0.001 | DP10: 0.032 | DQ10: 0.018 | DR10: 0.001 | DS10: 0.008 | DT10: 0.082 | DU10: 0 | DV10: 0.018 | DX10: 0.013 | DY10: 0 | DZ10: 0.001 | EA10: 0.039 | EB10: 0.612 | EC10: 0.084 | ED10: 0 | EE10: 0 | EF10: 0 | EG10: 0 | EH10: 0 | EI10: 0 | EJ10: 0.001 | EK10: 0.005 | EM10: 0.095 | EN10: 0.018 | EO10: 0 | EQ10: 0 | ER10: 0 | ES10: 0 | ET10: 0.005 | EU10: 0.024 | EV10: 0.005 | EW10: 0.004 | EX10: 0 | EY10: 0.097 | EZ10: 0.013 | FA10: 0 | FB10: 0.004 | FC10: 0.004 | FD10: 0.001 | FE10: 0.002 | FF10: 0 | FG10: 0.001 | FH10: 0.012 | FI10: 0 | FJ10: 0.004 | FK10: 0.001 | FL10: 0 | FM10: 0.043 | FN10: 0.154 | FO10: 0.173 | FP10: 0.333 | FQ10: 0.298 | FR10: 0.09 | FS10: 0.161 | FT10: 0.162 | FU10: 0.207 | FV10: 0.127 | FW10: 0.097 | FX10: 0.11 | FY10: 0.279 | FZ10: 0.788 | GA10: 0.069 | GB10: 0.333 | GC10: 0.188 | GD10: 0 | GE10: 0.038 | GK10: 0 | GL10: 0 | GM10: 0
A11: Total | B11: Formulado | C11: Formulado | D11: Formulado | E11: =SUBTOTAL(9,E3:E10) | F11: 100% | G11: =SUMPRODUCT($F$3:$F$10,$G$3:$G$10) | H11: =SUMPRODUCT($F$3:$F$10,$H$3:$H$10) | I11: =SUMPRODUCT($F$3:$F$10,$I$3:$I$10) | J11: =SUMPRODUCT($F$3:$F$10,$J$3:$J$10) | K11: =SUMPRODUCT($F$3:$F$10,$K$3:$K$10) | L11: =SUMPRODUCT($F$3:$F$10,$L$3:$L$10) | M11: =SUMPRODUCT($F$3:$F$10,$M$3:$M$10) | N11: =SUMPRODUCT($F$3:$F$10,$N$3:$N$10) | O11: =SUMPRODUCT($F$3:$F$10,$O$3:$O$10) | P11: =SUMPRODUCT($F$3:$F$10,$P$3:$P$10) | Q11: =SUMPRODUCT($F$3:$F$10,$Q$3:$Q$10) | R11: =SUMPRODUCT($F$3:$F$10,$R$3:$R$10) | S11: =SUMPRODUCT($F$3:$F$10,$S$3:$S$10) | T11: =SUMPRODUCT($F$3:$F$10,$T$3:$T$10) | U11: =SUMPRODUCT($F$3:$F$10,$U$3:$U$10) | V11: =SUMPRODUCT($F$3:$F$10,$V$3:$V$10) | W11: =SUMPRODUCT($F$3:$F$10,$W$3:$W$10) | X11: =SUMPRODUCT($F$3:$F$10,$X$3:$X$10) | Y11: =SUMPRODUCT($F$3:$F$10,$Y$3:$Y$10) | Z11: =SUMPRODUCT($F$3:$F$10,$Z$3:$Z$10) | AA11: =SUMPRODUCT($F$3:$F$10,$AA$3:$AA$10) | AB11: =SUMPRODUCT($F$3:$F$10,$AB$3:$AB$10) | AC11: =SUMPRODUCT($F$3:$F$10,$AC$3:$AC$10) | AD11: =SUMPRODUCT($F$3:$F$10,$AD$3:$AD$10) | AE11: =SUMPRODUCT($F$3:$F$10,$AE$3:$AE$10) | AF11: =SUMPRODUCT($F$3:$F$10,$AF$3:$AF$10) | AG11: =SUMPRODUCT($F$3:$F$10,$AG$3:$AG$10) | AH11: =SUMPRODUCT($F$3:$F$10,$AH$3:$AH$10) | AI11: =SUMPRODUCT($F$3:$F$10,$AI$3:$AI$10) | AJ11: =SUMPRODUCT($F$3:$F$10,$AJ$3:$AJ$10) | AK11: =SUMPRODUCT($F$3:$F$10,$AK$3:$AK$10) | AL11: =SUMPRODUCT($F$3:$F$10,$AL$3:$AL$10) | AM11: =SUMPRODUCT($F$3:$F$10,$AM$3:$AM$10) | AN11: =SUMPRODUCT($F$3:$F$10,$AN$3:$AN$10) | AO11: =SUMPRODUCT($F$3:$F$10,$AO$3:$AO$10) | AP11: =SUMPRODUCT($F$3:$F$10,$AP$3:$AP$10) | AQ11: =SUMPRODUCT($F$3:$F$10,$AQ$3:$AQ$10) | AR11: =SUMPRODUCT($F$3:$F$10,$AR$3:$AR$10) | AS11: =SUMPRODUCT($F$3:$F$10,$AS$3:$AS$10) | AT11: =SUMPRODUCT($F$3:$F$10,$AT$3:$AT$10) | AU11: =SUMPRODUCT($F$3:$F$10,$AU$3:$AU$10) | AV11: =SUMPRODUCT($F$3:$F$10,$AV$3:$AV$10) | AW11: =SUMPRODUCT($F$3:$F$10,$AW$3:$AW$10) | AX11: =SUMPRODUCT($F$3:$F$10,$AX$3:$AX$10) | AY11: =SUMPRODUCT($F$3:$F$10,$AY$3:$AY$10) | AZ11: =SUMPRODUCT($F$3:$F$10,$AZ$3:$AZ$10) | BA11: =SUMPRODUCT($F$3:$F$10,$BA$3:$BA$10) | BB11: =SUMPRODUCT($F$3:$F$10,$BB$3:$BB$10) | BC11: =SUMPRODUCT($F$3:$F$10,$BC$3:$BC$10) | BD11: =SUMPRODUCT($F$3:$F$10,$BD$3:$BD$10) | BE11: =SUMPRODUCT($F$3:$F$10,$BE$3:$BE$10) | BF11: =SUMPRODUCT($F$3:$F$10,$BF$3:$BF$10) | BG11: =SUMPRODUCT($F$3:$F$10,$BG$3:$BG$10) | BH11: =SUMPRODUCT($F$3:$F$10,$BH$3:$BH$10) | BI11: =SUMPRODUCT($F$3:$F$10,$BI$3:$BI$10) | BJ11: =SUMPRODUCT($F$3:$F$10,$BJ$3:$BJ$10) | BK11: =SUMPRODUCT($F$3:$F$10,$BK$3:$BK$10) | BL11: =SUMPRODUCT($F$3:$F$10,$BL$3:$BL$10) | BM11: =SUMPRODUCT($F$3:$F$10,$BM$3:$BM$10) | BN11: =SUMPRODUCT($F$3:$F$10,$BN$3:$BN$10) | BO11: =SUMPRODUCT($F$3:$F$10,$BO$3:$BO$10) | BP11: =SUMPRODUCT($F$3:$F$10,$BP$3:$BP$10) | BQ11: =SUMPRODUCT($F$3:$F$10,$BQ$3:$BQ$10) | BR11: =SUMPRODUCT($F$3:$F$10,$BR$3:$BR$10) | BS11: =SUMPRODUCT($F$3:$F$10,$BS$3:$BS$10) | BT11: =SUMPRODUCT($F$3:$F$10,$BT$3:$BT$10) | BU11: =SUMPRODUCT($F$3:$F$10,$BU$3:$BU$10) | BV11: =SUMPRODUCT($F$3:$F$10,$BV$3:$BV$10) | BW11: =SUMPRODUCT($F$3:$F$10,$BW$3:$BW$10) | BX11: =SUMPRODUCT($F$3:$F$10,$BX$3:$BX$10) | BY11: =SUMPRODUCT($F$3:$F$10,$BY$3:$BY$10) | BZ11: =SUMPRODUCT($F$3:$F$10,$BZ$3:$BZ$10) | CA11: =SUMPRODUCT($F$3:$F$10,$CA$3:$CA$10) | CB11: =SUMPRODUCT($F$3:$F$10,$CB$3:$CB$10) | CC11: =SUMPRODUCT($F$3:$F$10,$CC$3:$CC$10) | CD11: =SUMPRODUCT($F$3:$F$10,$CD$3:$CD$10) | CE11: =SUMPRODUCT($F$3:$F$10,$CE$3:$CE$10) | CF11: =SUMPRODUCT($F$3:$F$10,$CF$3:$CF$10) | CG11: =SUMPRODUCT($F$3:$F$10,$CG$3:$CG$10) | CH11: =SUMPRODUCT($F$3:$F$10,$CH$3:$CH$10) | CI11: =SUMPRODUCT($F$3:$F$10,$CI$3:$CI$10) | CJ11: =SUMPRODUCT($F$3:$F$10,$CJ$3:$CJ$10) | CK11: =SUMPRODUCT($F$3:$F$10,$CK$3:$CK$10) | CL11: =SUMPRODUCT($F$3:$F$10,$CL$3:$CL$10) | CM11: =SUMPRODUCT($F$3:$F$10,$CM$3:$CM$10) | CN11: =SUMPRODUCT($F$3:$F$10,$CN$3:$CN$10) | CO11: =SUMPRODUCT($F$3:$F$10,$CO$3:$CO$10) | CP11: =SUMPRODUCT($F$3:$F$10,$CP$3:$CP$10) | CQ11: =SUMPRODUCT($F$3:$F$10,$CQ$3:$CQ$10) | CR11: =SUMPRODUCT($F$3:$F$10,$CR$3:$CR$10) | CS11: =SUMPRODUCT($F$3:$F$10,$CS$3:$CS$10) | CT11: =SUMPRODUCT($F$3:$F$10,$CT$3:$CT$10) | CU11: =SUMPRODUCT($F$3:$F$10,$CU$3:$CU$10) | CV11: =SUMPRODUCT($F$3:$F$10,$CV$3:$CV$10) | CW11: =SUMPRODUCT($F$3:$F$10,$CW$3:$CW$10) | CX11: =SUMPRODUCT($F$3:$F$10,$CX$3:$CX$10) | CY11: =SUMPRODUCT($F$3:$F$10,$CY$3:$CY$10) | CZ11: =SUMPRODUCT($F$3:$F$10,$CZ$3:$CZ$10) | DA11: =SUMPRODUCT($F$3:$F$10,$DA$3:$DA$10) | DB11: =SUMPRODUCT($F$3:$F$10,$DB$3:$DB$10) | DC11: =SUMPRODUCT($F$3:$F$10,$DC$3:$DC$10) | DD11: =SUMPRODUCT($F$3:$F$10,$DD$3:$DD$10) | DE11: =SUMPRODUCT($F$3:$F$10,$DE$3:$DE$10) | DF11: =SUMPRODUCT($F$3:$F$10,$DF$3:$DF$10) | DG11: =SUMPRODUCT($F$3:$F$10,$DG$3:$DG$10) | DH11: =SUMPRODUCT($F$3:$F$10,$DH$3:$DH$10) | DI11: =SUMPRODUCT($F$3:$F$10,$DI$3:$DI$10) | DJ11: =SUMPRODUCT($F$3:$F$10,$DJ$3:$DJ$10) | DK11: =SUMPRODUCT($F$3:$F$10,$DK$3:$DK$10) | DL11: =SUMPRODUCT($F$3:$F$10,$DL$3:$DL$10) | DM11: =SUMPRODUCT($F$3:$F$10,$DM$3:$DM$10) | DN11: =SUMPRODUCT($F$3:$F$10,$DN$3:$DN$10) | DO11: =SUMPRODUCT($F$3:$F$10,$DO$3:$DO$10) | DP11: =SUMPRODUCT($F$3:$F$10,$DP$3:$DP$10) | DQ11: =SUMPRODUCT($F$3:$F$10,$DQ$3:$DQ$10) | DR11: =SUMPRODUCT($F$3:$F$10,$DR$3:$DR$10) | DS11: =SUMPRODUCT($F$3:$F$10,$DS$3:$DS$10) | DT11: =SUMPRODUCT($F$3:$F$10,$DT$3:$DT$10) | DU11: =SUMPRODUCT($F$3:$F$10,$DU$3:$DU$10) | DV11: =SUMPRODUCT($F$3:$F$10,$DV$3:$DV$10) | DW11: =SUMPRODUCT($F$3:$F$10,$DW$3:$DW$10) | DX11: =SUMPRODUCT($F$3:$F$10,$DX$3:$DX$10) | DY11: =SUMPRODUCT($F$3:$F$10,$DY$3:$DY$10) | DZ11: =SUMPRODUCT($F$3:$F$10,$DZ$3:$DZ$10) | EA11: =SUMPRODUCT($F$3:$F$10,$EA$3:$EA$10) | EB11: =SUMPRODUCT($F$3:$F$10,$EB$3:$EB$10) | EC11: =SUMPRODUCT($F$3:$F$10,$EC$3:$EC$10) | ED11: =SUMPRODUCT($F$3:$F$10,$ED$3:$ED$10) | EE11: =SUMPRODUCT($F$3:$F$10,$EE$3:$EE$10) | EF11: =SUMPRODUCT($F$3:$F$10,$EF$3:$EF$10) | EG11: =SUMPRODUCT($F$3:$F$10,$EG$3:$EG$10) | EH11: =SUMPRODUCT($F$3:$F$10,$EH$3:$EH$10) | EI11: =SUMPRODUCT($F$3:$F$10,$EI$3:$EI$10) | EJ11: =SUMPRODUCT($F$3:$F$10,$EJ$3:$EJ$10) | EK11: =SUMPRODUCT($F$3:$F$10,$EK$3:$EK$10) | EL11: =SUMPRODUCT($F$3:$F$10,$EL$3:$EL$10) | EM11: =SUMPRODUCT($F$3:$F$10,$EM$3:$EM$10) | EN11: =SUMPRODUCT($F$3:$F$10,$EN$3:$EN$10) | EO11: =SUMPRODUCT($F$3:$F$10,$EO$3:$EO$10) | EP11: =SUMPRODUCT($F$3:$F$10,$EP$3:$EP$10) | EQ11: =SUMPRODUCT($F$3:$F$10,$EQ$3:$EQ$10) | ER11: =SUMPRODUCT($F$3:$F$10,$ER$3:$ER$10) | ES11: =SUMPRODUCT($F$3:$F$10,$ES$3:$ES$10) | ET11: =SUMPRODUCT($F$3:$F$10,$ET$3:$ET$10) | EU11: =SUMPRODUCT($F$3:$F$10,$EU$3:$EU$10) | EV11: =SUMPRODUCT($F$3:$F$10,$EV$3:$EV$10) | EW11: =SUMPRODUCT($F$3:$F$10,$EW$3:$EW$10) | EX11: =SUMPRODUCT($F$3:$F$10,$EX$3:$EX$10) | EY11: =SUMPRODUCT($F$3:$F$10,$EY$3:$EY$10) | EZ11: =SUMPRODUCT($F$3:$F$10,$EZ$3:$EZ$10) | FA11: =SUMPRODUCT($F$3:$F$10,$FA$3:$FA$10) | FB11: =SUMPRODUCT($F$3:$F$10,$FB$3:$FB$10) | FC11: =SUMPRODUCT($F$3:$F$10,$FC$3:$FC$10) | FD11: =SUMPRODUCT($F$3:$F$10,$FD$3:$FD$10) | FE11: =SUMPRODUCT($F$3:$F$10,$FE$3:$FE$10) | FF11: =SUMPRODUCT($F$3:$F$10,$FF$3:$FF$10) | FG11: =SUMPRODUCT($F$3:$F$10,$FG$3:$FG$10) | FH11: =SUMPRODUCT($F$3:$F$10,$FH$3:$FH$10) | FI11: =SUMPRODUCT($F$3:$F$10,$FI$3:$FI$10) | FJ11: =SUMPRODUCT($F$3:$F$10,$FJ$3:$FJ$10) | FK11: =SUMPRODUCT($F$3:$F$10,$FK$3:$FK$10) | FL11: =SUMPRODUCT($F$3:$F$10,$FL$3:$FL$10) | FM11: =SUMPRODUCT($F$3:$F$10,$FM$3:$FM$10) | FN11: =SUMPRODUCT($F$3:$F$10,$FN$3:$FN$10) | FO11: =SUMPRODUCT($F$3:$F$10,$FO$3:$FO$10) | FP11: =SUMPRODUCT($F$3:$F$10,$FP$3:$FP$10) | FQ11: =SUMPRODUCT($F$3:$F$10,$FQ$3:$FQ$10) | FR11: =SUMPRODUCT($F$3:$F$10,$FR$3:$FR$10) | FS11: =SUMPRODUCT($F$3:$F$10,$FS$3:$FS$10) | FT11: =SUMPRODUCT($F$3:$F$10,$FT$3:$FT$10) | FU11: =SUMPRODUCT($F$3:$F$10,$FU$3:$FU$10) | FV11: =SUMPRODUCT($F$3:$F$10,$FV$3:$FV$10) | FW11: =SUMPRODUCT($F$3:$F$10,$FW$3:$FW$10) | FX11: =SUMPRODUCT($F$3:$F$10,$FX$3:$FX$10) | FY11: =SUMPRODUCT($F$3:$F$10,$FY$3:$FY$10) | FZ11: =SUMPRODUCT($F$3:$F$10,$FZ$3:$FZ$10) | GA11: =SUMPRODUCT($F$3:$F$10,$GA$3:$GA$10) | GB11: =SUMPRODUCT($F$3:$F$10,$GB$3:$GB$10) | GC11: =SUMPRODUCT($F$3:$F$10,$GC$3:$GC$10) | GD11: =SUMPRODUCT($F$3:$F$10,$GD$3:$GD$10) | GE11: =SUMPRODUCT($F$3:$F$10,$GE$3:$GE$10) | GF11: =SUMPRODUCT($F$3:$F$10,$GF$3:$GF$10) | GG11: =SUMPRODUCT($F$3:$F$10,$GG$3:$GG$10) | GH11: =SUMPRODUCT($F$3:$F$10,$GH$3:$GH$10) | GI11: =SUMPRODUCT($F$3:$F$10,$GI$3:$GI$10) | GJ11: =SUMPRODUCT($F$3:$F$10,$GJ$3:$GJ$10) | GK11: =SUMPRODUCT($F$3:$F$10,$GK$3:$GK$10) | GL11: =SUMPRODUCT($F$3:$F$10,$GL$3:$GL$10) | GM11: =SUMPRODUCT($F$3:$F$10,$GM$3:$GM$10)

Sheet Totales
A1: Nutriente | B1: Total | C1: Unidad
A2: Water | B2: =Ingredientes!G11 | C2: g
A3: Energy | B3: =Ingredientes!H11 | C3: kcal
A4: Energy | B4: =Ingredientes!I11 | C4: kJ
A5: Nitrogen | B5: =Ingredientes!J11 | C5: g
A6: Protein | B6: =Ingredientes!K11 | C6: g
A7: Total fat (NLEA) | B7: =Ingredientes!L11 | C7: g
A8: Total lipid (fat) | B8: =Ingredientes!M11 | C8: g
A9: Ash | B9: =Ingredientes!N11 | C9: g
A10: Carbohydrate, by difference | B10: =Ingredientes!O11 | C10: g
A11: Fiber, total dietary | B11: =Ingredientes!P11 | C11: g
A12: Sugars, Total | B12: =Ingredientes!Q11 | C12: g
A13: Sucrose | B13: =Ingredientes!R11 | C13: g
A14: Glucose | B14: =Ingredientes!S11 | C14: g
A15: Fructose | B15: =Ingredientes!T11 | C15: g
A16: Lactose | B16: =Ingredientes!U11 | C16: g
A17: Maltose | B17: =Ingredientes!V11 | C17: g
A18: Galactose | B18: =Ingredientes!W11 | C18: g
A19: Starch | B19: =Ingredientes!X11 | C19: g
A20: Resistant starch | B20: =Ingredientes!Y11 | C20: g
A21: Calcium, Ca | B21: =Ingredientes!Z11 | C21: mg
A22: Iron, Fe | B22: =Ingredientes!AA11 | C22: mg
A23: Magnesium, Mg | B23: =Ingredientes!AB11 | C23: mg
A24: Phosphorus, P | B24: =Ingredientes!AC11 | C24: mg
A25: Potassium, K | B25: =Ingredientes!AD11 | C25: mg
A26: Sodium, Na | B26: =Ingredientes!AE11 | C26: mg
A27: Zinc, Zn | B27: =Ingredientes!AF11 | C27: mg
A28: Copper, Cu | B28: =Ingredientes!AG11 | C28: mg
A29: Manganese, Mn | B29: =Ingredientes!AH11 | C29: mg
A30: Iodine, I | B30: =Ingredientes!AI11 | C30: μg
A31: Selenium, Se | B31: =Ingredientes!AJ11 | C31: μg
A32: Fluoride, F | B32: =Ingredientes!AK11 | C32: μg
A33: Thiamin | B33: =Ingredientes!AL11 | C33: mg
A34: Riboflavin | B34: =Ingredientes!AM11 | C34: mg
A35: Niacin | B35: =Ingredientes!AN11 | C35: mg
A36: Vitamin B-6 | B36: =Ingredientes!AO11 | C36: mg
A37: Folate, total | B37: =Ingredientes!AP11 | C37: μg
A38: Folic acid | B38: =Ingredientes!AQ11 | C38: μg
A39: Folate, DFE | B39: =Ingredientes!AR11 | C39: μg
A40: Choline, total | B40: =Ingredientes!AS11 | C40: mg
...

Sheet Costos
A1: Resumen de costos
A2: Masa tirada (g) | B2: Yield (%) | C2: Masa vendible (g) | D2: Costo insumos (MN) | E2: Costo procesos (MN) | F2: Costo total (MN)
A3: 5000 | B3: 95 | C3: 4750 | D3: 1223.2648 | E3: 223.33333 | F3: 1446.5981
A5: Cotizaciones
A6: Moneda | B6: Simbolo | C6: Cotizacion a MN
A7: Moneda Nacional | B7: $ | C7: 1
A8: Dolar | B8: U$D | C8: 40.5
A10: Insumos / Ingredientes
A11: Ingrediente | B11: Cantidad (g) | C11: Presentacion | D11: Unidad | E11: Moneda | F11: Simbolo | G11: Costo | H11: Cotizacion | I11: Costo (MN) | J11: Costo unitario (MN/kg) | K11: Costo tirada (MN) | L11: % insumos
A12: Eggs, Grade A, Large, egg whole | B12: 1616.4388 | C12: 1500 | D12: g | E12: Moneda Nacional | F12: $ | G12: 300 | H12: 1 | I12: 300 | J12: 200 | K12: 323.28777 | L12: 26.428274
A13: Water, bottled, generic | B13: 1017.9967 | C13: 6 | D13: kg | E13: Moneda Nacional | F13: $ | G13: 144 | H13: 1 | I13: 144 | J13: 24 | K13: 24.43192 | L13: 1.9972716
A14: Spices, cinnamon, ground | B14: 427.45827 | C14: 100 | D14: g | E14: Dolar | F14: U$D | G14: 3 | H14: 40.5 | I14: 121.5 | J14: 1215 | K14: 519.3618 | L14: 42.457023
A15: Oil, canola | B15: 323.28777 | C15: 10 | D15: lb | E15: Dolar | F15: U$D | G15: 10 | H15: 40.5 | I15: 405 | J15: 89.287216 | K15: 28.865465 | L15: 2.3597071
A16: Salt, table | B16: 33.731276 | C16: 500 | D16: g | E16: Moneda Nacional | F16: $ | G16: 60 | H16: 1 | I16: 60 | J16: 120 | K16: 4.0477532 | L16: 0.33089755
A17: Lentils, dry | B17: 353.46129 | C17: 25 | D17: kg | E17: Dolar | F17: U$D | G17: 140 | H17: 40.5 | I17: 5670 | J17: 226.8 | K17: 80.165021 | L17: 6.5533663
A18: Cookie, chocolate sandwich | B18: 150 | C18: 75 | D18: g | E18: Moneda Nacional | F18: $ | G18: 100 | H18: 1 | I18: 100 | J18: 1333.3333 | K18: 200 | L18: 16.34969
A19: Milk, whole, 3.25% milkfat, with added vitamin D | B19: 1077.6259 | C19: 1 | D19: kg | E19: Moneda Nacional | F19: $ | G19: 40 | H19: 1 | I19: 40 | J19: 40 | K19: 43.105036 | L19: 3.5237699
A21: Procesos
A22: Nombre | B22: Tipo | C22: Setup | D22: U | E22: Tiempo/kg | F22: U | G22: Tiempo total (h) | H22: Costo/h (MN) | I22: Costo total (MN) | J22: Notas
A23: Horneado | B23: MIXED | C23: 30 | D23: min | E23: 10 | F23: min | G23: 1.3333333 | H23: 85 | I23: 113.33333
A24: Mezclado | B24: FIXED | F24: min | G24: 0.5 | H24: 220 | I24: 110
A26: Packaging
A27: Nombre | B27: Cantidad/pack | C27: Costo unitario (MN) | D27: Subtotal (MN) | E27: Notas
A28: Etiqueta premium | B28: 1 | C28: 5 | D28: 5
A29: Envase | B29: 1 | C29: 8 | D29: 8
A30: Caja 15 un | B30: 0.067 | C30: 30 | D30: 2.01
