Workbook

Sheet Ingredientes
A1: Detalles de formulación | G1: Proximates | K1: Nutrientes | P1: Proximates | Q1: Nutrientes | T1: Carbohydrates | Y1: Minerals | AD1: Nutrientes | AE1: Minerals | AK1: Vitamins and Other Components | AP1: Lipids | AQ1: Nutrientes
A2: FDC ID | B2: Ingrediente | C2: Marca / Origen | D2: Tipo de dato | E2: Cantidad (g) | F2: Cantidad (%) | G2: Water (g) | H2: Energy (Atwater General Factors) (kcal) | I2: Energy (Atwater Specific Factors) (kcal) | J2: Nitrogen (g) | K2: Energy (kcal) | L2: Energy (kJ) | M2: Protein (g) | N2: Total lipid (fat) (g) | O2: Total fat (NLEA) (g) | P2: Ash (g) | Q2: Carbohydrate, by difference (g) | R2: Fiber, total dietary (g) | S2: Sugars, Total (g) | T2: Sucrose (g) | U2: Glucose (g) | V2: Fructose (g) | W2: Lactose (g) | X2: Maltose (g) | Y2: Calcium, Ca (mg) | Z2: Iron, Fe (mg) | AA2: Magnesium, Mg (mg) | AB2: Phosphorus, P (mg) | AC2: Potassium, K (mg) | AD2: Sodium, Na (mg) | AE2: Zinc, Zn (mg) | AF2: Copper, Cu (mg) | AG2: Manganese, Mn (mg) | AH2: Selenium, Se (µg) | AI2: Molybdenum, Mo (µg) | AJ2: Iodine, I (µg) | AK2: Thiamin (mg) | AL2: Riboflavin (mg) | AM2: Niacin (mg) | AN2: Vitamin B-6 (mg) | AO2: Folate, total (µg) | AP2: Cholesterol (mg) | AQ2: Protein (g) | AR2: Energy (kJ) | AS2: Fiber, total dietary (g) | AT2: Energy (kcal) | AU2: Sugars, Total (g) | AV2: Sodium, Na (mg) | AW2: Fatty acids, total saturated (g) | AX2: Carbohydrate, by difference (g) | AY2: Total lipid (fat) (g) | AZ2: Total fat (NLEA) (g)
A3: 1750340 | B3: Apples, fuji, with skin, raw | D3: Foundation | E3: 50 | F3: =E3/SUM($E$3:$E$6) | G3: 83.61 | H3: 64.6609 | I3: 58.20306 | J3: 0.02375 | K3: 64.6609 | L3: 270.54121 | M3: 0.1484375 | N3: 0.1625 | O3: 0.1625 | P3: 0.4279 | Q3: 15.405 | R3: 2.075 | S3: 13.33 | T3: 1.704 | U3: 3.038 | V3: 8.59 | W3: 0 | X3: 0 | Y3: 5.975 | Z3: 0.015 | AA3: 4.67 | AB3: 9.78 | AC3: 103.8 | AD3: 1.013 | AE3: 0.01676 | AF3: 0.03279 | AG3: 0.03263 | AK3: 0.00625 | AL3: 0.0675 | AM3: 0.09063 | AN3: 0.03544 | AO3: 0 | AQ3: 0.1484375 | AR3: 270.54121 | AS3: 2.075 | AT3: 64.6609 | AU3: 13.33 | AV3: 1.013 | AX3: 15.405 | AY3: 0.1625 | AZ3: 0.1625
A4: 789890 | B4: Flour, wheat, all-purpose, enriched, bleached | D4: Foundation | E4: 49 | F4: =E4/SUM($E$3:$E$6) | G4: 9.83 | J4: 1.75 | K4: 366 | L4: 1530 | M4: 10.9 | N4: 1.48 | O4: 1.48 | P4: 0.42 | Q4: 77.3 | Y4: 19 | Z4: 5.62 | AA4: 26.7 | AB4: 108 | AC4: 136 | AD4: 2 | AE4: 0.72 | AF4: 0.155 | AG4: 0.758 | AH4: 15.7 | AI4: 37.6 | AK4: 0.939 | AL4: 0.443 | AM4: 6.74 | AN4: 0.066 | AO4: 160 | AQ4: 10.9 | AR4: 1530 | AT4: 366 | AV4: 2 | AX4: 77.3 | AY4: 1.48 | AZ4: 1.48
A5: 789828 | B5: Butter, stick, unsalted | D5: Foundation | E5: 27 | F5: =E5/SUM($E$3:$E$6) | G5: 17.4 | K5: 733.5 | L5: 3068.964 | N5: 81.5 | O5: 81.5 | Y5: 14 | Z5: 0.03 | AA5: 1.6 | AB5: 19 | AC5: 19 | AD5: 10 | AE5: 0.07 | AF5: 0.001 | AG5: 0 | AJ5: 0 | AP5: 234 | AR5: 3068.964 | AT5: 733.5 | AV5: 10 | AY5: 81.5 | AZ5: 81.5
A6: 2511747 | B6: OREO SANDWICH, OREO | C6: Stark Group International, Inc. | D6: Branded | E6: 54 | F6: =E6/SUM($E$3:$E$6) | K6: 516 | L6: 2144.3837 | M6: 5.98 | N6: 27.72 | O6: 27.72 | Q6: 59.78 | R6: 2.2 | S6: 48.91 | AD6: 598 | AQ6: 5.98 | AR6: 2144.3837 | AS6: 2.2 | AT6: 516 | AU6: 48.91 | AV6: 598 | AW6: 15.76 | AX6: 59.78 | AY6: 27.72 | AZ6: 27.72
A7: Total | B7: Formulado | C7: Formulado | D7: Formulado | E7: =SUBTOTAL(9,E3:E6) | F7: 100% | G7: =SUMPRODUCT($F$3:$F$6,$G$3:$G$6) | H7: =SUMPRODUCT($F$3:$F$6,$H$3:$H$6) | I7: =SUMPRODUCT($F$3:$F$6,$I$3:$I$6) | J7: =SUMPRODUCT($F$3:$F$6,$J$3:$J$6) | K7: =SUMPRODUCT($F$3:$F$6,$K$3:$K$6) | L7: =SUMPRODUCT($F$3:$F$6,$L$3:$L$6) | M7: =SUMPRODUCT($F$3:$F$6,$M$3:$M$6) | N7: =SUMPRODUCT($F$3:$F$6,$N$3:$N$6) | O7: =SUMPRODUCT($F$3:$F$6,$O$3:$O$6) | P7: =SUMPRODUCT($F$3:$F$6,$P$3:$P$6) | Q7: =SUMPRODUCT($F$3:$F$6,$Q$3:$Q$6) | R7: =SUMPRODUCT($F$3:$F$6,$R$3:$R$6) | S7: =SUMPRODUCT($F$3:$F$6,$S$3:$S$6) | T7: =SUMPRODUCT($F$3:$F$6,$T$3:$T$6) | U7: =SUMPRODUCT($F$3:$F$6,$U$3:$U$6) | V7: =SUMPRODUCT($F$3:$F$6,$V$3:$V$6) | W7: =SUMPRODUCT($F$3:$F$6,$W$3:$W$6) | X7: =SUMPRODUCT($F$3:$F$6,$X$3:$X$6) | Y7: =SUMPRODUCT($F$3:$F$6,$Y$3:$Y$6) | Z7: =SUMPRODUCT($F$3:$F$6,$Z$3:$Z$6) | AA7: =SUMPRODUCT($F$3:$F$6,$AA$3:$AA$6) | AB7: =SUMPRODUCT($F$3:$F$6,$AB$3:$AB$6) | AC7: =SUMPRODUCT($F$3:$F$6,$AC$3:$AC$6) | AD7: =SUMPRODUCT($F$3:$F$6,$AD$3:$AD$6) | AE7: =SUMPRODUCT($F$3:$F$6,$AE$3:$AE$6) | AF7: =SUMPRODUCT($F$3:$F$6,$AF$3:$AF$6) | AG7: =SUMPRODUCT($F$3:$F$6,$AG$3:$AG$6) | AH7: =SUMPRODUCT($F$3:$F$6,$AH$3:$AH$6) | AI7: =SUMPRODUCT($F$3:$F$6,$AI$3:$AI$6) | AJ7: =SUMPRODUCT($F$3:$F$6,$AJ$3:$AJ$6) | AK7: =SUMPRODUCT($F$3:$F$6,$AK$3:$AK$6) | AL7: =SUMPRODUCT($F$3:$F$6,$AL$3:$AL$6) | AM7: =SUMPRODUCT($F$3:$F$6,$AM$3:$AM$6) | AN7: =SUMPRODUCT($F$3:$F$6,$AN$3:$AN$6) | AO7: =SUMPRODUCT($F$3:$F$6,$AO$3:$AO$6) | AP7: =SUMPRODUCT($F$3:$F$6,$AP$3:$AP$6) | AQ7: =SUMPRODUCT($F$3:$F$6,$AQ$3:$AQ$6) | AR7: =SUMPRODUCT($F$3:$F$6,$AR$3:$AR$6) | AS7: =SUMPRODUCT($F$3:$F$6,$AS$3:$AS$6) | AT7: =SUMPRODUCT($F$3:$F$6,$AT$3:$AT$6) | AU7: =SUMPRODUCT($F$3:$F$6,$AU$3:$AU$6) | AV7: =SUMPRODUCT($F$3:$F$6,$AV$3:$AV$6) | AW7: =SUMPRODUCT($F$3:$F$6,$AW$3:$AW$6) | AX7: =SUMPRODUCT($F$3:$F$6,$AX$3:$AX$6) | AY7: =SUMPRODUCT($F$3:$F$6,$AY$3:$AY$6) | AZ7: =SUMPRODUCT($F$3:$F$6,$AZ$3:$AZ$6)

Sheet Totales
A1: Nutriente | B1: Total | C1: Unidad
A2: Water | B2: =Ingredientes!G7 | C2: g
A3: Energy (Atwater General Factors) | B3: =Ingredientes!H7 | C3: kcal
A4: Energy (Atwater Specific Factors) | B4: =Ingredientes!I7 | C4: kcal
A5: Nitrogen | B5: =Ingredientes!J7 | C5: g
A6: Energy | B6: =Ingredientes!K7 | C6: kcal
A7: Energy | B7: =Ingredientes!L7 | C7: kJ
A8: Protein | B8: =Ingredientes!M7 | C8: g
A9: Total lipid (fat) | B9: =Ingredientes!N7 | C9: g
A10: Total fat (NLEA) | B10: =Ingredientes!O7 | C10: g
A11: Ash | B11: =Ingredientes!P7 | C11: g
A12: Carbohydrate, by difference | B12: =Ingredientes!Q7 | C12: g
A13: Fiber, total dietary | B13: =Ingredientes!R7 | C13: g
A14: Sugars, Total | B14: =Ingredientes!S7 | C14: g
A15: Sucrose | B15: =Ingredientes!T7 | C15: g
A16: Glucose | B16: =Ingredientes!U7 | C16: g
A17: Fructose | B17: =Ingredientes!V7 | C17: g
A18: Lactose | B18: =Ingredientes!W7 | C18: g
A19: Maltose | B19: =Ingredientes!X7 | C19: g
A20: Calcium, Ca | B20: =Ingredientes!Y7 | C20: mg
A21: Iron, Fe | B21: =Ingredientes!Z7 | C21: mg
A22: Magnesium, Mg | B22: =Ingredientes!AA7 | C22: mg
A23: Phosphorus, P | B23: =Ingredientes!AB7 | C23: mg
A24: Potassium, K | B24: =Ingredientes!AC7 | C24: mg
A25: Sodium, Na | B25: =Ingredientes!AD7 | C25: mg
A26: Zinc, Zn | B26: =Ingredientes!AE7 | C26: mg
A27: Copper, Cu | B27: =Ingredientes!AF7 | C27: mg
A28: Manganese, Mn | B28: =Ingredientes!AG7 | C28: mg
A29: Selenium, Se | B29: =Ingredientes!AH7 | C29: µg
A30: Molybdenum, Mo | B30: =Ingredientes!AI7 | C30: µg
A31: Iodine, I | B31: =Ingredientes!AJ7 | C31: µg
A32: Thiamin | B32: =Ingredientes!AK7 | C32: mg
A33: Riboflavin | B33: =Ingredientes!AL7 | C33: mg
A34: Niacin | B34: =Ingredientes!AM7 | C34: mg
A35: Vitamin B-6 | B35: =Ingredientes!AN7 | C35: mg
A36: Folate, total | B36: =Ingredientes!AO7 | C36: µg
A37: Cholesterol | B37: =Ingredientes!AP7 | C37: mg
A38: Protein | B38: =Ingredientes!AQ7 | C38: g
A39: Energy | B39: =Ingredientes!AR7 | C39: kJ
A40: Fiber, total dietary | B40: =Ingredientes!AS7 | C40: g
...
