Workbook

Sheet Ingredientes
A1: Detalles de formulación | G1: Proximates | P1: Carbohydrates | X1: Minerals | AI1: Vitamins and Other Components | BL1: Lipids | CA1: Amino acids | CT1: Nutrientes
A2: FDC ID | B2: Ingrediente | C2: Marca / Origen | D2: Tipo de dato | E2: Cantidad (kg) | F2: Cantidad (%) | G2: Water (g) | H2: Energy (kcal) | I2: Energy (kJ) | J2: Nitrogen (g) | K2: Protein (g) | L2: Total fat (NLEA) (g) | M2: Total lipid (fat) (g) | N2: Ash (g) | O2: Carbohydrate, by difference (g) | P2: Fiber, total dietary (g) | Q2: Sugars, Total (g) | R2: Sucrose (g) | S2: Glucose (g) | T2: Fructose (g) | U2: Lactose (g) | V2: Maltose (g) | W2: Starch (g) | X2: Calcium, Ca (mg) | Y2: Iron, Fe (mg) | Z2: Magnesium, Mg (mg) | AA2: Phosphorus, P (mg) | AB2: Potassium, K (mg) | AC2: Sodium, Na (mg) | AD2: Zinc, Zn (mg) | AE2: Copper, Cu (mg) | AF2: Manganese, Mn (mg) | AG2: Iodine, I (µg) | AH2: Selenium, Se (µg) | AI2: Thiamin (mg) | AJ2: Riboflavin (mg) | AK2: Niacin (mg) | AL2: Vitamin B-6 (mg) | AM2: Folate, total (µg) | AN2: Choline, total (mg) | AO2: Vitamin B-12 (µg) | AP2: Vitamin A, RAE (µg) | AQ2: Vitamin D (D2 + D3) (µg) | AR2: Retinol (µg) | AS2: Carotene, beta (µg) | AT2: cis-beta-Carotene (µg) | AU2: trans-beta-Carotene (µg) | AV2: Carotene, alpha (µg) | AW2: Vitamin D (D2 + D3), International Units (iu) | AX2: Vitamin D2 (ergocalciferol) (µg) | AY2: Vitamin D3 (cholecalciferol) (µg) | AZ2: Lycopene (µg) | BA2: cis-Lycopene (µg) | BB2: trans-Lycopene (µg) | BC2: Lutein (µg) | BD2: Zeaxanthin (µg) | BE2: cis-Lutein/Zeaxanthin (µg) | BF2: Choline, free (mg) | BG2: Choline, from phosphocholine (mg) | BH2: Choline, from phosphatidyl choline (mg) | BI2: Choline, from glycerophosphocholine (mg) | BJ2: Betaine (mg) | BK2: Choline, from sphingomyelin (mg) | BL2: Fatty acids, total saturated (g) | BM2: Fatty acids, total monounsaturated (g) | BN2: Fatty acids, total polyunsaturated (g) | BO2: Cholesterol (mg) | BP2: SFA 14:0 (g) | BQ2: SFA 16:0 (g) | BR2: SFA 18:0 (g) | BS2: MUFA 16:1 c (g) | BT2: MUFA 18:1 c (g) | BU2: PUFA 18:2 n-6 c,c (g) | BV2: PUFA 18:3 n-6 c,c,c (g) | BW2: PUFA 18:2 c (g) | BX2: PUFA 18:3 c (g) | BY2: PUFA 20:3 c (g) | BZ2: PUFA 20:3 n-6 (g) | CA2: Tryptophan (g) | CB2: Threonine (g) | CC2: Isoleucine (g) | CD2: Leucine (g) | CE2: Lysine (g) | CF2: Methionine (g) | CG2: Phenylalanine (g) | CH2: Tyrosine (g) | CI2: Valine (g) | CJ2: Arginine (g) | CK2: Histidine (g) | CL2: Alanine (g) | CM2: Aspartic acid (g) | CN2: Glutamic acid (g) | CO2: Glycine (g) | CP2: Proline (g) | CQ2: Serine (g) | CR2: Hydroxyproline (g) | CS2: Cysteine (g) | CT2: 25-hydroxycholecalciferol (µg) | CU2: Cryptoxanthin, beta (µg) | CV2: Cryptoxanthin, alpha (µg)
A3: 748967 | B3: Eggs, Grade A, Large, egg whole | D3: Foundation | E3: 1 | F3: =E3/SUM($E$3:$E$3) | G3: 75.8 | H3: 143.08 | I3: 598.64672 | J3: 1.99 | K3: 12.4 | L3: 8.65 | M3: 9.96 | N3: 0.85 | O3: 0.96 | P3: 0 | Q3: 0.2 | R3: 0 | S3: 0.2 | T3: 0 | U3: 0 | V3: 0 | W3: 0 | X3: 48 | Y3: 1.67 | Z3: 11.4 | AA3: 184 | AB3: 132 | AC3: 129 | AD3: 1.24 | AE3: 0 | AF3: 0 | AG3: 49.1 | AH3: 31.1 | AI3: 0.077 | AJ3: 0.419 | AK3: 0 | AL3: 0.063 | AM3: 71 | AN3: 335 | AO3: 1.02 | AP3: 180 | AQ3: 2.46 | AR3: 179 | AS3: 0 | AT3: 0 | AU3: 0 | AV3: 0 | AW3: 98.4 | AX3: 0 | AY3: 2.46 | AZ3: 0 | BA3: 0 | BB3: 0 | BC3: 230 | BD3: 229 | BE3: 57 | BF3: 0.6 | BG3: 309 | BH3: 0.2 | BI3: 0.2 | BJ3: 0.3 | BK3: 25.1 | BL3: 3.2 | BM3: 3.63 | BN3: 1.82 | BO3: 411 | BP3: 0.032 | BQ3: 2.32 | BR3: 0.813 | BS3: 0.238 | BT3: 3.35 | BU3: 1.46 | BV3: 0.011 | BW3: 1.46 | BX3: 0.011 | BY3: 0.02 | BZ3: 0.02 | CA3: 0.166 | CB3: 0.594 | CC3: 0.616 | CD3: 1.05 | CE3: 0.832 | CF3: 0.418 | CG3: 0.66 | CH3: 0.512 | CI3: 0.734 | CJ3: 0.787 | CK3: 0.283 | CL3: 0.667 | CM3: 1.27 | CN3: 1.63 | CO3: 0.408 | CP3: 0.56 | CQ3: 0.919 | CR3: 0 | CS3: 0.385 | CT3: 0.56 | CU3: 13 | CV3: 13
A4: Total | B4: Formulado | C4: Formulado | D4: Formulado | E4: =SUBTOTAL(9,E3:E3) | F4: 100% | G4: =SUMPRODUCT($F$3:$F$3,$G$3:$G$3) | H4: =SUMPRODUCT($F$3:$F$3,$H$3:$H$3) | I4: =SUMPRODUCT($F$3:$F$3,$I$3:$I$3) | J4: =SUMPRODUCT($F$3:$F$3,$J$3:$J$3) | K4: =SUMPRODUCT($F$3:$F$3,$K$3:$K$3) | L4: =SUMPRODUCT($F$3:$F$3,$L$3:$L$3) | M4: =SUMPRODUCT($F$3:$F$3,$M$3:$M$3) | N4: =SUMPRODUCT($F$3:$F$3,$N$3:$N$3) | O4: =SUMPRODUCT($F$3:$F$3,$O$3:$O$3) | P4: =SUMPRODUCT($F$3:$F$3,$P$3:$P$3) | Q4: =SUMPRODUCT($F$3:$F$3,$Q$3:$Q$3) | R4: =SUMPRODUCT($F$3:$F$3,$R$3:$R$3) | S4: =SUMPRODUCT($F$3:$F$3,$S$3:$S$3) | T4: =SUMPRODUCT($F$3:$F$3,$T$3:$T$3) | U4: =SUMPRODUCT($F$3:$F$3,$U$3:$U$3) | V4: =SUMPRODUCT($F$3:$F$3,$V$3:$V$3) | W4: =SUMPRODUCT($F$3:$F$3,$W$3:$W$3) | X4: =SUMPRODUCT($F$3:$F$3,$X$3:$X$3) | Y4: =SUMPRODUCT($F$3:$F$3,$Y$3:$Y$3) | Z4: =SUMPRODUCT($F$3:$F$3,$Z$3:$Z$3) | AA4: =SUMPRODUCT($F$3:$F$3,$AA$3:$AA$3) | AB4: =SUMPRODUCT($F$3:$F$3,$AB$3:$AB$3) | AC4: =SUMPRODUCT($F$3:$F$3,$AC$3:$AC$3) | AD4: =SUMPRODUCT($F$3:$F$3,$AD$3:$AD$3) | AE4: =SUMPRODUCT($F$3:$F$3,$AE$3:$AE$3) | AF4: =SUMPRODUCT($F$3:$F$3,$AF$3:$AF$3) | AG4: =SUMPRODUCT($F$3:$F$3,$AG$3:$AG$3) | AH4: =SUMPRODUCT($F$3:$F$3,$AH$3:$AH$3) | AI4: =SUMPRODUCT($F$3:$F$3,$AI$3:$AI$3) | AJ4: =SUMPRODUCT($F$3:$F$3,$AJ$3:$AJ$3) | AK4: =SUMPRODUCT($F$3:$F$3,$AK$3:$AK$3) | AL4: =SUMPRODUCT($F$3:$F$3,$AL$3:$AL$3) | AM4: =SUMPRODUCT($F$3:$F$3,$AM$3:$AM$3) | AN4: =SUMPRODUCT($F$3:$F$3,$AN$3:$AN$3) | AO4: =SUMPRODUCT($F$3:$F$3,$AO$3:$AO$3) | AP4: =SUMPRODUCT($F$3:$F$3,$AP$3:$AP$3) | AQ4: =SUMPRODUCT($F$3:$F$3,$AQ$3:$AQ$3) | AR4: =SUMPRODUCT($F$3:$F$3,$AR$3:$AR$3) | AS4: =SUMPRODUCT($F$3:$F$3,$AS$3:$AS$3) | AT4: =SUMPRODUCT($F$3:$F$3,$AT$3:$AT$3) | AU4: =SUMPRODUCT($F$3:$F$3,$AU$3:$AU$3) | AV4: =SUMPRODUCT($F$3:$F$3,$AV$3:$AV$3) | AW4: =SUMPRODUCT($F$3:$F$3,$AW$3:$AW$3) | AX4: =SUMPRODUCT($F$3:$F$3,$AX$3:$AX$3) | AY4: =SUMPRODUCT($F$3:$F$3,$AY$3:$AY$3) | AZ4: =SUMPRODUCT($F$3:$F$3,$AZ$3:$AZ$3) | BA4: =SUMPRODUCT($F$3:$F$3,$BA$3:$BA$3) | BB4: =SUMPRODUCT($F$3:$F$3,$BB$3:$BB$3) | BC4: =SUMPRODUCT($F$3:$F$3,$BC$3:$BC$3) | BD4: =SUMPRODUCT($F$3:$F$3,$BD$3:$BD$3) | BE4: =SUMPRODUCT($F$3:$F$3,$BE$3:$BE$3) | BF4: =SUMPRODUCT($F$3:$F$3,$BF$3:$BF$3) | BG4: =SUMPRODUCT($F$3:$F$3,$BG$3:$BG$3) | BH4: =SUMPRODUCT($F$3:$F$3,$BH$3:$BH$3) | BI4: =SUMPRODUCT($F$3:$F$3,$BI$3:$BI$3) | BJ4: =SUMPRODUCT($F$3:$F$3,$BJ$3:$BJ$3) | BK4: =SUMPRODUCT($F$3:$F$3,$BK$3:$BK$3) | BL4: =SUMPRODUCT($F$3:$F$3,$BL$3:$BL$3) | BM4: =SUMPRODUCT($F$3:$F$3,$BM$3:$BM$3) | BN4: =SUMPRODUCT($F$3:$F$3,$BN$3:$BN$3) | BO4: =SUMPRODUCT($F$3:$F$3,$BO$3:$BO$3) | BP4: =SUMPRODUCT($F$3:$F$3,$BP$3:$BP$3) | BQ4: =SUMPRODUCT($F$3:$F$3,$BQ$3:$BQ$3) | BR4: =SUMPRODUCT($F$3:$F$3,$BR$3:$BR$3) | BS4: =SUMPRODUCT($F$3:$F$3,$BS$3:$BS$3) | BT4: =SUMPRODUCT($F$3:$F$3,$BT$3:$BT$3) | BU4: =SUMPRODUCT($F$3:$F$3,$BU$3:$BU$3) | BV4: =SUMPRODUCT($F$3:$F$3,$BV$3:$BV$3) | BW4: =SUMPRODUCT($F$3:$F$3,$BW$3:$BW$3) | BX4: =SUMPRODUCT($F$3:$F$3,$BX$3:$BX$3) | BY4: =SUMPRODUCT($F$3:$F$3,$BY$3:$BY$3) | BZ4: =SUMPRODUCT($F$3:$F$3,$BZ$3:$BZ$3) | CA4: =SUMPRODUCT($F$3:$F$3,$CA$3:$CA$3) | CB4: =SUMPRODUCT($F$3:$F$3,$CB$3:$CB$3) | CC4: =SUMPRODUCT($F$3:$F$3,$CC$3:$CC$3) | CD4: =SUMPRODUCT($F$3:$F$3,$CD$3:$CD$3) | CE4: =SUMPRODUCT($F$3:$F$3,$CE$3:$CE$3) | CF4: =SUMPRODUCT($F$3:$F$3,$CF$3:$CF$3) | CG4: =SUMPRODUCT($F$3:$F$3,$CG$3:$CG$3) | CH4: =SUMPRODUCT($F$3:$F$3,$CH$3:$CH$3) | CI4: =SUMPRODUCT($F$3:$F$3,$CI$3:$CI$3) | CJ4: =SUMPRODUCT($F$3:$F$3,$CJ$3:$CJ$3) | CK4: =SUMPRODUCT($F$3:$F$3,$CK$3:$CK$3) | CL4: =SUMPRODUCT($F$3:$F$3,$CL$3:$CL$3) | CM4: =SUMPRODUCT($F$3:$F$3,$CM$3:$CM$3) | CN4: =SUMPRODUCT($F$3:$F$3,$CN$3:$CN$3) | CO4: =SUMPRODUCT($F$3:$F$3,$CO$3:$CO$3) | CP4: =SUMPRODUCT($F$3:$F$3,$CP$3:$CP$3) | CQ4: =SUMPRODUCT($F$3:$F$3,$CQ$3:$CQ$3) | CR4: =SUMPRODUCT($F$3:$F$3,$CR$3:$CR$3) | CS4: =SUMPRODUCT($F$3:$F$3,$CS$3:$CS$3) | CT4: =SUMPRODUCT($F$3:$F$3,$CT$3:$CT$3) | CU4: =SUMPRODUCT($F$3:$F$3,$CU$3:$CU$3) | CV4: =SUMPRODUCT($F$3:$F$3,$CV$3:$CV$3)

Sheet Totales
A1: Nutriente | B1: Total | C1: Unidad
A2: Water | B2: =Ingredientes!G4 | C2: g
A3: Energy | B3: =Ingredientes!H4 | C3: kcal
A4: Energy | B4: =Ingredientes!I4 | C4: kJ
A5: Nitrogen | B5: =Ingredientes!J4 | C5: g
A6: Protein | B6: =Ingredientes!K4 | C6: g
A7: Total fat (NLEA) | B7: =Ingredientes!L4 | C7: g
A8: Total lipid (fat) | B8: =Ingredientes!M4 | C8: g
A9: Ash | B9: =Ingredientes!N4 | C9: g
A10: Carbohydrate, by difference | B10: =Ingredientes!O4 | C10: g
A11: Fiber, total dietary | B11: =Ingredientes!P4 | C11: g
A12: Sugars, Total | B12: =Ingredientes!Q4 | C12: g
A13: Sucrose | B13: =Ingredientes!R4 | C13: g
A14: Glucose | B14: =Ingredientes!S4 | C14: g
A15: Fructose | B15: =Ingredientes!T4 | C15: g
A16: Lactose | B16: =Ingredientes!U4 | C16: g
A17: Maltose | B17: =Ingredientes!V4 | C17: g
A18: Starch | B18: =Ingredientes!W4 | C18: g
A19: Calcium, Ca | B19: =Ingredientes!X4 | C19: mg
A20: Iron, Fe | B20: =Ingredientes!Y4 | C20: mg
A21: Magnesium, Mg | B21: =Ingredientes!Z4 | C21: mg
A22: Phosphorus, P | B22: =Ingredientes!AA4 | C22: mg
A23: Potassium, K | B23: =Ingredientes!AB4 | C23: mg
A24: Sodium, Na | B24: =Ingredientes!AC4 | C24: mg
A25: Zinc, Zn | B25: =Ingredientes!AD4 | C25: mg
A26: Copper, Cu | B26: =Ingredientes!AE4 | C26: mg
A27: Manganese, Mn | B27: =Ingredientes!AF4 | C27: mg
A28: Iodine, I | B28: =Ingredientes!AG4 | C28: µg
A29: Selenium, Se | B29: =Ingredientes!AH4 | C29: µg
A30: Thiamin | B30: =Ingredientes!AI4 | C30: mg
A31: Riboflavin | B31: =Ingredientes!AJ4 | C31: mg
A32: Niacin | B32: =Ingredientes!AK4 | C32: mg
A33: Vitamin B-6 | B33: =Ingredientes!AL4 | C33: mg
A34: Folate, total | B34: =Ingredientes!AM4 | C34: µg
A35: Choline, total | B35: =Ingredientes!AN4 | C35: mg
A36: Vitamin B-12 | B36: =Ingredientes!AO4 | C36: µg
A37: Vitamin A, RAE | B37: =Ingredientes!AP4 | C37: µg
A38: Vitamin D (D2 + D3) | B38: =Ingredientes!AQ4 | C38: µg
A39: Retinol | B39: =Ingredientes!AR4 | C39: µg
A40: Carotene, beta | B40: =Ingredientes!AS4 | C40: µg
...
