Workbook

Sheet Ingredientes
A1: Detalles de formulación | G1: Proximates | ES1: Carbohydrates | ET1: Minerals | EY1: Vitamins and Other Components | GB1: Lipids | GE1: Nutrientes | HX1: Vitamin A | HY1: Phytosterols | IG1: Oligosaccharides | IJ1: Isoflavones
A2: FDC ID | B2: Ingrediente | C2: Marca / Origen | D2: Tipo de dato | E2: Cantidad (g) | F2: Cantidad (%) | G2: Water (g) | H2: Calcium, Ca (mg) | I2: Fatty acids, total monounsaturated (g) | J2: Fatty acids, total polyunsaturated (g) | K2: Fatty acids, total trans-polyenoic (g) | L2: MUFA 16:1 c (g) | M2: Potassium, K (mg) | N2: PUFA 18:2 CLAs (g) | O2: PUFA 18:3 n-6 c,c,c (g) | P2: PUFA 18:4 (g) | Q2: PUFA 20:2 n-6 c,c (g) | R2: PUFA 20:3 n-6 (g) | S2: PUFA 20:4 (g) | T2: Selenium, Se (ug) | U2: SFA 10:0 (g) | V2: SFA 15:0 (g) | W2: SFA 16:0 (g) | X2: SFA 18:0 (g) | Y2: SFA 20:0 (g) | Z2: SFA 4:0 (g) | AA2: SFA 6:0 (g) | AB2: TFA 18:1 t (g) | AC2: TFA 18:2 t not further defined (g) | AD2: TFA 22:1 t (g) | AE2: Zinc, Zn (mg) | AF2: Carbohydrate, by difference (g) | AG2: Niacin (mg) | AH2: Pantothenic acid (mg) | AI2: Thiamin (mg) | AJ2: Total fat (NLEA) (g) | AK2: Total lipid (fat) (g) | AL2: Vitamin B-6 (mg) | AM2: Vitamin E (alpha-tocopherol) (mg) | AN2: Vitamin K (phylloquinone) (ug) | AO2: Alanine (g) | AP2: Arginine (g) | AQ2: Aspartic acid (g) | AR2: Cysteine (g) | AS2: Glutamic acid (g) | AT2: Glycine (g) | AU2: Histidine (g) | AV2: Isoleucine (g) | AW2: Leucine (g) | AX2: Lysine (g) | AY2: Methionine (g) | AZ2: MUFA 14:1 c (g) | BA2: MUFA 20:1 c (g) | BB2: MUFA 22:1 n-9 (g) | BC2: Nitrogen (g) | BD2: Phenylalanine (g) | BE2: Proline (g) | BF2: PUFA 20:3 n-9 (g) | BG2: PUFA 22:2 (g) | BH2: Serine (g) | BI2: SFA 11:0 (g) | BJ2: TFA 18:3 t (g) | BK2: Threonine (g) | BL2: Tocopherol, beta (mg) | BM2: Tocopherol, delta (mg) | BN2: Tocopherol, gamma (mg) | BO2: Tocotrienol, alpha (mg) | BP2: Tocotrienol, beta (mg) | BQ2: Tocotrienol, delta (mg) | BR2: Tocotrienol, gamma (mg) | BS2: Tryptophan (g) | BT2: Tyrosine (g) | BU2: Valine (g) | BV2: Vitamin K (Dihydrophylloquinone) (ug) | BW2: Vitamin K (Menaquinone-4) (ug) | BX2: Fatty acids, total trans-dienoic (g) | BY2: MUFA 17:1 c (g) | BZ2: PUFA 18:2 c (g) | CA2: PUFA 18:3 c (g) | CB2: PUFA 20:2 c (g) | CC2: PUFA 20:3 c (g) | CD2: PUFA 20:4c (g) | CE2: PUFA 20:5c (g) | CF2: PUFA 22:5 c (g) | CG2: PUFA 22:6 c (g) | CH2: Retinol (ug) | CI2: Vitamin A, RAE (ug) | CJ2: Vitamin D3 (cholecalciferol) (ug) | CK2: Vitamin D (D2 + D3) (ug) | CL2: Carotene, beta (ug) | CM2: Fructose (g) | CN2: Galactose (g) | CO2: Glucose (g) | CP2: Lactose (g) | CQ2: Maltose (g) | CR2: Sucrose (g) | CS2: Vitamin D (D2 + D3), International Units (iu) | CT2: Carotene, alpha (ug) | CU2: Cryptoxanthin, beta (ug) | CV2: Lycopene (ug) | CW2: 25-hydroxycholecalciferol (ug) | CX2: Vitamin D2 (ergocalciferol) (ug) | CY2: Cryptoxanthin, alpha (ug) | CZ2: MUFA 12:1 (g) | DA2: MUFA 22:1 n-11 (g) | DB2: PUFA 22:3 (g) | DC2: SFA 21:0 (g) | DD2: SFA 23:0 (g) | DE2: SFA 5:0 (g) | DF2: SFA 7:0 (g) | DG2: SFA 9:0 (g) | DH2: TFA 14:1 t (g) | DI2: TFA 20:1 t (g) | DJ2: cis-beta-Carotene (ug) | DK2: cis-Lutein/Zeaxanthin (ug) | DL2: cis-Lycopene (ug) | DM2: Lutein (ug) | DN2: trans-beta-Carotene (ug) | DO2: trans-Lycopene (ug) | DP2: Zeaxanthin (ug) | DQ2: Choline, free (mg) | DR2: Choline, from glycerophosphocholine (mg) | DS2: Choline, from phosphocholine (mg) | DT2: Choline, from phosphotidyl choline (mg) | DU2: Choline, from sphingomyelin (mg) | DV2: Iodine, I (ug) | DW2: Sugars, Total (g) | DX2: Energy (Atwater General Factors) (kcal) | DY2: Energy (Atwater Specific Factors) (kcal) | DZ2: MUFA 14:1 (g) | EA2: MUFA 16:1 (g) | EB2: MUFA 20:1 (g) | EC2: PUFA 18:3i (g) | ED2: Vitamin C, total ascorbic acid (mg) | EE2: Fiber, total dietary (g) | EF2: Lutein + zeaxanthin (ug) | EG2: MUFA 18:1 (g) | EH2: MUFA 22:1 (g) | EI2: PUFA 18:2 (g) | EJ2: PUFA 18:3 (g) | EK2: PUFA 20:3 (g) | EL2: Cystine (g) | EM2: Folate, DFE (ug) | EN2: Folate, food (ug) | EO2: Vitamin A, IU (iu) | EP2: Phytosterols (mg) | EQ2: Energy (kcal) | ER2: Energy (kJ) | ES2: Resistant starch (g) | ET2: Sugars, added (g) | EU2: Iodine, I (µg) | EV2: Selenium, Se (µg) | EW2: Fluoride, F (µg) | EX2: Molybdenum, Mo (µg) | EY2: Biotin (µg) | EZ2: Folate, total (µg) | FA2: Folic acid (µg) | FB2: Folate, food (µg) | FC2: Folate, DFE (µg) | FD2: Vitamin B-12 (µg) | FE2: Vitamin B-12, added (µg) | FF2: Vitamin A, RAE (µg) | FG2: Retinol (µg) | FH2: Carotene, beta (µg) | FI2: cis-beta-Carotene (µg) | FJ2: trans-beta-Carotene (µg) | FK2: Carotene, alpha (µg) | FL2: Carotene, gamma (µg) | FM2: Cryptoxanthin, beta (µg) | FN2: Cryptoxanthin, alpha (µg) | FO2: Lycopene (µg) | FP2: cis-Lycopene (µg) | FQ2: trans-Lycopene (µg) | FR2: Lutein + zeaxanthin (µg) | FS2: cis-Lutein/Zeaxanthin (µg) | FT2: Lutein (µg) | FU2: Zeaxanthin (µg) | FV2: Vitamin D (D2 + D3) (µg) | FW2: Vitamin D2 (ergocalciferol) (µg) | FX2: Vitamin D3 (cholecalciferol) (µg) | FY2: 25-hydroxycholecalciferol (µg) | FZ2: Vitamin K (phylloquinone) (µg) | GA2: Vitamin K (Menaquinone-4) (µg) | GB2: SFA 13:0 (g) | GC2: TFA 18:2 t (g) | GD2: TFA 18:2 t,t (g) | GE2: Cholesterol (mg) | GF2: Fatty acids, total saturated (g) | GG2: Fatty acids, total trans (g) | GH2: Fatty acids, total trans-monoenoic (g) | GI2: Folate, total (ug) | GJ2: MUFA 15:1 (g) | GK2: MUFA 17:1 (g) | GL2: MUFA 18:1 c (g) | GM2: MUFA 22:1 c (g) | GN2: MUFA 24:1 c (g) | GO2: PUFA 18:2 n-6 c,c (g) | GP2: PUFA 18:3 n-3 c,c,c (ALA) (g) | GQ2: PUFA 20:3 n-3 (g) | GR2: PUFA 20:5 n-3 (EPA) (g) | GS2: PUFA 22:4 (g) | GT2: PUFA 22:5 n-3 (DPA) (g) | GU2: PUFA 22:6 n-3 (DHA) (g) | GV2: Riboflavin (mg) | GW2: SFA 12:0 (g) | GX2: SFA 14:0 (g) | GY2: SFA 17:0 (g) | GZ2: SFA 22:0 (g) | HA2: SFA 24:0 (g) | HB2: SFA 8:0 (g) | HC2: TFA 16:1 t (g) | HD2: Vitamin B-12 (ug) | HE2: Ash (g) | HF2: Copper, Cu (mg) | HG2: Hydroxyproline (g) | HH2: Iron, Fe (mg) | HI2: Magnesium, Mg (mg) | HJ2: Manganese, Mn (mg) | HK2: Phosphorus, P (mg) | HL2: Protein (g) | HM2: Sodium, Na (mg) | HN2: Betaine (mg) | HO2: Choline, total (mg) | HP2: Starch (g) | HQ2: Folic acid (ug) | HR2: Vitamin B-12, added (ug) | HS2: Alcohol, ethyl (g) | HT2: Caffeine (mg) | HU2: Theobromine (mg) | HV2: Vitamin E, added (mg) | HW2: Fluoride, F (ug) | HX2: Vitamin K (Dihydrophylloquinone) (µg) | HY2: Stigmasterol (mg) | HZ2: Campesterol (mg) | IA2: Brassicasterol (mg) | IB2: Beta-sitosterol (mg) | IC2: Campestanol (mg) | ID2: Beta-sitostanol (mg) | IE2: Delta-5-avenasterol (mg) | IF2: Phytosterols, other (mg) | IG2: Raffinose (g) | IH2: Stachyose (g) | II2: Verbascose (g) | IJ2: Daidzein (mg) | IK2: Genistein (mg) | IL2: Daidzin (mg) | IM2: Genistin (mg) | IN2: Glycitin (mg)
A3: 748967 | B3: Eggs, Grade A, Large, egg whole | D3: Foundation | E3: 150 | F3: =E3/SUM($E$3:$E$58) | G3: 75.8 | H3: 48 | I3: 3.63 | J3: 1.82 | L3: 0.238 | M3: 132 | O3: 0.011 | R3: 0.02 | W3: 2.32 | X3: 0.813 | AE3: 1.24 | AF3: 0.96 | AG3: 0 | AI3: 0.077 | AJ3: 8.65 | AK3: 9.96 | AL3: 0.063 | AO3: 0.667 | AP3: 0.787 | AQ3: 1.27 | AR3: 0.385 | AS3: 1.63 | AT3: 0.408 | AU3: 0.283 | AV3: 0.616 | AW3: 1.05 | AX3: 0.832 | AY3: 0.418 | BC3: 1.99 | BD3: 0.66 | BE3: 0.56 | BH3: 0.919 | BK3: 0.594 | BS3: 0.166 | BT3: 0.512 | BU3: 0.734 | BZ3: 1.46 | CA3: 0.011 | CC3: 0.02 | CM3: 0 | CO3: 0.2 | CP3: 0 | CQ3: 0 | CR3: 0 | CS3: 98.4 | DQ3: 0.6 | DR3: 0.2 | DS3: 309 | DT3: 0.2 | DU3: 25.1 | DW3: 0.2 | EE3: 0 | EQ3: 143.08 | ER3: 598.64672 | EU3: 49.1 | EV3: 31.1 | EZ3: 71 | FD3: 1.02 | FF3: 180 | FG3: 179 | FH3: 0 | FI3: 0 | FJ3: 0 | FK3: 0 | FM3: 13 | FN3: 13 | FO3: 0 | FP3: 0 | FQ3: 0 | FS3: 57 | FT3: 230 | FU3: 229 | FV3: 2.46 | FW3: 0 | FX3: 2.46 | FY3: 0.56 | GE3: 411 | GF3: 3.2 | GL3: 3.35 | GO3: 1.46 | GV3: 0.419 | GX3: 0.032 | HE3: 0.85 | HF3: 0 | HG3: 0 | HH3: 1.67 | HI3: 11.4 | HJ3: 0 | HK3: 184 | HL3: 12.4 | HM3: 129 | HN3: 0.3 | HO3: 335 | HP3: 0
A4: 174158 | B4: Water, bottled, generic | D4: SR Legacy | E4: 116.47304 | F4: =E4/SUM($E$3:$E$58) | G4: 99.98 | H4: 10 | I4: 0 | J4: 0 | M4: 0 | P4: 0 | S4: 0 | U4: 0 | W4: 0 | X4: 0 | Z4: 0 | AA4: 0 | AE4: 0 | AF4: 0 | AG4: 0 | AH4: 0 | AI4: 0 | AJ4: 0 | AK4: 0 | AL4: 0 | AM4: 0 | CS4: 0 | DW4: 0 | EA4: 0 | EB4: 0 | ED4: 0 | EE4: 0 | EG4: 0 | EH4: 0 | EI4: 0 | EJ4: 0 | EO4: 0 | EQ4: 0 | ER4: 0 | EV4: 0 | EZ4: 0 | FA4: 0 | FB4: 0 | FC4: 0 | FD4: 0 | FE4: 0 | FF4: 0 | FG4: 0 | FH4: 0 | FK4: 0 | FM4: 0 | FO4: 0 | FR4: 0 | FV4: 0 | FZ4: 0 | GE4: 0 | GF4: 0 | GG4: 0 | GR4: 0 | GT4: 0 | GU4: 0 | GV4: 0 | GW4: 0 | GX4: 0 | HB4: 0 | HE4: 0.07 | HF4: 0.007 | HH4: 0 | HI4: 2 | HK4: 0 | HL4: 0 | HM4: 2 | HO4: 0 | HS4: 0 | HT4: 0 | HU4: 0 | HV4: 0
A5: 171320 | B5: Spices, cinnamon, ground | D5: SR Legacy | E5: 39.666667 | F5: =E5/SUM($E$3:$E$58) | G5: 10.58 | H5: 1002 | I5: 0.246 | J5: 0.068 | M5: 431 | O5: 0 | P5: 0 | Q5: 0 | S5: 0 | U5: 0.003 | V5: 0 | W5: 0.104 | X5: 0.082 | Y5: 0 | Z5: 0 | AA5: 0 | AB5: 0 | AE5: 1.83 | AF5: 80.59 | AG5: 1.332 | AH5: 0.358 | AI5: 0.022 | AJ5: 1.24 | AK5: 1.24 | AL5: 0.158 | AM5: 2.32 | AO5: 0.166 | AP5: 0.166 | AQ5: 0.438 | AS5: 0.37 | AT5: 0.195 | AU5: 0.117 | AV5: 0.146 | AW5: 0.253 | AX5: 0.243 | AY5: 0.078 | BD5: 0.146 | BE5: 0.419 | BH5: 0.195 | BK5: 0.136 | BL5: 0 | BM5: 0.26 | BN5: 10.44 | BO5: 0 | BP5: 0 | BQ5: 0 | BR5: 0 | BS5: 0.049 | BT5: 0.136 | BU5: 0.224 | CM5: 1.11 | CN5: 0 | CO5: 1.04 | CP5: 0 | CQ5: 0 | CR5: 0.02 | CS5: 0 | DW5: 2.17 | DZ5: 0 | EA5: 0.001 | EB5: 0 | ED5: 3.8 | EE5: 53.1 | EG5: 0.246 | EH5: 0 | EI5: 0.044 | EJ5: 0.011 | EK5: 0 | EL5: 0.058 | EO5: 295 | EP5: 26 | EQ5: 349.48 | ER5: 1462.2243 | EV5: 3.1 | EZ5: 6 | FA5: 0 | FB5: 6 | FC5: 6 | FD5: 0 | FE5: 0 | FF5: 15 | FG5: 0 | FH5: 112 | FK5: 1 | FM5: 129 | FO5: 15 | FR5: 222 | FV5: 0 | FZ5: 31.2 | GB5: 0 | GE5: 0 | GF5: 0.345 | GG5: 0 | GH5: 0 | GJ5: 0 | GK5: 0 | GL5: 0.246 | GN5: 0 | GP5: 0.011 | GR5: 0 | GT5: 0 | GU5: 0 | GV5: 0.041 | GW5: 0.006 | GX5: 0.009 | GY5: 0.136 | GZ5: 0 | HA5: 0 | HB5: 0 | HE5: 3.6 | HF5: 0.339 | HG5: 0 | HH5: 8.32 | HI5: 60 | HJ5: 17.466 | HK5: 64 | HL5: 3.99 | HM5: 10 | HN5: 3.9 | HO5: 11 | HS5: 0 | HT5: 0 | HU5: 0 | HV5: 0 | HX5: 0
A6: 172336 | B6: Oil, canola | D6: SR Legacy | E6: 30 | F6: =E6/SUM($E$3:$E$58) | G6: 0 | H6: 0 | I6: 63.276 | J6: 28.142 | K6: 0.365 | M6: 0 | O6: 0 | P6: 0 | Q6: 0 | S6: 0 | U6: 0 | V6: 0 | W6: 4.298 | X6: 2.087 | Y6: 0.65 | Z6: 0 | AA6: 0 | AB6: 0.03 | AE6: 0 | AF6: 0 | AG6: 0 | AH6: 0 | AI6: 0 | AJ6: 100 | AK6: 100 | AL6: 0 | AM6: 17.46 | BL6: 0.01 | BM6: 0.99 | BN6: 27.34 | BO6: 0.03 | BP6: 0 | BQ6: 0.01 | BR6: 0 | CS6: 0 | DW6: 0 | DZ6: 0 | EA6: 0.214 | EB6: 1.317 | ED6: 0 | EE6: 0 | EG6: 61.744 | EH6: 0 | EI6: 19.005 | EJ6: 9.137 | EK6: 0 | EO6: 0 | EQ6: 900 | ER6: 3765.6 | EV6: 0 | EZ6: 0 | FA6: 0 | FB6: 0 | FC6: 0 | FD6: 0 | FE6: 0 | FF6: 0 | FG6: 0 | FH6: 0 | FK6: 0 | FM6: 0 | FO6: 0 | FR6: 0 | FV6: 0 | FZ6: 71.3 | GA6: 0 | GD6: 0.365 | GE6: 0 | GF6: 7.365 | GG6: 0.395 | GH6: 0.03 | GJ6: 0 | GK6: 0 | GL6: 61.714 | GO6: 18.64 | GP6: 9.137 | GR6: 0 | GT6: 0 | GU6: 0 | GV6: 0 | GW6: 0 | GX6: 0 | GY6: 0 | GZ6: 0.33 | HB6: 0 | HE6: 0 | HF6: 0 | HH6: 0 | HI6: 0 | HJ6: 0 | HK6: 0 | HL6: 0 | HM6: 0 | HN6: 0 | HO6: 0.2 | HS6: 0 | HT6: 0 | HU6: 0 | HV6: 0 | HX6: 0 | HY6: 3 | HZ6: 241 | IB6: 413
A7: 748366 | B7: Oil, soybean | D7: Foundation | E7: 5 | F7: =E7/SUM($E$3:$E$58) | I7: 22.1 | J7: 57.6 | L7: 0.08 | R7: 0 | V7: 0.014 | W7: 10.3 | X7: 3.71 | Y7: 0.294 | AJ7: 94.6 | AK7: 94.6 | AM7: 12.2 | BA7: 0.6 | BL7: 1.8 | BM7: 22 | BN7: 70.4 | BO7: 0 | BP7: 1.6 | BQ7: 0 | BR7: 0 | BZ7: 50.9 | CA7: 6.62 | CC7: 0 | DC7: 0.025 | EQ7: 851.4 | ER7: 3562.2576 | GF7: 14.9 | GL7: 21.4 | GO7: 50.9 | GP7: 6.62 | GX7: 0.075 | GY7: 0.086 | GZ7: 0.306 | HA7: 0.124 | HY7: 55.4 | HZ7: 58 | IA7: 0 | IB7: 153 | IC7: 2.15 | ID7: 5.62 | IE7: 10.5 | IF7: 20.8
A8: 173468 | B8: Salt, table | D8: SR Legacy | E8: 3.1301472 | F8: =E8/SUM($E$3:$E$58) | G8: 0.2 | H8: 24 | I8: 0 | J8: 0 | M8: 8 | P8: 0 | S8: 0 | U8: 0 | W8: 0 | X8: 0 | Z8: 0 | AA8: 0 | AE8: 0.1 | AF8: 0 | AG8: 0 | AH8: 0 | AI8: 0 | AJ8: 0 | AK8: 0 | AL8: 0 | AM8: 0 | AO8: 0 | AP8: 0 | AQ8: 0 | AS8: 0 | AT8: 0 | AU8: 0 | AV8: 0 | AW8: 0 | AX8: 0 | AY8: 0 | BD8: 0 | BE8: 0 | BH8: 0 | BK8: 0 | BS8: 0 | BT8: 0 | BU8: 0 | CS8: 0 | DW8: 0 | EA8: 0 | EB8: 0 | ED8: 0 | EE8: 0 | EG8: 0 | EH8: 0 | EI8: 0 | EJ8: 0 | EL8: 0 | EO8: 0 | EP8: 0 | EQ8: 0 | ER8: 0 | EV8: 0.1 | EW8: 2 | EZ8: 0 | FA8: 0 | FB8: 0 | FC8: 0 | FD8: 0 | FE8: 0 | FF8: 0 | FG8: 0 | FH8: 0 | FK8: 0 | FM8: 0 | FO8: 0 | FR8: 0 | FV8: 0 | FZ8: 0 | GE8: 0 | GF8: 0 | GG8: 0 | GR8: 0 | GT8: 0 | GU8: 0 | GV8: 0 | GW8: 0 | GX8: 0 | HB8: 0 | HE8: 99.8 | HF8: 0.03 | HH8: 0.33 | HI8: 1 | HJ8: 0.1 | HK8: 0 | HL8: 0 | HM8: 38758 | HO8: 0 | HS8: 0 | HT8: 0 | HU8: 0 | HV8: 0
A9: 2644283 | B9: Lentils, dry | D9: Foundation | E9: 32.8 | F9: =E9/SUM($E$3:$E$58) | G9: 9.451 | H9: 61.85 | M9: 948.9 | AE9: 3.863 | AF9: 62.17125 | AJ9: 1.925 | AK9: 1.925 | BC9: 3.771 | DX9: 360.285 | DY9: 350.9328 | EQ9: 360.285 | ER9: 1507.4324 | ES9: 16 | HE9: 2.884 | HF9: 0.8376 | HH9: 7.158 | HI9: 106.7 | HJ9: 1.569 | HK9: 373.6 | HL9: 23.56875 | HM9: 0 | HP9: 37.13
A10: 2707920 | B10: Cookie, chocolate sandwich | D10: Survey (FNDDS) | E10: 100 | F10: =E10/SUM($E$3:$E$58) | G10: 3.11 | H10: 21 | I10: 9.28 | J10: 3.56 | M10: 234 | P10: 0 | S10: 0.004 | U10: 0.011 | W10: 4.45 | X10: 0.857 | Z10: 0 | AA10: 0 | AE10: 0.74 | AF10: 71 | AG10: 2.6 | AI10: 0.197 | AJ10: 19.1 | AK10: 19.1 | AL10: 0.023 | AM10: 2.47 | DW10: 40.7 | EA10: 0.036 | EB10: 0.12 | ED10: 0 | EE10: 2.9 | EG10: 9.11 | EH10: 0.003 | EI10: 3.25 | EJ10: 0.298 | EQ10: 476.74 | ER10: 1994.6802 | EV10: 5.2 | EZ10: 61 | FA10: 58 | FB10: 3 | FC10: 102 | FD10: 0 | FE10: 0 | FF10: 1 | FG10: 0 | FH10: 0 | FK10: 0 | FM10: 0 | FO10: 0 | FR10: 4 | FV10: 0 | FZ10: 27.4 | GE10: 0 | GF10: 5.65 | GR10: 0 | GT10: 0 | GU10: 0 | GV10: 0.238 | GW10: 0.045 | GX10: 0.111 | HB10: 0.003 | HF10: 0.334 | HH10: 12.1 | HI10: 47 | HK10: 93 | HL10: 5.21 | HM10: 388 | HO10: 19.2 | HS10: 0 | HT10: 5 | HU10: 184 | HV10: 0
A11: 746782 | B11: Milk, whole, 3.25% milkfat, with added vitamin D | D11: Foundation | E11: 100 | F11: =E11/SUM($E$3:$E$58) | G11: 88.1 | H11: 123 | I11: 0.688 | J11: 0.108 | K11: 0 | L11: 0.039 | M11: 150 | N11: 0.013 | O11: 0.001 | P11: 0 | Q11: 0.001 | R11: 0.004 | S11: 0.004 | U11: 0.084 | V11: 0.032 | W11: 0.857 | X11: 0.309 | Y11: 0.004 | Z11: 0.067 | AA11: 0.054 | AB11: 0.082 | AC11: 0.018 | AD11: 0 | AE11: 0.42 | AF11: 4.63 | AG11: 0.105 | AH11: 0.362 | AI11: 0.056 | AJ11: 2.77 | AK11: 3.2 | AL11: 0.061 | AM11: 0.05 | AO11: 0.11 | AP11: 0.127 | AQ11: 0.279 | AR11: 0.038 | AS11: 0.788 | AT11: 0.069 | AU11: 0.097 | AV11: 0.173 | AW11: 0.333 | AX11: 0.298 | AY11: 0.09 | AZ11: 0.024 | BA11: 0.004 | BB11: 0 | BC11: 0.51 | BD11: 0.161 | BE11: 0.333 | BF11: 0 | BG11: 0 | BH11: 0.188 | BI11: 0 | BJ11: 0 | BK11: 0.154 | BL11: 0 | BM11: 0 | BN11: 0 | BO11: 0 | BP11: 0 | BQ11: 0 | BR11: 0 | BS11: 0.043 | BT11: 0.162 | BU11: 0.207 | BX11: 0.018 | BY11: 0.005 | BZ11: 0.097 | CA11: 0.013 | CB11: 0.001 | CC11: 0.004 | CD11: 0.004 | CE11: 0.001 | CF11: 0.002 | CG11: 0 | CM11: 0 | CN11: 0 | CO11: 0 | CP11: 4.81 | CQ11: 0 | CR11: 0 | CS11: 38.4 | CZ11: 0.001 | DA11: 0 | DB11: 0 | DC11: 0 | DD11: 0 | DE11: 0 | DF11: 0 | DG11: 0 | DH11: 0.005 | DI11: 0 | DQ11: 3 | DR11: 10.3 | DS11: 1.3 | DT11: 1.8 | DU11: 1.4 | DW11: 4.81 | EQ11: 60.4 | ER11: 252.7136 | EU11: 37.9 | EV11: 1.9 | EZ11: 0 | FD11: 0.54 | FF11: 32 | FG11: 31 | FH11: 7 | FI11: 2 | FJ11: 5 | FK11: 0 | FM11: 0 | FN11: 0 | FO11: 0 | FP11: 0 | FQ11: 0 | FS11: 0 | FT11: 5 | FU11: 1 | FV11: 0.96 | FW11: 0 | FX11: 0.96 | FY11: 0 | GE11: 12 | GF11: 1.86 | GG11: 0.112 | GH11: 0.095 | GJ11: 0 | GK11: 0.005 | GL11: 0.612 | GM11: 0 | GN11: 0 | GO11: 0.084 | GP11: 0.012 | GQ11: 0 | GR11: 0.001 | GS11: 0.001 | GT11: 0.002 | GU11: 0 | GV11: 0.138 | GW11: 0.097 | GX11: 0.303 | GY11: 0.018 | GZ11: 0.002 | HA11: 0.001 | HB11: 0.034 | HC11: 0.008 | HE11: 0.8 | HF11: 0.001 | HG11: 0 | HH11: 0 | HI11: 11.9 | HJ11: 0 | HK11: 101 | HL11: 3.27 | HM11: 38 | HN11: 0.7 | HO11: 17.8
A12: 2720960 | B12: Pringles Crisps Bbq 16.9oz | C12: Kellogg Company US | D12: Branded | E12: 100 | F12: =E12/SUM($E$3:$E$58) | H12: 9.7 | M12: 412 | AF12: 57.6 | AJ12: 31.2 | AK12: 31.2 | DW12: 4.3 | EE12: 2.4 | EQ12: 529.2 | ER12: 2214.1728 | ET12: 3.2 | FV12: 0 | GE12: 0 | GF12: 8.6 | GG12: 0 | HH12: 0.6 | HL12: 4.5 | HM12: 482
A13: 2257045 | B13: Almond milk, unsweetened, plain, refrigerated | D13: Foundation | E13: 100 | F13: =E13/SUM($E$3:$E$58) | G13: 96.52 | H13: 157.5 | M13: 49.27 | AE13: 0.07661 | AF13: 0.67075 | AG13: 0.08875 | AI13: 0.005 | AJ13: 1.558 | AK13: 1.558 | AL13: 0 | AO13: 0.02875 | AP13: 0.0925 | AQ13: 0.0775 | AR13: 0.00125 | AS13: 0.1375 | AT13: 0.045 | AU13: 0.01375 | AV13: 0.02625 | AW13: 0.04625 | AX13: 0.03125 | AY13: 0.00125 | BC13: 0.105 | BD13: 0.0425 | BE13: 0.03125 | BH13: 0.02 | BK13: 0.01 | BS13: 0.00125 | BT13: 0.01875 | BU13: 0.0175 | CM13: 0 | CN13: 0 | CO13: 0 | CP13: 0 | CQ13: 0 | CR13: 0.03857 | CS13: 63.6 | DX13: 19.33 | EE13: 0 | EQ13: 19.33 | ER13: 80.87672 | EY13: 1.425 | EZ13: 0 | FD13: 0.4492 | FG13: 60.92 | FV13: 1.59 | FW13: 1.578 | FX13: 0.01015 | FZ13: 0 | GA13: 0 | GV13: 0.08333 | HE13: 0.595 | HF13: 0.02688 | HG13: 0 | HH13: 0.1247 | HI13: 8.249 | HJ13: 0.05642 | HK13: 19.08 | HL13: 0.65625 | HM13: 59.22 | HX13: 0
A14: 1999631 | B14: Almond milk, unsweetened, plain, shelf stable | D14: Foundation | E14: 100 | F14: =E14/SUM($E$3:$E$58) | G14: 97.4 | H14: 172.7 | I14: 0.7288 | J14: 0.2763 | K14: 0 | L14: 0.005813 | M14: 30.79 | N14: 0 | O14: 0 | P14: 0 | Q14: 0 | R14: 0 | S14: 0 | U14: 0 | V14: 0.00125 | W14: 0.07781 | X14: 0.0195 | Y14: 0 | Z14: 0.003688 | AA14: 0 | AB14: 0 | AC14: 0.000125 | AD14: 0 | AE14: 0.1718 | AF14: 0.3371125 | AG14: 0.07438 | AI14: 0 | AJ14: 1.1089 | AK14: 1.221 | AL14: 0 | AM14: 3.323 | AZ14: 0 | BA14: 0.000875 | BB14: 0 | BC14: 0.08875 | BF14: 0 | BG14: 0 | BI14: 0 | BJ14: 0 | BL14: 0 | BM14: 0 | BN14: 0.02746 | BO14: 0 | BP14: 0 | BQ14: 0 | BR14: 0 | BY14: 0.00125 | BZ14: 0.2756 | CA14: 0.000625 | CB14: 0 | CC14: 0 | CD14: 0 | CE14: 0 | CF14: 0 | CG14: 0 | CM14: 0 | CN14: 0 | CO14: 0 | CP14: 0 | CQ14: 0 | CR14: 0 | CS14: 37.1 | CZ14: 0 | DA14: 0 | DB14: 0 | DC14: 0 | DD14: 0 | DE14: 0 | DF14: 0 | DG14: 0 | DH14: 0 | DI14: 0 | DW14: 0 | DX14: 14.5562 | DY14: 14.5562 | EE14: 0 | EQ14: 14.5562 | ER14: 60.903141 | EU14: 0 | EV14: 0 | EX14: 0 | EY14: 1.019 | EZ14: 0 | FD14: 0.3375 | FF14: 41.4 | FG14: 41.42 | FV14: 0.927 | FW14: 0.9266 | FX14: 0 | GC14: 0.000125 | GF14: 0.1038 | GG14: 0 | GH14: 0 | GJ14: 0 | GK14: 0.00125 | GL14: 0.7207 | GM14: 0 | GN14: 0 | GO14: 0.2756 | GP14: 0.000625 | GQ14: 0 | GR14: 0 | GS14: 0 | GT14: 0 | GU14: 0 | GV14: 0.03339 | GW14: 0 | GX14: 0.002375 | GY14: 0.000875 | GZ14: 0 | HA14: 0 | HB14: 0 | HC14: 0 | HE14: 0.4872 | HF14: 0.02126 | HH14: 0.2899 | HI14: 6.785 | HJ14: 0.04497 | HK14: 29.85 | HL14: 0.5546875 | HM14: 59.58 | IG14: 0.007875 | IH14: 0.0075 | II14: 0
A15: 746766 | B15: Cheese, ricotta, whole milk | D15: Foundation | E15: 100 | F15: =E15/SUM($E$3:$E$58) | G15: 72.9 | H15: 224 | I15: 2.56 | J15: 0.389 | K15: 0.001 | L15: 0.184 | M15: 230 | N15: 0.049 | O15: 0 | P15: 0.001 | Q15: 0.001 | R15: 0.012 | S15: 0.015 | T15: 5.5 | U15: 0.306 | V15: 0.116 | W15: 3.36 | X15: 1.02 | Y15: 0.014 | Z15: 0.251 | AA15: 0.199 | AB15: 0.251 | AC15: 0.068 | AD15: 0 | AE15: 0.56 | AF15: 6.86 | AG15: 0.168 | AH15: 0.673 | AI15: 0.043 | AJ15: 10.3 | AK15: 11 | AL15: 0.099 | AM15: 0.27 | AN15: 0.6 | AO15: 0.325 | AP15: 0.21 | AQ15: 0.735 | AR15: 0.18 | AS15: 1.3 | AT15: 0.135 | AU15: 0.175 | AV15: 0.365 | AW15: 0.785 | AX15: 0.655 | AY15: 0.17 | AZ15: 0.117 | BA15: 0.02 | BB15: 0.002 | BC15: 1.22 | BD15: 0.27 | BE15: 0.565 | BF15: 0 | BG15: 0 | BH15: 0.365 | BI15: 0 | BJ15: 0.001 | BK15: 0.395 | BL15: 0 | BM15: 0 | BN15: 0 | BO15: 0 | BP15: 0 | BQ15: 0 | BR15: 0 | BS15: 0.115 | BT15: 0.25 | BU15: 0.325 | BV15: 0 | BW15: 3.1 | BX15: 0.068 | BY15: 0.021 | BZ15: 0.308 | CA15: 0.042 | CB15: 0.001 | CC15: 0.012 | CD15: 0.015 | CE15: 0.005 | CF15: 0.007 | CG15: 0 | CH15: 127 | CI15: 127 | EQ15: 157.68 | ER15: 659.73312 | GE15: 48 | GF15: 6.97 | GG15: 0.351 | GH15: 0.283 | GI15: 4 | GJ15: 0 | GK15: 0.021 | GL15: 2.22 | GM15: 0.002 | GN15: 0 | GO15: 0.259 | GP15: 0.042 | GQ15: 0 | GR15: 0.005 | GS15: 0.003 | GT15: 0.007 | GU15: 0 | GV15: 0.327 | GW15: 0.36 | GX15: 1.15 | GY15: 0.067 | GZ15: 0.006 | HA15: 0.004 | HB15: 0.125 | HC15: 0.032 | HD15: 0.78 | HE15: 1.36 | HF15: 0 | HG15: 0 | HH15: 0.1 | HI15: 19.7 | HJ15: 0 | HK15: 162 | HL15: 7.81 | HM15: 105
A16: 2259796 | B16: Cheese, feta, whole milk, crumbled | D16: Foundation | E16: 100 | F16: =E16/SUM($E$3:$E$58) | G16: 51.89 | H16: 371.1 | I16: 4.184 | L16: 0.2849 | M16: 105.3 | U16: 0.481 | W16: 5.313 | X16: 1.741 | Z16: 0.4039 | AA16: 0.3336 | AE16: 2.353 | AF16: 5.58318 | AG16: 0.2644 | AI16: 0.05638 | AJ16: 19.08 | AK16: 19.08 | AL16: 0.03831 | BC16: 3.089 | CM16: 0 | CN16: 0.4294 | CO16: 0.5863 | CP16: 0.61 | CQ16: 0 | CR16: 0 | CS16: 0 | DW16: 1.6257 | DX16: 272.884 | DY16: 273.4725 | EQ16: 272.884 | ER16: 1141.7467 | EU16: 48.44 | EY16: 0.4638 | FG16: 146.9 | FV16: 0 | FW16: 0 | FX16: 0 | FZ16: 1.2 | GA16: 4.8 | GE16: 57.52 | GF16: 11.17 | GL16: 3.663 | GO16: 0.4244 | GV16: 0.4444 | GW16: 0.5449 | GX16: 1.797 | HE16: 3.739 | HF16: 0.03155 | HH16: 0.0675 | HI16: 17.69 | HJ16: 0.02003 | HK16: 327.6 | HL16: 19.70782 | HM16: 1034 | HX16: 0
A17: 746772 | B17: Milk, lowfat, fluid, 1% milkfat, with added vitamin A and vitamin D | D17: Foundation | E17: 100 | F17: =E17/SUM($E$3:$E$58) | G17: 89.7 | H17: 126 | I17: 0.21 | J17: 0.032 | K17: 0 | L17: 0.012 | M17: 159 | N17: 0.004 | O17: 0 | P17: 0 | Q17: 0 | R17: 0.001 | S17: 0.001 | T17: 2.1 | U17: 0.023 | V17: 0.01 | W17: 0.265 | X17: 0.096 | Y17: 0.001 | Z17: 0.022 | AA17: 0.015 | AB17: 0.027 | AC17: 0.004 | AD17: 0 | AE17: 0.43 | AF17: 5.18 | AG17: 0.113 | AH17: 0.368 | AI17: 0.057 | AJ17: 0.85 | AK17: 0.95 | AL17: 0.06 | AM17: 0.02 | AO17: 0.111 | AP17: 0.128 | AQ17: 0.286 | AR17: 0.036 | AS17: 0.809 | AT17: 0.069 | AU17: 0.099 | AV17: 0.174 | AW17: 0.342 | AX17: 0.308 | AY17: 0.092 | AZ17: 0.007 | BA17: 0.001 | BB17: 0 | BC17: 0.53 | BD17: 0.168 | BE17: 0.349 | BF17: 0 | BG17: 0 | BH17: 0.194 | BI17: 0 | BJ17: 0 | BK17: 0.158 | BL17: 0 | BM17: 0 | BN17: 0 | BO17: 0 | BP17: 0 | BQ17: 0 | BR17: 0 | BS17: 0.045 | BT17: 0.167 | BU17: 0.21 | BX17: 0.004 | BY17: 0.002 | BZ17: 0.029 | CA17: 0.004 | CB17: 0 | CC17: 0.001 | CD17: 0.001 | CE17: 0 | CF17: 0 | CG17: 0 | CH17: 58 | CI17: 58 | CJ17: 1.06 | CK17: 1.06 | CL17: 1 | CM17: 0 | CN17: 0 | CO17: 0 | CP17: 4.96 | CQ17: 0 | CR17: 0 | CS17: 42.4 | CT17: 0 | CU17: 0 | CV17: 0 | CW17: 0 | CX17: 0 | CY17: 0 | CZ17: 0 | DA17: 0 | DB17: 0 | DC17: 0 | DD17: 0 | DE17: 0 | DF17: 0 | DG17: 0 | DH17: 0.001 | DI17: 0 | DJ17: 0 | DK17: 0 | DL17: 0 | DM17: 0 | DN17: 1 | DO17: 0 | DP17: 0 | DQ17: 3 | DR17: 10.9 | DS17: 0.9 | DT17: 1.8 | DU17: 0.8 | DV17: 36.2 | DW17: 4.96 | EQ17: 42.79 | ER17: 179.03336 | GE17: 5 | GF17: 0.568 | GG17: 0.036 | GH17: 0.031 | GI17: 2 | GJ17: 0 | GK17: 0.002 | GL17: 0.187 | GM17: 0 | GN17: 0 | GO17: 0.026 | GP17: 0.004 | GQ17: 0 | GR17: 0 | GS17: 0 | GT17: 0 | GU17: 0 | GV17: 0.14 | GW17: 0.026 | GX17: 0.093 | GY17: 0.006 | GZ17: 0 | HA17: 0 | HB17: 0.011 | HC17: 0.002 | HD17: 0.61 | HE17: 0.8 | HF17: 0.001 | HG17: 0 | HH17: 0 | HI17: 12 | HJ17: 0 | HK17: 103 | HL17: 3.38 | HM17: 39 | HN17: 0.9 | HO17: 17.4
A18: 746776 | B18: Milk, nonfat, fluid, with added vitamin A and vitamin D (fat free or skim) | D18: Foundation | E18: 100 | F18: =E18/SUM($E$3:$E$58) | G18: 90.8 | H18: 132 | I18: 0.017 | J18: 0.006 | K18: 0 | L18: 0.001 | M18: 167 | N18: 0 | O18: 0 | P18: 0 | Q18: 0 | R18: 0 | S18: 0 | T18: 2 | U18: 0.002 | V18: 0.001 | W18: 0.021 | X18: 0.009 | Y18: 0 | Z18: 0.003 | AA18: 0.001 | AB18: 0.001 | AC18: 0 | AD18: 0 | AE18: 0.45 | AF18: 4.92 | AG18: 0.118 | AH18: 0.388 | AI18: 0.056 | AJ18: 0.07 | AK18: 0.08 | AL18: 0.058 | AM18: 0 | AO18: 0.118 | AP18: 0.131 | AQ18: 0.299 | AR18: 0.038 | AS18: 0.832 | AT18: 0.071 | AU18: 0.101 | AV18: 0.182 | AW18: 0.347 | AX18: 0.302 | AY18: 0.093 | AZ18: 0 | BA18: 0 | BB18: 0 | BC18: 0.54 | BD18: 0.168 | BE18: 0.348 | BF18: 0 | BG18: 0 | BH18: 0.202 | BI18: 0 | BJ18: 0 | BK18: 0.166 | BL18: 0 | BM18: 0 | BN18: 0 | BO18: 0 | BP18: 0 | BQ18: 0 | BR18: 0 | BS18: 0.048 | BT18: 0.168 | BU18: 0.222 | BX18: 0 | BY18: 0 | BZ18: 0.005 | CA18: 0 | CB18: 0 | CC18: 0 | CD18: 0 | CE18: 0 | CF18: 0 | CG18: 0 | CH18: 64 | CI18: 64 | CJ18: 1.1 | CK18: 1.1 | CL18: 2 | CM18: 0 | CN18: 0 | CO18: 0 | CP18: 5.05 | CQ18: 0 | CR18: 0 | CS18: 44 | CT18: 0 | CU18: 0 | CV18: 0 | CW18: 0 | CX18: 0 | CY18: 0 | CZ18: 0 | DA18: 0 | DB18: 0 | DC18: 0 | DD18: 0 | DE18: 0 | DF18: 0 | DG18: 0 | DH18: 0 | DI18: 0 | DJ18: 1 | DK18: 0 | DL18: 0 | DM18: 1 | DN18: 1 | DO18: 0 | DP18: 0 | DQ18: 3.1 | DR18: 11.5 | DS18: 0.8 | DT18: 2 | DU18: 0.9 | DV18: 35.7 | DW18: 5.05 | EQ18: 34.12 | ER18: 142.75808 | GE18: 3 | GF18: 0.049 | GG18: 0 | GH18: 0.001 | GI18: 2 | GJ18: 0 | GK18: 0 | GL18: 0.017 | GM18: 0 | GN18: 0 | GO18: 0.005 | GP18: 0 | GQ18: 0 | GR18: 0 | GS18: 0 | GT18: 0 | GU18: 0 | GV18: 0.131 | GW18: 0.002 | GX18: 0.008 | GY18: 0.001 | GZ18: 0 | HA18: 0 | HB18: 0.001 | HC18: 0 | HD18: 0.58 | HE18: 0.77 | HF18: 0.002 | HG18: 0 | HH18: 0 | HI18: 12.5 | HJ18: 0.001 | HK18: 107 | HL18: 3.43 | HM18: 41 | HN18: 0.9 | HO18: 18.2
A19: 746778 | B19: Milk, reduced fat, fluid, 2% milkfat, with added vitamin A and vitamin D | D19: Foundation | E19: 100 | F19: =E19/SUM($E$3:$E$58) | G19: 89.1 | H19: 126 | I19: 0.4 | J19: 0.058 | K19: 0 | L19: 0.024 | M19: 159 | N19: 0.007 | O19: 0 | P19: 0 | Q19: 0 | R19: 0.002 | S19: 0.003 | U19: 0.049 | V19: 0.019 | W19: 0.512 | X19: 0.184 | Y19: 0.002 | Z19: 0.041 | AA19: 0.032 | AB19: 0.052 | AC19: 0.009 | AD19: 0 | AE19: 0.43 | AF19: 4.9 | AG19: 0.112 | AH19: 0.39 | AI19: 0.059 | AJ19: 1.64 | AK19: 1.9 | AL19: 0.061 | AM19: 0.03 | AO19: 0.113 | AP19: 0.125 | AQ19: 0.291 | AR19: 0.035 | AS19: 0.801 | AT19: 0.068 | AU19: 0.099 | AV19: 0.173 | AW19: 0.335 | AX19: 0.293 | AY19: 0.089 | AZ19: 0.014 | BA19: 0.002 | BB19: 0 | BC19: 0.53 | BD19: 0.163 | BE19: 0.332 | BF19: 0 | BG19: 0 | BH19: 0.197 | BI19: 0 | BJ19: 0 | BK19: 0.162 | BL19: 0 | BM19: 0 | BN19: 0 | BO19: 0 | BP19: 0 | BQ19: 0 | BR19: 0 | BS19: 0.042 | BT19: 0.165 | BU19: 0.213 | BX19: 0.009 | BY19: 0.003 | BZ19: 0.052 | CA19: 0.007 | CB19: 0 | CC19: 0.002 | CD19: 0.003 | CE19: 0 | CF19: 0.001 | CG19: 0 | CM19: 0 | CN19: 0 | CO19: 0 | CP19: 4.89 | CQ19: 0 | CR19: 0 | CS19: 45.2 | CZ19: 0.001 | DA19: 0 | DB19: 0 | DC19: 0 | DD19: 0 | DE19: 0 | DF19: 0 | DG19: 0 | DH19: 0.003 | DI19: 0 | DQ19: 3.1 | DR19: 11 | DS19: 1.1 | DT19: 1.9 | DU19: 1.2 | DW19: 4.89 | EQ19: 50.14 | ER19: 209.78576 | EU19: 39.6 | EV19: 1.8 | EZ19: 2 | FD19: 0.55 | FF19: 83 | FG19: 83 | FH19: 3 | FI19: 1 | FJ19: 2 | FK19: 0 | FM19: 0 | FN19: 0 | FO19: 0 | FP19: 0 | FQ19: 0 | FS19: 0 | FT19: 0 | FU19: 0 | FV19: 1.13 | FW19: 0 | FX19: 1.13 | FY19: 0 | GE19: 8 | GF19: 1.11 | GG19: 0.07 | GH19: 0.06 | GJ19: 0 | GK19: 0.003 | GL19: 0.358 | GM19: 0 | GN19: 0 | GO19: 0.045 | GP19: 0.007 | GQ19: 0 | GR19: 0 | GS19: 0 | GT19: 0.001 | GU19: 0 | GV19: 0.137 | GW19: 0.058 | GX19: 0.181 | GY19: 0.011 | GZ19: 0.001 | HA19: 0 | HB19: 0.021 | HC19: 0.005 | HE19: 0.75 | HF19: 0.001 | HG19: 0 | HH19: 0 | HI19: 12 | HJ19: 0.001 | HK19: 103 | HL19: 3.36 | HM19: 39 | HN19: 0.7 | HO19: 18.2
A20: 746782 | B20: Milk, whole, 3.25% milkfat, with added vitamin D | D20: Foundation | E20: 100 | F20: =E20/SUM($E$3:$E$58) | G20: 88.1 | H20: 123 | I20: 0.688 | J20: 0.108 | K20: 0 | L20: 0.039 | M20: 150 | N20: 0.013 | O20: 0.001 | P20: 0 | Q20: 0.001 | R20: 0.004 | S20: 0.004 | T20: 1.9 | U20: 0.084 | V20: 0.032 | W20: 0.857 | X20: 0.309 | Y20: 0.004 | Z20: 0.067 | AA20: 0.054 | AB20: 0.082 | AC20: 0.018 | AD20: 0 | AE20: 0.42 | AF20: 4.63 | AG20: 0.105 | AH20: 0.362 | AI20: 0.056 | AJ20: 2.77 | AK20: 3.2 | AL20: 0.061 | AM20: 0.05 | AO20: 0.11 | AP20: 0.127 | AQ20: 0.279 | AR20: 0.038 | AS20: 0.788 | AT20: 0.069 | AU20: 0.097 | AV20: 0.173 | AW20: 0.333 | AX20: 0.298 | AY20: 0.09 | AZ20: 0.024 | BA20: 0.004 | BB20: 0 | BC20: 0.51 | BD20: 0.161 | BE20: 0.333 | BF20: 0 | BG20: 0 | BH20: 0.188 | BI20: 0 | BJ20: 0 | BK20: 0.154 | BL20: 0 | BM20: 0 | BN20: 0 | BO20: 0 | BP20: 0 | BQ20: 0 | BR20: 0 | BS20: 0.043 | BT20: 0.162 | BU20: 0.207 | BX20: 0.018 | BY20: 0.005 | BZ20: 0.097 | CA20: 0.013 | CB20: 0.001 | CC20: 0.004 | CD20: 0.004 | CE20: 0.001 | CF20: 0.002 | CG20: 0 | CH20: 31 | CI20: 32 | CJ20: 0.96 | CK20: 0.96 | CL20: 7 | CM20: 0 | CN20: 0 | CO20: 0 | CP20: 4.81 | CQ20: 0 | CR20: 0 | CS20: 38.4 | CT20: 0 | CU20: 0 | CV20: 0 | CW20: 0 | CX20: 0 | CY20: 0 | CZ20: 0.001 | DA20: 0 | DB20: 0 | DC20: 0 | DD20: 0 | DE20: 0 | DF20: 0 | DG20: 0 | DH20: 0.005 | DI20: 0 | DJ20: 2 | DK20: 0 | DL20: 0 | DM20: 5 | DN20: 5 | DO20: 0 | DP20: 1 | DQ20: 3 | DR20: 10.3 | DS20: 1.3 | DT20: 1.8 | DU20: 1.4 | DV20: 37.9 | DW20: 4.81 | EQ20: 60.4 | ER20: 252.7136 | GE20: 12 | GF20: 1.86 | GG20: 0.112 | GH20: 0.095 | GI20: 0 | GJ20: 0 | GK20: 0.005 | GL20: 0.612 | GM20: 0 | GN20: 0 | GO20: 0.084 | GP20: 0.012 | GQ20: 0 | GR20: 0.001 | GS20: 0.001 | GT20: 0.002 | GU20: 0 | GV20: 0.138 | GW20: 0.097 | GX20: 0.303 | GY20: 0.018 | GZ20: 0.002 | HA20: 0.001 | HB20: 0.034 | HC20: 0.008 | HD20: 0.54 | HE20: 0.8 | HF20: 0.001 | HG20: 0 | HH20: 0 | HI20: 11.9 | HJ20: 0 | HK20: 101 | HL20: 3.27 | HM20: 38 | HN20: 0.7 | HO20: 17.8
A21: 2257046 | B21: Oat milk, unsweetened, plain, refrigerated | D21: Foundation | E21: 100 | F21: =E21/SUM($E$3:$E$58) | G21: 90.56 | H21: 148.5 | M21: 148.4 | AE21: 0.09062 | AF21: 5.100325 | AG21: 0.09625 | AI21: 0.04 | AJ21: 2.749 | AK21: 2.749 | AL21: 0.0065 | AO21: 0.0375 | AP21: 0.0825 | AQ21: 0.0825 | AR21: 0.025 | AS21: 0.15 | AT21: 0.05625 | AU21: 0.0175 | AV21: 0.025 | AW21: 0.08125 | AX21: 0.06125 | AY21: 0.01 | BC21: 0.1275 | BD21: 0.0725 | BE21: 0.0725 | BH21: 0.05625 | BK21: 0.0225 | BS21: 0.00875 | BT21: 0.04125 | BU21: 0.0325 | CM21: 0 | CN21: 0 | CO21: 0.7706 | CP21: 0 | CQ21: 1.551 | CR21: 0 | CS21: 68 | DW21: 2.3216 | DX21: 48.3298 | EE21: 0 | EQ21: 48.3298 | ER21: 202.21188 | EV21: 0 | EX21: 10.09 | EY21: 1.406 | EZ21: 0 | FD21: 0.5064 | FG21: 84.73 | FV21: 1.7 | FW21: 1.694 | FX21: 0.007692 | FZ21: 0.4 | GA21: 0 | GV21: 0.2807 | HE21: 0.7938 | HF21: 0.02712 | HG21: 0 | HH21: 0.2612 | HI21: 5.909 | HJ21: 0.1262 | HK21: 89.18 | HL21: 0.796875 | HM21: 41.98 | HX21: 0
A22: 2257044 | B22: Soy milk, sweetened, plain, refrigerated | D22: Foundation | E22: 100 | F22: =E22/SUM($E$3:$E$58) | G22: 91.52 | H22: 154.8 | M22: 117.9 | AE22: 0.2636 | AF22: 2.996125 | AG22: 0.1329 | AI22: 0.04357 | AJ22: 1.957 | AK22: 1.957 | AL22: 0.03643 | AO22: 0.1 | AP22: 0.2 | AQ22: 0.3286 | AR22: 0.04857 | AS22: 0.4857 | AT22: 0.1 | AU22: 0.1 | AV22: 0.1 | AW22: 0.2 | AX22: 0.2 | AY22: 0.03286 | BC22: 0.4443 | BD22: 0.1571 | BE22: 0.1143 | BH22: 0.1714 | BK22: 0.1 | BS22: 0.03429 | BT22: 0.1 | BU22: 0.1014 | CM22: 0 | CN22: 0 | CO22: 0 | CP22: 0 | CQ22: 0 | CR22: 2.577 | CS22: 185 | DX22: 40.705 | EE22: 0 | EQ22: 40.705 | ER22: 170.30972 | EV22: 0 | EX22: 32.29 | EY22: 2.157 | EZ22: 15.81 | FD22: 1.327 | FG22: 89.43 | FV22: 4.63 | FW22: 4.61 | FX22: 0.02014 | FZ22: 2.8 | GA22: 0 | GV22: 0.3307 | HE22: 0.75 | HF22: 0.09561 | HG22: 0 | HH22: 0.3666 | HI22: 17.46 | HJ22: 0.1596 | HK22: 45.96 | HL22: 2.776875 | HM22: 39.44 | HX22: 0 | IJ22: 0.1393 | IK22: 0.2364 | IL22: 7.961 | IM22: 14.71 | IN22: 0.3643
A23: 1999630 | B23: Soy milk, unsweetened, plain, shelf stable | D23: Foundation | E23: 100 | F23: =E23/SUM($E$3:$E$58) | G23: 92.4 | H23: 101 | I23: 0.4163 | J23: 1.154 | K23: 0 | L23: 0.001938 | M23: 158.2 | N23: 0 | O23: 0 | P23: 0 | Q23: 0.0005625 | R23: 0 | S23: 0 | U23: 0 | V23: 0.001688 | W23: 0.2182 | X23: 0.07281 | Y23: 0.005625 | Z23: 0 | AA23: 0 | AB23: 0.0008125 | AC23: 0.001125 | AD23: 0 | AE23: 0.3118 | AF23: 1.293125 | AG23: 0.2356 | AI23: 0.06319 | AJ23: 1.8841 | AK23: 2.125 | AL23: 0.05525 | AM23: 0.1557 | AO23: 0.1394 | AP23: 0.2688 | AQ23: 0.3963 | AR23: 0.0575 | AS23: 0.6194 | AT23: 0.1413 | AU23: 0.0975 | AV23: 0.145 | AW23: 0.2494 | AX23: 0.2206 | AY23: 0.04625 | AZ23: 0 | BA23: 0.004813 | BB23: 0 | BC23: 0.5675 | BD23: 0.175 | BE23: 0.137 | BF23: 0 | BG23: 0 | BH23: 0.1675 | BI23: 0 | BJ23: 0 | BK23: 0.1281 | BL23: 0 | BM23: 0.8742 | BN23: 1.42 | BO23: 0 | BP23: 0 | BQ23: 0 | BR23: 0 | BS23: 0.04625 | BT23: 0.1238 | BU23: 0.1419 | BY23: 0.001 | BZ23: 0.9878 | CA23: 0.1664 | CB23: 0.0005625 | CC23: 0 | CD23: 0 | CE23: 0 | CF23: 0 | CG23: 0 | CM23: 0 | CN23: 0 | CO23: 0 | CP23: 0 | CQ23: 0 | CR23: 0.5569 | CS23: 27.2 | CZ23: 0 | DA23: 0 | DB23: 0 | DC23: 0 | DD23: 0 | DE23: 0 | DF23: 0 | DG23: 0 | DH23: 0 | DI23: 0 | DW23: 0.5569 | DX23: 38.485 | DY23: 38.485 | EE23: 0 | EQ23: 38.485 | ER23: 161.02124 | EU23: 0 | EV23: 1.942 | EX23: 58.38 | EY23: 3.338 | EZ23: 19.69 | FD23: 0.3931 | FF23: 58.2 | FG23: 58.23 | FH23: 0 | FI23: 0 | FJ23: 0 | FK23: 0 | FL23: 0 | FM23: 0 | FN23: 0 | FO23: 0 | FP23: 0 | FQ23: 0 | FR23: 8.2245 | FS23: 0.9655 | FU23: 7.259 | FV23: 0.681 | FW23: 0.6814 | FX23: 0 | GC23: 0.001125 | GF23: 0.3138 | GG23: 0 | GH23: 0.0008125 | GJ23: 0 | GK23: 0.001 | GL23: 0.4092 | GM23: 0 | GN23: 0 | GO23: 0.9878 | GP23: 0.1664 | GQ23: 0 | GR23: 0 | GS23: 0 | GT23: 0 | GU23: 0 | GV23: 0.084 | GW23: 0 | GX23: 0.003813 | GY23: 0.002 | GZ23: 0.00675 | HA23: 0.002313 | HB23: 0 | HC23: 0 | HE23: 0.635 | HF23: 0.1078 | HG23: 0 | HH23: 0.5416 | HI23: 21.54 | HJ23: 0.2077 | HK23: 68.65 | HL23: 3.546875 | HM23: 34.28 | IG23: 0.06653 | IH23: 0.4344 | II23: 0.02625 | IJ23: 0.4569 | IK23: 0.3801 | IL23: 12.91 | IM23: 18.81 | IN23: 1.365
A24: 2646174 | B24: Beef, chuck, roast, boneless, choice, raw | D24: Foundation | E24: 100 | F24: =E24/SUM($E$3:$E$58) | G24: 63.43 | H24: 4.576 | I24: 7.021 | J24: 0.5557 | M24: 281.1 | AE24: 5.386 | AF24: 0 | AJ24: 17.8 | AK24: 17.8 | BC24: 2.944 | DX24: 231.7048 | DY24: 237.09689 | EQ24: 233.8 | ER24: 978.2192 | GE24: 66.75 | GF24: 6.341 | GG24: 0.6686 | HE24: 0.8938 | HF24: 0.05405 | HH24: 2.059 | HI24: 16.99 | HJ24: 0 | HK24: 151 | HL24: 18.4 | HM24: 48.44
A25: 2646175 | B25: Beef, flank, steak, boneless, choice, raw | D25: Foundation | E25: 100 | F25: =E25/SUM($E$3:$E$58) | G25: 69.8 | H25: 3.84 | I25: 3.59 | J25: 0.314 | M25: 332 | AE25: 5.56 | AF25: 0 | AJ25: 9.4 | AK25: 9.4 | BC25: 3.22 | DX25: 164 | DY25: 170 | EQ25: 165 | ER25: 690.36 | GE25: 57.7 | GF25: 3.55 | GG25: 0.389 | HE25: 0.994 | HF25: 0.0447 | HH25: 1.83 | HI25: 18.9 | HJ25: 0.00169 | HK25: 167 | HL25: 20.1 | HM25: 51.3
A26: 2514744 | B26: Beef, ground, 80% lean meat / 20% fat, raw | D26: Foundation | E26: 100 | F26: =E26/SUM($E$3:$E$58) | G26: 62.82 | H26: 6.889 | I26: 7.247 | J26: 0.485 | M26: 273.3 | AE26: 3.848 | AF26: 0 | AJ26: 19.44 | AK26: 19.44 | BC26: 2.805 | DX26: 242.61 | DY26: 247.81268 | EQ26: 245.085 | ER26: 1025.4356 | GE26: 67.74 | GF26: 6.845 | GG26: 0.7 | HE26: 0.8275 | HF26: 0.0551 | HH26: 1.965 | HI26: 16.41 | HJ26: 0 | HK26: 144.4 | HL26: 17.53125 | HM26: 54.94
A27: 2514743 | B27: Beef, ground, 90% lean meat / 10% fat, raw | D27: Foundation | E27: 100 | F27: =E27/SUM($E$3:$E$58) | G27: 69 | H27: 7.135 | I27: 4.477 | J27: 0.361 | M27: 281.4 | AE27: 4.194 | AF27: 0 | AJ27: 12.85 | AK27: 12.85 | BC27: 2.905 | DX27: 184.8648 | DY27: 190.13482 | EQ27: 188.275 | ER27: 787.7426 | GE27: 65.9 | GF27: 5.051 | GG27: 0.484 | HE27: 0.8463 | HF27: 0.05616 | HH27: 2.128 | HI27: 16.49 | HJ27: 0 | HK27: 148 | HL27: 18.15625 | HM27: 61.64
A28: 746758 | B28: Beef, loin, tenderloin roast, separable lean only, boneless, trimmed to 0" fat, select, cooked, roasted | D28: Foundation | E28: 100 | F28: =E28/SUM($E$3:$E$58) | G28: 65.7 | H28: 13 | I28: 2.26 | J28: 0.472 | L28: 0.141 | M28: 352 | N28: 0.033 | Q28: 0.002 | R28: 0.016 | S28: 0.064 | T28: 25.4 | U28: 0.005 | V28: 0.03 | W28: 1.34 | X28: 0.85 | Y28: 0.005 | AB28: 0.303 | AC28: 0.034 | AE28: 3.7 | AF28: 0 | AG28: 5.76 | AJ28: 5.56 | AK28: 6.36 | AL28: 0.67 | AZ28: 0.031 | BA28: 0.012 | BX28: 0.034 | BY28: 0.047 | BZ28: 0.362 | CA28: 0.012 | CB28: 0.002 | CC28: 0.016 | CD28: 0.064 | CE28: 0.002 | CF28: 0.011 | CG28: 0.002 | EB28: 0.012 | EQ28: 168.04 | ER28: 703.07936 | GE28: 85 | GF28: 2.47 | GG28: 0.359 | GH28: 0.326 | GK28: 0.047 | GL28: 2.03 | GO28: 0.329 | GP28: 0.012 | GR28: 0.002 | GT28: 0.011 | GU28: 0.002 | GV28: 0.4 | GW28: 0.006 | GX28: 0.153 | GY28: 0.073 | HA28: 0.006 | HC28: 0.022 | HD28: 4.21 | HE28: 1.22 | HF28: 0.097 | HH28: 3.04 | HI28: 13.7 | HJ28: 0.008 | HK28: 259 | HL28: 27.7 | HM28: 54
A29: 746759 | B29: Beef, loin, top loin steak, boneless, lip-on, separable lean only, trimmed to 1/8" fat, choice, raw | D29: Foundation | E29: 100 | F29: =E29/SUM($E$3:$E$58) | G29: 69.9 | H29: 15 | I29: 2.71 | J29: 0.364 | L29: 0.211 | M29: 282 | N29: 0.022 | Q29: 0.001 | R29: 0.013 | S29: 0.048 | T29: 21.3 | U29: 0.006 | V29: 0.027 | W29: 1.5 | X29: 0.773 | Y29: 0.004 | AB29: 0.261 | AC29: 0.03 | AE29: 3.76 | AF29: 0 | AG29: 6.88 | AH29: 0.36 | AI29: 0.053 | AJ29: 5.93 | AK29: 6.39 | AL29: 0.575 | AM29: 0.25 | AZ29: 0.04 | BA29: 0.011 | BL29: 0 | BM29: 0 | BN29: 0.02 | BO29: 0 | BP29: 0 | BQ29: 0 | BR29: 0 | BX29: 0.03 | BY29: 0.054 | BZ29: 0.281 | CA29: 0.009 | CB29: 0.001 | CC29: 0.013 | CD29: 0.048 | CE29: 0.003 | CF29: 0.008 | CG29: 0 | CJ29: 0 | CK29: 0 | CS29: 0 | CW29: 0.26 | CX29: 0 | DQ29: 0.7 | DR29: 5.7 | DS29: 44 | DT29: 0.7 | DU29: 5.2 | EB29: 0.011 | EQ29: 148.71 | ER29: 622.20264 | GE29: 58 | GF29: 2.56 | GG29: 0.306 | GH29: 0.276 | GK29: 0.054 | GL29: 2.39 | GO29: 0.259 | GP29: 0.009 | GR29: 0.003 | GT29: 0.008 | GU29: 0 | GV29: 0.202 | GW29: 0.005 | GX29: 0.168 | GY29: 0.069 | HA29: 0.004 | HC29: 0.015 | HD29: 1.72 | HE29: 1.01 | HF29: 0.043 | HH29: 1.9 | HI29: 11.3 | HJ29: 0.002 | HK29: 206 | HL29: 22.8 | HM29: 45 | HN29: 10 | HO29: 56.3
A30: 2646172 | B30: Beef, ribeye, steak, boneless, choice, raw | D30: Foundation | E30: 100 | F30: =E30/SUM($E$3:$E$58) | G30: 60.63 | H30: 4.173 | I30: 7.731 | J30: 0.6286 | M30: 288 | AE30: 4.063 | AF30: 0 | AJ30: 20.04 | AK30: 20.04 | BC30: 2.999 | DX30: 254.11 | DY30: 259.61142 | EQ30: 255.335 | ER30: 1068.3216 | GE30: 62.66 | GF30: 7.966 | GG30: 0.9743 | HE30: 0.8925 | HF30: 0.04263 | HH30: 1.641 | HI30: 16.68 | HJ30: 0 | HK30: 149.7 | HL30: 18.74375 | HM30: 42.54
A31: 746761 | B31: Beef, round, top round roast, boneless, separable lean only, trimmed to 0" fat, select, raw | D31: Foundation | E31: 100 | F31: =E31/SUM($E$3:$E$58) | G31: 73.3 | H31: 13 | I31: 0.886 | J31: 0.208 | L31: 0.059 | M31: 316 | N31: 0.005 | Q31: 0.001 | R31: 0.012 | S31: 0.038 | T31: 22.7 | U31: 0.004 | V31: 0.009 | W31: 0.524 | X31: 0.307 | Y31: 0.001 | AB31: 0.112 | AC31: 0.008 | AE31: 3.54 | AF31: 0 | AG31: 6.16 | AH31: 0.37 | AI31: 0.064 | AJ31: 2.14 | AK31: 2.41 | AL31: 0.626 | AM31: 0.21 | AZ31: 0.011 | BA31: 0.002 | BL31: 0 | BM31: 0 | BN31: 0.04 | BO31: 0 | BP31: 0 | BQ31: 0 | BR31: 0 | BX31: 0.008 | BY31: 0.017 | BZ31: 0.141 | CA31: 0.003 | CB31: 0.001 | CC31: 0.012 | CD31: 0.038 | CE31: 0.002 | CF31: 0.008 | CG31: 0.002 | CJ31: 0 | CK31: 0 | CS31: 0 | CW31: 0.18 | CX31: 0 | DQ31: 0.3 | DR31: 9.2 | DS31: 48.7 | DT31: 0.5 | DU31: 5.3 | EB31: 0.002 | EQ31: 116.49 | ER31: 487.39416 | GE31: 63 | GF31: 0.924 | GG31: 0.125 | GH31: 0.117 | GK31: 0.017 | GL31: 0.797 | GO31: 0.136 | GP31: 0.003 | GR31: 0.002 | GT31: 0.008 | GU31: 0.002 | GV31: 0.25 | GW31: 0.002 | GX31: 0.049 | GY31: 0.027 | HA31: 0.002 | HC31: 0.005 | HD31: 1.62 | HE31: 1.11 | HF31: 0.047 | HH31: 2.34 | HI31: 11.9 | HJ31: 0.003 | HK31: 220 | HL31: 23.7 | HM31: 55 | HN31: 10.8 | HO31: 64.1
A32: 746760 | B32: Beef, round, eye of round roast, boneless, separable lean only, trimmed to 0" fat, select, raw | D32: Foundation | E32: 100 | F32: =E32/SUM($E$3:$E$58) | G32: 73.7 | H32: 13 | I32: 0.951 | J32: 0.192 | L32: 0.072 | M32: 312 | N32: 0.011 | Q32: 0.001 | R32: 0.012 | S32: 0.032 | T32: 22.2 | U32: 0.003 | V32: 0.011 | W32: 0.546 | X32: 0.297 | Y32: 0.002 | AB32: 0.11 | AC32: 0.011 | AE32: 3.38 | AF32: 0 | AG32: 6.58 | AJ32: 2.23 | AK32: 2.48 | AL32: 0.638 | AZ32: 0.018 | BA32: 0.007 | BX32: 0.011 | BY32: 0.021 | BZ32: 0.124 | CA32: 0.005 | CB32: 0.001 | CC32: 0.012 | CD32: 0.032 | CE32: 0.004 | CF32: 0.011 | CG32: 0.002 | EB32: 0.007 | EQ32: 115.92 | ER32: 485.00928 | GE32: 62 | GF32: 0.953 | GG32: 0.129 | GH32: 0.118 | GK32: 0.021 | GL32: 0.833 | GO32: 0.113 | GP32: 0.005 | GR32: 0.004 | GT32: 0.011 | GU32: 0.002 | GV32: 0.185 | GW32: 0.002 | GX32: 0.062 | GY32: 0.027 | HA32: 0.003 | HC32: 0.008 | HD32: 2.06 | HE32: 1.08 | HF32: 0.035 | HH32: 1.37 | HI32: 11.4 | HJ32: 0.002 | HK32: 222 | HL32: 23.4 | HM32: 50
A33: 2646173 | B33: Beef, round, top round, boneless, choice, raw | D33: Foundation | E33: 100 | F33: =E33/SUM($E$3:$E$58) | G33: 70.88 | H33: 4.07 | I33: 1.7 | J33: 0.2383 | M33: 351.5 | AE33: 3.778 | AF33: 0.852 | AJ33: 5.703 | AK33: 5.703 | BC33: 3.436 | DX33: 140.635 | DY33: 146.43655 | EQ33: 140.635 | ER33: 588.41684 | GE33: 59.26 | GF33: 1.695 | GG33: 0.2283 | HE33: 1.09 | HF33: 0.05515 | HH33: 1.901 | HI33: 22.08 | HJ33: 0.002875 | HK33: 192.3 | HL33: 21.475 | HM33: 45.54
A34: 2727572 | B34: Beef, short loin (NY strip steak), raw | D34: Foundation | E34: 100 | F34: =E34/SUM($E$3:$E$58) | G34: 66 | H34: 5.04 | M34: 323 | AE34: 3.28 | AF34: 0.221 | AJ34: 11.5 | AK34: 11.5 | BC34: 3.41 | DX34: 190 | DY34: 196 | EQ34: 189.584 | ER34: 793.21946 | GE34: 57.6 | HE34: 0.964 | HF34: 0.043 | HH34: 1.61 | HI34: 19.5 | HJ34: 0.00156 | HK34: 171 | HL34: 21.3 | HM34: 43.1
A35: 746762 | B35: Beef, short loin, porterhouse steak, separable lean only, trimmed to 1/8" fat, select, raw | D35: Foundation | E35: 100 | F35: =E35/SUM($E$3:$E$58) | G35: 71.4 | H35: 19 | I35: 1.9 | J35: 0.259 | L35: 0.145 | M35: 266 | N35: 0.014 | Q35: 0.001 | R35: 0.013 | S35: 0.034 | T35: 21.4 | U35: 0.005 | V35: 0.028 | W35: 1.18 | X35: 0.64 | Y35: 0.003 | AB35: 0.244 | AC35: 0.024 | AE35: 3.52 | AF35: 0 | AG35: 5.32 | AJ35: 4.5 | AK35: 5.32 | AL35: 0.751 | AZ35: 0.033 | BA35: 0.008 | BX35: 0.024 | BY35: 0.042 | BZ35: 0.192 | CA35: 0.008 | CB35: 0.001 | CC35: 0.013 | CD35: 0.034 | CE35: 0.002 | CF35: 0.008 | CG35: 0.001 | EB35: 0.008 | EQ35: 138.68 | ER35: 580.23712 | GE35: 57 | GF35: 2.07 | GG35: 0.28 | GH35: 0.256 | GK35: 0.042 | GL35: 1.67 | GO35: 0.178 | GP35: 0.008 | GR35: 0.002 | GT35: 0.008 | GU35: 0.001 | GV35: 0.23 | GW35: 0.005 | GX35: 0.144 | GY35: 0.062 | HA35: 0.002 | HC35: 0.012 | HD35: 1.98 | HE35: 1.02 | HF35: 0.075 | HH35: 2.26 | HI35: 10.7 | HJ35: 0.003 | HK35: 200 | HL35: 22.7 | HM35: 43
A36: 2727574 | B36: Beef, top sirloin steak, raw | D36: Foundation | E36: 100 | F36: =E36/SUM($E$3:$E$58) | G36: 71 | H36: 3.7 | M36: 349 | AE36: 3.45 | AF36: 0.218 | AJ36: 5.71 | AK36: 5.71 | BC36: 3.52 | DX36: 140 | DY36: 146 | EQ36: 140.262 | ER36: 586.85621 | GE36: 60.1 | HE36: 1.09 | HF36: 0.0702 | HH36: 2.22 | HI36: 22.1 | HJ36: 0.00156 | HK36: 193 | HL36: 22 | HM36: 42.8
A37: 2727573 | B37: Beef, tenderloin steak, raw | D37: Foundation | E37: 100 | F37: =E37/SUM($E$3:$E$58) | G37: 71.2 | H37: 4.09 | M37: 345 | AE37: 3.22 | AF37: 0.18 | AJ37: 6.46 | AK37: 6.46 | BC37: 3.38 | DX37: 143 | DY37: 149 | EQ37: 143.26 | ER37: 599.39984 | GE37: 64.4 | HE37: 1.06 | HF37: 0.105 | HH37: 2.53 | HI37: 22 | HJ37: 0.00478 | HK37: 190 | HL37: 21.1 | HM37: 44.8
A38: 323121 | B38: Frankfurter, beef, unheated | D38: Foundation | E38: 100 | F38: =E38/SUM($E$3:$E$58) | G38: 54.6 | H38: 15 | I38: 12.1 | J38: 0.954 | K38: 0.001 | L38: 0.985 | M38: 343 | N38: 0.169 | O38: 0.005 | P38: 0.003 | Q38: 0.008 | R38: 0.021 | S38: 0.029 | U38: 0.015 | V38: 0.138 | W38: 6.33 | X38: 3.66 | Y38: 0.029 | Z38: 0.004 | AA38: 0 | AB38: 1.38 | AC38: 0.131 | AD38: 0 | AE38: 2.06 | AF38: 2.89 | AG38: 2.25 | AH38: 0.263 | AI38: 0.033 | AJ38: 26 | AK38: 28 | AL38: 0.13 | AM38: 0.51 | AZ38: 0.267 | BA38: 0.117 | BB38: 0.064 | BC38: 1.87 | BF38: 0 | BG38: 0.001 | BI38: 0 | BJ38: 0.001 | BL38: 0 | BM38: 0 | BN38: 0.17 | BO38: 0 | BP38: 0 | BQ38: 0 | BR38: 0 | BX38: 0.131 | BY38: 0.257 | BZ38: 0.794 | CA38: 0.084 | CB38: 0.008 | CC38: 0.022 | CD38: 0.029 | CE38: 0.003 | CF38: 0.013 | CG38: 0 | CH38: 3 | CI38: 3 | CM38: 0 | CN38: 0 | CO38: 1.17 | CP38: 0 | CQ38: 0.09 | CR38: 0 | DW38: 1.26 | EQ38: 310.36 | ER38: 1298.5462 | GF38: 11.4 | GG38: 1.59 | GH38: 1.46 | GI38: 0 | GJ38: 0 | GK38: 0.257 | GL38: 10.4 | GM38: 0.064 | GN38: 0.005 | GO38: 0.625 | GP38: 0.078 | GQ38: 0.001 | GR38: 0.003 | GS38: 0.008 | GT38: 0.013 | GU38: 0 | GV38: 0.154 | GW38: 0.019 | GX38: 0.84 | GY38: 0.355 | GZ38: 0.008 | HA38: 0.002 | HB38: 0.005 | HC38: 0.087 | HD38: 0.97 | HE38: 2.74 | HF38: 0.046 | HH38: 1.14 | HI38: 11.5 | HJ38: 0.031 | HK38: 128 | HL38: 11.7 | HM38: 872
A39: 746779 | B39: Sausage, breakfast sausage, beef, pre-cooked, unprepared | D39: Foundation | E39: 100 | F39: =E39/SUM($E$3:$E$58) | G39: 51.7 | H39: 35 | I39: 12.7 | J39: 1.91 | K39: 0.002 | L39: 1.1 | M39: 263 | N39: 0.128 | O39: 0.002 | P39: 0.001 | Q39: 0.033 | R39: 0.028 | S39: 0.046 | T39: 11.6 | U39: 0.002 | V39: 0.105 | W39: 6.66 | X39: 3.47 | Y39: 0.027 | Z39: 0.004 | AA39: 0 | AB39: 1.02 | AC39: 0.093 | AD39: 0 | AE39: 2.14 | AF39: 3.37 | AG39: 2.43 | AH39: 0.322 | AI39: 0.054 | AJ39: 27.1 | AK39: 28.7 | AL39: 0.15 | AM39: 0.33 | AO39: 0.77 | AP39: 0.83 | AQ39: 1.19 | AR39: 0.17 | AS39: 1.89 | AT39: 0.94 | AU39: 0.35 | AV39: 0.46 | AW39: 0.93 | AX39: 0.95 | AY39: 0.26 | AZ39: 0.253 | BA39: 0.112 | BB39: 0.016 | BC39: 2.13 | BD39: 0.6 | BE39: 0.84 | BF39: 0 | BG39: 0 | BH39: 0.55 | BI39: 0 | BJ39: 0.002 | BK39: 0.5 | BL39: 0 | BM39: 0 | BN39: 0.14 | BO39: 0 | BP39: 0 | BQ39: 0 | BR39: 0 | BS39: 0.12 | BT39: 0.39 | BU39: 0.53 | BX39: 0.093 | BY39: 0.202 | BZ39: 1.7 | CA39: 0.094 | CB39: 0.033 | CC39: 0.031 | CD39: 0.046 | CE39: 0 | CF39: 0.009 | CG39: 0.002 | CH39: 18 | CI39: 18 | CM39: 0 | CN39: 0 | CO39: 1 | CP39: 0 | CQ39: 0 | CR39: 0 | DQ39: 2.3 | DR39: 1.9 | DS39: 27.7 | DT39: 0.4 | DU39: 6 | DW39: 1 | ED39: 19.2 | EQ39: 324.98 | ER39: 1359.7163 | GE39: 61 | GF39: 11.3 | GG39: 1.18 | GH39: 1.08 | GJ39: 0 | GK39: 0.202 | GL39: 11 | GM39: 0.016 | GN39: 0.002 | GO39: 1.57 | GP39: 0.092 | GQ39: 0.004 | GR39: 0 | GS39: 0.015 | GT39: 0.009 | GU39: 0.002 | GV39: 0.132 | GW39: 0.018 | GX39: 0.784 | GY39: 0.256 | GZ39: 0.004 | HA39: 0.003 | HB39: 0 | HC39: 0.062 | HD39: 1.13 | HE39: 2.97 | HF39: 0.075 | HG39: 0.29 | HH39: 1.55 | HI39: 19.7 | HJ39: 0.174 | HK39: 124 | HL39: 13.3 | HM39: 866 | HN39: 2.8 | HO39: 38.3
A40: 170791 | B40: ARBY'S, roast beef sandwich, classic | D40: SR Legacy | E40: 100 | F40: =E40/SUM($E$3:$E$58) | G40: 49.9 | H40: 55 | I40: 3.99 | J40: 1.76 | K40: 0.043 | L40: 0.258 | M40: 224 | N40: 0.044 | O40: 0.007 | P40: 0 | Q40: 0.002 | R40: 0.01 | S40: 0.022 | T40: 18.2 | U40: 0 | V40: 0.032 | W40: 1.95 | X40: 1.11 | Y40: 0.015 | Z40: 0 | AA40: 0 | AB40: 0.326 | AC40: 0.043 | AD40: 0 | AE40: 2.27 | AF40: 22.2 | AG40: 4.34 | AI40: 0.217 | AJ40: 10.3 | AK40: 10.3 | AL40: 0.215 | CM40: 1.5 | CN40: 0 | CO40: 1.34 | CP40: 0 | CQ40: 1 | CR40: 0 | DW40: 3.84 | DZ40: 0.062 | EA40: 0.279 | EB40: 0.034 | EC40: 0 | EE40: 1.3 | EG40: 3.56 | EH40: 0 | EI40: 1.55 | EJ40: 0.159 | EK40: 0.01 | EQ40: 242.3 | ER40: 1013.7832 | GE40: 30 | GF40: 3.4 | GG40: 0.389 | GH40: 0.346 | GI40: 51 | GJ40: 0 | GK40: 0.052 | GL40: 3.24 | GM40: 0 | GN40: 0 | GO40: 1.46 | GP40: 0.152 | GQ40: 0 | GR40: 0.005 | GS40: 0.004 | GT40: 0.008 | GU40: 0 | GV40: 0.287 | GW40: 0 | GX40: 0.2 | GY40: 0.079 | GZ40: 0.009 | HA40: 0.004 | HB40: 0 | HC40: 0.02 | HD40: 0.96 | HE40: 2.41 | HF40: 0.109 | HH40: 2.64 | HI40: 23 | HJ40: 0.234 | HK40: 200 | HL40: 15.2 | HM40: 653 | HN40: 21.3 | HO40: 40.1 | HP40: 17.6
...

Sheet Totales
A1: Nutriente | B1: Total | C1: Unidad
A2: Water | B2: =Ingredientes!G59 | C2: g
A3: Calcium, Ca | B3: =Ingredientes!H59 | C3: mg
A4: Fatty acids, total monounsaturated | B4: =Ingredientes!I59 | C4: g
A5: Fatty acids, total polyunsaturated | B5: =Ingredientes!J59 | C5: g
A6: Fatty acids, total trans-polyenoic | B6: =Ingredientes!K59 | C6: g
A7: MUFA 16:1 c | B7: =Ingredientes!L59 | C7: g
A8: Potassium, K | B8: =Ingredientes!M59 | C8: mg
A9: PUFA 18:2 CLAs | B9: =Ingredientes!N59 | C9: g
A10: PUFA 18:3 n-6 c,c,c | B10: =Ingredientes!O59 | C10: g
A11: PUFA 18:4 | B11: =Ingredientes!P59 | C11: g
A12: PUFA 20:2 n-6 c,c | B12: =Ingredientes!Q59 | C12: g
A13: PUFA 20:3 n-6 | B13: =Ingredientes!R59 | C13: g
A14: PUFA 20:4 | B14: =Ingredientes!S59 | C14: g
A15: Selenium, Se | B15: =Ingredientes!T59 | C15: ug
A16: SFA 10:0 | B16: =Ingredientes!U59 | C16: g
A17: SFA 15:0 | B17: =Ingredientes!V59 | C17: g
A18: SFA 16:0 | B18: =Ingredientes!W59 | C18: g
A19: SFA 18:0 | B19: =Ingredientes!X59 | C19: g
A20: SFA 20:0 | B20: =Ingredientes!Y59 | C20: g
A21: SFA 4:0 | B21: =Ingredientes!Z59 | C21: g
A22: SFA 6:0 | B22: =Ingredientes!AA59 | C22: g
A23: TFA 18:1 t | B23: =Ingredientes!AB59 | C23: g
A24: TFA 18:2 t not further defined | B24: =Ingredientes!AC59 | C24: g
A25: TFA 22:1 t | B25: =Ingredientes!AD59 | C25: g
A26: Zinc, Zn | B26: =Ingredientes!AE59 | C26: mg
A27: Carbohydrate, by difference | B27: =Ingredientes!AF59 | C27: g
A28: Niacin | B28: =Ingredientes!AG59 | C28: mg
A29: Pantothenic acid | B29: =Ingredientes!AH59 | C29: mg
A30: Thiamin | B30: =Ingredientes!AI59 | C30: mg
A31: Total fat (NLEA) | B31: =Ingredientes!AJ59 | C31: g
A32: Total lipid (fat) | B32: =Ingredientes!AK59 | C32: g
A33: Vitamin B-6 | B33: =Ingredientes!AL59 | C33: mg
A34: Vitamin E (alpha-tocopherol) | B34: =Ingredientes!AM59 | C34: mg
A35: Vitamin K (phylloquinone) | B35: =Ingredientes!AN59 | C35: ug
A36: Alanine | B36: =Ingredientes!AO59 | C36: g
A37: Arginine | B37: =Ingredientes!AP59 | C37: g
A38: Aspartic acid | B38: =Ingredientes!AQ59 | C38: g
A39: Cysteine | B39: =Ingredientes!AR59 | C39: g
A40: Glutamic acid | B40: =Ingredientes!AS59 | C40: g
...
