Workbook

Sheet Ingredientes
A1: Detalles de formulación | G1: Proximates | N1: Carbohydrates | AB1: Minerals | AO1: Vitamins and Other Components | CQ1: Lipids | FT1: Amino acids | GM1: Phytosterols | GT1: Organic acids | GX1: Oligosaccharides | HA1: Isoflavones | HF1: Nutrientes
A2: FDC ID | B2: Ingrediente | C2: Marca / Origen | D2: Tipo de dato | E2: Cantidad (g) | F2: Cantidad (%) | G2: Water (g) | H2: Energy (kcal) | I2: Protein (g) | J2: Total fat (NLEA) (g) | K2: Total lipid (fat) (g) | L2: Ash (g) | M2: Carbohydrate, by difference (g) | N2: Fiber, total dietary (g) | O2: Total dietary fiber (AOAC 2011.25) (g) | P2: High Molecular Weight Dietary Fiber (HMWDF) (g) | Q2: Low Molecular Weight Dietary Fiber (LMWDF) (g) | R2: Sugars, Total (g) | S2: Sucrose (g) | T2: Glucose (g) | U2: Fructose (g) | V2: Lactose (g) | W2: Maltose (g) | X2: Galactose (g) | Y2: Starch (g) | Z2: Resistant starch (g) | AA2: Sugars, added (g) | AB2: Calcium, Ca (mg) | AC2: Iron, Fe (mg) | AD2: Magnesium, Mg (mg) | AE2: Phosphorus, P (mg) | AF2: Potassium, K (mg) | AG2: Sodium, Na (mg) | AH2: Zinc, Zn (mg) | AI2: Copper, Cu (mg) | AJ2: Manganese, Mn (mg) | AK2: Iodine, I (μg) | AL2: Selenium, Se (μg) | AM2: Molybdenum, Mo (μg) | AN2: Fluoride, F (μg) | AO2: Thiamin (mg) | AP2: Riboflavin (mg) | AQ2: Niacin (mg) | AR2: Vitamin B-6 (mg) | AS2: Folate, total (μg) | AT2: Folic acid (μg) | AU2: Folate, DFE (μg) | AV2: Choline, total (mg) | AW2: Vitamin B-12 (μg) | AX2: Vitamin A, RAE (μg) | AY2: Vitamin A, IU (iu) | AZ2: Vitamin D (D2 + D3) (μg) | BA2: Vitamin K (phylloquinone) (μg) | BB2: Vitamin E (alpha-tocopherol) (mg) | BC2: Vitamin C, total ascorbic acid (mg) | BD2: Pantothenic acid (mg) | BE2: Biotin (μg) | BF2: Caffeine (mg) | BG2: Theobromine (mg) | BH2: Retinol (μg) | BI2: Carotene, beta (μg) | BJ2: cis-beta-Carotene (μg) | BK2: trans-beta-Carotene (μg) | BL2: Carotene, alpha (μg) | BM2: Vitamin D (D2 + D3), International Units (iu) | BN2: Vitamin D2 (ergocalciferol) (μg) | BO2: Vitamin D3 (cholecalciferol) (μg) | BP2: Carotene, gamma (μg) | BQ2: Vitamin A (mg) | BR2: Lycopene (μg) | BS2: cis-Lycopene (μg) | BT2: trans-Lycopene (μg) | BU2: Lutein + zeaxanthin (μg) | BV2: Lutein (μg) | BW2: Zeaxanthin (μg) | BX2: cis-Lutein/Zeaxanthin (μg) | BY2: Tocopherol, beta (mg) | BZ2: Tocopherol, gamma (mg) | CA2: Tocopherol, delta (mg) | CB2: Tocotrienol, alpha (mg) | CC2: Tocotrienol, beta (mg) | CD2: Tocotrienol, gamma (mg) | CE2: Tocotrienol, delta (mg) | CF2: Vitamin K (Menaquinone-4) (μg) | CG2: Vitamin K (Dihydrophylloquinone) (μg) | CH2: Folate, food (μg) | CI2: Choline, free (mg) | CJ2: Choline, from phosphocholine (mg) | CK2: Choline, from phosphatidyl choline (mg) | CL2: Choline, from glycerophosphocholine (mg) | CM2: Betaine (mg) | CN2: Choline, from sphingomyelin (mg) | CO2: Vitamin E, added (mg) | CP2: Vitamin B-12, added (μg) | CQ2: Fatty acids, total saturated (g) | CR2: Fatty acids, total monounsaturated (g) | CS2: Fatty acids, total polyunsaturated (g) | CT2: Fatty acids, total trans (g) | CU2: Cholesterol (mg) | CV2: SFA 4:0 (g) | CW2: SFA 6:0 (g) | CX2: SFA 8:0 (g) | CY2: SFA 10:0 (g) | CZ2: SFA 12:0 (g) | DA2: SFA 14:0 (g) | DB2: SFA 16:0 (g) | DC2: SFA 18:0 (g) | DD2: SFA 20:0 (g) | DE2: MUFA 18:1 (g) | DF2: PUFA 18:2 (g) | DG2: PUFA 18:3 (g) | DH2: PUFA 20:4 (g) | DI2: PUFA 22:6 n-3 (DHA) (g) | DJ2: SFA 22:0 (g) | DK2: MUFA 14:1 (g) | DL2: MUFA 16:1 (g) | DM2: PUFA 18:4 (g) | DN2: MUFA 20:1 (g) | DO2: PUFA 20:5 n-3 (EPA) (g) | DP2: MUFA 22:1 (g) | DQ2: PUFA 22:5 n-3 (DPA) (g) | DR2: SFA 5:0 (g) | DS2: SFA 7:0 (g) | DT2: SFA 9:0 (g) | DU2: MUFA 12:1 (g) | DV2: SFA 15:0 (g) | DW2: SFA 17:0 (g) | DX2: SFA 24:0 (g) | DY2: TFA 16:1 t (g) | DZ2: TFA 18:1 t (g) | EA2: TFA 22:1 t (g) | EB2: TFA 18:2 t not further defined (g) | EC2: TFA 18:2 t,t (g) | ED2: PUFA 18:2 CLAs (g) | EE2: MUFA 24:1 c (g) | EF2: PUFA 20:2 n-6 c,c (g) | EG2: MUFA 16:1 c (g) | EH2: MUFA 18:1 c (g) | EI2: PUFA 18:2 n-6 c,c (g) | EJ2: MUFA 22:1 c (g) | EK2: MUFA 22:1 n-9 (g) | EL2: MUFA 22:1 n-11 (g) | EM2: SFA 21:0 (g) | EN2: SFA 23:0 (g) | EO2: PUFA 22:3 (g) | EP2: PUFA 18:3 n-6 c,c,c (g) | EQ2: MUFA 17:1 (g) | ER2: PUFA 20:3 (g) | ES2: Fatty acids, total trans-monoenoic (g) | ET2: Fatty acids, total trans-dienoic (g) | EU2: Fatty acids, total trans-polyenoic (g) | EV2: SFA 13:0 (g) | EW2: MUFA 15:1 (g) | EX2: PUFA 22:2 (g) | EY2: SFA 11:0 (g) | EZ2: TFA 14:1 t (g) | FA2: MUFA 14:1 c (g) | FB2: MUFA 17:1 c (g) | FC2: MUFA 20:1 c (g) | FD2: TFA 20:1 t (g) | FE2: PUFA 18:2 c (g) | FF2: TFA 18:2 t (g) | FG2: PUFA 18:3 c (g) | FH2: TFA 18:3 t (g) | FI2: PUFA 20:3 c (g) | FJ2: PUFA 20:4c (g) | FK2: PUFA 20:5c (g) | FL2: PUFA 22:5 c (g) | FM2: PUFA 22:6 c (g) | FN2: PUFA 20:2 c (g) | FO2: PUFA 18:3 n-3 c,c,c (ALA) (g) | FP2: PUFA 20:3 n-3 (g) | FQ2: PUFA 20:3 n-6 (g) | FR2: PUFA 22:4 (g) | FS2: PUFA 20:3 n-9 (g) | FT2: Tryptophan (g) | FU2: Threonine (g) | FV2: Isoleucine (g) | FW2: Leucine (g) | FX2: Lysine (g) | FY2: Methionine (g) | FZ2: Phenylalanine (g) | GA2: Tyrosine (g) | GB2: Valine (g) | GC2: Arginine (g) | GD2: Histidine (g) | GE2: Alanine (g) | GF2: Aspartic acid (g) | GG2: Glutamic acid (g) | GH2: Glycine (g) | GI2: Proline (g) | GJ2: Serine (g) | GK2: Hydroxyproline (g) | GL2: Cysteine (g) | GM2: Phytosterols (mg) | GN2: Beta-sitosterol (mg) | GO2: Campesterol (mg) | GP2: Stigmasterol (mg) | GQ2: Brassicasterol (mg) | GR2: Delta-5-avenasterol (mg) | GS2: Phytosterols, other (mg) | GT2: Citric acid (mg) | GU2: Malic acid (mg) | GV2: Oxalic acid (mg) | GW2: Quinic acid (mg) | GX2: Verbascose (g) | GY2: Raffinose (g) | GZ2: Stachyose (g) | HA2: Daidzin (mg) | HB2: Genistin (mg) | HC2: Glycitin (mg) | HD2: Daidzein (mg) | HE2: Genistein (mg) | HF2: Alcohol, ethyl (g) | HG2: 25-hydroxycholecalciferol (μg) | HH2: Cryptoxanthin, beta (μg) | HI2: Cryptoxanthin, alpha (μg) | HJ2: Campestanol (mg) | HK2: Beta-sitostanol (mg)
A3: 748967 | B3: Eggs, Grade A, Large, egg whole | D3: Foundation | E3: 150 | F3: =E3/SUM($E$3:$E$33) -> 0.053751943 | G3: 75.8 | H3: 143.08 | I3: 12.4 | J3: 8.65 | K3: 9.96 | L3: 0.85 | M3: 0.96 | N3: 0 | R3: 0.2 | S3: 0 | T3: 0.2 | U3: 0 | V3: 0 | W3: 0 | Y3: 0 | AB3: 48 | AC3: 1.67 | AD3: 11.4 | AE3: 184 | AF3: 132 | AG3: 129 | AH3: 1.24 | AI3: 0 | AJ3: 0 | AK3: 49.1 | AL3: 31.1 | AO3: 0.077 | AP3: 0.419 | AQ3: 0 | AR3: 0.063 | AS3: 71 | AV3: 335 | AW3: 1.02 | AX3: 180 | AZ3: 2.46 | BH3: 179 | BI3: 0 | BJ3: 0 | BK3: 0 | BL3: 0 | BM3: 98.4 | BN3: 0 | BO3: 2.46 | BR3: 0 | BS3: 0 | BT3: 0 | BV3: 230 | BW3: 229 | BX3: 57 | CI3: 0.6 | CJ3: 309 | CK3: 0.2 | CL3: 0.2 | CM3: 0.3 | CN3: 25.1 | CQ3: 3.2 | CR3: 3.63 | CS3: 1.82 | CU3: 411 | DA3: 0.032 | DB3: 2.32 | DC3: 0.813 | EG3: 0.238 | EH3: 3.35 | EI3: 1.46 | EP3: 0.011 | FE3: 1.46 | FG3: 0.011 | FI3: 0.02 | FQ3: 0.02 | FT3: 0.166 | FU3: 0.594 | FV3: 0.616 | FW3: 1.05 | FX3: 0.832 | FY3: 0.418 | FZ3: 0.66 | GA3: 0.512 | GB3: 0.734 | GC3: 0.787 | GD3: 0.283 | GE3: 0.667 | GF3: 1.27 | GG3: 1.63 | GH3: 0.408 | GI3: 0.56 | GJ3: 0.919 | GK3: 0 | GL3: 0.385 | HG3: 0.56 | HH3: 13 | HI3: 13
A4: 174158 | B4: Water, bottled, generic | D4: SR Legacy | E4: 124.45483 | F4: =E4/SUM($E$3:$E$33) -> 0.044597927 | G4: 100 | H4: 0 | I4: 0 | J4: 0 | K4: 0 | L4: 0.07 | M4: 0 | N4: 0 | R4: 0 | AB4: 10 | AC4: 0 | AD4: 2 | AE4: 0 | AF4: 0 | AG4: 2 | AH4: 0 | AI4: 0.007 | AL4: 0 | AO4: 0 | AP4: 0 | AQ4: 0 | AR4: 0 | AS4: 0 | AT4: 0 | AU4: 0 | AV4: 0 | AW4: 0 | AX4: 0 | AY4: 0 | AZ4: 0 | BA4: 0 | BB4: 0 | BC4: 0 | BD4: 0 | BF4: 0 | BG4: 0 | BH4: 0 | BI4: 0 | BL4: 0 | BM4: 0 | BR4: 0 | BU4: 0 | CH4: 0 | CO4: 0 | CP4: 0 | CQ4: 0 | CR4: 0 | CS4: 0 | CT4: 0 | CU4: 0 | CV4: 0 | CW4: 0 | CX4: 0 | CY4: 0 | CZ4: 0 | DA4: 0 | DB4: 0 | DC4: 0 | DE4: 0 | DF4: 0 | DG4: 0 | DH4: 0 | DI4: 0 | DL4: 0 | DM4: 0 | DN4: 0 | DO4: 0 | DP4: 0 | DQ4: 0 | HF4: 0 | HH4: 0
A5: 171320 | B5: Spices, cinnamon, ground | D5: SR Legacy | E5: 39.666667 | F5: =E5/SUM($E$3:$E$33) -> 0.014214403 | G5: 10.6 | H5: 349.52 | I5: 3.99 | J5: 1.24 | K5: 1.24 | L5: 3.6 | M5: 80.6 | N5: 53.1 | R5: 2.17 | S5: 0.02 | T5: 1.04 | U5: 1.11 | V5: 0 | W5: 0 | X5: 0 | AB5: 1000 | AC5: 8.32 | AD5: 60 | AE5: 64 | AF5: 431 | AG5: 10 | AH5: 1.83 | AI5: 0.339 | AJ5: 17.5 | AL5: 3.1 | AO5: 0.022 | AP5: 0.041 | AQ5: 1.33 | AR5: 0.158 | AS5: 6 | AT5: 0 | AU5: 6 | AV5: 11 | AW5: 0 | AX5: 15 | AY5: 295 | AZ5: 0 | BA5: 31.2 | BB5: 2.32 | BC5: 3.8 | BD5: 0.358 | BF5: 0 | BG5: 0 | BH5: 0 | BI5: 112 | BL5: 1 | BM5: 0 | BR5: 15 | BU5: 222 | BY5: 0 | BZ5: 10.4 | CA5: 0.26 | CB5: 0 | CC5: 0 | CD5: 0 | CE5: 0 | CG5: 0 | CH5: 6 | CM5: 3.9 | CO5: 0 | CP5: 0 | CQ5: 0.345 | CR5: 0.246 | CS5: 0.068 | CT5: 0 | CU5: 0 | CV5: 0 | CW5: 0 | CX5: 0 | CY5: 0.003 | CZ5: 0.006 | DA5: 0.009 | DB5: 0.104 | DC5: 0.082 | DD5: 0 | DE5: 0.246 | DF5: 0.044 | DG5: 0.011 | DH5: 0 | DI5: 0 | DJ5: 0 | DK5: 0 | DL5: 0.001 | DM5: 0 | DN5: 0 | DO5: 0 | DP5: 0 | DQ5: 0 | DV5: 0 | DW5: 0.136 | DX5: 0 | DZ5: 0 | EE5: 0 | EF5: 0 | EH5: 0.246 | EP5: 0 | EQ5: 0 | ER5: 0 | ES5: 0 | EV5: 0 | EW5: 0 | FO5: 0.011 | FT5: 0.049 | FU5: 0.136 | FV5: 0.146 | FW5: 0.253 | FX5: 0.243 | FY5: 0.078 | FZ5: 0.146 | GA5: 0.136 | GB5: 0.224 | GC5: 0.166 | GD5: 0.117 | GE5: 0.166 | GF5: 0.438 | GG5: 0.37 | GH5: 0.195 | GI5: 0.419 | GJ5: 0.195 | GK5: 0 | GL5: 0.058 | GM5: 26 | HF5: 0 | HH5: 129
A6: 172336 | B6: Oil, canola | D6: SR Legacy | E6: 139.52984 | F6: =E6/SUM($E$3:$E$33) -> 0.05 | G6: 0 | H6: 900 | I6: 0 | J6: 100 | K6: 100 | L6: 0 | M6: 0 | N6: 0 | R6: 0 | AB6: 0 | AC6: 0 | AD6: 0 | AE6: 0 | AF6: 0 | AG6: 0 | AH6: 0 | AI6: 0 | AJ6: 0 | AL6: 0 | AO6: 0 | AP6: 0 | AQ6: 0 | AR6: 0 | AS6: 0 | AT6: 0 | AU6: 0 | AV6: 0.2 | AW6: 0 | AX6: 0 | AY6: 0 | AZ6: 0 | BA6: 71.3 | BB6: 17.5 | BC6: 0 | BD6: 0 | BF6: 0 | BG6: 0 | BH6: 0 | BI6: 0 | BL6: 0 | BM6: 0 | BR6: 0 | BU6: 0 | BY6: 0.01 | BZ6: 27.3 | CA6: 0.99 | CB6: 0.03 | CC6: 0 | CD6: 0 | CE6: 0.01 | CF6: 0 | CG6: 0 | CH6: 0 | CM6: 0 | CO6: 0 | CP6: 0 | CQ6: 7.36 | CR6: 63.3 | CS6: 28.1 | CT6: 0.395 | CU6: 0 | CV6: 0 | CW6: 0 | CX6: 0 | CY6: 0 | CZ6: 0 | DA6: 0 | DB6: 4.3 | DC6: 2.09 | DD6: 0.65 | DE6: 61.7 | DF6: 19 | DG6: 9.14 | DH6: 0 | DI6: 0 | DJ6: 0.33 | DK6: 0 | DL6: 0.214 | DM6: 0 | DN6: 1.32 | DO6: 0 | DP6: 0 | DQ6: 0 | DV6: 0 | DW6: 0 | DZ6: 0.03 | EC6: 0.365 | EF6: 0 | EH6: 61.7 | EI6: 18.6 | EP6: 0 | EQ6: 0 | ER6: 0 | ES6: 0.03 | EU6: 0.365 | EW6: 0 | FO6: 9.14 | GN6: 413 | GO6: 241 | GP6: 3 | HF6: 0 | HH6: 0
A7: 748366 | B7: Oil, soybean | D7: Foundation | E7: 4.7867244 | F7: =E7/SUM($E$3:$E$33) -> 0.0017153049 | H7: 851.4 | J7: 94.6 | K7: 94.6 | BB7: 12.2 | BY7: 1.8 | BZ7: 70.4 | CA7: 22 | CB7: 0 | CC7: 1.6 | CD7: 0 | CE7: 0 | CQ7: 14.9 | CR7: 22.1 | CS7: 57.6 | DA7: 0.075 | DB7: 10.3 | DC7: 3.71 | DD7: 0.294 | DJ7: 0.306 | DV7: 0.014 | DW7: 0.086 | DX7: 0.124 | EG7: 0.08 | EH7: 21.4 | EI7: 50.9 | EM7: 0.025 | FC7: 0.6 | FE7: 50.9 | FG7: 6.62 | FI7: 0 | FO7: 6.62 | FQ7: 0 | GN7: 153 | GO7: 58 | GP7: 55.4 | GQ7: 0 | GR7: 10.5 | GS7: 20.8 | HJ7: 2.15 | HK7: 5.62
A8: 173468 | B8: Salt, table | D8: SR Legacy | E8: 3.1301472 | F8: =E8/SUM($E$3:$E$33) -> 0.0011216766 | G8: 0.2 | H8: 0 | I8: 0 | J8: 0 | K8: 0 | L8: 99.8 | M8: 0 | N8: 0 | R8: 0 | AB8: 24 | AC8: 0.33 | AD8: 1 | AE8: 0 | AF8: 8 | AG8: 38800 | AH8: 0.1 | AI8: 0.03 | AJ8: 0.1 | AL8: 0.1 | AN8: 2 | AO8: 0 | AP8: 0 | AQ8: 0 | AR8: 0 | AS8: 0 | AT8: 0 | AU8: 0 | AV8: 0 | AW8: 0 | AX8: 0 | AY8: 0 | AZ8: 0 | BA8: 0 | BB8: 0 | BC8: 0 | BD8: 0 | BF8: 0 | BG8: 0 | BH8: 0 | BI8: 0 | BL8: 0 | BM8: 0 | BR8: 0 | BU8: 0 | CH8: 0 | CO8: 0 | CP8: 0 | CQ8: 0 | CR8: 0 | CS8: 0 | CT8: 0 | CU8: 0 | CV8: 0 | CW8: 0 | CX8: 0 | CY8: 0 | CZ8: 0 | DA8: 0 | DB8: 0 | DC8: 0 | DE8: 0 | DF8: 0 | DG8: 0 | DH8: 0 | DI8: 0 | DL8: 0 | DM8: 0 | DN8: 0 | DO8: 0 | DP8: 0 | DQ8: 0 | FT8: 0 | FU8: 0 | FV8: 0 | FW8: 0 | FX8: 0 | FY8: 0 | FZ8: 0 | GA8: 0 | GB8: 0 | GC8: 0 | GD8: 0 | GE8: 0 | GF8: 0 | GG8: 0 | GH8: 0 | GI8: 0 | GJ8: 0 | GL8: 0 | GM8: 0 | HF8: 0 | HH8: 0
A9: 2644283 | B9: Lentils, dry | D9: Foundation | E9: 31.400912 | F9: =E9/SUM($E$3:$E$33) -> 0.0112524 | G9: 9.45 | H9: 360.48 | I9: 23.6 | J9: 1.92 | K9: 1.92 | L9: 2.88 | M9: 62.2 | Y9: 37.1 | Z9: 16 | AB9: 61.8 | AC9: 7.16 | AD9: 107 | AE9: 374 | AF9: 949 | AG9: 0 | AH9: 3.86 | AI9: 0.838 | AJ9: 1.57
A10: 2707920 | B10: Cookie, chocolate sandwich | D10: Survey (FNDDS) | E10: 95.734487 | F10: =E10/SUM($E$3:$E$33) -> 0.034306098 | G10: 3.11 | H10: 476.74 | I10: 5.21 | J10: 19.1 | K10: 19.1 | M10: 71 | N10: 2.9 | R10: 40.7 | AB10: 21 | AC10: 12.1 | AD10: 47 | AE10: 93 | AF10: 234 | AG10: 388 | AH10: 0.74 | AI10: 0.334 | AL10: 5.2 | AO10: 0.197 | AP10: 0.238 | AQ10: 2.6 | AR10: 0.023 | AS10: 61 | AT10: 58 | AU10: 102 | AV10: 19.2 | AW10: 0 | AX10: 1 | AZ10: 0 | BA10: 27.4 | BB10: 2.47 | BC10: 0 | BF10: 5 | BG10: 184 | BH10: 0 | BI10: 0 | BL10: 0 | BR10: 0 | BU10: 4 | CH10: 3 | CO10: 0 | CP10: 0 | CQ10: 5.65 | CR10: 9.28 | CS10: 3.56 | CU10: 0 | CV10: 0 | CW10: 0 | CX10: 0.003 | CY10: 0.011 | CZ10: 0.045 | DA10: 0.111 | DB10: 4.45 | DC10: 0.857 | DE10: 9.11 | DF10: 3.25 | DG10: 0.298 | DH10: 0.004 | DI10: 0 | DL10: 0.036 | DM10: 0 | DN10: 0.12 | DO10: 0 | DP10: 0.003 | DQ10: 0 | HF10: 0 | HH10: 0
A11: 746782 | B11: Milk, whole, 3.25% milkfat, with added vitamin D | D11: Foundation | E11: 95.734487 | F11: =E11/SUM($E$3:$E$33) -> 0.034306098 | G11: 88.1 | H11: 60.4 | I11: 3.27 | J11: 2.77 | K11: 3.2 | L11: 0.8 | M11: 4.63 | R11: 4.81 | S11: 0 | T11: 0 | U11: 0 | V11: 4.81 | W11: 0 | X11: 0 | AB11: 123 | AC11: 0 | AD11: 11.9 | AE11: 101 | AF11: 150 | AG11: 38 | AH11: 0.42 | AI11: 0.001 | AJ11: 0 | AK11: 37.9 | AL11: 1.9 | AO11: 0.056 | AP11: 0.138 | AQ11: 0.105 | AR11: 0.061 | AS11: 0 | AV11: 17.8 | AW11: 0.54 | AX11: 32 | AZ11: 0.96 | BB11: 0.05 | BD11: 0.362 | BH11: 31 | BI11: 7 | BJ11: 2 | BK11: 5 | BL11: 0 | BM11: 38.4 | BN11: 0 | BO11: 0.96 | BR11: 0 | BS11: 0 | BT11: 0 | BV11: 5 | BW11: 1 | BX11: 0 | BY11: 0 | BZ11: 0 | CA11: 0 | CB11: 0 | CC11: 0 | CD11: 0 | CE11: 0 | CI11: 3 | CJ11: 1.3 | CK11: 1.8 | CL11: 10.3 | CM11: 0.7 | CN11: 1.4 | CQ11: 1.86 | CR11: 0.688 | CS11: 0.108 | CT11: 0.112 | CU11: 12 | CV11: 0.067 | CW11: 0.054 | CX11: 0.034 | CY11: 0.084 | CZ11: 0.097 | DA11: 0.303 | DB11: 0.857 | DC11: 0.309 | DD11: 0.004 | DH11: 0.004 | DI11: 0 | DJ11: 0.002 | DM11: 0 | DO11: 0.001 | DQ11: 0.002 | DR11: 0 | DS11: 0 | DT11: 0 | DU11: 0.001 | DV11: 0.032 | DW11: 0.018 | DX11: 0.001 | DY11: 0.008 | DZ11: 0.082 | EA11: 0 | EB11: 0.018 | ED11: 0.013 | EE11: 0 | EF11: 0.001 | EG11: 0.039 | EH11: 0.612 | EI11: 0.084 | EJ11: 0 | EK11: 0 | EL11: 0 | EM11: 0 | EN11: 0 | EO11: 0 | EP11: 0.001 | EQ11: 0.005 | ES11: 0.095 | ET11: 0.018 | EU11: 0 | EW11: 0 | EX11: 0 | EY11: 0 | EZ11: 0.005 | FA11: 0.024 | FB11: 0.005 | FC11: 0.004 | FD11: 0 | FE11: 0.097 | FG11: 0.013 | FH11: 0 | FI11: 0.004 | FJ11: 0.004 | FK11: 0.001 | FL11: 0.002 | FM11: 0 | FN11: 0.001 | FO11: 0.012 | FP11: 0 | FQ11: 0.004 | FR11: 0.001 | FS11: 0 | FT11: 0.043 | FU11: 0.154 | FV11: 0.173 | FW11: 0.333 | FX11: 0.298 | FY11: 0.09 | FZ11: 0.161 | GA11: 0.162 | GB11: 0.207 | GC11: 0.127 | GD11: 0.097 | GE11: 0.11 | GF11: 0.279 | GG11: 0.788 | GH11: 0.069 | GI11: 0.333 | GJ11: 0.188 | GK11: 0 | GL11: 0.038 | HG11: 0 | HH11: 0 | HI11: 0
A12: 2720960 | B12: Pringles Crisps Bbq 16.9oz | C12: Kellogg Company US | D12: Branded | E12: 95.734487 | F12: =E12/SUM($E$3:$E$33) -> 0.034306098 | G12: 4.3 | H12: 529.2 | I12: 4.5 | J12: 31.2 | K12: 31.2 | M12: 57.6 | N12: 2.4 | R12: 4.3 | AA12: 3.2 | AB12: 9.7 | AC12: 0.6 | AF12: 412 | AG12: 482 | AZ12: 0 | CQ12: 8.6 | CT12: 0 | CU12: 0
A13: 2257045 | B13: Almond milk, unsweetened, plain, refrigerated | D13: Foundation | E13: 95.734487 | F13: =E13/SUM($E$3:$E$33) -> 0.034306098 | G13: 96.5 | H13: 19.348 | I13: 0.656 | J13: 1.56 | K13: 1.56 | L13: 0.595 | M13: 0.671 | N13: 0 | S13: 0.0386 | T13: 0 | U13: 0 | V13: 0 | W13: 0 | X13: 0 | AB13: 158 | AC13: 0.125 | AD13: 8.25 | AE13: 19.1 | AF13: 49.3 | AG13: 59.2 | AH13: 0.0766 | AI13: 0.0269 | AJ13: 0.0564 | AO13: 0.005 | AP13: 0.0833 | AQ13: 0.0888 | AR13: 0 | AS13: 0 | AW13: 0.449 | AZ13: 1.59 | BA13: 0 | BE13: 1.42 | BH13: 60.9 | BM13: 63.6 | BN13: 1.58 | BO13: 0.0102 | BQ13: 0 | CF13: 0 | CG13: 0 | FT13: 0.00125 | FU13: 0.01 | FV13: 0.0262 | FW13: 0.0462 | FX13: 0.0312 | FY13: 0.00125 | FZ13: 0.0425 | GA13: 0.0188 | GB13: 0.0175 | GC13: 0.0925 | GD13: 0.0138 | GE13: 0.0288 | GF13: 0.0775 | GG13: 0.138 | GH13: 0.045 | GI13: 0.0312 | GJ13: 0.02 | GK13: 0 | GL13: 0.00125
A14: 1999631 | B14: Almond milk, unsweetened, plain, shelf stable | D14: Foundation | E14: 95.734487 | F14: =E14/SUM($E$3:$E$33) -> 0.034306098 | G14: 97.4 | H14: 14.548 | I14: 0.555 | J14: 1.11 | K14: 1.22 | L14: 0.487 | M14: 0.337 | N14: 0 | R14: 0 | S14: 0 | T14: 0 | U14: 0 | V14: 0 | W14: 0 | X14: 0 | AB14: 173 | AC14: 0.29 | AD14: 6.78 | AE14: 29.8 | AF14: 30.8 | AG14: 59.6 | AH14: 0.172 | AI14: 0.0213 | AJ14: 0.045 | AK14: 0 | AL14: 0 | AM14: 0 | AO14: 0 | AP14: 0.0334 | AQ14: 0.0744 | AR14: 0 | AS14: 0 | AW14: 0.338 | AX14: 41.4 | AZ14: 0.927 | BB14: 3.32 | BE14: 1.02 | BH14: 41.4 | BM14: 37.1 | BN14: 0.927 | BO14: 0 | BY14: 0 | BZ14: 0.0275 | CA14: 0 | CB14: 0 | CC14: 0 | CD14: 0 | CE14: 0 | CQ14: 0.104 | CR14: 0.729 | CS14: 0.276 | CT14: 0 | CV14: 0.00369 | CW14: 0 | CX14: 0 | CY14: 0 | CZ14: 0 | DA14: 0.00238 | DB14: 0.0778 | DC14: 0.0195 | DD14: 0 | DH14: 0 | DI14: 0 | DJ14: 0 | DM14: 0 | DO14: 0 | DQ14: 0 | DR14: 0 | DS14: 0 | DT14: 0 | DU14: 0 | DV14: 0.00125 | DW14: 0.000875 | DX14: 0 | DY14: 0 | DZ14: 0 | EA14: 0 | EB14: 0.000125 | ED14: 0 | EE14: 0 | EF14: 0 | EG14: 0.00581 | EH14: 0.721 | EI14: 0.276 | EJ14: 0 | EK14: 0 | EL14: 0 | EM14: 0 | EN14: 0 | EO14: 0 | EP14: 0 | EQ14: 0.00125 | ES14: 0 | EU14: 0 | EW14: 0 | EX14: 0 | EY14: 0 | EZ14: 0 | FA14: 0 | FB14: 0.00125 | FC14: 0.000875 | FD14: 0 | FE14: 0.276 | FF14: 0.000125 | FG14: 0.000625 | FH14: 0 | FI14: 0 | FJ14: 0 | FK14: 0 | FL14: 0 | FM14: 0 | FN14: 0 | FO14: 0.000625 | FP14: 0 | FQ14: 0 | FR14: 0 | FS14: 0 | GX14: 0 | GY14: 0.00788 | GZ14: 0.0075
A15: 2259796 | B15: Cheese, feta, whole milk, crumbled | D15: Foundation | E15: 95.734487 | F15: =E15/SUM($E$3:$E$33) -> 0.034306098 | G15: 51.9 | H15: 273.02 | I15: 19.7 | J15: 19.1 | K15: 19.1 | L15: 3.74 | M15: 5.58 | R15: 1.63 | S15: 0 | T15: 0.586 | U15: 0 | V15: 0.61 | W15: 0 | X15: 0.429 | AB15: 371 | AC15: 0.0675 | AD15: 17.7 | AE15: 328 | AF15: 105 | AG15: 1030 | AH15: 2.35 | AI15: 0.0316 | AJ15: 0.02 | AK15: 48.4 | AO15: 0.0564 | AP15: 0.444 | AQ15: 0.264 | AR15: 0.0383 | AZ15: 0 | BA15: 1.2 | BE15: 0.464 | BH15: 147 | BM15: 0 | BN15: 0 | BO15: 0 | BQ15: 0 | CF15: 4.8 | CG15: 0 | CQ15: 11.2 | CR15: 4.18 | CU15: 57.5 | CV15: 0.404 | CW15: 0.334 | CY15: 0.481 | CZ15: 0.545 | DA15: 1.8 | DB15: 5.31 | DC15: 1.74 | EG15: 0.285 | EH15: 3.66 | EI15: 0.424
A16: 746766 | B16: Cheese, ricotta, whole milk | D16: Foundation | E16: 95.734487 | F16: =E16/SUM($E$3:$E$33) -> 0.034306098 | G16: 72.9 | H16: 157.68 | I16: 7.81 | J16: 10.3 | K16: 11 | L16: 1.36 | M16: 6.86 | AB16: 224 | AC16: 0.1 | AD16: 19.7 | AE16: 162 | AF16: 230 | AG16: 105 | AH16: 0.56 | AI16: 0 | AJ16: 0 | AL16: 5.5 | AO16: 0.043 | AP16: 0.327 | AQ16: 0.168 | AR16: 0.099 | AS16: 4 | AW16: 0.78 | AX16: 127 | BA16: 0.6 | BB16: 0.27 | BD16: 0.673 | BH16: 127 | BY16: 0 | BZ16: 0 | CA16: 0 | CB16: 0 | CC16: 0 | CD16: 0 | CE16: 0 | CF16: 3.1 | CG16: 0 | CQ16: 6.97 | CR16: 2.56 | CS16: 0.389 | CT16: 0.351 | CU16: 48 | CV16: 0.251 | CW16: 0.199 | CX16: 0.125 | CY16: 0.306 | CZ16: 0.36 | DA16: 1.15 | DB16: 3.36 | DC16: 1.02 | DD16: 0.014 | DH16: 0.015 | DI16: 0 | DJ16: 0.006 | DM16: 0.001 | DO16: 0.005 | DQ16: 0.007 | DV16: 0.116 | DW16: 0.067 | DX16: 0.004 | DY16: 0.032 | DZ16: 0.251 | EA16: 0 | EB16: 0.068 | ED16: 0.049 | EE16: 0 | EF16: 0.001 | EG16: 0.184 | EH16: 2.22 | EI16: 0.259 | EJ16: 0.002 | EK16: 0.002 | EP16: 0 | EQ16: 0.021 | ES16: 0.283 | ET16: 0.068 | EU16: 0.001 | EW16: 0 | EX16: 0 | EY16: 0 | FA16: 0.117 | FB16: 0.021 | FC16: 0.02 | FE16: 0.308 | FG16: 0.042 | FH16: 0.001 | FI16: 0.012 | FJ16: 0.015 | FK16: 0.005 | FL16: 0.007 | FM16: 0 | FN16: 0.001 | FO16: 0.042 | FP16: 0 | FQ16: 0.012 | FR16: 0.003 | FS16: 0 | FT16: 0.115 | FU16: 0.395 | FV16: 0.365 | FW16: 0.785 | FX16: 0.655 | FY16: 0.17 | FZ16: 0.27 | GA16: 0.25 | GB16: 0.325 | GC16: 0.21 | GD16: 0.175 | GE16: 0.325 | GF16: 0.735 | GG16: 1.3 | GH16: 0.135 | GI16: 0.565 | GJ16: 0.365 | GK16: 0 | GL16: 0.18
A17: 746772 | B17: Milk, lowfat, fluid, 1% milkfat, with added vitamin A and vitamin D | D17: Foundation | E17: 95.734487 | F17: =E17/SUM($E$3:$E$33) -> 0.034306098 | G17: 89.7 | H17: 42.79 | I17: 3.38 | J17: 0.85 | K17: 0.95 | L17: 0.8 | M17: 5.18 | R17: 4.96 | S17: 0 | T17: 0 | U17: 0 | V17: 4.96 | W17: 0 | X17: 0 | AB17: 126 | AC17: 0 | AD17: 12 | AE17: 103 | AF17: 159 | AG17: 39 | AH17: 0.43 | AI17: 0.001 | AJ17: 0 | AK17: 36.2 | AL17: 2.1 | AO17: 0.057 | AP17: 0.14 | AQ17: 0.113 | AR17: 0.06 | AS17: 2 | AV17: 17.4 | AW17: 0.61 | AX17: 58 | AZ17: 1.06 | BB17: 0.02 | BD17: 0.368 | BH17: 58 | BI17: 1 | BJ17: 0 | BK17: 1 | BL17: 0 | BM17: 42.4 | BN17: 0 | BO17: 1.06 | BR17: 0 | BS17: 0 | BT17: 0 | BV17: 0 | BW17: 0 | BX17: 0 | BY17: 0 | BZ17: 0 | CA17: 0 | CB17: 0 | CC17: 0 | CD17: 0 | CE17: 0 | CI17: 3 | CJ17: 0.9 | CK17: 1.8 | CL17: 10.9 | CM17: 0.9 | CN17: 0.8 | CQ17: 0.568 | CR17: 0.21 | CS17: 0.032 | CT17: 0.036 | CU17: 5 | CV17: 0.022 | CW17: 0.015 | CX17: 0.011 | CY17: 0.023 | CZ17: 0.026 | DA17: 0.093 | DB17: 0.265 | DC17: 0.096 | DD17: 0.001 | DH17: 0.001 | DI17: 0 | DJ17: 0 | DM17: 0 | DO17: 0 | DQ17: 0 | DR17: 0 | DS17: 0 | DT17: 0 | DU17: 0 | DV17: 0.01 | DW17: 0.006 | DX17: 0 | DY17: 0.002 | DZ17: 0.027 | EA17: 0 | EB17: 0.004 | ED17: 0.004 | EE17: 0 | EF17: 0 | EG17: 0.012 | EH17: 0.187 | EI17: 0.026 | EJ17: 0 | EK17: 0 | EL17: 0 | EM17: 0 | EN17: 0 | EO17: 0 | EP17: 0 | EQ17: 0.002 | ES17: 0.031 | ET17: 0.004 | EU17: 0 | EW17: 0 | EX17: 0 | EY17: 0 | EZ17: 0.001 | FA17: 0.007 | FB17: 0.002 | FC17: 0.001 | FD17: 0 | FE17: 0.029 | FG17: 0.004 | FH17: 0 | FI17: 0.001 | FJ17: 0.001 | FK17: 0 | FL17: 0 | FM17: 0 | FN17: 0 | FO17: 0.004 | FP17: 0 | FQ17: 0.001 | FR17: 0 | FS17: 0 | FT17: 0.045 | FU17: 0.158 | FV17: 0.174 | FW17: 0.342 | FX17: 0.308 | FY17: 0.092 | FZ17: 0.168 | GA17: 0.167 | GB17: 0.21 | GC17: 0.128 | GD17: 0.099 | GE17: 0.111 | GF17: 0.286 | GG17: 0.809 | GH17: 0.069 | GI17: 0.349 | GJ17: 0.194 | GK17: 0 | GL17: 0.036 | HG17: 0 | HH17: 0 | HI17: 0
A18: 746776 | B18: Milk, nonfat, fluid, with added vitamin A and vitamin D (fat free or skim) | D18: Foundation | E18: 95.734487 | F18: =E18/SUM($E$3:$E$33) -> 0.034306098 | G18: 90.8 | H18: 34.12 | I18: 3.43 | J18: 0.07 | K18: 0.08 | L18: 0.77 | M18: 4.92 | R18: 5.05 | S18: 0 | T18: 0 | U18: 0 | V18: 5.05 | W18: 0 | X18: 0 | AB18: 132 | AC18: 0 | AD18: 12.5 | AE18: 107 | AF18: 167 | AG18: 41 | AH18: 0.45 | AI18: 0.002 | AJ18: 0.001 | AK18: 35.7 | AL18: 2 | AO18: 0.056 | AP18: 0.131 | AQ18: 0.118 | AR18: 0.058 | AS18: 2 | AV18: 18.2 | AW18: 0.58 | AX18: 64 | AZ18: 1.1 | BB18: 0 | BD18: 0.388 | BH18: 64 | BI18: 2 | BJ18: 1 | BK18: 1 | BL18: 0 | BM18: 44 | BN18: 0 | BO18: 1.1 | BR18: 0 | BS18: 0 | BT18: 0 | BV18: 1 | BW18: 0 | BX18: 0 | BY18: 0 | BZ18: 0 | CA18: 0 | CB18: 0 | CC18: 0 | CD18: 0 | CE18: 0 | CI18: 3.1 | CJ18: 0.8 | CK18: 2 | CL18: 11.5 | CM18: 0.9 | CN18: 0.9 | CQ18: 0.049 | CR18: 0.017 | CS18: 0.006 | CT18: 0 | CU18: 3 | CV18: 0.003 | CW18: 0.001 | CX18: 0.001 | CY18: 0.002 | CZ18: 0.002 | DA18: 0.008 | DB18: 0.021 | DC18: 0.009 | DD18: 0 | DH18: 0 | DI18: 0 | DJ18: 0 | DM18: 0 | DO18: 0 | DQ18: 0 | DR18: 0 | DS18: 0 | DT18: 0 | DU18: 0 | DV18: 0.001 | DW18: 0.001 | DX18: 0 | DY18: 0 | DZ18: 0.001 | EA18: 0 | EB18: 0 | ED18: 0 | EE18: 0 | EF18: 0 | EG18: 0.001 | EH18: 0.017 | EI18: 0.005 | EJ18: 0 | EK18: 0 | EL18: 0 | EM18: 0 | EN18: 0 | EO18: 0 | EP18: 0 | EQ18: 0 | ES18: 0.001 | ET18: 0 | EU18: 0 | EW18: 0 | EX18: 0 | EY18: 0 | EZ18: 0 | FA18: 0 | FB18: 0 | FC18: 0 | FD18: 0 | FE18: 0.005 | FG18: 0 | FH18: 0 | FI18: 0 | FJ18: 0 | FK18: 0 | FL18: 0 | FM18: 0 | FN18: 0 | FO18: 0 | FP18: 0 | FQ18: 0 | FR18: 0 | FS18: 0 | FT18: 0.048 | FU18: 0.166 | FV18: 0.182 | FW18: 0.347 | FX18: 0.302 | FY18: 0.093 | FZ18: 0.168 | GA18: 0.168 | GB18: 0.222 | GC18: 0.131 | GD18: 0.101 | GE18: 0.118 | GF18: 0.299 | GG18: 0.832 | GH18: 0.071 | GI18: 0.348 | GJ18: 0.202 | GK18: 0 | GL18: 0.038 | HG18: 0 | HH18: 0 | HI18: 0
A19: 746778 | B19: Milk, reduced fat, fluid, 2% milkfat, with added vitamin A and vitamin D | D19: Foundation | E19: 95.734487 | F19: =E19/SUM($E$3:$E$33) -> 0.034306098 | G19: 89.1 | H19: 50.14 | I19: 3.36 | J19: 1.64 | K19: 1.9 | L19: 0.75 | M19: 4.9 | R19: 4.89 | S19: 0 | T19: 0 | U19: 0 | V19: 4.89 | W19: 0 | X19: 0 | AB19: 126 | AC19: 0 | AD19: 12 | AE19: 103 | AF19: 159 | AG19: 39 | AH19: 0.43 | AI19: 0.001 | AJ19: 0.001 | AK19: 39.6 | AL19: 1.8 | AO19: 0.059 | AP19: 0.137 | AQ19: 0.112 | AR19: 0.061 | AS19: 2 | AV19: 18.2 | AW19: 0.55 | AX19: 83 | AZ19: 1.13 | BB19: 0.03 | BD19: 0.39 | BH19: 83 | BI19: 3 | BJ19: 1 | BK19: 2 | BL19: 0 | BM19: 45.2 | BN19: 0 | BO19: 1.13 | BR19: 0 | BS19: 0 | BT19: 0 | BV19: 0 | BW19: 0 | BX19: 0 | BY19: 0 | BZ19: 0 | CA19: 0 | CB19: 0 | CC19: 0 | CD19: 0 | CE19: 0 | CI19: 3.1 | CJ19: 1.1 | CK19: 1.9 | CL19: 11 | CM19: 0.7 | CN19: 1.2 | CQ19: 1.11 | CR19: 0.4 | CS19: 0.058 | CT19: 0.07 | CU19: 8 | CV19: 0.041 | CW19: 0.032 | CX19: 0.021 | CY19: 0.049 | CZ19: 0.058 | DA19: 0.181 | DB19: 0.512 | DC19: 0.184 | DD19: 0.002 | DH19: 0.003 | DI19: 0 | DJ19: 0.001 | DM19: 0 | DO19: 0 | DQ19: 0.001 | DR19: 0 | DS19: 0 | DT19: 0 | DU19: 0.001 | DV19: 0.019 | DW19: 0.011 | DX19: 0 | DY19: 0.005 | DZ19: 0.052 | EA19: 0 | EB19: 0.009 | ED19: 0.007 | EE19: 0 | EF19: 0 | EG19: 0.024 | EH19: 0.358 | EI19: 0.045 | EJ19: 0 | EK19: 0 | EL19: 0 | EM19: 0 | EN19: 0 | EO19: 0 | EP19: 0 | EQ19: 0.003 | ES19: 0.06 | ET19: 0.009 | EU19: 0 | EW19: 0 | EX19: 0 | EY19: 0 | EZ19: 0.003 | FA19: 0.014 | FB19: 0.003 | FC19: 0.002 | FD19: 0 | FE19: 0.052 | FG19: 0.007 | FH19: 0 | FI19: 0.002 | FJ19: 0.003 | FK19: 0 | FL19: 0.001 | FM19: 0 | FN19: 0 | FO19: 0.007 | FP19: 0 | FQ19: 0.002 | FR19: 0 | FS19: 0 | FT19: 0.042 | FU19: 0.162 | FV19: 0.173 | FW19: 0.335 | FX19: 0.293 | FY19: 0.089 | FZ19: 0.163 | GA19: 0.165 | GB19: 0.213 | GC19: 0.125 | GD19: 0.099 | GE19: 0.113 | GF19: 0.291 | GG19: 0.801 | GH19: 0.068 | GI19: 0.332 | GJ19: 0.197 | GK19: 0 | GL19: 0.035 | HG19: 0 | HH19: 0 | HI19: 0
A20: 2257046 | B20: Oat milk, unsweetened, plain, refrigerated | D20: Foundation | E20: 95.734487 | F20: =E20/SUM($E$3:$E$33) -> 0.034306098 | G20: 90.6 | H20: 48.338 | I20: 0.797 | J20: 2.75 | K20: 2.75 | L20: 0.794 | M20: 5.1 | N20: 0 | R20: 2.32 | S20: 0 | T20: 0.771 | U20: 0 | V20: 0 | W20: 1.55 | X20: 0 | AB20: 148 | AC20: 0.261 | AD20: 5.91 | AE20: 89.2 | AF20: 148 | AG20: 42 | AH20: 0.0906 | AI20: 0.0271 | AJ20: 0.126 | AL20: 0 | AM20: 10.1 | AO20: 0.04 | AP20: 0.281 | AQ20: 0.0962 | AR20: 0.0065 | AS20: 0 | AW20: 0.506 | AZ20: 1.7 | BA20: 0.4 | BE20: 1.41 | BH20: 84.7 | BM20: 68 | BN20: 1.69 | BO20: 0.00769 | BQ20: 0 | CF20: 0 | CG20: 0 | FT20: 0.00875 | FU20: 0.0225 | FV20: 0.025 | FW20: 0.0812 | FX20: 0.0612 | FY20: 0.01 | FZ20: 0.0725 | GA20: 0.0412 | GB20: 0.0325 | GC20: 0.0825 | GD20: 0.0175 | GE20: 0.0375 | GF20: 0.0825 | GG20: 0.15 | GH20: 0.0562 | GI20: 0.0725 | GJ20: 0.0562 | GK20: 0 | GL20: 0.025
A21: 2257044 | B21: Soy milk, sweetened, plain, refrigerated | D21: Foundation | E21: 95.734487 | F21: =E21/SUM($E$3:$E$33) -> 0.034306098 | G21: 91.5 | H21: 40.76 | I21: 2.78 | J21: 1.96 | K21: 1.96 | L21: 0.75 | M21: 3 | N21: 0 | S21: 2.58 | T21: 0 | U21: 0 | V21: 0 | W21: 0 | X21: 0 | AB21: 155 | AC21: 0.367 | AD21: 17.5 | AE21: 46 | AF21: 118 | AG21: 39.4 | AH21: 0.264 | AI21: 0.0956 | AJ21: 0.16 | AL21: 0 | AM21: 32.3 | AO21: 0.0436 | AP21: 0.331 | AQ21: 0.133 | AR21: 0.0364 | AS21: 15.8 | AW21: 1.33 | AZ21: 4.63 | BA21: 2.8 | BE21: 2.16 | BH21: 89.4 | BM21: 185 | BN21: 4.61 | BO21: 0.0201 | BQ21: 0 | CF21: 0 | CG21: 0 | FT21: 0.0343 | FU21: 0.1 | FV21: 0.1 | FW21: 0.2 | FX21: 0.2 | FY21: 0.0329 | FZ21: 0.157 | GA21: 0.1 | GB21: 0.101 | GC21: 0.2 | GD21: 0.1 | GE21: 0.1 | GF21: 0.329 | GG21: 0.486 | GH21: 0.1 | GI21: 0.114 | GJ21: 0.171 | GK21: 0 | GL21: 0.0486 | HA21: 7.96 | HB21: 14.7 | HC21: 0.364 | HD21: 0.139 | HE21: 0.236
A22: 1999630 | B22: Soy milk, unsweetened, plain, shelf stable | D22: Foundation | E22: 95.734487 | F22: =E22/SUM($E$3:$E$33) -> 0.034306098 | G22: 92.4 | H22: 38.44 | I22: 3.55 | J22: 1.88 | K22: 2.12 | L22: 0.635 | M22: 1.29 | N22: 0 | R22: 0.557 | S22: 0.557 | T22: 0 | U22: 0 | V22: 0 | W22: 0 | X22: 0 | AB22: 101 | AC22: 0.542 | AD22: 21.5 | AE22: 68.6 | AF22: 158 | AG22: 34.3 | AH22: 0.312 | AI22: 0.108 | AJ22: 0.208 | AK22: 0 | AL22: 1.94 | AM22: 58.4 | AO22: 0.0632 | AP22: 0.084 | AQ22: 0.236 | AR22: 0.0552 | AS22: 19.7 | AW22: 0.393 | AX22: 58.2 | AZ22: 0.681 | BB22: 0.156 | BE22: 3.34 | BH22: 58.2 | BI22: 0 | BJ22: 0 | BK22: 0 | BL22: 0 | BM22: 27.2 | BN22: 0.681 | BO22: 0 | BP22: 0 | BR22: 0 | BS22: 0 | BT22: 0 | BU22: 8.22 | BW22: 7.26 | BX22: 0.966 | BY22: 0 | BZ22: 1.42 | CA22: 0.874 | CB22: 0 | CC22: 0 | CD22: 0 | CE22: 0 | CQ22: 0.314 | CR22: 0.416 | CS22: 1.15 | CT22: 0 | CV22: 0 | CW22: 0 | CX22: 0 | CY22: 0 | CZ22: 0 | DA22: 0.00381 | DB22: 0.218 | DC22: 0.0728 | DD22: 0.00562 | DH22: 0 | DI22: 0 | DJ22: 0.00675 | DM22: 0 | DO22: 0 | DQ22: 0 | DR22: 0 | DS22: 0 | DT22: 0 | DU22: 0 | DV22: 0.00169 | DW22: 0.002 | DX22: 0.00231 | DY22: 0 | DZ22: 0.000812 | EA22: 0 | EB22: 0.00112 | ED22: 0 | EE22: 0 | EF22: 0.000562 | EG22: 0.00194 | EH22: 0.409 | EI22: 0.988 | EJ22: 0 | EK22: 0 | EL22: 0 | EM22: 0 | EN22: 0 | EO22: 0 | EP22: 0 | EQ22: 0.001 | ES22: 0.000812 | EU22: 0 | EW22: 0 | EX22: 0 | EY22: 0 | EZ22: 0 | FA22: 0 | FB22: 0.001 | FC22: 0.00481 | FD22: 0 | FE22: 0.988 | FF22: 0.00112 | FG22: 0.166 | FH22: 0 | FI22: 0 | FJ22: 0 | FK22: 0 | FL22: 0 | FM22: 0 | FN22: 0.000562 | FO22: 0.166 | FP22: 0 | FQ22: 0 | FR22: 0 | FS22: 0 | FT22: 0.0462 | FU22: 0.128 | FV22: 0.145 | FW22: 0.249 | FX22: 0.221 | FY22: 0.0462 | FZ22: 0.175 | GA22: 0.124 | GB22: 0.142 | GC22: 0.269 | GD22: 0.0975 | GE22: 0.139 | GF22: 0.396 | GG22: 0.619 | GH22: 0.141 | GI22: 0.137 | GJ22: 0.168 | GK22: 0 | GL22: 0.0575 | GX22: 0.0262 | GY22: 0.0665 | GZ22: 0.434 | HA22: 12.9 | HB22: 18.8 | HC22: 1.36 | HD22: 0.457 | HE22: 0.38 | HH22: 0 | HI22: 0
A23: 173532 | B23: Babyfood, cereal, mixed, with honey, prepared with whole milk | D23: SR Legacy | E23: 95.734487 | F23: =E23/SUM($E$3:$E$33) -> 0.034306098 | G23: 74.2 | H23: 116 | I23: 5 | J23: 3.6 | K23: 3.6 | L23: 1.2 | M23: 15.9 | AB23: 294 | AC23: 11.3 | AD23: 28 | AE23: 184 | AF23: 171 | AG23: 48 | AH23: 0.72 | AI23: 0.064 | AO23: 0.447 | AP23: 0.583 | AQ23: 6.26 | AR23: 0.067 | AS23: 11 | AT23: 0 | AU23: 11 | AW23: 0.3 | BD23: 0.443 | CH23: 11
A24: 173534 | B24: Babyfood, cereal, rice, with bananas, prepared with whole milk | D24: SR Legacy | E24: 95.734487 | F24: =E24/SUM($E$3:$E$33) -> 0.034306098 | G24: 81.8 | H24: 86.16 | I24: 3.57 | J24: 3.32 | K24: 3.32 | L24: 0.81 | M24: 10.5 | N24: 0.1 | R24: 6.13 | S24: 0 | T24: 0 | U24: 0 | V24: 4.67 | W24: 0 | X24: 0 | AB24: 156 | AC24: 3.63 | AD24: 20 | AE24: 109 | AF24: 180 | AG24: 47 | AH24: 0.46 | AI24: 0.042 | AJ24: 0.004 | AL24: 4.3 | AO24: 0.684 | AP24: 0.444 | AQ24: 1.85 | AR24: 0.085 | AS24: 6 | AT24: 0 | AU24: 6 | AV24: 15.2 | AW24: 0.43 | AX24: 43 | AY24: 152 | AZ24: 1.2 | BA24: 0.5 | BB24: 0.09 | BC24: 0.2 | BD24: 0.345 | BF24: 0 | BG24: 0 | BH24: 42 | BI24: 7 | BL24: 1 | BM24: 47 | BO24: 1.2 | BR24: 0 | BU24: 3 | BY24: 0 | BZ24: 0 | CA24: 0 | CB24: 0 | CC24: 0 | CD24: 0 | CE24: 0 | CF24: 0.9 | CG24: 0 | CH24: 6 | CM24: 0.6 | CO24: 0 | CP24: 0 | CQ24: 1.8 | CR24: 0.826 | CS24: 0.294 | CU24: 10 | CV24: 0.069 | CW24: 0.069 | CX24: 0.069 | CY24: 0.069 | CZ24: 0.071 | DA24: 0.276 | DB24: 0.826 | DC24: 0.345 | DD24: 0 | DE24: 0.823 | DF24: 0.209 | DG24: 0.085 | DH24: 0 | DI24: 0 | DJ24: 0 | DK24: 0 | DL24: 0.002 | DM24: 0 | DN24: 0 | DO24: 0 | DP24: 0 | DQ24: 0 | DV24: 0 | DW24: 0 | DX24: 0 | EV24: 0 | FT24: 0.079 | FU24: 0.163 | FV24: 0.184 | FW24: 0.302 | FX24: 0.161 | FY24: 0.085 | FZ24: 0.163 | GA24: 0.165 | GB24: 0.215 | GC24: 0.113 | GD24: 0.088 | GE24: 0.131 | GF24: 0.28 | GG24: 0.702 | GH24: 0.095 | GI24: 0.341 | GJ24: 0.132 | GL24: 0.029 | HF24: 0 | HH24: 0
A25: 2003591 | B25: Orange juice, no pulp, not fortified, from concentrate, refrigerated | D25: Foundation | E25: 95.734487 | F25: =E25/SUM($E$3:$E$33) -> 0.034306098 | G25: 88.2 | H25: 47.061 | I25: 0.734 | J25: 0.325 | K25: 0.325 | L25: 0.35 | M25: 10.3 | R25: 8.28 | S25: 4.39 | T25: 1.79 | U25: 2.1 | V25: 0 | W25: 0 | X25: 0 | AB25: 12.8 | AC25: 0.0646 | AD25: 10.6 | AE25: 18.2 | AF25: 180 | AG25: 5.23 | AH25: 0.0319 | AI25: 0.0322 | AJ25: 0.0299 | AO25: 0.0701 | AQ25: 0.0403 | AR25: 0.0429 | AS25: 29.8 | BC25: 26.9 | GT25: 706 | GU25: 161 | GV25: 0 | GW25: 12.3
A26: 2003597 | B26: Orange juice, no pulp, not fortified, not from concentrate, refrigerated | D26: Foundation | E26: 95.734487 | F26: =E26/SUM($E$3:$E$33) -> 0.034306098 | G26: 88.5 | H26: 46.452 | I26: 0.812 | J26: 0.356 | K26: 0.356 | L26: 0.339 | M26: 10 | R26: 8.08 | S26: 4.14 | T26: 1.81 | U26: 2.12 | V26: 0 | W26: 0 | X26: 0 | AB26: 9.29 | AC26: 0.0706 | AD26: 10.3 | AE26: 19 | AF26: 183 | AG26: 0.075 | AH26: 0.0321 | AI26: 0.0353 | AJ26: 0.0277 | AO26: 0.0746 | AQ26: 0.0291 | AR26: 0.0411 | AS26: 29 | BC26: 30.5 | GT26: 757 | GU26: 160 | GV26: 0 | GW26: 0
A27: 169102 | B27: Orange juice, frozen concentrate, unsweetened, diluted with 3 volume water | D27: SR Legacy | E27: 95.734487 | F27: =E27/SUM($E$3:$E$33) -> 0.034306098 | G27: 90.1 | H27: 38.14 | I27: 0.6 | J27: 0.06 | K27: 0.06 | L27: 0.47 | M27: 8.8 | N27: 0.2 | R27: 7.42 | AB27: 12 | AC27: 0.08 | AD27: 10 | AE27: 15 | AF27: 158 | AG27: 4 | AH27: 0.04 | AI27: 0.021 | AL27: 0.1 | AO27: 0.069 | AP27: 0.044 | AQ27: 0.273 | AR27: 0.065 | AS27: 19 | AT27: 0 | AU27: 19 | AV27: 5 | AW27: 0 | AX27: 3 | AY27: 66 | AZ27: 0 | BA27: 0.1 | BB27: 0.15 | BC27: 36.2 | BF27: 0 | BG27: 0 | BH27: 0 | BI27: 13 | BL27: 5 | BM27: 0 | BR27: 0 | BU27: 83 | CH27: 19 | CO27: 0 | CP27: 0 | CQ27: 0.015 | CR27: 0.012 | CS27: 0.016 | CT27: 0 | CU27: 0 | CV27: 0 | CW27: 0 | CX27: 0 | CY27: 0 | CZ27: 0.001 | DA27: 0.001 | DB27: 0.011 | DC27: 0.002 | DE27: 0.011 | DF27: 0.012 | DG27: 0.004 | DH27: 0 | DI27: 0 | DL27: 0.002 | DM27: 0 | DN27: 0 | DO27: 0 | DP27: 0 | DQ27: 0 | HF27: 0 | HH27: 48
A28: 168113 | B28: Frozen novelties, juice type, orange | D28: SR Legacy | E28: 95.734487 | F28: =E28/SUM($E$3:$E$33) -> 0.034306098 | G28: 76.1 | H28: 94.8 | I28: 0.5 | J28: 0 | K28: 0 | L28: 0.23 | M28: 23.2 | N28: 0.1 | R28: 20 | AB28: 9 | AC28: 0.47 | AD28: 8 | AE28: 13 | AF28: 100 | AG28: 8 | AH28: 0.02 | AI28: 0.022 | AJ28: 0.008 | AL28: 0.1 | AN28: 77 | AO28: 0.01 | AP28: 0.03 | AQ28: 0.16 | AR28: 0.018 | AS28: 18 | AT28: 0 | AU28: 18 | AV28: 2.9 | AW28: 0 | AX28: 1 | AY28: 21 | AZ28: 0 | BA28: 0.1 | BB28: 0.04 | BC28: 25.7 | BD28: 0.065 | BF28: 0 | BG28: 0 | BH28: 0 | BI28: 12 | BL28: 0 | BM28: 0 | BR28: 0 | BU28: 39 | CH28: 18 | CO28: 0 | CP28: 0 | CQ28: 0 | CR28: 0 | CS28: 0 | CU28: 0 | CV28: 0 | CW28: 0 | CX28: 0 | CY28: 0 | CZ28: 0 | DA28: 0 | DB28: 0 | DC28: 0 | DE28: 0 | DF28: 0 | DG28: 0 | DH28: 0 | DI28: 0 | DL28: 0 | DM28: 0 | DN28: 0 | DO28: 0 | DP28: 0 | DQ28: 0 | HF28: 0 | HH28: 0
A29: 171354 | B29: Babyfood, juice, orange | D29: SR Legacy | E29: 95.734487 | F29: =E29/SUM($E$3:$E$33) -> 0.034306098 | G29: 88.5 | H29: 45.9 | I29: 0.6 | J29: 0.3 | K29: 0.3 | L29: 0.4 | M29: 10.2 | N29: 0.1 | R29: 8.26 | AB29: 12 | AC29: 0.17 | AD29: 9 | AE29: 11 | AF29: 184 | AG29: 0 | AH29: 0.06 | AI29: 0.046 | AL29: 0.1 | AO29: 0.045 | AP29: 0.028 | AQ29: 0.239 | AR29: 0.054 | AS29: 26 | AT29: 0 | AU29: 26 | AV29: 6.2 | AW29: 0 | AX29: 3 | AY29: 55 | AZ29: 0 | BA29: 0.1 | BB29: 0.04 | BC29: 62.5 | BD29: 0.137 | BF29: 0 | BG29: 0 | BH29: 0 | BI29: 9 | BL29: 2 | BM29: 0 | BR29: 0 | BU29: 113 | CH29: 26 | CO29: 0 | CP29: 0 | CQ29: 0.035 | CR29: 0.05 | CS29: 0.06 | CU29: 0 | CV29: 0 | CW29: 0 | CX29: 0 | CY29: 0 | CZ29: 0 | DA29: 0 | DB29: 0.035 | DC29: 0 | DE29: 0.045 | DF29: 0.045 | DG29: 0.015 | DH29: 0 | DI29: 0 | DL29: 0.005 | DM29: 0 | DN29: 0 | DO29: 0 | DP29: 0 | DQ29: 0 | HF29: 0 | HH29: 47
A30: 1104812 | B30: Flour, rice, brown | D30: Foundation | E30: 95.734487 | F30: =E30/SUM($E$3:$E$33) -> 0.034306098 | G30: 12.1 | H30: 365.41 | I30: 7.19 | J30: 3.85 | K30: 3.85 | L30: 1.4 | M30: 75.5 | AB30: 10 | AC30: 1.5 | AD30: 124 | AE30: 319 | AF30: 265 | AG30: 1 | AH30: 1.91 | AI30: 0.286 | AJ30: 2.84 | AL30: 9.68 | AM30: 56.2 | AO30: 0.322 | AP30: 0.008 | AQ30: 5.99 | AR30: 0.132
A31: 169707 | B31: Rice, white, long-grain, parboiled, enriched, dry | D31: SR Legacy | E31: 95.734487 | F31: =E31/SUM($E$3:$E$33) -> 0.034306098 | G31: 9.86 | H31: 362.91 | I31: 7.51 | J31: 1.03 | K31: 1.03 | L31: 0.71 | M31: 80.9 | N31: 1.8 | R31: 0.33 | S31: 0.21 | T31: 0.11 | U31: 0.02 | V31: 0 | W31: 0 | X31: 0 | Y31: 68.3 | AB31: 71 | AC31: 3.33 | AD31: 27 | AE31: 153 | AF31: 174 | AG31: 2 | AH31: 1.02 | AI31: 0.284 | AJ31: 1.04 | AL31: 19.9 | AO31: 0.603 | AP31: 0.05 | AQ31: 5.05 | AR31: 0.452 | AS31: 257 | AT31: 249 | AU31: 431 | AV31: 6 | AW31: 0 | AX31: 0 | AY31: 0 | AZ31: 0 | BA31: 0.1 | BB31: 0.03 | BC31: 0 | BD31: 0.672 | BF31: 0 | BG31: 0 | BH31: 0 | BI31: 0 | BL31: 0 | BM31: 0 | BR31: 0 | BU31: 0 | BY31: 0.02 | BZ31: 0.17 | CA31: 0 | CB31: 0.05 | CC31: 0 | CD31: 0 | CE31: 0 | CH31: 8 | CO31: 0 | CP31: 0 | CQ31: 0.294 | CR31: 0.258 | CS31: 0.322 | CU31: 0 | CV31: 0 | CW31: 0 | CX31: 0 | CY31: 0 | CZ31: 0 | DA31: 0 | DB31: 0.277 | DC31: 0.017 | DD31: 0 | DE31: 0.258 | DF31: 0.305 | DG31: 0.017 | DH31: 0 | DI31: 0 | DJ31: 0 | DK31: 0 | DL31: 0 | DM31: 0 | DN31: 0 | DO31: 0 | DP31: 0 | DQ31: 0 | DV31: 0 | DW31: 0 | DX31: 0 | FT31: 0.103 | FU31: 0.271 | FV31: 0.339 | FW31: 0.656 | FX31: 0.215 | FY31: 0.183 | FZ31: 0.398 | GA31: 0.216 | GB31: 0.47 | GC31: 0.651 | GD31: 0.185 | GE31: 0.433 | GF31: 0.795 | GG31: 1.4 | GH31: 0.358 | GI31: 0.484 | GJ31: 0.366 | GL31: 0.153 | HF31: 0 | HH31: 0
A32: 169758 | B32: Rice, white, long-grain, parboiled, unenriched, dry | D32: SR Legacy | E32: 95.734487 | F32: =E32/SUM($E$3:$E$33) -> 0.034306098 | G32: 9.86 | H32: 362.91 | I32: 7.51 | J32: 1.03 | K32: 1.03 | L32: 0.71 | M32: 80.9 | N32: 1.8 | R32: 0.33 | S32: 0.21 | T32: 0.11 | U32: 0.02 | V32: 0 | W32: 0 | X32: 0 | Y32: 68.3 | AB32: 71 | AC32: 0.74 | AD32: 27 | AE32: 153 | AF32: 174 | AG32: 2 | AH32: 1.02 | AI32: 0.284 | AJ32: 1.04 | AL32: 19.9 | AO32: 0.224 | AP32: 0.05 | AQ32: 5.05 | AR32: 0.452 | AS32: 8 | AT32: 0 | AU32: 8 | AW32: 0 | AY32: 0 | AZ32: 0 | BA32: 0.1 | BB32: 0.03 | BC32: 0 | BD32: 0.672 | BH32: 0 | BM32: 0 | BY32: 0.02 | BZ32: 0.17 | CA32: 0 | CB32: 0.05 | CC32: 0 | CD32: 0 | CE32: 0 | CH32: 8 | CO32: 0 | CP32: 0 | CQ32: 0.294 | CR32: 0.258 | CS32: 0.322 | CU32: 0 | CV32: 0 | CW32: 0 | CX32: 0 | CY32: 0 | CZ32: 0 | DA32: 0 | DB32: 0.277 | DC32: 0.017 | DD32: 0 | DE32: 0.258 | DF32: 0.305 | DG32: 0.017 | DH32: 0 | DI32: 0 | DJ32: 0 | DK32: 0 | DL32: 0 | DM32: 0 | DN32: 0 | DO32: 0 | DP32: 0 | DQ32: 0 | DV32: 0 | DW32: 0 | DX32: 0 | FT32: 0.103 | FU32: 0.271 | FV32: 0.339 | FW32: 0.656 | FX32: 0.215 | FY32: 0.183 | FZ32: 0.398 | GA32: 0.216 | GB32: 0.47 | GC32: 0.651 | GD32: 0.185 | GE32: 0.433 | GF32: 0.795 | GG32: 1.4 | GH32: 0.358 | GI32: 0.484 | GJ32: 0.366 | GL32: 0.153 | HF32: 0
A33: 2512381 | B33: Rice, white, long grain, unenriched, raw | D33: Foundation | E33: 95.734487 | F33: =E33/SUM($E$3:$E$33) -> 0.034306098 | G33: 11.2 | H33: 358.63 | I33: 7.04 | J33: 1.03 | K33: 1.03 | L33: 0.425 | M33: 80.3 | N33: 0.149 | O33: 2.77 | P33: 1.93 | Q33: 0.296 | Y33: 74.4 | AB33: 4.46 | AC33: 0.14 | AD33: 26.5 | AE33: 108 | AF33: 82.3 | AG33: 0.462 | AH33: 1.35 | AI33: 0.214 | AJ33: 0.981 | AL33: 6.6 | AM33: 64.2 | AO33: 0.065 | AP33: 0.08 | AQ33: 1.43 | AR33: 0.0579 | BE33: 0
A34: Total | B34: Formulado | C34: Formulado | D34: Formulado | E34: =SUBTOTAL(9,E3:E33) -> 2790.5968 | F34: 100% | G34: =SUMPRODUCT($F$3:$F$33,$G$3:$G$33) -> 63.294549 | H34: =SUMPRODUCT($F$3:$F$33,$H$3:$H$33) -> 190.44781 | I34: =SUMPRODUCT($F$3:$F$33,$I$3:$I$33) -> 4.4216016 | J34: =SUMPRODUCT($F$3:$F$33,$J$3:$J$33) -> 9.4123697 | K34: =SUMPRODUCT($F$3:$F$33,$K$3:$K$33) -> 9.5462511 | L34: =SUMPRODUCT($F$3:$F$33,$L$3:$L$33) -> 0.87985355 | M34: =SUMPRODUCT($F$3:$F$33,$M$3:$M$33) -> 21.711286 | N34: =SUMPRODUCT($F$3:$F$33,$N$3:$N$33) -> 1.0823737 | O34: =SUMPRODUCT($F$3:$F$33,$O$3:$O$33) -> 0.095027891 | P34: =SUMPRODUCT($F$3:$F$33,$P$3:$P$33) -> 0.066210769 | Q34: =SUMPRODUCT($F$3:$F$33,$Q$3:$Q$33) -> 0.010154605 | R34: =SUMPRODUCT($F$3:$F$33,$R$3:$R$33) -> 4.4343885 | S34: =SUMPRODUCT($F$3:$F$33,$S$3:$S$33) -> 0.41626631 | T34: =SUMPRODUCT($F$3:$F$33,$T$3:$T$33) -> 0.20313604 | U34: =SUMPRODUCT($F$3:$F$33,$U$3:$U$33) -> 0.16192196 | V34: =SUMPRODUCT($F$3:$F$33,$V$3:$V$33) -> 0.85730938 | W34: =SUMPRODUCT($F$3:$F$33,$W$3:$W$33) -> 0.053174452 | X34: =SUMPRODUCT($F$3:$F$33,$X$3:$X$33) -> 0.014717316 | Y34: =SUMPRODUCT($F$3:$F$33,$Y$3:$Y$33) -> 7.6560507 | Z34: =SUMPRODUCT($F$3:$F$33,$Z$3:$Z$33) -> 0.1800384 | AA34: =SUMPRODUCT($F$3:$F$33,$AA$3:$AA$33) -> 0.10977951 | AB34: =SUMPRODUCT($F$3:$F$33,$AB$3:$AB$33) -> 104.73149 | AC34: =SUMPRODUCT($F$3:$F$33,$AC$3:$AC$33) -> 1.5221922 | AD34: =SUMPRODUCT($F$3:$F$33,$AD$3:$AD$33) -> 19.67767 | AE34: =SUMPRODUCT($F$3:$F$33,$AE$3:$AE$33) -> 95.692988 | AF34: =SUMPRODUCT($F$3:$F$33,$AF$3:$AF$33) -> 160.1524 | AG34: =SUMPRODUCT($F$3:$F$33,$AG$3:$AG$33) -> 136.94108 | AH34: =SUMPRODUCT($F$3:$F$33,$AH$3:$AH$33) -> 0.58079078 | AI34: =SUMPRODUCT($F$3:$F$33,$AI$3:$AI$33) -> 0.082520103 | AJ34: =SUMPRODUCT($F$3:$F$33,$AJ$3:$AJ$33) -> 0.49253905 | AK34: =SUMPRODUCT($F$3:$F$33,$AK$3:$AK$33) -> 9.4249665 | AL34: =SUMPRODUCT($F$3:$F$33,$AL$3:$AL$33) -> 4.4987729 | AM34: =SUMPRODUCT($F$3:$F$33,$AM$3:$AM$33) -> 7.5885088 | AN34: =SUMPRODUCT($F$3:$F$33,$AN$3:$AN$33) -> 2.6438129 | AO34: =SUMPRODUCT($F$3:$F$33,$AO$3:$AO$33) -> 0.11731525 | AP34: =SUMPRODUCT($F$3:$F$33,$AP$3:$AP$33) -> 0.14951253 | AQ34: =SUMPRODUCT($F$3:$F$33,$AQ$3:$AQ$33) -> 1.0645482 | AR34: =SUMPRODUCT($F$3:$F$33,$AR$3:$AR$33) -> 0.073054022 | AS34: =SUMPRODUCT($F$3:$F$33,$AS$3:$AS$33) -> 21.408076 | AT34: =SUMPRODUCT($F$3:$F$33,$AT$3:$AT$33) -> 10.531972 | AU34: =SUMPRODUCT($F$3:$F$33,$AU$3:$AU$33) -> 21.389373 | AV34: =SUMPRODUCT($F$3:$F$33,$AV$3:$AV$33) -> 22.499258 | AW34: =SUMPRODUCT($F$3:$F$33,$AW$3:$AW$33) -> 0.28831428 | AX34: =SUMPRODUCT($F$3:$F$33,$AX$3:$AX$33) -> 27.542484 | AY34: =SUMPRODUCT($F$3:$F$33,$AY$3:$AY$33) -> 14.279242 | AZ34: =SUMPRODUCT($F$3:$F$33,$AZ$3:$AZ$33) -> 0.64606651 | BA34: =SUMPRODUCT($F$3:$F$33,$BA$3:$BA$33) -> 5.154313 | BB34: =SUMPRODUCT($F$3:$F$33,$BB$3:$BB$33) -> 1.1586178 | BC34: =SUMPRODUCT($F$3:$F$33,$BC$3:$BC$33) -> 6.2977245 | BD34: =SUMPRODUCT($F$3:$F$33,$BD$3:$BD$33) -> 0.15998079 | BE34: =SUMPRODUCT($F$3:$F$33,$BE$3:$BE$33) -> 0.33668004 | BF34: =SUMPRODUCT($F$3:$F$33,$BF$3:$BF$33) -> 0.17153049 | BG34: =SUMPRODUCT($F$3:$F$33,$BG$3:$BG$33) -> 6.312322 | BH34: =SUMPRODUCT($F$3:$F$33,$BH$3:$BH$33) -> 40.037384 | BI34: =SUMPRODUCT($F$3:$F$33,$BI$3:$BI$33) -> 3.4445424 | BJ34: =SUMPRODUCT($F$3:$F$33,$BJ$3:$BJ$33) -> 0.13722439 | BK34: =SUMPRODUCT($F$3:$F$33,$BK$3:$BK$33) -> 0.30875488 | BL34: =SUMPRODUCT($F$3:$F$33,$BL$3:$BL$33) -> 0.28866318 | BM34: =SUMPRODUCT($F$3:$F$33,$BM$3:$BM$33) -> 25.800807 | BN34: =SUMPRODUCT($F$3:$F$33,$BN$3:$BN$33) -> 0.32549626 | BO34: =SUMPRODUCT($F$3:$F$33,$BO$3:$BO$33) -> 0.3205013 | BP34: =SUMPRODUCT($F$3:$F$33,$BP$3:$BP$33) -> 0 | BQ34: =SUMPRODUCT($F$3:$F$33,$BQ$3:$BQ$33) -> 0 | BR34: =SUMPRODUCT($F$3:$F$33,$BR$3:$BR$33) -> 0.21321604 | BS34: =SUMPRODUCT($F$3:$F$33,$BS$3:$BS$33) -> 0 | BT34: =SUMPRODUCT($F$3:$F$33,$BT$3:$BT$33) -> 0 | BU34: =SUMPRODUCT($F$3:$F$33,$BU$3:$BU$33) -> 11.739669 | BV34: =SUMPRODUCT($F$3:$F$33,$BV$3:$BV$33) -> 12.568783 | BW34: =SUMPRODUCT($F$3:$F$33,$BW$3:$BW$33) -> 12.592563 | BX34: =SUMPRODUCT($F$3:$F$33,$BX$3:$BX$33) -> 3.0970004 | BY34: =SUMPRODUCT($F$3:$F$33,$BY$3:$BY$33) -> 0.0049597927 | BZ34: =SUMPRODUCT($F$3:$F$33,$BZ$3:$BZ$33) -> 1.6949094 | CA34: =SUMPRODUCT($F$3:$F$33,$CA$3:$CA$33) -> 0.12091598 | CB34: =SUMPRODUCT($F$3:$F$33,$CB$3:$CB$33) -> 0.0049306098 | CC34: =SUMPRODUCT($F$3:$F$33,$CC$3:$CC$33) -> 0.0027444878 | CD34: =SUMPRODUCT($F$3:$F$33,$CD$3:$CD$33) -> 0 | CE34: =SUMPRODUCT($F$3:$F$33,$CE$3:$CE$33) -> 0.0005 | CF34: =SUMPRODUCT($F$3:$F$33,$CF$3:$CF$33) -> 0.30189366 | CG34: =SUMPRODUCT($F$3:$F$33,$CG$3:$CG$33) -> 0 | CH34: =SUMPRODUCT($F$3:$F$33,$CH$3:$CH$33) -> 3.4815901 | CI34: =SUMPRODUCT($F$3:$F$33,$CI$3:$CI$33) -> 0.45078556 | CJ34: =SUMPRODUCT($F$3:$F$33,$CJ$3:$CJ$33) -> 16.750005 | CK34: =SUMPRODUCT($F$3:$F$33,$CK$3:$CK$33) -> 0.26804612 | CL34: =SUMPRODUCT($F$3:$F$33,$CL$3:$CL$33) -> 1.5099269 | CM34: =SUMPRODUCT($F$3:$F$33,$CM$3:$CM$33) -> 0.20192492 | CN34: =SUMPRODUCT($F$3:$F$33,$CN$3:$CN$33) -> 1.49669 | CO34: =SUMPRODUCT($F$3:$F$33,$CO$3:$CO$33) -> 0 | CP34: =SUMPRODUCT($F$3:$F$33,$CP$3:$CP$33) -> 0 | CQ34: =SUMPRODUCT($F$3:$F$33,$CQ$3:$CQ$33) -> 1.9037061 | CR34: =SUMPRODUCT($F$3:$F$33,$CR$3:$CR$33) -> 4.083667 | CS34: =SUMPRODUCT($F$3:$F$33,$CS$3:$CS$33) -> 1.8287768 | CT34: =SUMPRODUCT($F$3:$F$33,$CT$3:$CT$33) -> 0.03927017 | CU34: =SUMPRODUCT($F$3:$F$33,$CU$3:$CU$33) -> 27.014973 | CV34: =SUMPRODUCT($F$3:$F$33,$CV$3:$CV$33) -> 0.029526915 | CW34: =SUMPRODUCT($F$3:$F$33,$CW$3:$CW$33) -> 0.024151493 | CX34: =SUMPRODUCT($F$3:$F$33,$CX$3:$CX$33) -> 0.0090568098 | CY34: =SUMPRODUCT($F$3:$F$33,$CY$3:$CY$33) -> 0.035206393 | CZ34: =SUMPRODUCT($F$3:$F$33,$CZ$3:$CZ$33) -> 0.041424134 | DA34: =SUMPRODUCT($F$3:$F$33,$DA$3:$DA$33) -> 0.13677182 | DB34: =SUMPRODUCT($F$3:$F$33,$DB$3:$DB$33) -> 0.92479128 | DC34: =SUMPRODUCT($F$3:$F$33,$DC$3:$DC$33) -> 0.31656697 | DD34: =SUMPRODUCT($F$3:$F$33,$DD$3:$DD$33) -> 0.033917528 | DE34: =SUMPRODUCT($F$3:$F$33,$DE$3:$DE$33) -> 3.4488823 | DF34: =SUMPRODUCT($F$3:$F$33,$DF$3:$DF$33) -> 1.0921724 | DG34: =SUMPRODUCT($F$3:$F$33,$DG$3:$DG$33) -> 0.47211382 | DH34: =SUMPRODUCT($F$3:$F$33,$DH$3:$DH$33) -> 0.00092626464 | DI34: =SUMPRODUCT($F$3:$F$33,$DI$3:$DI$33) -> 0 | DJ34: =SUMPRODUCT($F$3:$F$33,$DJ$3:$DJ$33) -> 0.017565204 | DK34: =SUMPRODUCT($F$3:$F$33,$DK$3:$DK$33) -> 0 | DL34: =SUMPRODUCT($F$3:$F$33,$DL$3:$DL$33) -> 0.012257989 | DM34: =SUMPRODUCT($F$3:$F$33,$DM$3:$DM$33) -> 3.4306098e-05 | DN34: =SUMPRODUCT($F$3:$F$33,$DN$3:$DN$33) -> 0.070116732 | DO34: =SUMPRODUCT($F$3:$F$33,$DO$3:$DO$33) -> 0.00020583659 | DP34: =SUMPRODUCT($F$3:$F$33,$DP$3:$DP$33) -> 0.00010291829 | DQ34: =SUMPRODUCT($F$3:$F$33,$DQ$3:$DQ$33) -> 0.00034306098 | DR34: =SUMPRODUCT($F$3:$F$33,$DR$3:$DR$33) -> 0 | DS34: =SUMPRODUCT($F$3:$F$33,$DS$3:$DS$33) -> 0 | DT34: =SUMPRODUCT($F$3:$F$33,$DT$3:$DT$33) -> 0 | DU34: =SUMPRODUCT($F$3:$F$33,$DU$3:$DU$33) -> 6.8612196e-05 | DV34: =SUMPRODUCT($F$3:$F$33,$DV$3:$DV$33) -> 0.0062313596 | DW34: =SUMPRODUCT($F$3:$F$33,$DW$3:$DW$33) -> 0.0057128331 | DX34: =SUMPRODUCT($F$3:$F$33,$DX$3:$DX$33) -> 0.00046347538 | DY34: =SUMPRODUCT($F$3:$F$33,$DY$3:$DY$33) -> 0.0016123866 | DZ34: =SUMPRODUCT($F$3:$F$33,$DZ$3:$DZ$33) -> 0.015696275 | EA34: =SUMPRODUCT($F$3:$F$33,$EA$3:$EA$33) -> 0 | EB34: =SUMPRODUCT($F$3:$F$33,$EB$3:$EB$33) -> 0.0034390148 | EC34: =SUMPRODUCT($F$3:$F$33,$EC$3:$EC$33) -> 0.01825 | ED34: =SUMPRODUCT($F$3:$F$33,$ED$3:$ED$33) -> 0.0025043451 | EE34: =SUMPRODUCT($F$3:$F$33,$EE$3:$EE$33) -> 0 | EF34: =SUMPRODUCT($F$3:$F$33,$EF$3:$EF$33) -> 8.7892222e-05 | EG34: =SUMPRODUCT($F$3:$F$33,$EG$3:$EG$33) -> 0.031892882 | EH34: =SUMPRODUCT($F$3:$F$33,$EH$3:$EH$33) -> 3.5860344 | EI34: =SUMPRODUCT($F$3:$F$33,$EI$3:$EI$33) -> 1.1680698 | EJ34: =SUMPRODUCT($F$3:$F$33,$EJ$3:$EJ$33) -> 6.8612196e-05 | EK34: =SUMPRODUCT($F$3:$F$33,$EK$3:$EK$33) -> 6.8612196e-05 | EL34: =SUMPRODUCT($F$3:$F$33,$EL$3:$EL$33) -> 0 | EM34: =SUMPRODUCT($F$3:$F$33,$EM$3:$EM$33) -> 4.2882622e-05 | EN34: =SUMPRODUCT($F$3:$F$33,$EN$3:$EN$33) -> 0 | EO34: =SUMPRODUCT($F$3:$F$33,$EO$3:$EO$33) -> 0 | EP34: =SUMPRODUCT($F$3:$F$33,$EP$3:$EP$33) -> 0.00062557747 | EQ34: =SUMPRODUCT($F$3:$F$33,$EQ$3:$EQ$33) -> 0.0011406778 | ER34: =SUMPRODUCT($F$3:$F$33,$ER$3:$ER$33) -> 0 | ES34: =SUMPRODUCT($F$3:$F$33,$ES$3:$ES$33) -> 0.017651722 | ET34: =SUMPRODUCT($F$3:$F$33,$ET$3:$ET$33) -> 0.0033963037 | EU34: =SUMPRODUCT($F$3:$F$33,$EU$3:$EU$33) -> 0.018284306 | EV34: =SUMPRODUCT($F$3:$F$33,$EV$3:$EV$33) -> 0 | EW34: =SUMPRODUCT($F$3:$F$33,$EW$3:$EW$33) -> 0 | EX34: =SUMPRODUCT($F$3:$F$33,$EX$3:$EX$33) -> 0 | EY34: =SUMPRODUCT($F$3:$F$33,$EY$3:$EY$33) -> 0 | EZ34: =SUMPRODUCT($F$3:$F$33,$EZ$3:$EZ$33) -> 0.00030875488 | FA34: =SUMPRODUCT($F$3:$F$33,$FA$3:$FA$33) -> 0.0055575878 | FB34: =SUMPRODUCT($F$3:$F$33,$FB$3:$FB$33) -> 0.0011406778 | FC34: =SUMPRODUCT($F$3:$F$33,$FC$3:$FC$33) -> 0.0021504777 | FD34: =SUMPRODUCT($F$3:$F$33,$FD$3:$FD$33) -> 0 | FE34: =SUMPRODUCT($F$3:$F$33,$FE$3:$FE$33) -> 0.22599406 | FF34: =SUMPRODUCT($F$3:$F$33,$FF$3:$FF$33) -> 4.2711092e-05 | FG34: =SUMPRODUCT($F$3:$F$33,$FG$3:$FG$33) -> 0.019927046 | FH34: =SUMPRODUCT($F$3:$F$33,$FH$3:$FH$33) -> 3.4306098e-05 | FI34: =SUMPRODUCT($F$3:$F$33,$FI$3:$FI$33) -> 0.0017268547 | FJ34: =SUMPRODUCT($F$3:$F$33,$FJ$3:$FJ$33) -> 0.00078904025 | FK34: =SUMPRODUCT($F$3:$F$33,$FK$3:$FK$33) -> 0.00020583659 | FL34: =SUMPRODUCT($F$3:$F$33,$FL$3:$FL$33) -> 0.00034306098 | FM34: =SUMPRODUCT($F$3:$F$33,$FM$3:$FM$33) -> 0 | FN34: =SUMPRODUCT($F$3:$F$33,$FN$3:$FN$33) -> 8.7892222e-05 | FO34: =SUMPRODUCT($F$3:$F$33,$FO$3:$FO$33) -> 0.47645783 | FP34: =SUMPRODUCT($F$3:$F$33,$FP$3:$FP$33) -> 0 | FQ34: =SUMPRODUCT($F$3:$F$33,$FQ$3:$FQ$33) -> 0.0017268547 | FR34: =SUMPRODUCT($F$3:$F$33,$FR$3:$FR$33) -> 0.00013722439 | FS34: =SUMPRODUCT($F$3:$F$33,$FS$3:$FS$33) -> 0 | FT34: =SUMPRODUCT($F$3:$F$33,$FT$3:$FT$33) -> 0.032552955 | FU34: =SUMPRODUCT($F$3:$F$33,$FU$3:$FU$33) -> 0.10249116 | FV34: =SUMPRODUCT($F$3:$F$33,$FV$3:$FV$33) -> 0.11152443 | FW34: =SUMPRODUCT($F$3:$F$33,$FW$3:$FW$33) -> 0.20866352 | FX34: =SUMPRODUCT($F$3:$F$33,$FX$3:$FX$33) -> 0.14973549 | FY34: =SUMPRODUCT($F$3:$F$33,$FY$3:$FY$33) -> 0.060468098 | FZ34: =SUMPRODUCT($F$3:$F$33,$FZ$3:$FZ$33) -> 0.11769063 | GA34: =SUMPRODUCT($F$3:$F$33,$GA$3:$GA$33) -> 0.090964987 | GB34: =SUMPRODUCT($F$3:$F$33,$GB$3:$GB$33) -> 0.13269146 | GC34: =SUMPRODUCT($F$3:$F$33,$GC$3:$GC$33) -> 0.14003332 | GD34: =SUMPRODUCT($F$3:$F$33,$GD$3:$GD$33) -> 0.060025095 | GE34: =SUMPRODUCT($F$3:$F$33,$GE$3:$GE$33) -> 0.10954481 | GF34: =SUMPRODUCT($F$3:$F$33,$GF$3:$GF$33) -> 0.2338427 | GG34: =SUMPRODUCT($F$3:$F$33,$GG$3:$GG$33) -> 0.41620997 | GH34: =SUMPRODUCT($F$3:$F$33,$GH$3:$GH$33) -> 0.078398505 | GI34: =SUMPRODUCT($F$3:$F$33,$GI$3:$GI$33) -> 0.15923983 | GJ34: =SUMPRODUCT($F$3:$F$33,$GJ$3:$GJ$33) -> 0.13536899 | GK34: =SUMPRODUCT($F$3:$F$33,$GK$3:$GK$33) -> 0 | GL34: =SUMPRODUCT($F$3:$F$33,$GL$3:$GL$33) -> 0.048769982 | GM34: =SUMPRODUCT($F$3:$F$33,$GM$3:$GM$33) -> 0.36957447 | GN34: =SUMPRODUCT($F$3:$F$33,$GN$3:$GN$33) -> 20.912442 | GO34: =SUMPRODUCT($F$3:$F$33,$GO$3:$GO$33) -> 12.149488 | GP34: =SUMPRODUCT($F$3:$F$33,$GP$3:$GP$33) -> 0.24502789 | GQ34: =SUMPRODUCT($F$3:$F$33,$GQ$3:$GQ$33) -> 0 | GR34: =SUMPRODUCT($F$3:$F$33,$GR$3:$GR$33) -> 0.018010701 | GS34: =SUMPRODUCT($F$3:$F$33,$GS$3:$GS$33) -> 0.035678342 | GT34: =SUMPRODUCT($F$3:$F$33,$GT$3:$GT$33) -> 50.189821 | GU34: =SUMPRODUCT($F$3:$F$33,$GU$3:$GU$33) -> 11.012257 | GV34: =SUMPRODUCT($F$3:$F$33,$GV$3:$GV$33) -> 0 | GW34: =SUMPRODUCT($F$3:$F$33,$GW$3:$GW$33) -> 0.421965 | GX34: =SUMPRODUCT($F$3:$F$33,$GX$3:$GX$33) -> 0.00089881976 | GY34: =SUMPRODUCT($F$3:$F$33,$GY$3:$GY$33) -> 0.0025516876 | GZ34: =SUMPRODUCT($F$3:$F$33,$GZ$3:$GZ$33) -> 0.015146142 | HA34: =SUMPRODUCT($F$3:$F$33,$HA$3:$HA$33) -> 0.7156252 | HB34: =SUMPRODUCT($F$3:$F$33,$HB$3:$HB$33) -> 1.1492543 | HC34: =SUMPRODUCT($F$3:$F$33,$HC$3:$HC$33) -> 0.059143713 | HD34: =SUMPRODUCT($F$3:$F$33,$HD$3:$HD$33) -> 0.020446434 | HE34: =SUMPRODUCT($F$3:$F$33,$HE$3:$HE$33) -> 0.021132556 | HF34: =SUMPRODUCT($F$3:$F$33,$HF$3:$HF$33) -> 0 | HG34: =SUMPRODUCT($F$3:$F$33,$HG$3:$HG$33) -> 0.030101088 | HH34: =SUMPRODUCT($F$3:$F$33,$HH$3:$HH$33) -> 5.7915125 | HI34: =SUMPRODUCT($F$3:$F$33,$HI$3:$HI$33) -> 0.69877525 | HJ34: =SUMPRODUCT($F$3:$F$33,$HJ$3:$HJ$33) -> 0.0036879055 | HK34: =SUMPRODUCT($F$3:$F$33,$HK$3:$HK$33) -> 0.0096400135

Sheet Totales
A1: Nutriente | B1: Total | C1: Unidad
A2: Water | B2: =Ingredientes!G34 -> 63.294549 | C2: g
A3: Energy | B3: =Ingredientes!H34 -> 190.44781 | C3: kcal
A4: Protein | B4: =Ingredientes!I34 -> 4.4216016 | C4: g
A5: Total fat (NLEA) | B5: =Ingredientes!J34 -> 9.4123697 | C5: g
A6: Total lipid (fat) | B6: =Ingredientes!K34 -> 9.5462511 | C6: g
A7: Ash | B7: =Ingredientes!L34 -> 0.87985355 | C7: g
A8: Carbohydrate, by difference | B8: =Ingredientes!M34 -> 21.711286 | C8: g
A9: Fiber, total dietary | B9: =Ingredientes!N34 -> 1.0823737 | C9: g
A10: Total dietary fiber (AOAC 2011.25) | B10: =Ingredientes!O34 -> 0.095027891 | C10: g
A11: High Molecular Weight Dietary Fiber (HMWDF) | B11: =Ingredientes!P34 -> 0.066210769 | C11: g
A12: Low Molecular Weight Dietary Fiber (LMWDF) | B12: =Ingredientes!Q34 -> 0.010154605 | C12: g
A13: Sugars, Total | B13: =Ingredientes!R34 -> 4.4343885 | C13: g
A14: Sucrose | B14: =Ingredientes!S34 -> 0.41626631 | C14: g
A15: Glucose | B15: =Ingredientes!T34 -> 0.20313604 | C15: g
A16: Fructose | B16: =Ingredientes!U34 -> 0.16192196 | C16: g
A17: Lactose | B17: =Ingredientes!V34 -> 0.85730938 | C17: g
A18: Maltose | B18: =Ingredientes!W34 -> 0.053174452 | C18: g
A19: Galactose | B19: =Ingredientes!X34 -> 0.014717316 | C19: g
A20: Starch | B20: =Ingredientes!Y34 -> 7.6560507 | C20: g
A21: Resistant starch | B21: =Ingredientes!Z34 -> 0.1800384 | C21: g
A22: Sugars, added | B22: =Ingredientes!AA34 -> 0.10977951 | C22: g
A23: Calcium, Ca | B23: =Ingredientes!AB34 -> 104.73149 | C23: mg
A24: Iron, Fe | B24: =Ingredientes!AC34 -> 1.5221922 | C24: mg
A25: Magnesium, Mg | B25: =Ingredientes!AD34 -> 19.67767 | C25: mg
A26: Phosphorus, P | B26: =Ingredientes!AE34 -> 95.692988 | C26: mg
A27: Potassium, K | B27: =Ingredientes!AF34 -> 160.1524 | C27: mg
A28: Sodium, Na | B28: =Ingredientes!AG34 -> 136.94108 | C28: mg
A29: Zinc, Zn | B29: =Ingredientes!AH34 -> 0.58079078 | C29: mg
A30: Copper, Cu | B30: =Ingredientes!AI34 -> 0.082520103 | C30: mg
A31: Manganese, Mn | B31: =Ingredientes!AJ34 -> 0.49253905 | C31: mg
A32: Iodine, I | B32: =Ingredientes!AK34 -> 9.4249665 | C32: μg
A33: Selenium, Se | B33: =Ingredientes!AL34 -> 4.4987729 | C33: μg
A34: Molybdenum, Mo | B34: =Ingredientes!AM34 -> 7.5885088 | C34: μg
A35: Fluoride, F | B35: =Ingredientes!AN34 -> 2.6438129 | C35: μg
A36: Thiamin | B36: =Ingredientes!AO34 -> 0.11731525 | C36: mg
A37: Riboflavin | B37: =Ingredientes!AP34 -> 0.14951253 | C37: mg
A38: Niacin | B38: =Ingredientes!AQ34 -> 1.0645482 | C38: mg
A39: Vitamin B-6 | B39: =Ingredientes!AR34 -> 0.073054022 | C39: mg
A40: Folate, total | B40: =Ingredientes!AS34 -> 21.408076 | C40: μg
...
